Workbook

Sheet G3 MT Reading Scoresheet
A1: CRLA2v1
A3: ASSESSMENT TYPE | C3: EoSY
A4: School ID: | C4: 117443 | D4: Total Enrolment | F4: =D6+E6 -> 25 | G4: Total Assessed : | I4: =COUNTIF(F11:F110,"<>") -> 25
A5: Schoo Name: | C5: ROMANA ELEM. SCHOOL | D5: Male | E5: Female | F5: Assessment Part 1 (Word Recognition and Sentences Reading) | J5: WORDS SCORE 0 to 10 – Full Refresher 11 to 16 – Moderate Refresher SENTENCE SCORE 17 to 26 – Light Refresher 27 to 30 – Grade Ready | K5: Assessment Part 2 (Reading Fluency and Comprehension)
A6: Teacher: | C6: KEMBERLY G. BELMIS | D6: 10 | E6: 15
A7: Grade: | C7: Grade 3 | D7: Total Words per Story | F7: Task 1 – Write the number of Words sounded out correctly | G7: Rhymes (Task 2) If task 1 score is 0 to 6 | H7: Sentence (Task 2) If task 1 score is 7 to 10 Task 2L=10 | I7: Total Score = Task 1 Score + Task 2L+Task 2H Score | K7: Total Words Per Story | L7: Story 1 | M7: =_xlfn.IFNA(IF(X9=1,Y9,IF(D9>0,D9,120)),"") -> 121 | N7: Story 2 | P7: =_xlfn.IFNA(IF(X9=1,Z9,IF(E9>0,E9,120)),"") -> 119
A8: Section: | C8: 1 | D8: Story 1 | E8: Story 2 | K8: Story Number 1 or 2 | L8: Total Reading Miscues | M8: Number of words read within 3 mins | N8: Total Time Used in Reading (Max : 3 Mins) | P8: Number of Words per Minute (WPM)
A9: Language: | C9: Hiligaynon | X9: =IF(_xlfn.IFNA(VLOOKUP($C$9,List!$G$2:$M$21,1,0),"")=C9,1,0) -> 1 | Y9: =VLOOKUP($C$9,List!$G$2:$M$21,4,0) -> 121 | Z9: =VLOOKUP($C$9,List!$G$2:$M$21,7,0) -> 119
A10: S/N | B10: LRN | C10: Name of Learner | D10: Sex | E10: Date of Asessment | F10: Task 1 (10) | G10: Task 2L Words (10) | H10: Task 2H Sentences (10) | I10: Total Score | J10: Part 1 Reading Level | K10: Story Number | L10: Number of Miscue | M10: Words Read | N10: Total Mins Secs | P10: WPM | Q10: % of Correct Words Read | R10: Total Correct Answer | S10: Leaner Experience (Rating 1-5) | T10: Observation Level | U10: READING PROFILE | V10: Remarks
A11: 1 | B11: 117443220001 | C11: ABAY, KENNETH ALEXANDER, NALAONAN | D11: Male | E11: 06/23/2025 | F11: 7 | H11: 9 | I11: =IF(AND(F11="",G11=""),"",IF(F11<7,F11+G11,F11+10+H11)) -> 26 | J11: =IF(I11="","",IF(F11<7,IF(I11<=10,"Full Refresher","Moderate Refresher"),IF(I11<27,"Light Refresher","Grade Ready"))) -> Light Refresher | K11: 1 | L11: 2 | M11: =IF($C$9<>"",IF(OR(K11=1,K11=2),IF(K11=1,M$7-L11,$P$7-L11),""),"") -> 119 | N11: 3 | O11: 0 | P11: =IFERROR(IF(AND(K11>0,M11>0,OR(N11>0,O11>0)),(M11/((N11*60)+O11))*60,""),"") -> 39.666667 | Q11: =IFERROR(IF(OR(K11=1,K11=2),IF(K11=1,M11/$M$7,M11/$P$7),""),"") -> 0.98347107 | R11: 5 | S11: 5 | T11: Level 2 | U11: =IF(J11<>"",IF(J11="Full Refresher","Low Emerging Reader",IF(AND(K11>0,Q11<>""),IF(OR(Q11<=25%,AND(Q11>25%,Q11<=50%,R11<=1)),"High Emerging Reader",IF(OR(AND(Q11>25%,Q11<51%,R11>=2),AND(Q11>50%,Q11<76%,R11<=3)),"Developing Reader",IF(OR(AND(Q11>=51%,Q11<76%,R11>=4),AND(Q11>75%,R11<=5)),"Transitioning Reader",IF(AND(Q11>75%,R11>=6),"Reading At Grade Level","")))),"")),"") -> Transitioning Reader
A12: 2 | B12: 11744322002 | C12: BANARAIA, KEEPER, ABAY | D12: Male | E12: 06/23/2025 | F12: 5 | G12: 6 | H12: 8 | I12: =IF(AND(F12="",G12=""),"",IF(F12<7,F12+G12,F12+10+H12)) -> 11 | J12: =IF(I12="","",IF(F12<7,IF(I12<=10,"Full Refresher","Moderate Refresher"),IF(I12<27,"Light Refresher","Grade Ready"))) -> Moderate Refresher | K12: 1 | M12: =IF($C$9<>"",IF(OR(K12=1,K12=2),IF(K12=1,M$7-L12,$P$7-L12),""),"") -> 121 | N12: 2 | O12: 46 | P12: =IFERROR(IF(AND(K12>0,M12>0,OR(N12>0,O12>0)),(M12/((N12*60)+O12))*60,""),"") -> 43.73494 | Q12: =IFERROR(IF(OR(K12=1,K12=2),IF(K12=1,M12/$M$7,M12/$P$7),""),"") -> 1 | R12: 6 | S12: 5 | T12: Level 2 | U12: =IF(J12<>"",IF(J12="Full Refresher","Low Emerging Reader",IF(AND(K12>0,Q12<>""),IF(OR(Q12<=25%,AND(Q12>25%,Q12<=50%,R12<=1)),"High Emerging Reader",IF(OR(AND(Q12>25%,Q12<51%,R12>=2),AND(Q12>50%,Q12<76%,R12<=3)),"Developing Reader",IF(OR(AND(Q12>=51%,Q12<76%,R12>=4),AND(Q12>75%,R12<=5)),"Transitioning Reader",IF(AND(Q12>75%,R12>=6),"Reading At Grade Level","")))),"")),"") -> Reading At Grade Level
A13: 3 | B13: 117443220017 | C13: BARGASA, EDSEL JHON,- | D13: Male | E13: 06/23/2025 | F13: 8 | H13: 8 | I13: =IF(AND(F13="",G13=""),"",IF(F13<7,F13+G13,F13+10+H13)) -> 26 | J13: =IF(I13="","",IF(F13<7,IF(I13<=10,"Full Refresher","Moderate Refresher"),IF(I13<27,"Light Refresher","Grade Ready"))) -> Light Refresher | K13: 1 | L13: 5 | M13: =IF($C$9<>"",IF(OR(K13=1,K13=2),IF(K13=1,M$7-L13,$P$7-L13),""),"") -> 116 | N13: 1 | O13: 35 | P13: =IFERROR(IF(AND(K13>0,M13>0,OR(N13>0,O13>0)),(M13/((N13*60)+O13))*60,""),"") -> 73.263158 | Q13: =IFERROR(IF(OR(K13=1,K13=2),IF(K13=1,M13/$M$7,M13/$P$7),""),"") -> 0.95867769 | R13: 7 | S13: 5 | T13: Level 4 | U13: =IF(J13<>"",IF(J13="Full Refresher","Low Emerging Reader",IF(AND(K13>0,Q13<>""),IF(OR(Q13<=25%,AND(Q13>25%,Q13<=50%,R13<=1)),"High Emerging Reader",IF(OR(AND(Q13>25%,Q13<51%,R13>=2),AND(Q13>50%,Q13<76%,R13<=3)),"Developing Reader",IF(OR(AND(Q13>=51%,Q13<76%,R13>=4),AND(Q13>75%,R13<=5)),"Transitioning Reader",IF(AND(Q13>75%,R13>=6),"Reading At Grade Level","")))),"")),"") -> Reading At Grade Level
A14: 4 | B14: 117443220006 | C14: DUMANIEL, KEVIN JOHN , ALVAREZ | D14: Male | E14: 06/23/2025 | F14: 8 | H14: 8 | I14: =IF(AND(F14="",G14=""),"",IF(F14<7,F14+G14,F14+10+H14)) -> 26 | J14: =IF(I14="","",IF(F14<7,IF(I14<=10,"Full Refresher","Moderate Refresher"),IF(I14<27,"Light Refresher","Grade Ready"))) -> Light Refresher | K14: 1 | L14: 7 | M14: =IF($C$9<>"",IF(OR(K14=1,K14=2),IF(K14=1,M$7-L14,$P$7-L14),""),"") -> 114 | N14: 3 | O14: 0 | P14: =IFERROR(IF(AND(K14>0,M14>0,OR(N14>0,O14>0)),(M14/((N14*60)+O14))*60,""),"") -> 38 | Q14: =IFERROR(IF(OR(K14=1,K14=2),IF(K14=1,M14/$M$7,M14/$P$7),""),"") -> 0.94214876 | R14: 3 | S14: 4 | T14: Level 1 | U14: =IF(J14<>"",IF(J14="Full Refresher","Low Emerging Reader",IF(AND(K14>0,Q14<>""),IF(OR(Q14<=25%,AND(Q14>25%,Q14<=50%,R14<=1)),"High Emerging Reader",IF(OR(AND(Q14>25%,Q14<51%,R14>=2),AND(Q14>50%,Q14<76%,R14<=3)),"Developing Reader",IF(OR(AND(Q14>=51%,Q14<76%,R14>=4),AND(Q14>75%,R14<=5)),"Transitioning Reader",IF(AND(Q14>75%,R14>=6),"Reading At Grade Level","")))),"")),"") -> Transitioning Reader
A15: 5 | B15: 117443220018 | C15: ESTOCADA, JOEMARIE III, OMPAD | D15: Male | E15: 06/24/2025 | F15: 8 | H15: 8 | I15: =IF(AND(F15="",G15=""),"",IF(F15<7,F15+G15,F15+10+H15)) -> 26 | J15: =IF(I15="","",IF(F15<7,IF(I15<=10,"Full Refresher","Moderate Refresher"),IF(I15<27,"Light Refresher","Grade Ready"))) -> Light Refresher | K15: 1 | L15: 5 | M15: =IF($C$9<>"",IF(OR(K15=1,K15=2),IF(K15=1,M$7-L15,$P$7-L15),""),"") -> 116 | N15: 3 | O15: 0 | P15: =IFERROR(IF(AND(K15>0,M15>0,OR(N15>0,O15>0)),(M15/((N15*60)+O15))*60,""),"") -> 38.666667 | Q15: =IFERROR(IF(OR(K15=1,K15=2),IF(K15=1,M15/$M$7,M15/$P$7),""),"") -> 0.95867769 | R15: 3 | S15: 4 | T15: Level 1 | U15: =IF(J15<>"",IF(J15="Full Refresher","Low Emerging Reader",IF(AND(K15>0,Q15<>""),IF(OR(Q15<=25%,AND(Q15>25%,Q15<=50%,R15<=1)),"High Emerging Reader",IF(OR(AND(Q15>25%,Q15<51%,R15>=2),AND(Q15>50%,Q15<76%,R15<=3)),"Developing Reader",IF(OR(AND(Q15>=51%,Q15<76%,R15>=4),AND(Q15>75%,R15<=5)),"Transitioning Reader",IF(AND(Q15>75%,R15>=6),"Reading At Grade Level","")))),"")),"") -> Transitioning Reader
A16: 6 | B16: 117542220012 | C16: GO, NEAL XANDRIE, DOMANIEL | D16: Male | E16: 06/24/2025 | F16: 8 | H16: 8 | I16: =IF(AND(F16="",G16=""),"",IF(F16<7,F16+G16,F16+10+H16)) -> 26 | J16: =IF(I16="","",IF(F16<7,IF(I16<=10,"Full Refresher","Moderate Refresher"),IF(I16<27,"Light Refresher","Grade Ready"))) -> Light Refresher | K16: 1 | L16: 5 | M16: =IF($C$9<>"",IF(OR(K16=1,K16=2),IF(K16=1,M$7-L16,$P$7-L16),""),"") -> 116 | N16: 3 | O16: 0 | P16: =IFERROR(IF(AND(K16>0,M16>0,OR(N16>0,O16>0)),(M16/((N16*60)+O16))*60,""),"") -> 38.666667 | Q16: =IFERROR(IF(OR(K16=1,K16=2),IF(K16=1,M16/$M$7,M16/$P$7),""),"") -> 0.95867769 | R16: 6 | S16: 4 | T16: Level 2 | U16: =IF(J16<>"",IF(J16="Full Refresher","Low Emerging Reader",IF(AND(K16>0,Q16<>""),IF(OR(Q16<=25%,AND(Q16>25%,Q16<=50%,R16<=1)),"High Emerging Reader",IF(OR(AND(Q16>25%,Q16<51%,R16>=2),AND(Q16>50%,Q16<76%,R16<=3)),"Developing Reader",IF(OR(AND(Q16>=51%,Q16<76%,R16>=4),AND(Q16>75%,R16<=5)),"Transitioning Reader",IF(AND(Q16>75%,R16>=6),"Reading At Grade Level","")))),"")),"") -> Reading At Grade Level
A17: 7 | B17: 1174432290003 | C17: GREGORIO, JOHN MARK, ABELLAR | D17: Male | E17: 06/24/2025 | F17: 4 | G17: 1 | H17: 5 | I17: =IF(AND(F17="",G17=""),"",IF(F17<7,F17+G17,F17+10+H17)) -> 5 | J17: =IF(I17="","",IF(F17<7,IF(I17<=10,"Full Refresher","Moderate Refresher"),IF(I17<27,"Light Refresher","Grade Ready"))) -> Full Refresher | K17: 2 | L17: 56 | M17: =IF($C$9<>"",IF(OR(K17=1,K17=2),IF(K17=1,M$7-L17,$P$7-L17),""),"") -> 63 | N17: 3 | O17: 0 | P17: =IFERROR(IF(AND(K17>0,M17>0,OR(N17>0,O17>0)),(M17/((N17*60)+O17))*60,""),"") -> 21 | Q17: =IFERROR(IF(OR(K17=1,K17=2),IF(K17=1,M17/$M$7,M17/$P$7),""),"") -> 0.52941176 | R17: 2 | S17: 2 | T17: Level 1 | U17: =IF(J17<>"",IF(J17="Full Refresher","Low Emerging Reader",IF(AND(K17>0,Q17<>""),IF(OR(Q17<=25%,AND(Q17>25%,Q17<=50%,R17<=1)),"High Emerging Reader",IF(OR(AND(Q17>25%,Q17<51%,R17>=2),AND(Q17>50%,Q17<76%,R17<=3)),"Developing Reader",IF(OR(AND(Q17>=51%,Q17<76%,R17>=4),AND(Q17>75%,R17<=5)),"Transitioning Reader",IF(AND(Q17>75%,R17>=6),"Reading At Grade Level","")))),"")),"") -> Low Emerging Reader
A18: 8 | B18: 117443220005 | C18: JUMBAS, CYREL JAY, BARILLO | D18: Male | E18: 06/24/2025 | F18: 6 | G18: 7 | H18: 8 | I18: =IF(AND(F18="",G18=""),"",IF(F18<7,F18+G18,F18+10+H18)) -> 13 | J18: =IF(I18="","",IF(F18<7,IF(I18<=10,"Full Refresher","Moderate Refresher"),IF(I18<27,"Light Refresher","Grade Ready"))) -> Moderate Refresher | K18: 2 | L18: 10 | M18: =IF($C$9<>"",IF(OR(K18=1,K18=2),IF(K18=1,M$7-L18,$P$7-L18),""),"") -> 109 | N18: 2 | O18: 45 | P18: =IFERROR(IF(AND(K18>0,M18>0,OR(N18>0,O18>0)),(M18/((N18*60)+O18))*60,""),"") -> 39.636364 | Q18: =IFERROR(IF(OR(K18=1,K18=2),IF(K18=1,M18/$M$7,M18/$P$7),""),"") -> 0.91596639 | R18: 6 | S18: 4 | T18: Level 2 | U18: =IF(J18<>"",IF(J18="Full Refresher","Low Emerging Reader",IF(AND(K18>0,Q18<>""),IF(OR(Q18<=25%,AND(Q18>25%,Q18<=50%,R18<=1)),"High Emerging Reader",IF(OR(AND(Q18>25%,Q18<51%,R18>=2),AND(Q18>50%,Q18<76%,R18<=3)),"Developing Reader",IF(OR(AND(Q18>=51%,Q18<76%,R18>=4),AND(Q18>75%,R18<=5)),"Transitioning Reader",IF(AND(Q18>75%,R18>=6),"Reading At Grade Level","")))),"")),"") -> Reading At Grade Level
A19: 9 | B19: 11744322007 | C19: LEMORINAS, ARTHUR, BAYLON | D19: Male | E19: 06/24/2025 | F19: 3 | G19: 2 | H19: 10 | I19: =IF(AND(F19="",G19=""),"",IF(F19<7,F19+G19,F19+10+H19)) -> 5 | J19: =IF(I19="","",IF(F19<7,IF(I19<=10,"Full Refresher","Moderate Refresher"),IF(I19<27,"Light Refresher","Grade Ready"))) -> Full Refresher | K19: 2 | L19: 2 | M19: =IF($C$9<>"",IF(OR(K19=1,K19=2),IF(K19=1,M$7-L19,$P$7-L19),""),"") -> 117 | N19: 2 | O19: 29 | P19: =IFERROR(IF(AND(K19>0,M19>0,OR(N19>0,O19>0)),(M19/((N19*60)+O19))*60,""),"") -> 47.114094 | Q19: =IFERROR(IF(OR(K19=1,K19=2),IF(K19=1,M19/$M$7,M19/$P$7),""),"") -> 0.98319328 | R19: 7 | S19: 5 | T19: Level 1 | U19: =IF(J19<>"",IF(J19="Full Refresher","Low Emerging Reader",IF(AND(K19>0,Q19<>""),IF(OR(Q19<=25%,AND(Q19>25%,Q19<=50%,R19<=1)),"High Emerging Reader",IF(OR(AND(Q19>25%,Q19<51%,R19>=2),AND(Q19>50%,Q19<76%,R19<=3)),"Developing Reader",IF(OR(AND(Q19>=51%,Q19<76%,R19>=4),AND(Q19>75%,R19<=5)),"Transitioning Reader",IF(AND(Q19>75%,R19>=6),"Reading At Grade Level","")))),"")),"") -> Low Emerging Reader
A20: 10 | B20: 117443220008 | C20: MARASIGAN, ZHENKIE NATHAN, DELA CRUZ | D20: Male | E20: 06/24/2025 | F20: 9 | H20: 8 | I20: =IF(AND(F20="",G20=""),"",IF(F20<7,F20+G20,F20+10+H20)) -> 27 | J20: =IF(I20="","",IF(F20<7,IF(I20<=10,"Full Refresher","Moderate Refresher"),IF(I20<27,"Light Refresher","Grade Ready"))) -> Grade Ready | K20: 2 | L20: 1 | M20: =IF($C$9<>"",IF(OR(K20=1,K20=2),IF(K20=1,M$7-L20,$P$7-L20),""),"") -> 118 | N20: 3 | O20: 0 | P20: =IFERROR(IF(AND(K20>0,M20>0,OR(N20>0,O20>0)),(M20/((N20*60)+O20))*60,""),"") -> 39.333333 | Q20: =IFERROR(IF(OR(K20=1,K20=2),IF(K20=1,M20/$M$7,M20/$P$7),""),"") -> 0.99159664 | R20: 6 | S20: 5 | T20: Level 3 | U20: =IF(J20<>"",IF(J20="Full Refresher","Low Emerging Reader",IF(AND(K20>0,Q20<>""),IF(OR(Q20<=25%,AND(Q20>25%,Q20<=50%,R20<=1)),"High Emerging Reader",IF(OR(AND(Q20>25%,Q20<51%,R20>=2),AND(Q20>50%,Q20<76%,R20<=3)),"Developing Reader",IF(OR(AND(Q20>=51%,Q20<76%,R20>=4),AND(Q20>75%,R20<=5)),"Transitioning Reader",IF(AND(Q20>75%,R20>=6),"Reading At Grade Level","")))),"")),"") -> Reading At Grade Level
A21: 11 | B21: 136651220284 | C21: ABRINILLO, VERONICA, SIASAT | D21: Male | E21: 06/24/2025 | F21: 9 | H21: 4 | I21: =IF(AND(F21="",G21=""),"",IF(F21<7,F21+G21,F21+10+H21)) -> 23 | J21: =IF(I21="","",IF(F21<7,IF(I21<=10,"Full Refresher","Moderate Refresher"),IF(I21<27,"Light Refresher","Grade Ready"))) -> Light Refresher | K21: 2 | L21: 68 | M21: =IF($C$9<>"",IF(OR(K21=1,K21=2),IF(K21=1,M$7-L21,$P$7-L21),""),"") -> 51 | N21: 3 | O21: 0 | P21: =IFERROR(IF(AND(K21>0,M21>0,OR(N21>0,O21>0)),(M21/((N21*60)+O21))*60,""),"") -> 17 | Q21: =IFERROR(IF(OR(K21=1,K21=2),IF(K21=1,M21/$M$7,M21/$P$7),""),"") -> 0.42857143 | R21: 2 | S21: 2 | T21: Level 1 | U21: =IF(J21<>"",IF(J21="Full Refresher","Low Emerging Reader",IF(AND(K21>0,Q21<>""),IF(OR(Q21<=25%,AND(Q21>25%,Q21<=50%,R21<=1)),"High Emerging Reader",IF(OR(AND(Q21>25%,Q21<51%,R21>=2),AND(Q21>50%,Q21<76%,R21<=3)),"Developing Reader",IF(OR(AND(Q21>=51%,Q21<76%,R21>=4),AND(Q21>75%,R21<=5)),"Transitioning Reader",IF(AND(Q21>75%,R21>=6),"Reading At Grade Level","")))),"")),"") -> Developing Reader
A22: 12 | B22: 117443220019 | C22: CARDINAL,KISHIA,- | D22: Female | E22: 06/24/2025 | F22: 10 | H22: 8 | I22: =IF(AND(F22="",G22=""),"",IF(F22<7,F22+G22,F22+10+H22)) -> 28 | J22: =IF(I22="","",IF(F22<7,IF(I22<=10,"Full Refresher","Moderate Refresher"),IF(I22<27,"Light Refresher","Grade Ready"))) -> Grade Ready | K22: 2 | L22: 1 | M22: =IF($C$9<>"",IF(OR(K22=1,K22=2),IF(K22=1,M$7-L22,$P$7-L22),""),"") -> 118 | N22: 1 | O22: 32 | P22: =IFERROR(IF(AND(K22>0,M22>0,OR(N22>0,O22>0)),(M22/((N22*60)+O22))*60,""),"") -> 76.956522 | Q22: =IFERROR(IF(OR(K22=1,K22=2),IF(K22=1,M22/$M$7,M22/$P$7),""),"") -> 0.99159664 | R22: 6 | S22: 4 | T22: Level 2 | U22: =IF(J22<>"",IF(J22="Full Refresher","Low Emerging Reader",IF(AND(K22>0,Q22<>""),IF(OR(Q22<=25%,AND(Q22>25%,Q22<=50%,R22<=1)),"High Emerging Reader",IF(OR(AND(Q22>25%,Q22<51%,R22>=2),AND(Q22>50%,Q22<76%,R22<=3)),"Developing Reader",IF(OR(AND(Q22>=51%,Q22<76%,R22>=4),AND(Q22>75%,R22<=5)),"Transitioning Reader",IF(AND(Q22>75%,R22>=6),"Reading At Grade Level","")))),"")),"") -> Reading At Grade Level
A23: 13 | B23: 117443220009 | C23: CARDINAL, LEXIE, SUNDAYON | D23: Female | E23: 45721 | F23: 10 | H23: 7 | I23: =IF(AND(F23="",G23=""),"",IF(F23<7,F23+G23,F23+10+H23)) -> 27 | J23: =IF(I23="","",IF(F23<7,IF(I23<=10,"Full Refresher","Moderate Refresher"),IF(I23<27,"Light Refresher","Grade Ready"))) -> Grade Ready | K23: 2 | L23: 0 | M23: =IF($C$9<>"",IF(OR(K23=1,K23=2),IF(K23=1,M$7-L23,$P$7-L23),""),"") -> 119 | N23: 2 | O23: 3 | P23: =IFERROR(IF(AND(K23>0,M23>0,OR(N23>0,O23>0)),(M23/((N23*60)+O23))*60,""),"") -> 58.04878 | Q23: =IFERROR(IF(OR(K23=1,K23=2),IF(K23=1,M23/$M$7,M23/$P$7),""),"") -> 1 | R23: 7 | S23: 5 | T23: Level 3 | U23: =IF(J23<>"",IF(J23="Full Refresher","Low Emerging Reader",IF(AND(K23>0,Q23<>""),IF(OR(Q23<=25%,AND(Q23>25%,Q23<=50%,R23<=1)),"High Emerging Reader",IF(OR(AND(Q23>25%,Q23<51%,R23>=2),AND(Q23>50%,Q23<76%,R23<=3)),"Developing Reader",IF(OR(AND(Q23>=51%,Q23<76%,R23>=4),AND(Q23>75%,R23<=5)),"Transitioning Reader",IF(AND(Q23>75%,R23>=6),"Reading At Grade Level","")))),"")),"") -> Reading At Grade Level
A24: 14 | C24: DIONSON, AIRA, BAUTISTA | D24: Female | E24: 45721 | F24: 4 | G24: 2 | H24: 10 | I24: =IF(AND(F24="",G24=""),"",IF(F24<7,F24+G24,F24+10+H24)) -> 6 | J24: =IF(I24="","",IF(F24<7,IF(I24<=10,"Full Refresher","Moderate Refresher"),IF(I24<27,"Light Refresher","Grade Ready"))) -> Full Refresher | K24: 1 | L24: 0 | M24: =IF($C$9<>"",IF(OR(K24=1,K24=2),IF(K24=1,M$7-L24,$P$7-L24),""),"") -> 121 | N24: 1 | O24: 35 | P24: =IFERROR(IF(AND(K24>0,M24>0,OR(N24>0,O24>0)),(M24/((N24*60)+O24))*60,""),"") -> 76.421053 | Q24: =IFERROR(IF(OR(K24=1,K24=2),IF(K24=1,M24/$M$7,M24/$P$7),""),"") -> 1 | R24: 7 | S24: 5 | T24: Level 4 | U24: =IF(J24<>"",IF(J24="Full Refresher","Low Emerging Reader",IF(AND(K24>0,Q24<>""),IF(OR(Q24<=25%,AND(Q24>25%,Q24<=50%,R24<=1)),"High Emerging Reader",IF(OR(AND(Q24>25%,Q24<51%,R24>=2),AND(Q24>50%,Q24<76%,R24<=3)),"Developing Reader",IF(OR(AND(Q24>=51%,Q24<76%,R24>=4),AND(Q24>75%,R24<=5)),"Transitioning Reader",IF(AND(Q24>75%,R24>=6),"Reading At Grade Level","")))),"")),"") -> Low Emerging Reader
A25: 15 | C25: ESTOCADA, ANGEL, E. | D25: Female | E25: 45721 | F25: 7 | H25: 6 | I25: =IF(AND(F25="",G25=""),"",IF(F25<7,F25+G25,F25+10+H25)) -> 23 | J25: =IF(I25="","",IF(F25<7,IF(I25<=10,"Full Refresher","Moderate Refresher"),IF(I25<27,"Light Refresher","Grade Ready"))) -> Light Refresher | K25: 1 | L25: 0 | M25: =IF($C$9<>"",IF(OR(K25=1,K25=2),IF(K25=1,M$7-L25,$P$7-L25),""),"") -> 121 | N25: 1 | O25: 30 | P25: =IFERROR(IF(AND(K25>0,M25>0,OR(N25>0,O25>0)),(M25/((N25*60)+O25))*60,""),"") -> 80.666667 | Q25: =IFERROR(IF(OR(K25=1,K25=2),IF(K25=1,M25/$M$7,M25/$P$7),""),"") -> 1 | R25: 7 | S25: 5 | T25: Level 4 | U25: =IF(J25<>"",IF(J25="Full Refresher","Low Emerging Reader",IF(AND(K25>0,Q25<>""),IF(OR(Q25<=25%,AND(Q25>25%,Q25<=50%,R25<=1)),"High Emerging Reader",IF(OR(AND(Q25>25%,Q25<51%,R25>=2),AND(Q25>50%,Q25<76%,R25<=3)),"Developing Reader",IF(OR(AND(Q25>=51%,Q25<76%,R25>=4),AND(Q25>75%,R25<=5)),"Transitioning Reader",IF(AND(Q25>75%,R25>=6),"Reading At Grade Level","")))),"")),"") -> Reading At Grade Level
A26: 16 | B26: 117443220010 | C26: ESTOCADA, GENYZA, BACARO | D26: Female | E26: 45721 | F26: 8 | H26: 8 | I26: =IF(AND(F26="",G26=""),"",IF(F26<7,F26+G26,F26+10+H26)) -> 26 | J26: =IF(I26="","",IF(F26<7,IF(I26<=10,"Full Refresher","Moderate Refresher"),IF(I26<27,"Light Refresher","Grade Ready"))) -> Light Refresher | K26: 2 | L26: 10 | M26: =IF($C$9<>"",IF(OR(K26=1,K26=2),IF(K26=1,M$7-L26,$P$7-L26),""),"") -> 109 | N26: 3 | O26: 0 | P26: =IFERROR(IF(AND(K26>0,M26>0,OR(N26>0,O26>0)),(M26/((N26*60)+O26))*60,""),"") -> 36.333333 | Q26: =IFERROR(IF(OR(K26=1,K26=2),IF(K26=1,M26/$M$7,M26/$P$7),""),"") -> 0.91596639 | R26: 6 | S26: 5 | T26: Level 2 | U26: =IF(J26<>"",IF(J26="Full Refresher","Low Emerging Reader",IF(AND(K26>0,Q26<>""),IF(OR(Q26<=25%,AND(Q26>25%,Q26<=50%,R26<=1)),"High Emerging Reader",IF(OR(AND(Q26>25%,Q26<51%,R26>=2),AND(Q26>50%,Q26<76%,R26<=3)),"Developing Reader",IF(OR(AND(Q26>=51%,Q26<76%,R26>=4),AND(Q26>75%,R26<=5)),"Transitioning Reader",IF(AND(Q26>75%,R26>=6),"Reading At Grade Level","")))),"")),"") -> Reading At Grade Level
A27: 17 | C27: ESTOCADA, JERCEL JANE, SIASAT | D27: Female | E27: 45722 | F27: 10 | H27: 9 | I27: =IF(AND(F27="",G27=""),"",IF(F27<7,F27+G27,F27+10+H27)) -> 29 | J27: =IF(I27="","",IF(F27<7,IF(I27<=10,"Full Refresher","Moderate Refresher"),IF(I27<27,"Light Refresher","Grade Ready"))) -> Grade Ready | K27: 1 | L27: 0 | M27: =IF($C$9<>"",IF(OR(K27=1,K27=2),IF(K27=1,M$7-L27,$P$7-L27),""),"") -> 121 | N27: 2 | O27: 20 | P27: =IFERROR(IF(AND(K27>0,M27>0,OR(N27>0,O27>0)),(M27/((N27*60)+O27))*60,""),"") -> 51.857143 | Q27: =IFERROR(IF(OR(K27=1,K27=2),IF(K27=1,M27/$M$7,M27/$P$7),""),"") -> 1 | R27: 7 | S27: 5 | T27: Level 4 | U27: =IF(J27<>"",IF(J27="Full Refresher","Low Emerging Reader",IF(AND(K27>0,Q27<>""),IF(OR(Q27<=25%,AND(Q27>25%,Q27<=50%,R27<=1)),"High Emerging Reader",IF(OR(AND(Q27>25%,Q27<51%,R27>=2),AND(Q27>50%,Q27<76%,R27<=3)),"Developing Reader",IF(OR(AND(Q27>=51%,Q27<76%,R27>=4),AND(Q27>75%,R27<=5)),"Transitioning Reader",IF(AND(Q27>75%,R27>=6),"Reading At Grade Level","")))),"")),"") -> Reading At Grade Level
A28: 18 | B28: 1206372200024 | C28: ESTOCADA, REANNA, LLAGOSO | D28: Female | E28: 45722 | F28: 9 | H28: 9 | I28: =IF(AND(F28="",G28=""),"",IF(F28<7,F28+G28,F28+10+H28)) -> 28 | J28: =IF(I28="","",IF(F28<7,IF(I28<=10,"Full Refresher","Moderate Refresher"),IF(I28<27,"Light Refresher","Grade Ready"))) -> Grade Ready | K28: 2 | L28: 1 | M28: =IF($C$9<>"",IF(OR(K28=1,K28=2),IF(K28=1,M$7-L28,$P$7-L28),""),"") -> 118 | N28: 3 | O28: 28 | P28: =IFERROR(IF(AND(K28>0,M28>0,OR(N28>0,O28>0)),(M28/((N28*60)+O28))*60,""),"") -> 34.038462 | Q28: =IFERROR(IF(OR(K28=1,K28=2),IF(K28=1,M28/$M$7,M28/$P$7),""),"") -> 0.99159664 | R28: 7 | S28: 5 | T28: Level 3 | U28: =IF(J28<>"",IF(J28="Full Refresher","Low Emerging Reader",IF(AND(K28>0,Q28<>""),IF(OR(Q28<=25%,AND(Q28>25%,Q28<=50%,R28<=1)),"High Emerging Reader",IF(OR(AND(Q28>25%,Q28<51%,R28>=2),AND(Q28>50%,Q28<76%,R28<=3)),"Developing Reader",IF(OR(AND(Q28>=51%,Q28<76%,R28>=4),AND(Q28>75%,R28<=5)),"Transitioning Reader",IF(AND(Q28>75%,R28>=6),"Reading At Grade Level","")))),"")),"") -> Reading At Grade Level
A29: 19 | B29: 117443220012 | C29: ESTOCADA, RHEAN SHAN, DEMAFILES | D29: Female | E29: 45722 | F29: 5 | G29: 6 | H29: 8 | I29: =IF(AND(F29="",G29=""),"",IF(F29<7,F29+G29,F29+10+H29)) -> 11 | J29: =IF(I29="","",IF(F29<7,IF(I29<=10,"Full Refresher","Moderate Refresher"),IF(I29<27,"Light Refresher","Grade Ready"))) -> Moderate Refresher | K29: 2 | L29: 49 | M29: =IF($C$9<>"",IF(OR(K29=1,K29=2),IF(K29=1,M$7-L29,$P$7-L29),""),"") -> 70 | N29: 3 | O29: 0 | P29: =IFERROR(IF(AND(K29>0,M29>0,OR(N29>0,O29>0)),(M29/((N29*60)+O29))*60,""),"") -> 23.333333 | Q29: =IFERROR(IF(OR(K29=1,K29=2),IF(K29=1,M29/$M$7,M29/$P$7),""),"") -> 0.58823529 | R29: 5 | S29: 2 | T29: Level 1 | U29: =IF(J29<>"",IF(J29="Full Refresher","Low Emerging Reader",IF(AND(K29>0,Q29<>""),IF(OR(Q29<=25%,AND(Q29>25%,Q29<=50%,R29<=1)),"High Emerging Reader",IF(OR(AND(Q29>25%,Q29<51%,R29>=2),AND(Q29>50%,Q29<76%,R29<=3)),"Developing Reader",IF(OR(AND(Q29>=51%,Q29<76%,R29>=4),AND(Q29>75%,R29<=5)),"Transitioning Reader",IF(AND(Q29>75%,R29>=6),"Reading At Grade Level","")))),"")),"") -> Transitioning Reader
A30: 20 | B30: 117443220020 | C30: LABANZA, HOPE ANGELAINE,- | D30: Female | E30: 45722 | F30: 5 | G30: 6 | H30: 8 | I30: =IF(AND(F30="",G30=""),"",IF(F30<7,F30+G30,F30+10+H30)) -> 11 | J30: =IF(I30="","",IF(F30<7,IF(I30<=10,"Full Refresher","Moderate Refresher"),IF(I30<27,"Light Refresher","Grade Ready"))) -> Moderate Refresher | K30: 2 | L30: 2 | M30: =IF($C$9<>"",IF(OR(K30=1,K30=2),IF(K30=1,M$7-L30,$P$7-L30),""),"") -> 117 | N30: 3 | O30: 0 | P30: =IFERROR(IF(AND(K30>0,M30>0,OR(N30>0,O30>0)),(M30/((N30*60)+O30))*60,""),"") -> 39 | Q30: =IFERROR(IF(OR(K30=1,K30=2),IF(K30=1,M30/$M$7,M30/$P$7),""),"") -> 0.98319328 | R30: 6 | S30: 4 | T30: Level 2 | U30: =IF(J30<>"",IF(J30="Full Refresher","Low Emerging Reader",IF(AND(K30>0,Q30<>""),IF(OR(Q30<=25%,AND(Q30>25%,Q30<=50%,R30<=1)),"High Emerging Reader",IF(OR(AND(Q30>25%,Q30<51%,R30>=2),AND(Q30>50%,Q30<76%,R30<=3)),"Developing Reader",IF(OR(AND(Q30>=51%,Q30<76%,R30>=4),AND(Q30>75%,R30<=5)),"Transitioning Reader",IF(AND(Q30>75%,R30>=6),"Reading At Grade Level","")))),"")),"") -> Reading At Grade Level
A31: 21 | C31: LABANZA, JESEL, PARBA | D31: Female | E31: 45722 | F31: 7 | H31: 7 | I31: =IF(AND(F31="",G31=""),"",IF(F31<7,F31+G31,F31+10+H31)) -> 24 | J31: =IF(I31="","",IF(F31<7,IF(I31<=10,"Full Refresher","Moderate Refresher"),IF(I31<27,"Light Refresher","Grade Ready"))) -> Light Refresher | K31: 1 | L31: 0 | M31: =IF($C$9<>"",IF(OR(K31=1,K31=2),IF(K31=1,M$7-L31,$P$7-L31),""),"") -> 121 | N31: 2 | O31: 40 | P31: =IFERROR(IF(AND(K31>0,M31>0,OR(N31>0,O31>0)),(M31/((N31*60)+O31))*60,""),"") -> 45.375 | Q31: =IFERROR(IF(OR(K31=1,K31=2),IF(K31=1,M31/$M$7,M31/$P$7),""),"") -> 1 | R31: 6 | S31: 5 | T31: Level 3 | U31: =IF(J31<>"",IF(J31="Full Refresher","Low Emerging Reader",IF(AND(K31>0,Q31<>""),IF(OR(Q31<=25%,AND(Q31>25%,Q31<=50%,R31<=1)),"High Emerging Reader",IF(OR(AND(Q31>25%,Q31<51%,R31>=2),AND(Q31>50%,Q31<76%,R31<=3)),"Developing Reader",IF(OR(AND(Q31>=51%,Q31<76%,R31>=4),AND(Q31>75%,R31<=5)),"Transitioning Reader",IF(AND(Q31>75%,R31>=6),"Reading At Grade Level","")))),"")),"") -> Reading At Grade Level
A32: 22 | C32: LANOJAN, JASHLYN KATE, JADIA | D32: Female | E32: 45722 | F32: 10 | H32: 9 | I32: =IF(AND(F32="",G32=""),"",IF(F32<7,F32+G32,F32+10+H32)) -> 29 | J32: =IF(I32="","",IF(F32<7,IF(I32<=10,"Full Refresher","Moderate Refresher"),IF(I32<27,"Light Refresher","Grade Ready"))) -> Grade Ready | K32: 1 | L32: 0 | M32: =IF($C$9<>"",IF(OR(K32=1,K32=2),IF(K32=1,M$7-L32,$P$7-L32),""),"") -> 121 | N32: 2 | O32: 4 | P32: =IFERROR(IF(AND(K32>0,M32>0,OR(N32>0,O32>0)),(M32/((N32*60)+O32))*60,""),"") -> 58.548387 | Q32: =IFERROR(IF(OR(K32=1,K32=2),IF(K32=1,M32/$M$7,M32/$P$7),""),"") -> 1 | R32: 7 | S32: 5 | T32: Level 4 | U32: =IF(J32<>"",IF(J32="Full Refresher","Low Emerging Reader",IF(AND(K32>0,Q32<>""),IF(OR(Q32<=25%,AND(Q32>25%,Q32<=50%,R32<=1)),"High Emerging Reader",IF(OR(AND(Q32>25%,Q32<51%,R32>=2),AND(Q32>50%,Q32<76%,R32<=3)),"Developing Reader",IF(OR(AND(Q32>=51%,Q32<76%,R32>=4),AND(Q32>75%,R32<=5)),"Transitioning Reader",IF(AND(Q32>75%,R32>=6),"Reading At Grade Level","")))),"")),"") -> Reading At Grade Level
A33: 23 | B33: 117443220015 | C33: MANGUBAT, AMARAH DENISE, LABANZA | D33: Female | E33: 06/24/2025 | F33: 6 | G33: 6 | I33: =IF(AND(F33="",G33=""),"",IF(F33<7,F33+G33,F33+10+H33)) -> 12 | J33: =IF(I33="","",IF(F33<7,IF(I33<=10,"Full Refresher","Moderate Refresher"),IF(I33<27,"Light Refresher","Grade Ready"))) -> Moderate Refresher | K33: 2 | L33: 10 | M33: =IF($C$9<>"",IF(OR(K33=1,K33=2),IF(K33=1,M$7-L33,$P$7-L33),""),"") -> 109 | N33: 3 | P33: =IFERROR(IF(AND(K33>0,M33>0,OR(N33>0,O33>0)),(M33/((N33*60)+O33))*60,""),"") -> 36.333333 | Q33: =IFERROR(IF(OR(K33=1,K33=2),IF(K33=1,M33/$M$7,M33/$P$7),""),"") -> 0.91596639 | R33: 5 | S33: 5 | T33: Level 2 | U33: =IF(J33<>"",IF(J33="Full Refresher","Low Emerging Reader",IF(AND(K33>0,Q33<>""),IF(OR(Q33<=25%,AND(Q33>25%,Q33<=50%,R33<=1)),"High Emerging Reader",IF(OR(AND(Q33>25%,Q33<51%,R33>=2),AND(Q33>50%,Q33<76%,R33<=3)),"Developing Reader",IF(OR(AND(Q33>=51%,Q33<76%,R33>=4),AND(Q33>75%,R33<=5)),"Transitioning Reader",IF(AND(Q33>75%,R33>=6),"Reading At Grade Level","")))),"")),"") -> Transitioning Reader
A34: 24 | B34: 117443220016 | C34: SUMOLAY, GRACE ANN, ESPARTERO | D34: Female | E34: 06/24/2025 | F34: 10 | H34: 9 | I34: =IF(AND(F34="",G34=""),"",IF(F34<7,F34+G34,F34+10+H34)) -> 29 | J34: =IF(I34="","",IF(F34<7,IF(I34<=10,"Full Refresher","Moderate Refresher"),IF(I34<27,"Light Refresher","Grade Ready"))) -> Grade Ready | K34: 2 | L34: 2 | M34: =IF($C$9<>"",IF(OR(K34=1,K34=2),IF(K34=1,M$7-L34,$P$7-L34),""),"") -> 117 | N34: 2 | P34: =IFERROR(IF(AND(K34>0,M34>0,OR(N34>0,O34>0)),(M34/((N34*60)+O34))*60,""),"") -> 58.5 | Q34: =IFERROR(IF(OR(K34=1,K34=2),IF(K34=1,M34/$M$7,M34/$P$7),""),"") -> 0.98319328 | R34: 7 | S34: 5 | T34: Level 4 | U34: =IF(J34<>"",IF(J34="Full Refresher","Low Emerging Reader",IF(AND(K34>0,Q34<>""),IF(OR(Q34<=25%,AND(Q34>25%,Q34<=50%,R34<=1)),"High Emerging Reader",IF(OR(AND(Q34>25%,Q34<51%,R34>=2),AND(Q34>50%,Q34<76%,R34<=3)),"Developing Reader",IF(OR(AND(Q34>=51%,Q34<76%,R34>=4),AND(Q34>75%,R34<=5)),"Transitioning Reader",IF(AND(Q34>75%,R34>=6),"Reading At Grade Level","")))),"")),"") -> Reading At Grade Level
A35: 25 | B35: 117692220048 | C35: TAPIC, KYZYL ZYNN MJ,- | D35: Female | E35: 06/24/2025 | F35: 8 | H35: 8 | I35: =IF(AND(F35="",G35=""),"",IF(F35<7,F35+G35,F35+10+H35)) -> 26 | J35: =IF(I35="","",IF(F35<7,IF(I35<=10,"Full Refresher","Moderate Refresher"),IF(I35<27,"Light Refresher","Grade Ready"))) -> Light Refresher | K35: 2 | L35: 8 | M35: =IF($C$9<>"",IF(OR(K35=1,K35=2),IF(K35=1,M$7-L35,$P$7-L35),""),"") -> 111 | N35: 2 | O35: 0 | P35: =IFERROR(IF(AND(K35>0,M35>0,OR(N35>0,O35>0)),(M35/((N35*60)+O35))*60,""),"") -> 55.5 | Q35: =IFERROR(IF(OR(K35=1,K35=2),IF(K35=1,M35/$M$7,M35/$P$7),""),"") -> 0.93277311 | R35: 4 | S35: 4 | T35: Level 3 | U35: =IF(J35<>"",IF(J35="Full Refresher","Low Emerging Reader",IF(AND(K35>0,Q35<>""),IF(OR(Q35<=25%,AND(Q35>25%,Q35<=50%,R35<=1)),"High Emerging Reader",IF(OR(AND(Q35>25%,Q35<51%,R35>=2),AND(Q35>50%,Q35<76%,R35<=3)),"Developing Reader",IF(OR(AND(Q35>=51%,Q35<76%,R35>=4),AND(Q35>75%,R35<=5)),"Transitioning Reader",IF(AND(Q35>75%,R35>=6),"Reading At Grade Level","")))),"")),"") -> Transitioning Reader
A36: 26 | I36: =IF(AND(F36="",G36=""),"",IF(F36<7,F36+G36,F36+10+H36)) | J36: =IF(I36="","",IF(F36<7,IF(I36<=10,"Full Refresher","Moderate Refresher"),IF(I36<27,"Light Refresher","Grade Ready"))) | M36: =IF($C$9<>"",IF(OR(K36=1,K36=2),IF(K36=1,M$7-L36,$P$7-L36),""),"") | P36: =IFERROR(IF(AND(K36>0,M36>0,OR(N36>0,O36>0)),(M36/((N36*60)+O36))*60,""),"") | Q36: =IFERROR(IF(OR(K36=1,K36=2),IF(K36=1,M36/$M$7,M36/$P$7),""),"") | U36: =IF(J36<>"",IF(J36="Full Refresher","Low Emerging Reader",IF(AND(K36>0,Q36<>""),IF(OR(Q36<=25%,AND(Q36>25%,Q36<=50%,R36<=1)),"High Emerging Reader",IF(OR(AND(Q36>25%,Q36<51%,R36>=2),AND(Q36>50%,Q36<76%,R36<=3)),"Developing Reader",IF(OR(AND(Q36>=51%,Q36<76%,R36>=4),AND(Q36>75%,R36<=5)),"Transitioning Reader",IF(AND(Q36>75%,R36>=6),"Reading At Grade Level","")))),"")),"")
A37: 27 | I37: =IF(AND(F37="",G37=""),"",IF(F37<7,F37+G37,F37+10+H37)) | J37: =IF(I37="","",IF(F37<7,IF(I37<=10,"Full Refresher","Moderate Refresher"),IF(I37<27,"Light Refresher","Grade Ready"))) | M37: =IF($C$9<>"",IF(OR(K37=1,K37=2),IF(K37=1,M$7-L37,$P$7-L37),""),"") | P37: =IFERROR(IF(AND(K37>0,M37>0,OR(N37>0,O37>0)),(M37/((N37*60)+O37))*60,""),"") | Q37: =IFERROR(IF(OR(K37=1,K37=2),IF(K37=1,M37/$M$7,M37/$P$7),""),"") | U37: =IF(J37<>"",IF(J37="Full Refresher","Low Emerging Reader",IF(AND(K37>0,Q37<>""),IF(OR(Q37<=25%,AND(Q37>25%,Q37<=50%,R37<=1)),"High Emerging Reader",IF(OR(AND(Q37>25%,Q37<51%,R37>=2),AND(Q37>50%,Q37<76%,R37<=3)),"Developing Reader",IF(OR(AND(Q37>=51%,Q37<76%,R37>=4),AND(Q37>75%,R37<=5)),"Transitioning Reader",IF(AND(Q37>75%,R37>=6),"Reading At Grade Level","")))),"")),"")
A38: 28 | I38: =IF(AND(F38="",G38=""),"",IF(F38<7,F38+G38,F38+10+H38)) | J38: =IF(I38="","",IF(F38<7,IF(I38<=10,"Full Refresher","Moderate Refresher"),IF(I38<27,"Light Refresher","Grade Ready"))) | M38: =IF($C$9<>"",IF(OR(K38=1,K38=2),IF(K38=1,M$7-L38,$P$7-L38),""),"") | P38: =IFERROR(IF(AND(K38>0,M38>0,OR(N38>0,O38>0)),(M38/((N38*60)+O38))*60,""),"") | Q38: =IFERROR(IF(OR(K38=1,K38=2),IF(K38=1,M38/$M$7,M38/$P$7),""),"") | U38: =IF(J38<>"",IF(J38="Full Refresher","Low Emerging Reader",IF(AND(K38>0,Q38<>""),IF(OR(Q38<=25%,AND(Q38>25%,Q38<=50%,R38<=1)),"High Emerging Reader",IF(OR(AND(Q38>25%,Q38<51%,R38>=2),AND(Q38>50%,Q38<76%,R38<=3)),"Developing Reader",IF(OR(AND(Q38>=51%,Q38<76%,R38>=4),AND(Q38>75%,R38<=5)),"Transitioning Reader",IF(AND(Q38>75%,R38>=6),"Reading At Grade Level","")))),"")),"")
A39: 29 | I39: =IF(AND(F39="",G39=""),"",IF(F39<7,F39+G39,F39+10+H39)) | J39: =IF(I39="","",IF(F39<7,IF(I39<=10,"Full Refresher","Moderate Refresher"),IF(I39<27,"Light Refresher","Grade Ready"))) | M39: =IF($C$9<>"",IF(OR(K39=1,K39=2),IF(K39=1,M$7-L39,$P$7-L39),""),"") | P39: =IFERROR(IF(AND(K39>0,M39>0,OR(N39>0,O39>0)),(M39/((N39*60)+O39))*60,""),"") | Q39: =IFERROR(IF(OR(K39=1,K39=2),IF(K39=1,M39/$M$7,M39/$P$7),""),"") | U39: =IF(J39<>"",IF(J39="Full Refresher","Low Emerging Reader",IF(AND(K39>0,Q39<>""),IF(OR(Q39<=25%,AND(Q39>25%,Q39<=50%,R39<=1)),"High Emerging Reader",IF(OR(AND(Q39>25%,Q39<51%,R39>=2),AND(Q39>50%,Q39<76%,R39<=3)),"Developing Reader",IF(OR(AND(Q39>=51%,Q39<76%,R39>=4),AND(Q39>75%,R39<=5)),"Transitioning Reader",IF(AND(Q39>75%,R39>=6),"Reading At Grade Level","")))),"")),"")
A40: 30 | I40: =IF(AND(F40="",G40=""),"",IF(F40<7,F40+G40,F40+10+H40)) | J40: =IF(I40="","",IF(F40<7,IF(I40<=10,"Full Refresher","Moderate Refresher"),IF(I40<27,"Light Refresher","Grade Ready"))) | M40: =IF($C$9<>"",IF(OR(K40=1,K40=2),IF(K40=1,M$7-L40,$P$7-L40),""),"") | P40: =IFERROR(IF(AND(K40>0,M40>0,OR(N40>0,O40>0)),(M40/((N40*60)+O40))*60,""),"") | Q40: =IFERROR(IF(OR(K40=1,K40=2),IF(K40=1,M40/$M$7,M40/$P$7),""),"") | U40: =IF(J40<>"",IF(J40="Full Refresher","Low Emerging Reader",IF(AND(K40>0,Q40<>""),IF(OR(Q40<=25%,AND(Q40>25%,Q40<=50%,R40<=1)),"High Emerging Reader",IF(OR(AND(Q40>25%,Q40<51%,R40>=2),AND(Q40>50%,Q40<76%,R40<=3)),"Developing Reader",IF(OR(AND(Q40>=51%,Q40<76%,R40>=4),AND(Q40>75%,R40<=5)),"Transitioning Reader",IF(AND(Q40>75%,R40>=6),"Reading At Grade Level","")))),"")),"")
A41: 31 | I41: =IF(AND(F41="",G41=""),"",IF(F41<7,F41+G41,F41+10+H41)) | J41: =IF(I41="","",IF(F41<7,IF(I41<=10,"Full Refresher","Moderate Refresher"),IF(I41<27,"Light Refresher","Grade Ready"))) | M41: =IF($C$9<>"",IF(OR(K41=1,K41=2),IF(K41=1,M$7-L41,$P$7-L41),""),"") | P41: =IFERROR(IF(AND(K41>0,M41>0,OR(N41>0,O41>0)),(M41/((N41*60)+O41))*60,""),"") | Q41: =IFERROR(IF(OR(K41=1,K41=2),IF(K41=1,M41/$M$7,M41/$P$7),""),"") | U41: =IF(J41<>"",IF(J41="Full Refresher","Low Emerging Reader",IF(AND(K41>0,Q41<>""),IF(OR(Q41<=25%,AND(Q41>25%,Q41<=50%,R41<=1)),"High Emerging Reader",IF(OR(AND(Q41>25%,Q41<51%,R41>=2),AND(Q41>50%,Q41<76%,R41<=3)),"Developing Reader",IF(OR(AND(Q41>=51%,Q41<76%,R41>=4),AND(Q41>75%,R41<=5)),"Transitioning Reader",IF(AND(Q41>75%,R41>=6),"Reading At Grade Level","")))),"")),"")
...

Sheet G3 FIL Reading Scoresheet
A1: ='G3 MT Reading Scoresheet'!$A$1 -> CRLA2v1
A3: ASSESSMENT TYPE | C3: ='G3 MT Reading Scoresheet'!$C$3 -> EoSY
A4: School ID: | C4: ='G3 MT Reading Scoresheet'!C4 -> 117443 | D4: Total Enrolment | F4: =D6+E6 -> 25 | G4: Total Assessed : | I4: =COUNTIF(F11:F110,"<>") -> 25
A5: Schoo Name: | C5: ='G3 MT Reading Scoresheet'!C5 -> ROMANA ELEM. SCHOOL | D5: Male | E5: Female | F5: Assessment Part 1 (Word Recognition and Sentences Reading) | J5: WORDS SCORE 0 to 10 – Full Refresher 11 to 16 – Moderate Refresher SENTENCE SCORE 17 to 26 – Light Refresher 27 to 30 – Grade Ready | K5: Assessment Part 2 (Reading Fluency and Comprehension)
A6: Teacher: | C6: ='G3 MT Reading Scoresheet'!C6 -> KEMBERLY G. BELMIS | D6: ='G3 MT Reading Scoresheet'!D6 -> 10 | E6: ='G3 MT Reading Scoresheet'!E6 -> 15
A7: Grade: | C7: ='G3 MT Reading Scoresheet'!C7 -> Grade 3 | D7: Total Words per Story | F7: Task 1 – Write the number of Words sounded out correctly | G7: Sentence (Task 2) If task 1 score is 7 to 10 Task 2L=10 | H7: Total Score = Task 1 Score + Task 2L+Task 2H Score | I7: Total Score = Task 1 Score + Task 2 Score | K7: Total Words Per Story | L7: Story 1 | M7: =_xlfn.IFNA(IF(X9=1,Y9,D9),"") -> 121 | N7: Story 2 | P7: =_xlfn.IFNA(IF(X9=1,Z9,E9),"") -> 121
A8: Section: | C8: ='G3 MT Reading Scoresheet'!C8 -> 1 | D8: Story 1 | E8: Story 2 | K8: Story Number 1 or 2 | L8: Total Reading Miscues | M8: Number of words read within 3 mins | N8: Total Time Used in Reading (Max : 3 Mins) | P8: Number of Words per Minute (WPM)
A9: Language: | C9: Filipino | X9: =IF(_xlfn.IFNA(VLOOKUP($C$9,List!$G$2:$M$20,1,0),"")=C9,1,0) -> 1 | Y9: =VLOOKUP($C$9,List!$G$2:$M$21,4,0) -> 121 | Z9: =VLOOKUP($C$9,List!$G$2:$M$21,7,0) -> 121
A10: S/N | B10: LRN | C10: Name of Learner | D10: Sex | E10: Date of Asessment | F10: Task 1 (10) | G10: Task 2L Words (10) | H10: Task 2H Sentences (10) | I10: Total Score | J10: Part 1 Reading Level | K10: Story Number | L10: Number of Miscue | M10: Words Read | N10: Total Mins Secs | P10: WPM | Q10: % of Correct Words Read | R10: Total Correct Answer | S10: Leaner Experience (Rating 1-5) | T10: Observation Level | U10: READING PROFILE | V10: Remarks
A11: 1 | B11: =IF('G3 MT Reading Scoresheet'!B11<>"",'G3 MT Reading Scoresheet'!B11,"") -> 117443220001 | C11: =IF('G3 MT Reading Scoresheet'!C11<>"",'G3 MT Reading Scoresheet'!C11,"") -> ABAY, KENNETH ALEXANDER, NALAONAN | D11: =IF('G3 MT Reading Scoresheet'!D11<>"",'G3 MT Reading Scoresheet'!D11,"") -> Male | E11: =IF('G3 MT Reading Scoresheet'!E11<>"",'G3 MT Reading Scoresheet'!E11,"") -> 06/23/2025 | F11: 8 | H11: 8 | I11: =IF(AND(F11="",G11=""),"",IF(F11<7,F11+G11,F11+10+H11)) -> 26 | J11: =IF(I11="","",IF(F11<7,IF(I11<=10,"Full Refresher","Moderate Refresher"),IF(I11<27,"Light Refresher","Grade Ready"))) -> Light Refresher | K11: 2 | L11: 20 | M11: =IF(OR(K11=1,K11=2),IF(K11=1,M$7-L11,$P$7-L11),"") -> 101 | N11: 3 | O11: 0 | P11: =IFERROR(IF(AND(K11>0,M11>0,OR(N11>0,O11>0)),(M11/((N11*60)+O11))*60,""),"") -> 33.666667 | Q11: =IFERROR(IF(OR(K11=1,K11=2),IF(K11=1,M11/$M$7,M11/$P$7),""),"") -> 0.83471074 | R11: 3 | S11: 3 | T11: Level 1 | U11: =IF(J11<>"",IF(J11="Full Refresher","Low Emerging Reader",IF(AND(K11>0,Q11<>""),IF(OR(Q11<=25%,AND(Q11>25%,Q11<=50%,R11<=1)),"High Emerging Reader",IF(OR(AND(Q11>25%,Q11<51%,R11>=2),AND(Q11>50%,Q11<76%,R11<=3)),"Developing Reader",IF(OR(AND(Q11>=51%,Q11<76%,R11>=4),AND(Q11>75%,R11<=5)),"Transitioning Reader",IF(AND(Q11>75%,R11>=6),"Reading At Grade Level","")))),"")),"") -> Transitioning Reader
A12: 2 | B12: =IF('G3 MT Reading Scoresheet'!B12<>"",'G3 MT Reading Scoresheet'!B12,"") -> 11744322002 | C12: =IF('G3 MT Reading Scoresheet'!C12<>"",'G3 MT Reading Scoresheet'!C12,"") -> BANARAIA, KEEPER, ABAY | D12: =IF('G3 MT Reading Scoresheet'!D12<>"",'G3 MT Reading Scoresheet'!D12,"") -> Male | E12: =IF('G3 MT Reading Scoresheet'!E12<>"",'G3 MT Reading Scoresheet'!E12,"") -> 06/23/2025 | F12: 5 | G12: 5 | H12: 10 | I12: =IF(AND(F12="",G12=""),"",IF(F12<7,F12+G12,F12+10+H12)) -> 10 | J12: =IF(I12="","",IF(F12<7,IF(I12<=10,"Full Refresher","Moderate Refresher"),IF(I12<27,"Light Refresher","Grade Ready"))) -> Full Refresher | K12: 2 | L12: 5 | M12: =IF(OR(K12=1,K12=2),IF(K12=1,M$7-L12,$P$7-L12),"") -> 116 | N12: 2 | O12: 5 | P12: =IF(AND(K12>0,M12>0,OR(N12>0,O12>0)),(M12/((N12*60)+O12))*60,"") -> 55.68 | Q12: =IFERROR(IF(OR(K12=1,K12=2),IF(K12=1,M12/$M$7,M12/$P$7),""),"") -> 0.95867769 | R12: 6 | S12: 4 | T12: Level 2 | U12: =IF(J12<>"",IF(J12="Full Refresher","Low Emerging Reader",IF(AND(K12>0,Q12<>""),IF(OR(Q12<=25%,AND(Q12>25%,Q12<=50%,R12<=1)),"High Emerging Reader",IF(OR(AND(Q12>25%,Q12<51%,R12>=2),AND(Q12>50%,Q12<76%,R12<=3)),"Developing Reader",IF(OR(AND(Q12>=51%,Q12<76%,R12>=4),AND(Q12>75%,R12<=5)),"Transitioning Reader",IF(AND(Q12>75%,R12>=6),"Reading At Grade Level","")))),"")),"") -> Low Emerging Reader
A13: 3 | B13: =IF('G3 MT Reading Scoresheet'!B13<>"",'G3 MT Reading Scoresheet'!B13,"") -> 117443220017 | C13: =IF('G3 MT Reading Scoresheet'!C13<>"",'G3 MT Reading Scoresheet'!C13,"") -> BARGASA, EDSEL JHON,- | D13: =IF('G3 MT Reading Scoresheet'!D13<>"",'G3 MT Reading Scoresheet'!D13,"") -> Male | E13: =IF('G3 MT Reading Scoresheet'!E13<>"",'G3 MT Reading Scoresheet'!E13,"") -> 06/23/2025 | F13: 8 | H13: 10 | I13: =IF(AND(F13="",G13=""),"",IF(F13<7,F13+G13,F13+10+H13)) -> 28 | J13: =IF(I13="","",IF(F13<7,IF(I13<=10,"Full Refresher","Moderate Refresher"),IF(I13<27,"Light Refresher","Grade Ready"))) -> Grade Ready | K13: 1 | L13: 1 | M13: =IF(OR(K13=1,K13=2),IF(K13=1,M$7-L13,$P$7-L13),"") -> 120 | N13: 1 | O13: 39 | P13: =IF(AND(K13>0,M13>0,OR(N13>0,O13>0)),(M13/((N13*60)+O13))*60,"") -> 72.727273 | Q13: =IFERROR(IF(OR(K13=1,K13=2),IF(K13=1,M13/$M$7,M13/$P$7),""),"") -> 0.99173554 | R13: 7 | S13: 5 | T13: Level 4 | U13: =IF(J13<>"",IF(J13="Full Refresher","Low Emerging Reader",IF(AND(K13>0,Q13<>""),IF(OR(Q13<=25%,AND(Q13>25%,Q13<=50%,R13<=1)),"High Emerging Reader",IF(OR(AND(Q13>25%,Q13<51%,R13>=2),AND(Q13>50%,Q13<76%,R13<=3)),"Developing Reader",IF(OR(AND(Q13>=51%,Q13<76%,R13>=4),AND(Q13>75%,R13<=5)),"Transitioning Reader",IF(AND(Q13>75%,R13>=6),"Reading At Grade Level","")))),"")),"") -> Reading At Grade Level
A14: 4 | B14: =IF('G3 MT Reading Scoresheet'!B14<>"",'G3 MT Reading Scoresheet'!B14,"") -> 117443220006 | C14: =IF('G3 MT Reading Scoresheet'!C14<>"",'G3 MT Reading Scoresheet'!C14,"") -> DUMANIEL, KEVIN JOHN , ALVAREZ | D14: =IF('G3 MT Reading Scoresheet'!D14<>"",'G3 MT Reading Scoresheet'!D14,"") -> Male | E14: =IF('G3 MT Reading Scoresheet'!E14<>"",'G3 MT Reading Scoresheet'!E14,"") -> 06/23/2025 | F14: 8 | H14: 9 | I14: =IF(AND(F14="",G14=""),"",IF(F14<7,F14+G14,F14+10+H14)) -> 27 | J14: =IF(I14="","",IF(F14<7,IF(I14<=10,"Full Refresher","Moderate Refresher"),IF(I14<27,"Light Refresher","Grade Ready"))) -> Grade Ready | K14: 1 | L14: 5 | M14: =IF(OR(K14=1,K14=2),IF(K14=1,M$7-L14,$P$7-L14),"") -> 116 | N14: 3 | O14: 0 | P14: =IF(AND(K14>0,M14>0,OR(N14>0,O14>0)),(M14/((N14*60)+O14))*60,"") -> 38.666667 | Q14: =IFERROR(IF(OR(K14=1,K14=2),IF(K14=1,M14/$M$7,M14/$P$7),""),"") -> 0.95867769 | R14: 6 | S14: 3 | T14: Level 1 | U14: =IF(J14<>"",IF(J14="Full Refresher","Low Emerging Reader",IF(AND(K14>0,Q14<>""),IF(OR(Q14<=25%,AND(Q14>25%,Q14<=50%,R14<=1)),"High Emerging Reader",IF(OR(AND(Q14>25%,Q14<51%,R14>=2),AND(Q14>50%,Q14<76%,R14<=3)),"Developing Reader",IF(OR(AND(Q14>=51%,Q14<76%,R14>=4),AND(Q14>75%,R14<=5)),"Transitioning Reader",IF(AND(Q14>75%,R14>=6),"Reading At Grade Level","")))),"")),"") -> Reading At Grade Level
A15: 5 | B15: =IF('G3 MT Reading Scoresheet'!B15<>"",'G3 MT Reading Scoresheet'!B15,"") -> 117443220018 | C15: =IF('G3 MT Reading Scoresheet'!C15<>"",'G3 MT Reading Scoresheet'!C15,"") -> ESTOCADA, JOEMARIE III, OMPAD | D15: =IF('G3 MT Reading Scoresheet'!D15<>"",'G3 MT Reading Scoresheet'!D15,"") -> Male | E15: =IF('G3 MT Reading Scoresheet'!E15<>"",'G3 MT Reading Scoresheet'!E15,"") -> 06/24/2025 | F15: 7 | H15: 7 | I15: =IF(AND(F15="",G15=""),"",IF(F15<7,F15+G15,F15+10+H15)) -> 24 | J15: =IF(I15="","",IF(F15<7,IF(I15<=10,"Full Refresher","Moderate Refresher"),IF(I15<27,"Light Refresher","Grade Ready"))) -> Light Refresher | K15: 1 | L15: 10 | M15: =IF(OR(K15=1,K15=2),IF(K15=1,M$7-L15,$P$7-L15),"") -> 111 | N15: 3 | O15: 0 | P15: =IF(AND(K15>0,M15>0,OR(N15>0,O15>0)),(M15/((N15*60)+O15))*60,"") -> 37 | Q15: =IFERROR(IF(OR(K15=1,K15=2),IF(K15=1,M15/$M$7,M15/$P$7),""),"") -> 0.91735537 | R15: 3 | S15: 3 | T15: Level 1 | U15: =IF(J15<>"",IF(J15="Full Refresher","Low Emerging Reader",IF(AND(K15>0,Q15<>""),IF(OR(Q15<=25%,AND(Q15>25%,Q15<=50%,R15<=1)),"High Emerging Reader",IF(OR(AND(Q15>25%,Q15<51%,R15>=2),AND(Q15>50%,Q15<76%,R15<=3)),"Developing Reader",IF(OR(AND(Q15>=51%,Q15<76%,R15>=4),AND(Q15>75%,R15<=5)),"Transitioning Reader",IF(AND(Q15>75%,R15>=6),"Reading At Grade Level","")))),"")),"") -> Transitioning Reader
A16: 6 | B16: =IF('G3 MT Reading Scoresheet'!B16<>"",'G3 MT Reading Scoresheet'!B16,"") -> 117542220012 | C16: =IF('G3 MT Reading Scoresheet'!C16<>"",'G3 MT Reading Scoresheet'!C16,"") -> GO, NEAL XANDRIE, DOMANIEL | D16: =IF('G3 MT Reading Scoresheet'!D16<>"",'G3 MT Reading Scoresheet'!D16,"") -> Male | E16: =IF('G3 MT Reading Scoresheet'!E16<>"",'G3 MT Reading Scoresheet'!E16,"") -> 06/24/2025 | F16: 8 | H16: 8 | I16: =IF(AND(F16="",G16=""),"",IF(F16<7,F16+G16,F16+10+H16)) -> 26 | J16: =IF(I16="","",IF(F16<7,IF(I16<=10,"Full Refresher","Moderate Refresher"),IF(I16<27,"Light Refresher","Grade Ready"))) -> Light Refresher | K16: 1 | L16: 8 | M16: =IF(OR(K16=1,K16=2),IF(K16=1,M$7-L16,$P$7-L16),"") -> 113 | N16: 2 | O16: 25 | P16: =IF(AND(K16>0,M16>0,OR(N16>0,O16>0)),(M16/((N16*60)+O16))*60,"") -> 46.758621 | Q16: =IFERROR(IF(OR(K16=1,K16=2),IF(K16=1,M16/$M$7,M16/$P$7),""),"") -> 0.9338843 | R16: 5 | S16: 3 | T16: Level 2 | U16: =IF(J16<>"",IF(J16="Full Refresher","Low Emerging Reader",IF(AND(K16>0,Q16<>""),IF(OR(Q16<=25%,AND(Q16>25%,Q16<=50%,R16<=1)),"High Emerging Reader",IF(OR(AND(Q16>25%,Q16<51%,R16>=2),AND(Q16>50%,Q16<76%,R16<=3)),"Developing Reader",IF(OR(AND(Q16>=51%,Q16<76%,R16>=4),AND(Q16>75%,R16<=5)),"Transitioning Reader",IF(AND(Q16>75%,R16>=6),"Reading At Grade Level","")))),"")),"") -> Transitioning Reader
A17: 7 | B17: =IF('G3 MT Reading Scoresheet'!B17<>"",'G3 MT Reading Scoresheet'!B17,"") -> 1174432290003 | C17: =IF('G3 MT Reading Scoresheet'!C17<>"",'G3 MT Reading Scoresheet'!C17,"") -> GREGORIO, JOHN MARK, ABELLAR | D17: =IF('G3 MT Reading Scoresheet'!D17<>"",'G3 MT Reading Scoresheet'!D17,"") -> Male | E17: =IF('G3 MT Reading Scoresheet'!E17<>"",'G3 MT Reading Scoresheet'!E17,"") -> 06/24/2025 | F17: 4 | H17: 7 | I17: =IF(AND(F17="",G17=""),"",IF(F17<7,F17+G17,F17+10+H17)) -> 4 | J17: =IF(I17="","",IF(F17<7,IF(I17<=10,"Full Refresher","Moderate Refresher"),IF(I17<27,"Light Refresher","Grade Ready"))) -> Full Refresher | K17: 1 | L17: 50 | M17: =IF(OR(K17=1,K17=2),IF(K17=1,M$7-L17,$P$7-L17),"") -> 71 | N17: 3 | O17: 0 | P17: =IF(AND(K17>0,M17>0,OR(N17>0,O17>0)),(M17/((N17*60)+O17))*60,"") -> 23.666667 | Q17: =IFERROR(IF(OR(K17=1,K17=2),IF(K17=1,M17/$M$7,M17/$P$7),""),"") -> 0.58677686 | R17: 1 | S17: 2 | T17: Level 1 | U17: =IF(J17<>"",IF(J17="Full Refresher","Low Emerging Reader",IF(AND(K17>0,Q17<>""),IF(OR(Q17<=25%,AND(Q17>25%,Q17<=50%,R17<=1)),"High Emerging Reader",IF(OR(AND(Q17>25%,Q17<51%,R17>=2),AND(Q17>50%,Q17<76%,R17<=3)),"Developing Reader",IF(OR(AND(Q17>=51%,Q17<76%,R17>=4),AND(Q17>75%,R17<=5)),"Transitioning Reader",IF(AND(Q17>75%,R17>=6),"Reading At Grade Level","")))),"")),"") -> Low Emerging Reader
A18: 8 | B18: =IF('G3 MT Reading Scoresheet'!B18<>"",'G3 MT Reading Scoresheet'!B18,"") -> 117443220005 | C18: =IF('G3 MT Reading Scoresheet'!C18<>"",'G3 MT Reading Scoresheet'!C18,"") -> JUMBAS, CYREL JAY, BARILLO | D18: =IF('G3 MT Reading Scoresheet'!D18<>"",'G3 MT Reading Scoresheet'!D18,"") -> Male | E18: =IF('G3 MT Reading Scoresheet'!E18<>"",'G3 MT Reading Scoresheet'!E18,"") -> 06/24/2025 | F18: 7 | H18: 8 | I18: =IF(AND(F18="",G18=""),"",IF(F18<7,F18+G18,F18+10+H18)) -> 25 | J18: =IF(I18="","",IF(F18<7,IF(I18<=10,"Full Refresher","Moderate Refresher"),IF(I18<27,"Light Refresher","Grade Ready"))) -> Light Refresher | K18: 1 | L18: 7 | M18: =IF(OR(K18=1,K18=2),IF(K18=1,M$7-L18,$P$7-L18),"") -> 114 | N18: 3 | O18: 0 | P18: =IF(AND(K18>0,M18>0,OR(N18>0,O18>0)),(M18/((N18*60)+O18))*60,"") -> 38 | Q18: =IFERROR(IF(OR(K18=1,K18=2),IF(K18=1,M18/$M$7,M18/$P$7),""),"") -> 0.94214876 | R18: 6 | S18: 4 | T18: Level 1 | U18: =IF(J18<>"",IF(J18="Full Refresher","Low Emerging Reader",IF(AND(K18>0,Q18<>""),IF(OR(Q18<=25%,AND(Q18>25%,Q18<=50%,R18<=1)),"High Emerging Reader",IF(OR(AND(Q18>25%,Q18<51%,R18>=2),AND(Q18>50%,Q18<76%,R18<=3)),"Developing Reader",IF(OR(AND(Q18>=51%,Q18<76%,R18>=4),AND(Q18>75%,R18<=5)),"Transitioning Reader",IF(AND(Q18>75%,R18>=6),"Reading At Grade Level","")))),"")),"") -> Reading At Grade Level
A19: 9 | B19: =IF('G3 MT Reading Scoresheet'!B19<>"",'G3 MT Reading Scoresheet'!B19,"") -> 11744322007 | C19: =IF('G3 MT Reading Scoresheet'!C19<>"",'G3 MT Reading Scoresheet'!C19,"") -> LEMORINAS, ARTHUR, BAYLON | D19: =IF('G3 MT Reading Scoresheet'!D19<>"",'G3 MT Reading Scoresheet'!D19,"") -> Male | E19: =IF('G3 MT Reading Scoresheet'!E19<>"",'G3 MT Reading Scoresheet'!E19,"") -> 06/24/2025 | F19: 4 | G19: 4 | H19: 10 | I19: =IF(AND(F19="",G19=""),"",IF(F19<7,F19+G19,F19+10+H19)) -> 8 | J19: =IF(I19="","",IF(F19<7,IF(I19<=10,"Full Refresher","Moderate Refresher"),IF(I19<27,"Light Refresher","Grade Ready"))) -> Full Refresher | K19: 1 | L19: 50 | M19: =IF(OR(K19=1,K19=2),IF(K19=1,M$7-L19,$P$7-L19),"") -> 71 | N19: 2 | O19: 0 | P19: =IF(AND(K19>0,M19>0,OR(N19>0,O19>0)),(M19/((N19*60)+O19))*60,"") -> 35.5 | Q19: =IFERROR(IF(OR(K19=1,K19=2),IF(K19=1,M19/$M$7,M19/$P$7),""),"") -> 0.58677686 | R19: 7 | S19: 5 | T19: Level 4 | U19: =IF(J19<>"",IF(J19="Full Refresher","Low Emerging Reader",IF(AND(K19>0,Q19<>""),IF(OR(Q19<=25%,AND(Q19>25%,Q19<=50%,R19<=1)),"High Emerging Reader",IF(OR(AND(Q19>25%,Q19<51%,R19>=2),AND(Q19>50%,Q19<76%,R19<=3)),"Developing Reader",IF(OR(AND(Q19>=51%,Q19<76%,R19>=4),AND(Q19>75%,R19<=5)),"Transitioning Reader",IF(AND(Q19>75%,R19>=6),"Reading At Grade Level","")))),"")),"") -> Low Emerging Reader
A20: 10 | B20: =IF('G3 MT Reading Scoresheet'!B20<>"",'G3 MT Reading Scoresheet'!B20,"") -> 117443220008 | C20: =IF('G3 MT Reading Scoresheet'!C20<>"",'G3 MT Reading Scoresheet'!C20,"") -> MARASIGAN, ZHENKIE NATHAN, DELA CRUZ | D20: =IF('G3 MT Reading Scoresheet'!D20<>"",'G3 MT Reading Scoresheet'!D20,"") -> Male | E20: =IF('G3 MT Reading Scoresheet'!E20<>"",'G3 MT Reading Scoresheet'!E20,"") -> 06/24/2025 | F20: 8 | H20: 9 | I20: =IF(AND(F20="",G20=""),"",IF(F20<7,F20+G20,F20+10+H20)) -> 27 | J20: =IF(I20="","",IF(F20<7,IF(I20<=10,"Full Refresher","Moderate Refresher"),IF(I20<27,"Light Refresher","Grade Ready"))) -> Grade Ready | K20: 1 | L20: 29 | M20: =IF(OR(K20=1,K20=2),IF(K20=1,M$7-L20,$P$7-L20),"") -> 92 | N20: 3 | O20: 0 | P20: =IF(AND(K20>0,M20>0,OR(N20>0,O20>0)),(M20/((N20*60)+O20))*60,"") -> 30.666667 | Q20: =IFERROR(IF(OR(K20=1,K20=2),IF(K20=1,M20/$M$7,M20/$P$7),""),"") -> 0.76033058 | R20: 6 | S20: 5 | T20: Level 2 | U20: =IF(J20<>"",IF(J20="Full Refresher","Low Emerging Reader",IF(AND(K20>0,Q20<>""),IF(OR(Q20<=25%,AND(Q20>25%,Q20<=50%,R20<=1)),"High Emerging Reader",IF(OR(AND(Q20>25%,Q20<51%,R20>=2),AND(Q20>50%,Q20<76%,R20<=3)),"Developing Reader",IF(OR(AND(Q20>=51%,Q20<76%,R20>=4),AND(Q20>75%,R20<=5)),"Transitioning Reader",IF(AND(Q20>75%,R20>=6),"Reading At Grade Level","")))),"")),"") -> Reading At Grade Level
A21: 11 | B21: =IF('G3 MT Reading Scoresheet'!B21<>"",'G3 MT Reading Scoresheet'!B21,"") -> 136651220284 | C21: =IF('G3 MT Reading Scoresheet'!C21<>"",'G3 MT Reading Scoresheet'!C21,"") -> ABRINILLO, VERONICA, SIASAT | D21: =IF('G3 MT Reading Scoresheet'!D21<>"",'G3 MT Reading Scoresheet'!D21,"") -> Male | E21: =IF('G3 MT Reading Scoresheet'!E21<>"",'G3 MT Reading Scoresheet'!E21,"") -> 06/24/2025 | F21: 7 | G21: 3 | H21: 3 | I21: =IF(AND(F21="",G21=""),"",IF(F21<7,F21+G21,F21+10+H21)) -> 20 | J21: =IF(I21="","",IF(F21<7,IF(I21<=10,"Full Refresher","Moderate Refresher"),IF(I21<27,"Light Refresher","Grade Ready"))) -> Light Refresher | K21: 1 | L21: 60 | M21: =IF(OR(K21=1,K21=2),IF(K21=1,M$7-L21,$P$7-L21),"") -> 61 | N21: 3 | O21: 0 | P21: =IF(AND(K21>0,M21>0,OR(N21>0,O21>0)),(M21/((N21*60)+O21))*60,"") -> 20.333333 | Q21: =IFERROR(IF(OR(K21=1,K21=2),IF(K21=1,M21/$M$7,M21/$P$7),""),"") -> 0.50413223 | R21: 1 | S21: 2 | T21: Level 1 | U21: =IF(J21<>"",IF(J21="Full Refresher","Low Emerging Reader",IF(AND(K21>0,Q21<>""),IF(OR(Q21<=25%,AND(Q21>25%,Q21<=50%,R21<=1)),"High Emerging Reader",IF(OR(AND(Q21>25%,Q21<51%,R21>=2),AND(Q21>50%,Q21<76%,R21<=3)),"Developing Reader",IF(OR(AND(Q21>=51%,Q21<76%,R21>=4),AND(Q21>75%,R21<=5)),"Transitioning Reader",IF(AND(Q21>75%,R21>=6),"Reading At Grade Level","")))),"")),"") -> Developing Reader
A22: 12 | B22: =IF('G3 MT Reading Scoresheet'!B22<>"",'G3 MT Reading Scoresheet'!B22,"") -> 117443220019 | C22: =IF('G3 MT Reading Scoresheet'!C22<>"",'G3 MT Reading Scoresheet'!C22,"") -> CARDINAL,KISHIA,- | D22: =IF('G3 MT Reading Scoresheet'!D22<>"",'G3 MT Reading Scoresheet'!D22,"") -> Female | E22: =IF('G3 MT Reading Scoresheet'!E22<>"",'G3 MT Reading Scoresheet'!E22,"") -> 06/24/2025 | F22: 9 | H22: 10 | I22: =IF(AND(F22="",G22=""),"",IF(F22<7,F22+G22,F22+10+H22)) -> 29 | J22: =IF(I22="","",IF(F22<7,IF(I22<=10,"Full Refresher","Moderate Refresher"),IF(I22<27,"Light Refresher","Grade Ready"))) -> Grade Ready | K22: 1 | L22: 15 | M22: =IF(OR(K22=1,K22=2),IF(K22=1,M$7-L22,$P$7-L22),"") -> 106 | N22: 3 | O22: 0 | P22: =IF(AND(K22>0,M22>0,OR(N22>0,O22>0)),(M22/((N22*60)+O22))*60,"") -> 35.333333 | Q22: =IFERROR(IF(OR(K22=1,K22=2),IF(K22=1,M22/$M$7,M22/$P$7),""),"") -> 0.87603306 | R22: 6 | S22: 3 | T22: Level 2 | U22: =IF(J22<>"",IF(J22="Full Refresher","Low Emerging Reader",IF(AND(K22>0,Q22<>""),IF(OR(Q22<=25%,AND(Q22>25%,Q22<=50%,R22<=1)),"High Emerging Reader",IF(OR(AND(Q22>25%,Q22<51%,R22>=2),AND(Q22>50%,Q22<76%,R22<=3)),"Developing Reader",IF(OR(AND(Q22>=51%,Q22<76%,R22>=4),AND(Q22>75%,R22<=5)),"Transitioning Reader",IF(AND(Q22>75%,R22>=6),"Reading At Grade Level","")))),"")),"") -> Reading At Grade Level
A23: 13 | B23: =IF('G3 MT Reading Scoresheet'!B23<>"",'G3 MT Reading Scoresheet'!B23,"") -> 117443220009 | C23: =IF('G3 MT Reading Scoresheet'!C23<>"",'G3 MT Reading Scoresheet'!C23,"") -> CARDINAL, LEXIE, SUNDAYON | D23: =IF('G3 MT Reading Scoresheet'!D23<>"",'G3 MT Reading Scoresheet'!D23,"") -> Female | E23: =IF('G3 MT Reading Scoresheet'!E23<>"",'G3 MT Reading Scoresheet'!E23,"") -> 45721 | F23: 10 | H23: 10 | I23: =IF(AND(F23="",G23=""),"",IF(F23<7,F23+G23,F23+10+H23)) -> 30 | J23: =IF(I23="","",IF(F23<7,IF(I23<=10,"Full Refresher","Moderate Refresher"),IF(I23<27,"Light Refresher","Grade Ready"))) -> Grade Ready | K23: 1 | L23: 2 | M23: =IF(OR(K23=1,K23=2),IF(K23=1,M$7-L23,$P$7-L23),"") -> 119 | N23: 1 | O23: 40 | P23: =IF(AND(K23>0,M23>0,OR(N23>0,O23>0)),(M23/((N23*60)+O23))*60,"") -> 71.4 | Q23: =IFERROR(IF(OR(K23=1,K23=2),IF(K23=1,M23/$M$7,M23/$P$7),""),"") -> 0.98347107 | R23: 7 | S23: 5 | T23: Level 4 | U23: =IF(J23<>"",IF(J23="Full Refresher","Low Emerging Reader",IF(AND(K23>0,Q23<>""),IF(OR(Q23<=25%,AND(Q23>25%,Q23<=50%,R23<=1)),"High Emerging Reader",IF(OR(AND(Q23>25%,Q23<51%,R23>=2),AND(Q23>50%,Q23<76%,R23<=3)),"Developing Reader",IF(OR(AND(Q23>=51%,Q23<76%,R23>=4),AND(Q23>75%,R23<=5)),"Transitioning Reader",IF(AND(Q23>75%,R23>=6),"Reading At Grade Level","")))),"")),"") -> Reading At Grade Level
A24: 14 | B24: =IF('G3 MT Reading Scoresheet'!B24<>"",'G3 MT Reading Scoresheet'!B24,"") | C24: =IF('G3 MT Reading Scoresheet'!C24<>"",'G3 MT Reading Scoresheet'!C24,"") -> DIONSON, AIRA, BAUTISTA | D24: =IF('G3 MT Reading Scoresheet'!D24<>"",'G3 MT Reading Scoresheet'!D24,"") -> Female | E24: =IF('G3 MT Reading Scoresheet'!E24<>"",'G3 MT Reading Scoresheet'!E24,"") -> 45721 | F24: 2 | G24: 5 | H24: 10 | I24: =IF(AND(F24="",G24=""),"",IF(F24<7,F24+G24,F24+10+H24)) -> 7 | J24: =IF(I24="","",IF(F24<7,IF(I24<=10,"Full Refresher","Moderate Refresher"),IF(I24<27,"Light Refresher","Grade Ready"))) -> Full Refresher | K24: 1 | L24: 1 | M24: =IF(OR(K24=1,K24=2),IF(K24=1,M$7-L24,$P$7-L24),"") -> 120 | N24: 1 | O24: 33 | P24: =IF(AND(K24>0,M24>0,OR(N24>0,O24>0)),(M24/((N24*60)+O24))*60,"") -> 77.419355 | Q24: =IFERROR(IF(OR(K24=1,K24=2),IF(K24=1,M24/$M$7,M24/$P$7),""),"") -> 0.99173554 | R24: 6 | S24: 5 | T24: Level 4 | U24: =IF(J24<>"",IF(J24="Full Refresher","Low Emerging Reader",IF(AND(K24>0,Q24<>""),IF(OR(Q24<=25%,AND(Q24>25%,Q24<=50%,R24<=1)),"High Emerging Reader",IF(OR(AND(Q24>25%,Q24<51%,R24>=2),AND(Q24>50%,Q24<76%,R24<=3)),"Developing Reader",IF(OR(AND(Q24>=51%,Q24<76%,R24>=4),AND(Q24>75%,R24<=5)),"Transitioning Reader",IF(AND(Q24>75%,R24>=6),"Reading At Grade Level","")))),"")),"") -> Low Emerging Reader
A25: 15 | B25: =IF('G3 MT Reading Scoresheet'!B25<>"",'G3 MT Reading Scoresheet'!B25,"") | C25: =IF('G3 MT Reading Scoresheet'!C25<>"",'G3 MT Reading Scoresheet'!C25,"") -> ESTOCADA, ANGEL, E. | D25: =IF('G3 MT Reading Scoresheet'!D25<>"",'G3 MT Reading Scoresheet'!D25,"") -> Female | E25: =IF('G3 MT Reading Scoresheet'!E25<>"",'G3 MT Reading Scoresheet'!E25,"") -> 45721 | F25: 8 | H25: 10 | I25: =IF(AND(F25="",G25=""),"",IF(F25<7,F25+G25,F25+10+H25)) -> 28 | J25: =IF(I25="","",IF(F25<7,IF(I25<=10,"Full Refresher","Moderate Refresher"),IF(I25<27,"Light Refresher","Grade Ready"))) -> Grade Ready | K25: 1 | L25: 0 | M25: =IF(OR(K25=1,K25=2),IF(K25=1,M$7-L25,$P$7-L25),"") -> 121 | N25: 1 | O25: 35 | P25: =IF(AND(K25>0,M25>0,OR(N25>0,O25>0)),(M25/((N25*60)+O25))*60,"") -> 76.421053 | Q25: =IFERROR(IF(OR(K25=1,K25=2),IF(K25=1,M25/$M$7,M25/$P$7),""),"") -> 1 | R25: 7 | S25: 5 | T25: Level 4 | U25: =IF(J25<>"",IF(J25="Full Refresher","Low Emerging Reader",IF(AND(K25>0,Q25<>""),IF(OR(Q25<=25%,AND(Q25>25%,Q25<=50%,R25<=1)),"High Emerging Reader",IF(OR(AND(Q25>25%,Q25<51%,R25>=2),AND(Q25>50%,Q25<76%,R25<=3)),"Developing Reader",IF(OR(AND(Q25>=51%,Q25<76%,R25>=4),AND(Q25>75%,R25<=5)),"Transitioning Reader",IF(AND(Q25>75%,R25>=6),"Reading At Grade Level","")))),"")),"") -> Reading At Grade Level
A26: 16 | B26: =IF('G3 MT Reading Scoresheet'!B26<>"",'G3 MT Reading Scoresheet'!B26,"") -> 117443220010 | C26: =IF('G3 MT Reading Scoresheet'!C26<>"",'G3 MT Reading Scoresheet'!C26,"") -> ESTOCADA, GENYZA, BACARO | D26: =IF('G3 MT Reading Scoresheet'!D26<>"",'G3 MT Reading Scoresheet'!D26,"") -> Female | E26: =IF('G3 MT Reading Scoresheet'!E26<>"",'G3 MT Reading Scoresheet'!E26,"") -> 45721 | F26: 10 | H26: 10 | I26: =IF(AND(F26="",G26=""),"",IF(F26<7,F26+G26,F26+10+H26)) -> 30 | J26: =IF(I26="","",IF(F26<7,IF(I26<=10,"Full Refresher","Moderate Refresher"),IF(I26<27,"Light Refresher","Grade Ready"))) -> Grade Ready | K26: 1 | L26: 15 | M26: =IF(OR(K26=1,K26=2),IF(K26=1,M$7-L26,$P$7-L26),"") -> 106 | N26: 3 | O26: 0 | P26: =IF(AND(K26>0,M26>0,OR(N26>0,O26>0)),(M26/((N26*60)+O26))*60,"") -> 35.333333 | Q26: =IFERROR(IF(OR(K26=1,K26=2),IF(K26=1,M26/$M$7,M26/$P$7),""),"") -> 0.87603306 | R26: 6 | S26: 4 | T26: Level 2 | U26: =IF(J26<>"",IF(J26="Full Refresher","Low Emerging Reader",IF(AND(K26>0,Q26<>""),IF(OR(Q26<=25%,AND(Q26>25%,Q26<=50%,R26<=1)),"High Emerging Reader",IF(OR(AND(Q26>25%,Q26<51%,R26>=2),AND(Q26>50%,Q26<76%,R26<=3)),"Developing Reader",IF(OR(AND(Q26>=51%,Q26<76%,R26>=4),AND(Q26>75%,R26<=5)),"Transitioning Reader",IF(AND(Q26>75%,R26>=6),"Reading At Grade Level","")))),"")),"") -> Reading At Grade Level
A27: 17 | B27: =IF('G3 MT Reading Scoresheet'!B27<>"",'G3 MT Reading Scoresheet'!B27,"") | C27: =IF('G3 MT Reading Scoresheet'!C27<>"",'G3 MT Reading Scoresheet'!C27,"") -> ESTOCADA, JERCEL JANE, SIASAT | D27: =IF('G3 MT Reading Scoresheet'!D27<>"",'G3 MT Reading Scoresheet'!D27,"") -> Female | E27: =IF('G3 MT Reading Scoresheet'!E27<>"",'G3 MT Reading Scoresheet'!E27,"") -> 45722 | F27: 10 | H27: 10 | I27: =IF(AND(F27="",G27=""),"",IF(F27<7,F27+G27,F27+10+H27)) -> 30 | J27: =IF(I27="","",IF(F27<7,IF(I27<=10,"Full Refresher","Moderate Refresher"),IF(I27<27,"Light Refresher","Grade Ready"))) -> Grade Ready | K27: 1 | L27: 1 | M27: =IF(OR(K27=1,K27=2),IF(K27=1,M$7-L27,$P$7-L27),"") -> 120 | N27: 2 | O27: 32 | P27: =IF(AND(K27>0,M27>0,OR(N27>0,O27>0)),(M27/((N27*60)+O27))*60,"") -> 47.368421 | Q27: =IFERROR(IF(OR(K27=1,K27=2),IF(K27=1,M27/$M$7,M27/$P$7),""),"") -> 0.99173554 | R27: 6 | S27: 5 | T27: Level 4 | U27: =IF(J27<>"",IF(J27="Full Refresher","Low Emerging Reader",IF(AND(K27>0,Q27<>""),IF(OR(Q27<=25%,AND(Q27>25%,Q27<=50%,R27<=1)),"High Emerging Reader",IF(OR(AND(Q27>25%,Q27<51%,R27>=2),AND(Q27>50%,Q27<76%,R27<=3)),"Developing Reader",IF(OR(AND(Q27>=51%,Q27<76%,R27>=4),AND(Q27>75%,R27<=5)),"Transitioning Reader",IF(AND(Q27>75%,R27>=6),"Reading At Grade Level","")))),"")),"") -> Reading At Grade Level
A28: 18 | B28: =IF('G3 MT Reading Scoresheet'!B28<>"",'G3 MT Reading Scoresheet'!B28,"") -> 1206372200024 | C28: =IF('G3 MT Reading Scoresheet'!C28<>"",'G3 MT Reading Scoresheet'!C28,"") -> ESTOCADA, REANNA, LLAGOSO | D28: =IF('G3 MT Reading Scoresheet'!D28<>"",'G3 MT Reading Scoresheet'!D28,"") -> Female | E28: =IF('G3 MT Reading Scoresheet'!E28<>"",'G3 MT Reading Scoresheet'!E28,"") -> 45722 | F28: 10 | H28: 10 | I28: =IF(AND(F28="",G28=""),"",IF(F28<7,F28+G28,F28+10+H28)) -> 30 | J28: =IF(I28="","",IF(F28<7,IF(I28<=10,"Full Refresher","Moderate Refresher"),IF(I28<27,"Light Refresher","Grade Ready"))) -> Grade Ready | K28: 1 | L28: 3 | M28: =IF(OR(K28=1,K28=2),IF(K28=1,M$7-L28,$P$7-L28),"") -> 118 | N28: 1 | O28: 35 | P28: =IF(AND(K28>0,M28>0,OR(N28>0,O28>0)),(M28/((N28*60)+O28))*60,"") -> 74.526316 | Q28: =IFERROR(IF(OR(K28=1,K28=2),IF(K28=1,M28/$M$7,M28/$P$7),""),"") -> 0.97520661 | R28: 6 | S28: 5 | T28: Level 3 | U28: =IF(J28<>"",IF(J28="Full Refresher","Low Emerging Reader",IF(AND(K28>0,Q28<>""),IF(OR(Q28<=25%,AND(Q28>25%,Q28<=50%,R28<=1)),"High Emerging Reader",IF(OR(AND(Q28>25%,Q28<51%,R28>=2),AND(Q28>50%,Q28<76%,R28<=3)),"Developing Reader",IF(OR(AND(Q28>=51%,Q28<76%,R28>=4),AND(Q28>75%,R28<=5)),"Transitioning Reader",IF(AND(Q28>75%,R28>=6),"Reading At Grade Level","")))),"")),"") -> Reading At Grade Level
