Workbook

Sheet G1 MT Reading Scoresheet
A1: CRLA3v3
A3: ASSESSMENT TYPE | C3: EoSY
A4: School ID: | C4: 117443 | D4: Total Enrolment | F4: =D6+E6 -> 14 | G4: Total Assessed : | I4: =COUNTIF(F11:F110,"<>") -> 14
A5: Schoo Name: | C5: ROMANA ELEMENTARY SCHOOL | D5: Male | E5: Female | F5: Assessment Part 1 (Letter Sounds, Rhyming Words and Sentences Reading) | J5: RHYME SCORE 0 to 10 – Full Refresher 11 to 16 – Moderate Refresher SENTENCE SCORE 17 to 26 – Light Refresher 27 to 30 – Grade Ready | K5: Asssessment Part 2 (Reading Fluency and Comprehension)
A6: Teacher: | C6: MARIAN GRACE D. DE LA TORRE | D6: 10 | E6: 4
A7: Grade: | C7: Grade 1 | D7: Total Words per Story | F7: Task 1 – Write the number of letters sounded out correctly | G7: Rhymes (Task 2) If task 1 score is 0 to 6 | H7: Sentence (Task 2) If task 1 score is 7 to 10 Task 2L=10 | I7: Total Score = Task 1 Score + Task 2L+Task 2H Score | K7: Total Words Per Story | L7: Story 1 | M7: =_xlfn.IFNA(IF(X8=1,Y8,IF(D9>0,D9,50)),"") -> 50 | N7: Story 2 | P7: =_xlfn.IFNA(IF(X8=1,Z8,IF(E9>0,E9,50)),"") -> 49 | Y7: Story 1 | Z7: Story 2
A8: Section: | C8: 1 | D8: Story 1 | E8: Story 2 | K8: Story Number 1 or 2 | L8: Total Reading Miscues | M8: Number of Words Read within 1 min | N8: Total Time Used in Reading (Max : 1 Min) | P8: Number of Words per Minute (WPM) | X8: =IF(_xlfn.IFNA(VLOOKUP(C9,List!G2:G21,1,0),"")=C9,1,0) -> 1 | Y8: =VLOOKUP($C$9,List!$G$2:$M$21,4,0) -> 50 | Z8: =VLOOKUP($C$9,List!$G$2:$M$21,7,0) -> 49
A9: Language: | C9: Hiligaynon | X9: 10 | Y9: 20 | AA9: 5
A10: S/N | B10: LRN | C10: Name of Learner | D10: Sex | E10: Date of Asessment | F10: Task 1 (10) | G10: Task 2L Rymes (10) | H10: Task 2H Sentences (10) | I10: Total Score | J10: Assessment Part 1 Reading Level | K10: Story Number | L10: Number of Miscue | M10: Words Read | N10: Total Mins Secs | P10: WPM | Q10: % of Correct Words Read | R10: Total Correct Answer | S10: Leaner Experience (Rating 1-5) | T10: Observation Level | U10: LEARNER READING PROFILE | V10: Remarks | X10: Task 1 | Z10: Task 3 | AA10: Task 4
A11: 1 | B11: 117443240002 | C11: CARDINAL,CIAN, DEMIAR | D11: Male | E11: 46072 | F11: 10 | H11: 8 | I11: =IF(AND(F11="",G11=""),"",IF(F11<7,F11+G11,F11+10+H11)) -> 28 | J11: =IF(I11="","",IF(F11<7,IF(I11<=10,"Full Refresher","Moderate Refresher"),IF(I11<27,"Light Refresher","Grade Ready"))) -> Grade Ready | K11: 1 | L11: 15 | M11: =IF($C$9<>"",IF(OR(K11=1,K11=2),IF(K11=1,M$7-L11,$P$7-L11),""),"") -> 35 | N11: 1 | O11: 0 | P11: =IFERROR(IF(AND(K11>0,M11>0,OR(N11>0,O11>0)),(M11/((N11*60)+O11))*60,""),"") -> 35 | Q11: =IFERROR(IF(OR(K11=1,K11=2),IF(K11=1,M11/$M$7,M11/$P$7),""),"") -> 0.7 | R11: 3 | S11: 5 | T11: Level 1 | U11: =IF(J11<>"",IF(OR(J11="Full Refresher",J11="Moderate Refresher"),"Low Emerging Reader",IF(AND(K11>0,Q11<>""),IF(OR(Q11<=25%,AND(Q11>25%,Q11<=50%,R11=0)),"High Emerging Reader",IF(OR(AND(Q11>25%,Q11<51%,R11>=1),AND(Q11>50%,Q11<76%,R11<=1)),"Developing Reader",IF(OR(AND(Q11>=51%,Q11<76%,R11>=2),AND(Q11>75%,R11<=3)),"Transitioning Reader",IF(AND(Q11>75%,R11>=4),"Reading At Grade Level","")))),"")),"") -> Transitioning Reader | X11: =IF(C11<>"",$I11/30,"") -> 0.93333333 | Z11: =IF($C11<>"",IF($F11>6,Q11,0%),"") -> 0.7 | AA11: =IF($C11<>"",IF($F11>6,S11/$AA$9,0%),"") -> 1
A12: 2 | B12: 117443240003 | C12: CARDINAL,REY ROES, PANGANTIHON | D12: Male | E12: 46072 | F12: 10 | H12: 10 | I12: =IF(AND(F12="",G12=""),"",IF(F12<7,F12+G12,F12+10+H12)) -> 30 | J12: =IF(I12="","",IF(F12<7,IF(I12<=10,"Full Refresher","Moderate Refresher"),IF(I12<27,"Light Refresher","Grade Ready"))) -> Grade Ready | K12: 1 | L12: 0 | M12: =IF($C$9<>"",IF(OR(K12=1,K12=2),IF(K12=1,M$7-L12,$P$7-L12),""),"") -> 50 | N12: 1 | O12: 0 | P12: =IFERROR(IF(AND(K12>0,M12>0,OR(N12>0,O12>0)),(M12/((N12*60)+O12))*60,""),"") -> 50 | Q12: =IFERROR(IF(OR(K12=1,K12=2),IF(K12=1,M12/$M$7,M12/$P$7),""),"") -> 1 | R12: 5 | S12: 5 | T12: Level 3 | U12: =IF(J12<>"",IF(OR(J12="Full Refresher",J12="Moderate Refresher"),"Low Emerging Reader",IF(AND(K12>0,Q12<>""),IF(OR(Q12<=25%,AND(Q12>25%,Q12<=50%,R12=0)),"High Emerging Reader",IF(OR(AND(Q12>25%,Q12<51%,R12>=1),AND(Q12>50%,Q12<76%,R12<=1)),"Developing Reader",IF(OR(AND(Q12>=51%,Q12<76%,R12>=2),AND(Q12>75%,R12<=3)),"Transitioning Reader",IF(AND(Q12>75%,R12>=4),"Reading At Grade Level","")))),"")),"") -> Reading At Grade Level | X12: =IF(C12<>"",$I12/30,"") -> 1 | Z12: =IF($C12<>"",IF($F12>6,Q12,0%),"") -> 1 | AA12: =IF($C12<>"",IF($F12>6,S12/$AA$9,0%),"") -> 1
A13: 3 | B13: 117443240005 | C13: FRANTE,ARK JAY, CABALLERO | D13: Male | E13: 46072 | F13: 10 | H13: 10 | I13: =IF(AND(F13="",G13=""),"",IF(F13<7,F13+G13,F13+10+H13)) -> 30 | J13: =IF(I13="","",IF(F13<7,IF(I13<=10,"Full Refresher","Moderate Refresher"),IF(I13<27,"Light Refresher","Grade Ready"))) -> Grade Ready | K13: 1 | L13: 0 | M13: =IF($C$9<>"",IF(OR(K13=1,K13=2),IF(K13=1,M$7-L13,$P$7-L13),""),"") -> 50 | N13: 1 | O13: 0 | P13: =IFERROR(IF(AND(K13>0,M13>0,OR(N13>0,O13>0)),(M13/((N13*60)+O13))*60,""),"") -> 50 | Q13: =IFERROR(IF(OR(K13=1,K13=2),IF(K13=1,M13/$M$7,M13/$P$7),""),"") -> 1 | R13: 4 | S13: 5 | T13: Level 3 | U13: =IF(J13<>"",IF(OR(J13="Full Refresher",J13="Moderate Refresher"),"Low Emerging Reader",IF(AND(K13>0,Q13<>""),IF(OR(Q13<=25%,AND(Q13>25%,Q13<=50%,R13=0)),"High Emerging Reader",IF(OR(AND(Q13>25%,Q13<51%,R13>=1),AND(Q13>50%,Q13<76%,R13<=1)),"Developing Reader",IF(OR(AND(Q13>=51%,Q13<76%,R13>=2),AND(Q13>75%,R13<=3)),"Transitioning Reader",IF(AND(Q13>75%,R13>=4),"Reading At Grade Level","")))),"")),"") -> Reading At Grade Level | X13: =IF(C13<>"",$I13/30,"") -> 1 | Z13: =IF($C13<>"",IF($F13>6,Q13,0%),"") -> 1 | AA13: =IF($C13<>"",IF($F13>6,S13/$AA$9,0%),"") -> 1
A14: 4 | B14: 117443240006 | C14: GANCIA,JELLO, GIER | D14: Male | E14: 46072 | F14: 3 | G14: 4 | I14: =IF(AND(F14="",G14=""),"",IF(F14<7,F14+G14,F14+10+H14)) -> 7 | J14: =IF(I14="","",IF(F14<7,IF(I14<=10,"Full Refresher","Moderate Refresher"),IF(I14<27,"Light Refresher","Grade Ready"))) -> Full Refresher | M14: =IF($C$9<>"",IF(OR(K14=1,K14=2),IF(K14=1,M$7-L14,$P$7-L14),""),"") | N14: 1 | P14: =IFERROR(IF(AND(K14>0,M14>0,OR(N14>0,O14>0)),(M14/((N14*60)+O14))*60,""),"") | Q14: =IFERROR(IF(OR(K14=1,K14=2),IF(K14=1,M14/$M$7,M14/$P$7),""),"") | U14: =IF(J14<>"",IF(OR(J14="Full Refresher",J14="Moderate Refresher"),"Low Emerging Reader",IF(AND(K14>0,Q14<>""),IF(OR(Q14<=25%,AND(Q14>25%,Q14<=50%,R14=0)),"High Emerging Reader",IF(OR(AND(Q14>25%,Q14<51%,R14>=1),AND(Q14>50%,Q14<76%,R14<=1)),"Developing Reader",IF(OR(AND(Q14>=51%,Q14<76%,R14>=2),AND(Q14>75%,R14<=3)),"Transitioning Reader",IF(AND(Q14>75%,R14>=4),"Reading At Grade Level","")))),"")),"") -> Low Emerging Reader | X14: =IF(C14<>"",$I14/30,"") -> 0.23333333 | Z14: =IF($C14<>"",IF($F14>6,Q14,0%),"") -> 0 | AA14: =IF($C14<>"",IF($F14>6,S14/$AA$9,0%),"") -> 0
A15: 5 | B15: 117443230006 | C15: GANCIA, RHAYCO, NARCISO | D15: Male | E15: 46072 | F15: 7 | H15: 5 | I15: =IF(AND(F15="",G15=""),"",IF(F15<7,F15+G15,F15+10+H15)) -> 22 | J15: =IF(I15="","",IF(F15<7,IF(I15<=10,"Full Refresher","Moderate Refresher"),IF(I15<27,"Light Refresher","Grade Ready"))) -> Light Refresher | K15: 1 | L15: 20 | M15: =IF($C$9<>"",IF(OR(K15=1,K15=2),IF(K15=1,M$7-L15,$P$7-L15),""),"") -> 30 | N15: 1 | O15: 0 | P15: =IFERROR(IF(AND(K15>0,M15>0,OR(N15>0,O15>0)),(M15/((N15*60)+O15))*60,""),"") -> 30 | Q15: =IFERROR(IF(OR(K15=1,K15=2),IF(K15=1,M15/$M$7,M15/$P$7),""),"") -> 0.6 | R15: 2 | S15: 5 | T15: Level 1 | U15: =IF(J15<>"",IF(OR(J15="Full Refresher",J15="Moderate Refresher"),"Low Emerging Reader",IF(AND(K15>0,Q15<>""),IF(OR(Q15<=25%,AND(Q15>25%,Q15<=50%,R15=0)),"High Emerging Reader",IF(OR(AND(Q15>25%,Q15<51%,R15>=1),AND(Q15>50%,Q15<76%,R15<=1)),"Developing Reader",IF(OR(AND(Q15>=51%,Q15<76%,R15>=2),AND(Q15>75%,R15<=3)),"Transitioning Reader",IF(AND(Q15>75%,R15>=4),"Reading At Grade Level","")))),"")),"") -> Transitioning Reader | X15: =IF(C15<>"",$I15/30,"") -> 0.73333333 | Z15: =IF($C15<>"",IF($F15>6,Q15,0%),"") -> 0.6 | AA15: =IF($C15<>"",IF($F15>6,S15/$AA$9,0%),"") -> 1
A16: 6 | B16: 117443240004 | C16: GARDOSE,KIETH DION, CADUCOY | D16: Male | E16: 46072 | F16: 7 | G16: 7 | H16: 3 | I16: =IF(AND(F16="",G16=""),"",IF(F16<7,F16+G16,F16+10+H16)) -> 20 | J16: =IF(I16="","",IF(F16<7,IF(I16<=10,"Full Refresher","Moderate Refresher"),IF(I16<27,"Light Refresher","Grade Ready"))) -> Light Refresher | K16: 1 | L16: 25 | M16: =IF($C$9<>"",IF(OR(K16=1,K16=2),IF(K16=1,M$7-L16,$P$7-L16),""),"") -> 25 | N16: 1 | O16: 0 | P16: =IFERROR(IF(AND(K16>0,M16>0,OR(N16>0,O16>0)),(M16/((N16*60)+O16))*60,""),"") -> 25 | Q16: =IFERROR(IF(OR(K16=1,K16=2),IF(K16=1,M16/$M$7,M16/$P$7),""),"") -> 0.5 | R16: 2 | S16: 5 | T16: Level 1 | U16: =IF(J16<>"",IF(OR(J16="Full Refresher",J16="Moderate Refresher"),"Low Emerging Reader",IF(AND(K16>0,Q16<>""),IF(OR(Q16<=25%,AND(Q16>25%,Q16<=50%,R16=0)),"High Emerging Reader",IF(OR(AND(Q16>25%,Q16<51%,R16>=1),AND(Q16>50%,Q16<76%,R16<=1)),"Developing Reader",IF(OR(AND(Q16>=51%,Q16<76%,R16>=2),AND(Q16>75%,R16<=3)),"Transitioning Reader",IF(AND(Q16>75%,R16>=4),"Reading At Grade Level","")))),"")),"") -> Developing Reader | X16: =IF(C16<>"",$I16/30,"") -> 0.66666667 | Z16: =IF($C16<>"",IF($F16>6,Q16,0%),"") -> 0.5 | AA16: =IF($C16<>"",IF($F16>6,S16/$AA$9,0%),"") -> 1
A17: 7 | B17: 117443240007 | C17: GILUA,ARON JAMES, SUNDAYON | D17: Male | E17: 46072 | F17: 10 | H17: 8 | I17: =IF(AND(F17="",G17=""),"",IF(F17<7,F17+G17,F17+10+H17)) -> 28 | J17: =IF(I17="","",IF(F17<7,IF(I17<=10,"Full Refresher","Moderate Refresher"),IF(I17<27,"Light Refresher","Grade Ready"))) -> Grade Ready | K17: 1 | L17: 10 | M17: =IF($C$9<>"",IF(OR(K17=1,K17=2),IF(K17=1,M$7-L17,$P$7-L17),""),"") -> 40 | N17: 1 | O17: 0 | P17: =IFERROR(IF(AND(K17>0,M17>0,OR(N17>0,O17>0)),(M17/((N17*60)+O17))*60,""),"") -> 40 | Q17: =IFERROR(IF(OR(K17=1,K17=2),IF(K17=1,M17/$M$7,M17/$P$7),""),"") -> 0.8 | R17: 4 | S17: 5 | T17: Level 2 | U17: =IF(J17<>"",IF(OR(J17="Full Refresher",J17="Moderate Refresher"),"Low Emerging Reader",IF(AND(K17>0,Q17<>""),IF(OR(Q17<=25%,AND(Q17>25%,Q17<=50%,R17=0)),"High Emerging Reader",IF(OR(AND(Q17>25%,Q17<51%,R17>=1),AND(Q17>50%,Q17<76%,R17<=1)),"Developing Reader",IF(OR(AND(Q17>=51%,Q17<76%,R17>=2),AND(Q17>75%,R17<=3)),"Transitioning Reader",IF(AND(Q17>75%,R17>=4),"Reading At Grade Level","")))),"")),"") -> Reading At Grade Level | X17: =IF(C17<>"",$I17/30,"") -> 0.93333333 | Z17: =IF($C17<>"",IF($F17>6,Q17,0%),"") -> 0.8 | AA17: =IF($C17<>"",IF($F17>6,S17/$AA$9,0%),"") -> 1
A18: 8 | B18: 117443240008 | C18: LABANZA,DAVID RHON, PALACIO | D18: Male | E18: 46072 | F18: 10 | H18: 8 | I18: =IF(AND(F18="",G18=""),"",IF(F18<7,F18+G18,F18+10+H18)) -> 28 | J18: =IF(I18="","",IF(F18<7,IF(I18<=10,"Full Refresher","Moderate Refresher"),IF(I18<27,"Light Refresher","Grade Ready"))) -> Grade Ready | K18: 1 | L18: 20 | M18: =IF($C$9<>"",IF(OR(K18=1,K18=2),IF(K18=1,M$7-L18,$P$7-L18),""),"") -> 30 | N18: 1 | O18: 0 | P18: =IFERROR(IF(AND(K18>0,M18>0,OR(N18>0,O18>0)),(M18/((N18*60)+O18))*60,""),"") -> 30 | Q18: =IFERROR(IF(OR(K18=1,K18=2),IF(K18=1,M18/$M$7,M18/$P$7),""),"") -> 0.6 | R18: 4 | S18: 5 | T18: Level 1 | U18: =IF(J18<>"",IF(OR(J18="Full Refresher",J18="Moderate Refresher"),"Low Emerging Reader",IF(AND(K18>0,Q18<>""),IF(OR(Q18<=25%,AND(Q18>25%,Q18<=50%,R18=0)),"High Emerging Reader",IF(OR(AND(Q18>25%,Q18<51%,R18>=1),AND(Q18>50%,Q18<76%,R18<=1)),"Developing Reader",IF(OR(AND(Q18>=51%,Q18<76%,R18>=2),AND(Q18>75%,R18<=3)),"Transitioning Reader",IF(AND(Q18>75%,R18>=4),"Reading At Grade Level","")))),"")),"") -> Transitioning Reader | X18: =IF(C18<>"",$I18/30,"") -> 0.93333333 | Z18: =IF($C18<>"",IF($F18>6,Q18,0%),"") -> 0.6 | AA18: =IF($C18<>"",IF($F18>6,S18/$AA$9,0%),"") -> 1
A19: 9 | B19: 117443240009 | C19: LABANZA,JAY-K, NOBLE | D19: Male | E19: 46072 | F19: 3 | G19: 4 | I19: =IF(AND(F19="",G19=""),"",IF(F19<7,F19+G19,F19+10+H19)) -> 7 | J19: =IF(I19="","",IF(F19<7,IF(I19<=10,"Full Refresher","Moderate Refresher"),IF(I19<27,"Light Refresher","Grade Ready"))) -> Full Refresher | M19: =IF($C$9<>"",IF(OR(K19=1,K19=2),IF(K19=1,M$7-L19,$P$7-L19),""),"") | P19: =IFERROR(IF(AND(K19>0,M19>0,OR(N19>0,O19>0)),(M19/((N19*60)+O19))*60,""),"") | Q19: =IFERROR(IF(OR(K19=1,K19=2),IF(K19=1,M19/$M$7,M19/$P$7),""),"") | U19: =IF(J19<>"",IF(OR(J19="Full Refresher",J19="Moderate Refresher"),"Low Emerging Reader",IF(AND(K19>0,Q19<>""),IF(OR(Q19<=25%,AND(Q19>25%,Q19<=50%,R19=0)),"High Emerging Reader",IF(OR(AND(Q19>25%,Q19<51%,R19>=1),AND(Q19>50%,Q19<76%,R19<=1)),"Developing Reader",IF(OR(AND(Q19>=51%,Q19<76%,R19>=2),AND(Q19>75%,R19<=3)),"Transitioning Reader",IF(AND(Q19>75%,R19>=4),"Reading At Grade Level","")))),"")),"") -> Low Emerging Reader | X19: =IF(C19<>"",$I19/30,"") -> 0.23333333 | Z19: =IF($C19<>"",IF($F19>6,Q19,0%),"") -> 0 | AA19: =IF($C19<>"",IF($F19>6,S19/$AA$9,0%),"") -> 0
A20: 10 | B20: 117443240010 | C20: LANGYON,JOHN KENNETH, ESTOCADA | D20: Male | E20: 46072 | F20: 0 | G20: 0 | I20: =IF(AND(F20="",G20=""),"",IF(F20<7,F20+G20,F20+10+H20)) -> 0 | J20: =IF(I20="","",IF(F20<7,IF(I20<=10,"Full Refresher","Moderate Refresher"),IF(I20<27,"Light Refresher","Grade Ready"))) -> Full Refresher | M20: =IF($C$9<>"",IF(OR(K20=1,K20=2),IF(K20=1,M$7-L20,$P$7-L20),""),"") | P20: =IFERROR(IF(AND(K20>0,M20>0,OR(N20>0,O20>0)),(M20/((N20*60)+O20))*60,""),"") | Q20: =IFERROR(IF(OR(K20=1,K20=2),IF(K20=1,M20/$M$7,M20/$P$7),""),"") | U20: =IF(J20<>"",IF(OR(J20="Full Refresher",J20="Moderate Refresher"),"Low Emerging Reader",IF(AND(K20>0,Q20<>""),IF(OR(Q20<=25%,AND(Q20>25%,Q20<=50%,R20=0)),"High Emerging Reader",IF(OR(AND(Q20>25%,Q20<51%,R20>=1),AND(Q20>50%,Q20<76%,R20<=1)),"Developing Reader",IF(OR(AND(Q20>=51%,Q20<76%,R20>=2),AND(Q20>75%,R20<=3)),"Transitioning Reader",IF(AND(Q20>75%,R20>=4),"Reading At Grade Level","")))),"")),"") -> Low Emerging Reader | X20: =IF(C20<>"",$I20/30,"") -> 0 | Z20: =IF($C20<>"",IF($F20>6,Q20,0%),"") -> 0 | AA20: =IF($C20<>"",IF($F20>6,S20/$AA$9,0%),"") -> 0
A21: 11 | B21: 117443240012 | C21: ESLANA,SHANEL, JACOMILLA | D21: Female | E21: 46073 | F21: 10 | H21: 10 | I21: =IF(AND(F21="",G21=""),"",IF(F21<7,F21+G21,F21+10+H21)) -> 30 | J21: =IF(I21="","",IF(F21<7,IF(I21<=10,"Full Refresher","Moderate Refresher"),IF(I21<27,"Light Refresher","Grade Ready"))) -> Grade Ready | K21: 1 | L21: 0 | M21: =IF($C$9<>"",IF(OR(K21=1,K21=2),IF(K21=1,M$7-L21,$P$7-L21),""),"") -> 50 | N21: 1 | O21: 0 | P21: =IFERROR(IF(AND(K21>0,M21>0,OR(N21>0,O21>0)),(M21/((N21*60)+O21))*60,""),"") -> 50 | Q21: =IFERROR(IF(OR(K21=1,K21=2),IF(K21=1,M21/$M$7,M21/$P$7),""),"") -> 1 | R21: 5 | S21: 5 | T21: Level 3 | U21: =IF(J21<>"",IF(OR(J21="Full Refresher",J21="Moderate Refresher"),"Low Emerging Reader",IF(AND(K21>0,Q21<>""),IF(OR(Q21<=25%,AND(Q21>25%,Q21<=50%,R21=0)),"High Emerging Reader",IF(OR(AND(Q21>25%,Q21<51%,R21>=1),AND(Q21>50%,Q21<76%,R21<=1)),"Developing Reader",IF(OR(AND(Q21>=51%,Q21<76%,R21>=2),AND(Q21>75%,R21<=3)),"Transitioning Reader",IF(AND(Q21>75%,R21>=4),"Reading At Grade Level","")))),"")),"") -> Reading At Grade Level | X21: =IF(C21<>"",$I21/30,"") -> 1 | Z21: =IF($C21<>"",IF($F21>6,Q21,0%),"") -> 1 | AA21: =IF($C21<>"",IF($F21>6,S21/$AA$9,0%),"") -> 1
A22: 12 | B22: 117443240013 | C22: JUMBAS,JHANEZZA KAYE, ARCENAL | D22: Female | E22: 46073 | F22: 10 | H22: 10 | I22: =IF(AND(F22="",G22=""),"",IF(F22<7,F22+G22,F22+10+H22)) -> 30 | J22: =IF(I22="","",IF(F22<7,IF(I22<=10,"Full Refresher","Moderate Refresher"),IF(I22<27,"Light Refresher","Grade Ready"))) -> Grade Ready | K22: 1 | L22: 0 | M22: =IF($C$9<>"",IF(OR(K22=1,K22=2),IF(K22=1,M$7-L22,$P$7-L22),""),"") -> 50 | N22: 1 | O22: 0 | P22: =IFERROR(IF(AND(K22>0,M22>0,OR(N22>0,O22>0)),(M22/((N22*60)+O22))*60,""),"") -> 50 | Q22: =IFERROR(IF(OR(K22=1,K22=2),IF(K22=1,M22/$M$7,M22/$P$7),""),"") -> 1 | R22: 5 | S22: 5 | T22: Level 3 | U22: =IF(J22<>"",IF(OR(J22="Full Refresher",J22="Moderate Refresher"),"Low Emerging Reader",IF(AND(K22>0,Q22<>""),IF(OR(Q22<=25%,AND(Q22>25%,Q22<=50%,R22=0)),"High Emerging Reader",IF(OR(AND(Q22>25%,Q22<51%,R22>=1),AND(Q22>50%,Q22<76%,R22<=1)),"Developing Reader",IF(OR(AND(Q22>=51%,Q22<76%,R22>=2),AND(Q22>75%,R22<=3)),"Transitioning Reader",IF(AND(Q22>75%,R22>=4),"Reading At Grade Level","")))),"")),"") -> Reading At Grade Level | X22: =IF(C22<>"",$I22/30,"") -> 1 | Z22: =IF($C22<>"",IF($F22>6,Q22,0%),"") -> 1 | AA22: =IF($C22<>"",IF($F22>6,S22/$AA$9,0%),"") -> 1
A23: 13 | B23: 117443240014 | C23: LLAGOSO,PAULA JADE, RICABO | D23: Female | E23: 46073 | F23: 10 | H23: 10 | I23: =IF(AND(F23="",G23=""),"",IF(F23<7,F23+G23,F23+10+H23)) -> 30 | J23: =IF(I23="","",IF(F23<7,IF(I23<=10,"Full Refresher","Moderate Refresher"),IF(I23<27,"Light Refresher","Grade Ready"))) -> Grade Ready | K23: 1 | L23: 0 | M23: =IF($C$9<>"",IF(OR(K23=1,K23=2),IF(K23=1,M$7-L23,$P$7-L23),""),"") -> 50 | N23: 1 | O23: 0 | P23: =IFERROR(IF(AND(K23>0,M23>0,OR(N23>0,O23>0)),(M23/((N23*60)+O23))*60,""),"") -> 50 | Q23: =IFERROR(IF(OR(K23=1,K23=2),IF(K23=1,M23/$M$7,M23/$P$7),""),"") -> 1 | R23: 5 | S23: 5 | T23: Level 4 | U23: =IF(J23<>"",IF(OR(J23="Full Refresher",J23="Moderate Refresher"),"Low Emerging Reader",IF(AND(K23>0,Q23<>""),IF(OR(Q23<=25%,AND(Q23>25%,Q23<=50%,R23=0)),"High Emerging Reader",IF(OR(AND(Q23>25%,Q23<51%,R23>=1),AND(Q23>50%,Q23<76%,R23<=1)),"Developing Reader",IF(OR(AND(Q23>=51%,Q23<76%,R23>=2),AND(Q23>75%,R23<=3)),"Transitioning Reader",IF(AND(Q23>75%,R23>=4),"Reading At Grade Level","")))),"")),"") -> Reading At Grade Level | X23: =IF(C23<>"",$I23/30,"") -> 1 | Z23: =IF($C23<>"",IF($F23>6,Q23,0%),"") -> 1 | AA23: =IF($C23<>"",IF($F23>6,S23/$AA$9,0%),"") -> 1
A24: 14 | B24: 117441240034 | C24: MESIAS, SAVINNAH DOMINIQUE, GARDOSE | D24: Female | E24: 46073 | F24: 10 | H24: 10 | I24: =IF(AND(F24="",G24=""),"",IF(F24<7,F24+G24,F24+10+H24)) -> 30 | J24: =IF(I24="","",IF(F24<7,IF(I24<=10,"Full Refresher","Moderate Refresher"),IF(I24<27,"Light Refresher","Grade Ready"))) -> Grade Ready | K24: 1 | L24: 0 | M24: =IF($C$9<>"",IF(OR(K24=1,K24=2),IF(K24=1,M$7-L24,$P$7-L24),""),"") -> 50 | N24: 1 | O24: 0 | P24: =IFERROR(IF(AND(K24>0,M24>0,OR(N24>0,O24>0)),(M24/((N24*60)+O24))*60,""),"") -> 50 | Q24: =IFERROR(IF(OR(K24=1,K24=2),IF(K24=1,M24/$M$7,M24/$P$7),""),"") -> 1 | R24: 5 | S24: 5 | T24: Level 3 | U24: =IF(J24<>"",IF(OR(J24="Full Refresher",J24="Moderate Refresher"),"Low Emerging Reader",IF(AND(K24>0,Q24<>""),IF(OR(Q24<=25%,AND(Q24>25%,Q24<=50%,R24=0)),"High Emerging Reader",IF(OR(AND(Q24>25%,Q24<51%,R24>=1),AND(Q24>50%,Q24<76%,R24<=1)),"Developing Reader",IF(OR(AND(Q24>=51%,Q24<76%,R24>=2),AND(Q24>75%,R24<=3)),"Transitioning Reader",IF(AND(Q24>75%,R24>=4),"Reading At Grade Level","")))),"")),"") -> Reading At Grade Level | X24: =IF(C24<>"",$I24/30,"") -> 1 | Z24: =IF($C24<>"",IF($F24>6,Q24,0%),"") -> 1 | AA24: =IF($C24<>"",IF($F24>6,S24/$AA$9,0%),"") -> 1
A25: 15 | I25: =IF(AND(F25="",G25=""),"",IF(F25<7,F25+G25,F25+10+H25)) | J25: =IF(I25="","",IF(F25<7,IF(I25<=10,"Full Refresher","Moderate Refresher"),IF(I25<27,"Light Refresher","Grade Ready"))) | M25: =IF($C$9<>"",IF(OR(K25=1,K25=2),IF(K25=1,M$7-L25,$P$7-L25),""),"") | P25: =IFERROR(IF(AND(K25>0,M25>0,OR(N25>0,O25>0)),(M25/((N25*60)+O25))*60,""),"") | Q25: =IFERROR(IF(OR(K25=1,K25=2),IF(K25=1,M25/$M$7,M25/$P$7),""),"") | U25: =IF(J25<>"",IF(OR(J25="Full Refresher",J25="Moderate Refresher"),"Low Emerging Reader",IF(AND(K25>0,Q25<>""),IF(OR(Q25<=25%,AND(Q25>25%,Q25<=50%,R25=0)),"High Emerging Reader",IF(OR(AND(Q25>25%,Q25<51%,R25>=1),AND(Q25>50%,Q25<76%,R25<=1)),"Developing Reader",IF(OR(AND(Q25>=51%,Q25<76%,R25>=2),AND(Q25>75%,R25<=3)),"Transitioning Reader",IF(AND(Q25>75%,R25>=4),"Reading At Grade Level","")))),"")),"") | X25: =IF(C25<>"",$I25/30,"") | Z25: =IF($C25<>"",IF($F25>6,Q25,0%),"") | AA25: =IF($C25<>"",IF($F25>6,S25/$AA$9,0%),"")
A26: 16 | I26: =IF(AND(F26="",G26=""),"",IF(F26<7,F26+G26,F26+10+H26)) | J26: =IF(I26="","",IF(F26<7,IF(I26<=10,"Full Refresher","Moderate Refresher"),IF(I26<27,"Light Refresher","Grade Ready"))) | M26: =IF($C$9<>"",IF(OR(K26=1,K26=2),IF(K26=1,M$7-L26,$P$7-L26),""),"") | P26: =IFERROR(IF(AND(K26>0,M26>0,OR(N26>0,O26>0)),(M26/((N26*60)+O26))*60,""),"") | Q26: =IFERROR(IF(OR(K26=1,K26=2),IF(K26=1,M26/$M$7,M26/$P$7),""),"") | U26: =IF(J26<>"",IF(OR(J26="Full Refresher",J26="Moderate Refresher"),"Low Emerging Reader",IF(AND(K26>0,Q26<>""),IF(OR(Q26<=25%,AND(Q26>25%,Q26<=50%,R26=0)),"High Emerging Reader",IF(OR(AND(Q26>25%,Q26<51%,R26>=1),AND(Q26>50%,Q26<76%,R26<=1)),"Developing Reader",IF(OR(AND(Q26>=51%,Q26<76%,R26>=2),AND(Q26>75%,R26<=3)),"Transitioning Reader",IF(AND(Q26>75%,R26>=4),"Reading At Grade Level","")))),"")),"") | X26: =IF(C26<>"",$I26/30,"") | Z26: =IF($C26<>"",IF($F26>6,Q26,0%),"") | AA26: =IF($C26<>"",IF($F26>6,S26/$AA$9,0%),"")
A27: 17 | I27: =IF(AND(F27="",G27=""),"",IF(F27<7,F27+G27,F27+10+H27)) | J27: =IF(I27="","",IF(F27<7,IF(I27<=10,"Full Refresher","Moderate Refresher"),IF(I27<27,"Light Refresher","Grade Ready"))) | M27: =IF($C$9<>"",IF(OR(K27=1,K27=2),IF(K27=1,M$7-L27,$P$7-L27),""),"") | P27: =IFERROR(IF(AND(K27>0,M27>0,OR(N27>0,O27>0)),(M27/((N27*60)+O27))*60,""),"") | Q27: =IFERROR(IF(OR(K27=1,K27=2),IF(K27=1,M27/$M$7,M27/$P$7),""),"") | U27: =IF(J27<>"",IF(OR(J27="Full Refresher",J27="Moderate Refresher"),"Low Emerging Reader",IF(AND(K27>0,Q27<>""),IF(OR(Q27<=25%,AND(Q27>25%,Q27<=50%,R27=0)),"High Emerging Reader",IF(OR(AND(Q27>25%,Q27<51%,R27>=1),AND(Q27>50%,Q27<76%,R27<=1)),"Developing Reader",IF(OR(AND(Q27>=51%,Q27<76%,R27>=2),AND(Q27>75%,R27<=3)),"Transitioning Reader",IF(AND(Q27>75%,R27>=4),"Reading At Grade Level","")))),"")),"") | X27: =IF(C27<>"",$I27/30,"") | Z27: =IF($C27<>"",IF($F27>6,Q27,0%),"") | AA27: =IF($C27<>"",IF($F27>6,S27/$AA$9,0%),"")
A28: 18 | I28: =IF(AND(F28="",G28=""),"",IF(F28<7,F28+G28,F28+10+H28)) | J28: =IF(I28="","",IF(F28<7,IF(I28<=10,"Full Refresher","Moderate Refresher"),IF(I28<27,"Light Refresher","Grade Ready"))) | M28: =IF($C$9<>"",IF(OR(K28=1,K28=2),IF(K28=1,M$7-L28,$P$7-L28),""),"") | P28: =IFERROR(IF(AND(K28>0,M28>0,OR(N28>0,O28>0)),(M28/((N28*60)+O28))*60,""),"") | Q28: =IFERROR(IF(OR(K28=1,K28=2),IF(K28=1,M28/$M$7,M28/$P$7),""),"") | U28: =IF(J28<>"",IF(OR(J28="Full Refresher",J28="Moderate Refresher"),"Low Emerging Reader",IF(AND(K28>0,Q28<>""),IF(OR(Q28<=25%,AND(Q28>25%,Q28<=50%,R28=0)),"High Emerging Reader",IF(OR(AND(Q28>25%,Q28<51%,R28>=1),AND(Q28>50%,Q28<76%,R28<=1)),"Developing Reader",IF(OR(AND(Q28>=51%,Q28<76%,R28>=2),AND(Q28>75%,R28<=3)),"Transitioning Reader",IF(AND(Q28>75%,R28>=4),"Reading At Grade Level","")))),"")),"") | X28: =IF(C28<>"",$I28/30,"") | Z28: =IF($C28<>"",IF($F28>6,Q28,0%),"") | AA28: =IF($C28<>"",IF($F28>6,S28/$AA$9,0%),"")
A29: 19 | I29: =IF(AND(F29="",G29=""),"",IF(F29<7,F29+G29,F29+10+H29)) | J29: =IF(I29="","",IF(F29<7,IF(I29<=10,"Full Refresher","Moderate Refresher"),IF(I29<27,"Light Refresher","Grade Ready"))) | M29: =IF($C$9<>"",IF(OR(K29=1,K29=2),IF(K29=1,M$7-L29,$P$7-L29),""),"") | P29: =IFERROR(IF(AND(K29>0,M29>0,OR(N29>0,O29>0)),(M29/((N29*60)+O29))*60,""),"") | Q29: =IFERROR(IF(OR(K29=1,K29=2),IF(K29=1,M29/$M$7,M29/$P$7),""),"") | U29: =IF(J29<>"",IF(OR(J29="Full Refresher",J29="Moderate Refresher"),"Low Emerging Reader",IF(AND(K29>0,Q29<>""),IF(OR(Q29<=25%,AND(Q29>25%,Q29<=50%,R29=0)),"High Emerging Reader",IF(OR(AND(Q29>25%,Q29<51%,R29>=1),AND(Q29>50%,Q29<76%,R29<=1)),"Developing Reader",IF(OR(AND(Q29>=51%,Q29<76%,R29>=2),AND(Q29>75%,R29<=3)),"Transitioning Reader",IF(AND(Q29>75%,R29>=4),"Reading At Grade Level","")))),"")),"") | X29: =IF(C29<>"",$I29/30,"") | Z29: =IF($C29<>"",IF($F29>6,Q29,0%),"") | AA29: =IF($C29<>"",IF($F29>6,S29/$AA$9,0%),"")
A30: 20 | I30: =IF(AND(F30="",G30=""),"",IF(F30<7,F30+G30,F30+10+H30)) | J30: =IF(I30="","",IF(F30<7,IF(I30<=10,"Full Refresher","Moderate Refresher"),IF(I30<27,"Light Refresher","Grade Ready"))) | M30: =IF($C$9<>"",IF(OR(K30=1,K30=2),IF(K30=1,M$7-L30,$P$7-L30),""),"") | P30: =IFERROR(IF(AND(K30>0,M30>0,OR(N30>0,O30>0)),(M30/((N30*60)+O30))*60,""),"") | Q30: =IFERROR(IF(OR(K30=1,K30=2),IF(K30=1,M30/$M$7,M30/$P$7),""),"") | U30: =IF(J30<>"",IF(OR(J30="Full Refresher",J30="Moderate Refresher"),"Low Emerging Reader",IF(AND(K30>0,Q30<>""),IF(OR(Q30<=25%,AND(Q30>25%,Q30<=50%,R30=0)),"High Emerging Reader",IF(OR(AND(Q30>25%,Q30<51%,R30>=1),AND(Q30>50%,Q30<76%,R30<=1)),"Developing Reader",IF(OR(AND(Q30>=51%,Q30<76%,R30>=2),AND(Q30>75%,R30<=3)),"Transitioning Reader",IF(AND(Q30>75%,R30>=4),"Reading At Grade Level","")))),"")),"") | X30: =IF(C30<>"",$I30/30,"") | Z30: =IF($C30<>"",IF($F30>6,Q30,0%),"") | AA30: =IF($C30<>"",IF($F30>6,S30/$AA$9,0%),"")
A31: 21 | I31: =IF(AND(F31="",G31=""),"",IF(F31<7,F31+G31,F31+10+H31)) | J31: =IF(I31="","",IF(F31<7,IF(I31<=10,"Full Refresher","Moderate Refresher"),IF(I31<27,"Light Refresher","Grade Ready"))) | M31: =IF($C$9<>"",IF(OR(K31=1,K31=2),IF(K31=1,M$7-L31,$P$7-L31),""),"") | P31: =IFERROR(IF(AND(K31>0,M31>0,OR(N31>0,O31>0)),(M31/((N31*60)+O31))*60,""),"") | Q31: =IFERROR(IF(OR(K31=1,K31=2),IF(K31=1,M31/$M$7,M31/$P$7),""),"") | U31: =IF(J31<>"",IF(OR(J31="Full Refresher",J31="Moderate Refresher"),"Low Emerging Reader",IF(AND(K31>0,Q31<>""),IF(OR(Q31<=25%,AND(Q31>25%,Q31<=50%,R31=0)),"High Emerging Reader",IF(OR(AND(Q31>25%,Q31<51%,R31>=1),AND(Q31>50%,Q31<76%,R31<=1)),"Developing Reader",IF(OR(AND(Q31>=51%,Q31<76%,R31>=2),AND(Q31>75%,R31<=3)),"Transitioning Reader",IF(AND(Q31>75%,R31>=4),"Reading At Grade Level","")))),"")),"") | X31: =IF(C31<>"",$I31/30,"") | Z31: =IF($C31<>"",IF($F31>6,Q31,0%),"") | AA31: =IF($C31<>"",IF($F31>6,S31/$AA$9,0%),"")
A32: 22 | I32: =IF(AND(F32="",G32=""),"",IF(F32<7,F32+G32,F32+10+H32)) | J32: =IF(I32="","",IF(F32<7,IF(I32<=10,"Full Refresher","Moderate Refresher"),IF(I32<27,"Light Refresher","Grade Ready"))) | M32: =IF($C$9<>"",IF(OR(K32=1,K32=2),IF(K32=1,M$7-L32,$P$7-L32),""),"") | P32: =IFERROR(IF(AND(K32>0,M32>0,OR(N32>0,O32>0)),(M32/((N32*60)+O32))*60,""),"") | Q32: =IFERROR(IF(OR(K32=1,K32=2),IF(K32=1,M32/$M$7,M32/$P$7),""),"") | U32: =IF(J32<>"",IF(OR(J32="Full Refresher",J32="Moderate Refresher"),"Low Emerging Reader",IF(AND(K32>0,Q32<>""),IF(OR(Q32<=25%,AND(Q32>25%,Q32<=50%,R32=0)),"High Emerging Reader",IF(OR(AND(Q32>25%,Q32<51%,R32>=1),AND(Q32>50%,Q32<76%,R32<=1)),"Developing Reader",IF(OR(AND(Q32>=51%,Q32<76%,R32>=2),AND(Q32>75%,R32<=3)),"Transitioning Reader",IF(AND(Q32>75%,R32>=4),"Reading At Grade Level","")))),"")),"") | X32: =IF(C32<>"",$I32/30,"") | Z32: =IF($C32<>"",IF($F32>6,Q32,0%),"") | AA32: =IF($C32<>"",IF($F32>6,S32/$AA$9,0%),"")
A33: 23 | I33: =IF(AND(F33="",G33=""),"",IF(F33<7,F33+G33,F33+10+H33)) | J33: =IF(I33="","",IF(F33<7,IF(I33<=10,"Full Refresher","Moderate Refresher"),IF(I33<27,"Light Refresher","Grade Ready"))) | M33: =IF($C$9<>"",IF(OR(K33=1,K33=2),IF(K33=1,M$7-L33,$P$7-L33),""),"") | P33: =IFERROR(IF(AND(K33>0,M33>0,OR(N33>0,O33>0)),(M33/((N33*60)+O33))*60,""),"") | Q33: =IFERROR(IF(OR(K33=1,K33=2),IF(K33=1,M33/$M$7,M33/$P$7),""),"") | U33: =IF(J33<>"",IF(OR(J33="Full Refresher",J33="Moderate Refresher"),"Low Emerging Reader",IF(AND(K33>0,Q33<>""),IF(OR(Q33<=25%,AND(Q33>25%,Q33<=50%,R33=0)),"High Emerging Reader",IF(OR(AND(Q33>25%,Q33<51%,R33>=1),AND(Q33>50%,Q33<76%,R33<=1)),"Developing Reader",IF(OR(AND(Q33>=51%,Q33<76%,R33>=2),AND(Q33>75%,R33<=3)),"Transitioning Reader",IF(AND(Q33>75%,R33>=4),"Reading At Grade Level","")))),"")),"") | X33: =IF(C33<>"",$I33/30,"") | Z33: =IF($C33<>"",IF($F33>6,Q33,0%),"") | AA33: =IF($C33<>"",IF($F33>6,S33/$AA$9,0%),"")
A34: 24 | I34: =IF(AND(F34="",G34=""),"",IF(F34<7,F34+G34,F34+10+H34)) | J34: =IF(I34="","",IF(F34<7,IF(I34<=10,"Full Refresher","Moderate Refresher"),IF(I34<27,"Light Refresher","Grade Ready"))) | M34: =IF($C$9<>"",IF(OR(K34=1,K34=2),IF(K34=1,M$7-L34,$P$7-L34),""),"") | P34: =IFERROR(IF(AND(K34>0,M34>0,OR(N34>0,O34>0)),(M34/((N34*60)+O34))*60,""),"") | Q34: =IFERROR(IF(OR(K34=1,K34=2),IF(K34=1,M34/$M$7,M34/$P$7),""),"") | U34: =IF(J34<>"",IF(OR(J34="Full Refresher",J34="Moderate Refresher"),"Low Emerging Reader",IF(AND(K34>0,Q34<>""),IF(OR(Q34<=25%,AND(Q34>25%,Q34<=50%,R34=0)),"High Emerging Reader",IF(OR(AND(Q34>25%,Q34<51%,R34>=1),AND(Q34>50%,Q34<76%,R34<=1)),"Developing Reader",IF(OR(AND(Q34>=51%,Q34<76%,R34>=2),AND(Q34>75%,R34<=3)),"Transitioning Reader",IF(AND(Q34>75%,R34>=4),"Reading At Grade Level","")))),"")),"") | X34: =IF(C34<>"",$I34/30,"") | Z34: =IF($C34<>"",IF($F34>6,Q34,0%),"") | AA34: =IF($C34<>"",IF($F34>6,S34/$AA$9,0%),"")
A35: 25 | I35: =IF(AND(F35="",G35=""),"",IF(F35<7,F35+G35,F35+10+H35)) | J35: =IF(I35="","",IF(F35<7,IF(I35<=10,"Full Refresher","Moderate Refresher"),IF(I35<27,"Light Refresher","Grade Ready"))) | M35: =IF($C$9<>"",IF(OR(K35=1,K35=2),IF(K35=1,M$7-L35,$P$7-L35),""),"") | P35: =IFERROR(IF(AND(K35>0,M35>0,OR(N35>0,O35>0)),(M35/((N35*60)+O35))*60,""),"") | Q35: =IFERROR(IF(OR(K35=1,K35=2),IF(K35=1,M35/$M$7,M35/$P$7),""),"") | U35: =IF(J35<>"",IF(OR(J35="Full Refresher",J35="Moderate Refresher"),"Low Emerging Reader",IF(AND(K35>0,Q35<>""),IF(OR(Q35<=25%,AND(Q35>25%,Q35<=50%,R35=0)),"High Emerging Reader",IF(OR(AND(Q35>25%,Q35<51%,R35>=1),AND(Q35>50%,Q35<76%,R35<=1)),"Developing Reader",IF(OR(AND(Q35>=51%,Q35<76%,R35>=2),AND(Q35>75%,R35<=3)),"Transitioning Reader",IF(AND(Q35>75%,R35>=4),"Reading At Grade Level","")))),"")),"") | X35: =IF(C35<>"",$I35/30,"") | Z35: =IF($C35<>"",IF($F35>6,Q35,0%),"") | AA35: =IF($C35<>"",IF($F35>6,S35/$AA$9,0%),"")
A36: 26 | I36: =IF(AND(F36="",G36=""),"",IF(F36<7,F36+G36,F36+10+H36)) | J36: =IF(I36="","",IF(F36<7,IF(I36<=10,"Full Refresher","Moderate Refresher"),IF(I36<27,"Light Refresher","Grade Ready"))) | M36: =IF($C$9<>"",IF(OR(K36=1,K36=2),IF(K36=1,M$7-L36,$P$7-L36),""),"") | P36: =IFERROR(IF(AND(K36>0,M36>0,OR(N36>0,O36>0)),(M36/((N36*60)+O36))*60,""),"") | Q36: =IFERROR(IF(OR(K36=1,K36=2),IF(K36=1,M36/$M$7,M36/$P$7),""),"") | U36: =IF(J36<>"",IF(OR(J36="Full Refresher",J36="Moderate Refresher"),"Low Emerging Reader",IF(AND(K36>0,Q36<>""),IF(OR(Q36<=25%,AND(Q36>25%,Q36<=50%,R36=0)),"High Emerging Reader",IF(OR(AND(Q36>25%,Q36<51%,R36>=1),AND(Q36>50%,Q36<76%,R36<=1)),"Developing Reader",IF(OR(AND(Q36>=51%,Q36<76%,R36>=2),AND(Q36>75%,R36<=3)),"Transitioning Reader",IF(AND(Q36>75%,R36>=4),"Reading At Grade Level","")))),"")),"") | X36: =IF(C36<>"",$I36/30,"") | Z36: =IF($C36<>"",IF($F36>6,Q36,0%),"") | AA36: =IF($C36<>"",IF($F36>6,S36/$AA$9,0%),"")
... A69: 59 | I69: =IF(AND(F69="",G69=""),"",IF(F69<7,F69+G69,F69+10+H69)) | J69: =IF(I69="","",IF(F69<7,IF(I69<=10,"Full Refresher","Moderate Refresher"),IF(I69<27,"Light Refresher","Grade Ready"))) | M69: =IF($C$9<>"",IF(OR(K69=1,K69=2),IF(K69=1,M$7-L69,$P$7-L69),""),"") | P69: =IFERROR(IF(AND(K69>0,M69>0,OR(N69>0,O69>0)),(M69/((N69*60)+O69))*60,""),"") | Q69: =IFERROR(IF(OR(K69=1,K69=2),IF(K69=1,M69/$M$7,M69/$P$7),""),"") | U69: =IF(J69<>"",IF(OR(J69="Full Refresher",J69="Moderate Refresher"),"Low Emerging Reader",IF(AND(K69>0,Q69<>""),IF(OR(Q69<=25%,AND(Q69>25%,Q69<=50%,R69=0)),"High Emerging Reader",IF(OR(AND(Q69>25%,Q69<51%,R69>=1),AND(Q69>50%,Q69<76%,R69<=1)),"Developing Reader",IF(OR(AND(Q69>=51%,Q69<76%,R69>=2),AND(Q69>75%,R69<=3)),"Transitioning Reader",IF(AND(Q69>75%,R69>=4),"Reading At Grade Level","")))),"")),"") | X69: =IF(C69<>"",$I69/30,"") | Z69: =IF($C69<>"",IF($F69>6,Q69,0%),"") | AA69: =IF($C69<>"",IF($F69>6,S69/$AA$9,0%),"")
A70: =A69+1 -> 60 | I70: =IF(AND(F70="",G70=""),"",IF(F70<7,F70+G70,F70+10+H70)) | J70: =IF(I70="","",IF(F70<7,IF(I70<=10,"Full Refresher","Moderate Refresher"),IF(I70<27,"Light Refresher","Grade Ready"))) | M70: =IF($C$9<>"",IF(OR(K70=1,K70=2),IF(K70=1,M$7-L70,$P$7-L70),""),"") | P70: =IFERROR(IF(AND(K70>0,M70>0,OR(N70>0,O70>0)),(M70/((N70*60)+O70))*60,""),"") | Q70: =IFERROR(IF(OR(K70=1,K70=2),IF(K70=1,M70/$M$7,M70/$P$7),""),"") | U70: =IF(J70<>"",IF(OR(J70="Full Refresher",J70="Moderate Refresher"),"Low Emerging Reader",IF(AND(K70>0,Q70<>""),IF(OR(Q70<=25%,AND(Q70>25%,Q70<=50%,R70=0)),"High Emerging Reader",IF(OR(AND(Q70>25%,Q70<51%,R70>=1),AND(Q70>50%,Q70<76%,R70<=1)),"Developing Reader",IF(OR(AND(Q70>=51%,Q70<76%,R70>=2),AND(Q70>75%,R70<=3)),"Transitioning Reader",IF(AND(Q70>75%,R70>=4),"Reading At Grade Level","")))),"")),"") | X70: =IF(C70<>"",$I70/30,"") | Z70: =IF($C70<>"",IF($F70>6,Q70,0%),"") | AA70: =IF($C70<>"",IF($F70>6,S70/$AA$9,0%),"")
A71: =A70+1 -> 61 | I71: =IF(AND(F71="",G71=""),"",IF(F71<7,F71+G71,F71+10+H71)) | J71: =IF(I71="","",IF(F71<7,IF(I71<=10,"Full Refresher","Moderate Refresher"),IF(I71<27,"Light Refresher","Grade Ready"))) | M71: =IF($C$9<>"",IF(OR(K71=1,K71=2),IF(K71=1,M$7-L71,$P$7-L71),""),"") | P71: =IFERROR(IF(AND(K71>0,M71>0,OR(N71>0,O71>0)),(M71/((N71*60)+O71))*60,""),"") | Q71: =IFERROR(IF(OR(K71=1,K71=2),IF(K71=1,M71/$M$7,M71/$P$7),""),"") | U71: =IF(J71<>"",IF(OR(J71="Full Refresher",J71="Moderate Refresher"),"Low Emerging Reader",IF(AND(K71>0,Q71<>""),IF(OR(Q71<=25%,AND(Q71>25%,Q71<=50%,R71=0)),"High Emerging Reader",IF(OR(AND(Q71>25%,Q71<51%,R71>=1),AND(Q71>50%,Q71<76%,R71<=1)),"Developing Reader",IF(OR(AND(Q71>=51%,Q71<76%,R71>=2),AND(Q71>75%,R71<=3)),"Transitioning Reader",IF(AND(Q71>75%,R71>=4),"Reading At Grade Level","")))),"")),"") | X71: =IF(C71<>"",$I71/30,"") | Z71: =IF($C71<>"",IF($F71>6,Q71,0%),"") | AA71: =IF($C71<>"",IF($F71>6,S71/$AA$9,0%),"")
A72: =A71+1 -> 62 | I72: =IF(AND(F72="",G72=""),"",IF(F72<7,F72+G72,F72+10+H72)) | J72: =IF(I72="","",IF(F72<7,IF(I72<=10,"Full Refresher","Moderate Refresher"),IF(I72<27,"Light Refresher","Grade Ready"))) | M72: =IF($C$9<>"",IF(OR(K72=1,K72=2),IF(K72=1,M$7-L72,$P$7-L72),""),"") | P72: =IFERROR(IF(AND(K72>0,M72>0,OR(N72>0,O72>0)),(M72/((N72*60)+O72))*60,""),"") | Q72: =IFERROR(IF(OR(K72=1,K72=2),IF(K72=1,M72/$M$7,M72/$P$7),""),"") | U72: =IF(J72<>"",IF(OR(J72="Full Refresher",J72="Moderate Refresher"),"Low Emerging Reader",IF(AND(K72>0,Q72<>""),IF(OR(Q72<=25%,AND(Q72>25%,Q72<=50%,R72=0)),"High Emerging Reader",IF(OR(AND(Q72>25%,Q72<51%,R72>=1),AND(Q72>50%,Q72<76%,R72<=1)),"Developing Reader",IF(OR(AND(Q72>=51%,Q72<76%,R72>=2),AND(Q72>75%,R72<=3)),"Transitioning Reader",IF(AND(Q72>75%,R72>=4),"Reading At Grade Level","")))),"")),"") | X72: =IF(C72<>"",$I72/30,"") | Z72: =IF($C72<>"",IF($F72>6,Q72,0%),"") | AA72: =IF($C72<>"",IF($F72>6,S72/$AA$9,0%),"")
A73: =A72+1 -> 63 | I73: =IF(AND(F73="",G73=""),"",IF(F73<7,F73+G73,F73+10+H73)) | J73: =IF(I73="","",IF(F73<7,IF(I73<=10,"Full Refresher","Moderate Refresher"),IF(I73<27,"Light Refresher","Grade Ready"))) | M73: =IF($C$9<>"",IF(OR(K73=1,K73=2),IF(K73=1,M$7-L73,$P$7-L73),""),"") | P73: =IFERROR(IF(AND(K73>0,M73>0,OR(N73>0,O73>0)),(M73/((N73*60)+O73))*60,""),"") | Q73: =IFERROR(IF(OR(K73=1,K73=2),IF(K73=1,M73/$M$7,M73/$P$7),""),"") | U73: =IF(J73<>"",IF(OR(J73="Full Refresher",J73="Moderate Refresher"),"Low Emerging Reader",IF(AND(K73>0,Q73<>""),IF(OR(Q73<=25%,AND(Q73>25%,Q73<=50%,R73=0)),"High Emerging Reader",IF(OR(AND(Q73>25%,Q73<51%,R73>=1),AND(Q73>50%,Q73<76%,R73<=1)),"Developing Reader",IF(OR(AND(Q73>=51%,Q73<76%,R73>=2),AND(Q73>75%,R73<=3)),"Transitioning Reader",IF(AND(Q73>75%,R73>=4),"Reading At Grade Level","")))),"")),"") | X73: =IF(C73<>"",$I73/30,"") | Z73: =IF($C73<>"",IF($F73>6,Q73,0%),"") | AA73: =IF($C73<>"",IF($F73>6,S73/$AA$9,0%),"")
...

Sheet Class Record
A4: School: | C4: ='G1 MT Reading Scoresheet'!$C$5 -> ROMANA ELEMENTARY SCHOOL | E4: GRADE 1 Reading Assessment CLASS RECORD
A5: Teacher: | C5: ='G1 MT Reading Scoresheet'!C6 -> MARIAN GRACE D. DE LA TORRE | E5: =CONCATENATE("MOTHER TONGUE","(",'G1 MT Reading Scoresheet'!C9,")") -> MOTHER TONGUE(Hiligaynon)
A6: Grade: | C6: Grade 1 | E6: Assessment Part 1 | G6: Assessment Part 2 | J6: READING PROFILE
A7: S/N | B7: LRN | C7: Name of Learner | D7: Sex | E7: Assessment Part 1 Level | F7: % of Total Score | G7: Reading Fluency | H7: Reading Comprehension | I7: Average Word Per Minute | K7: REMARKS
A8: 1 | B8: =IF('G1 MT Reading Scoresheet'!B11<>"",'G1 MT Reading Scoresheet'!B11,"") -> 117443240002 | C8: =IF('G1 MT Reading Scoresheet'!C11<>"",'G1 MT Reading Scoresheet'!C11,"") -> CARDINAL,CIAN, DEMIAR | D8: =IF('G1 MT Reading Scoresheet'!D11<>"",'G1 MT Reading Scoresheet'!D11,"") -> Male | E8: ='G1 MT Reading Scoresheet'!J11 -> Grade Ready | F8: =IF($C8<>"",'G1 MT Reading Scoresheet'!$I11/30,"") -> 0.93333333 | G8: =IF(AND($C8<>"",$E8<>"Full Refresher"),'G1 MT Reading Scoresheet'!$Q11,"") -> 0.7 | H8: =IF(AND($C8<>"",$E8<>"Full Refresher"),'G1 MT Reading Scoresheet'!$R11/5,"") -> 0.6 | I8: =IF(AND($C8<>"",$E8<>"Full Refresher"),'G1 MT Reading Scoresheet'!$P11,"") -> 35 | J8: ='G1 MT Reading Scoresheet'!$U11 -> Transitioning Reader | K8: =IF('G1 MT Reading Scoresheet'!V11<>"",'G1 MT Reading Scoresheet'!V11,"")
A9: 2 | B9: =IF('G1 MT Reading Scoresheet'!B12<>"",'G1 MT Reading Scoresheet'!B12,"") -> 117443240003 | C9: =IF('G1 MT Reading Scoresheet'!C12<>"",'G1 MT Reading Scoresheet'!C12,"") -> CARDINAL,REY ROES, PANGANTIHON | D9: =IF('G1 MT Reading Scoresheet'!D12<>"",'G1 MT Reading Scoresheet'!D12,"") -> Male | E9: ='G1 MT Reading Scoresheet'!J12 -> Grade Ready | F9: =IF($C9<>"",'G1 MT Reading Scoresheet'!$I12/30,"") -> 1 | G9: =IF(AND($C9<>"",$E9<>"Full Refresher"),'G1 MT Reading Scoresheet'!$Q12,"") -> 1 | H9: =IF(AND($C9<>"",$E9<>"Full Refresher"),'G1 MT Reading Scoresheet'!$R12/5,"") -> 1 | I9: =IF(AND($C9<>"",$E9<>"Full Refresher"),'G1 MT Reading Scoresheet'!$P12,"") -> 50 | J9: ='G1 MT Reading Scoresheet'!$U12 -> Reading At Grade Level | K9: =IF('G1 MT Reading Scoresheet'!V12<>"",'G1 MT Reading Scoresheet'!V12,"")
A10: 3 | B10: =IF('G1 MT Reading Scoresheet'!B13<>"",'G1 MT Reading Scoresheet'!B13,"") -> 117443240005 | C10: =IF('G1 MT Reading Scoresheet'!C13<>"",'G1 MT Reading Scoresheet'!C13,"") -> FRANTE,ARK JAY, CABALLERO | D10: =IF('G1 MT Reading Scoresheet'!D13<>"",'G1 MT Reading Scoresheet'!D13,"") -> Male | E10: ='G1 MT Reading Scoresheet'!J13 -> Grade Ready | F10: =IF($C10<>"",'G1 MT Reading Scoresheet'!$I13/30,"") -> 1 | G10: =IF(AND($C10<>"",$E10<>"Full Refresher"),'G1 MT Reading Scoresheet'!$Q13,"") -> 1 | H10: =IF(AND($C10<>"",$E10<>"Full Refresher"),'G1 MT Reading Scoresheet'!$R13/5,"") -> 0.8 | I10: =IF(AND($C10<>"",$E10<>"Full Refresher"),'G1 MT Reading Scoresheet'!$P13,"") -> 50 | J10: ='G1 MT Reading Scoresheet'!$U13 -> Reading At Grade Level | K10: =IF('G1 MT Reading Scoresheet'!V13<>"",'G1 MT Reading Scoresheet'!V13,"")
A11: 4 | B11: =IF('G1 MT Reading Scoresheet'!B14<>"",'G1 MT Reading Scoresheet'!B14,"") -> 117443240006 | C11: =IF('G1 MT Reading Scoresheet'!C14<>"",'G1 MT Reading Scoresheet'!C14,"") -> GANCIA,JELLO, GIER | D11: =IF('G1 MT Reading Scoresheet'!D14<>"",'G1 MT Reading Scoresheet'!D14,"") -> Male | E11: ='G1 MT Reading Scoresheet'!J14 -> Full Refresher | F11: =IF($C11<>"",'G1 MT Reading Scoresheet'!$I14/30,"") -> 0.23333333 | G11: =IF(AND($C11<>"",$E11<>"Full Refresher"),'G1 MT Reading Scoresheet'!$Q14,"") | H11: =IF(AND($C11<>"",$E11<>"Full Refresher"),'G1 MT Reading Scoresheet'!$R14/5,"") | I11: =IF(AND($C11<>"",$E11<>"Full Refresher"),'G1 MT Reading Scoresheet'!$P14,"") | J11: ='G1 MT Reading Scoresheet'!$U14 -> Low Emerging Reader | K11: =IF('G1 MT Reading Scoresheet'!V14<>"",'G1 MT Reading Scoresheet'!V14,"")
A12: 5 | B12: =IF('G1 MT Reading Scoresheet'!B15<>"",'G1 MT Reading Scoresheet'!B15,"") -> 117443230006 | C12: =IF('G1 MT Reading Scoresheet'!C15<>"",'G1 MT Reading Scoresheet'!C15,"") -> GANCIA, RHAYCO, NARCISO | D12: =IF('G1 MT Reading Scoresheet'!D15<>"",'G1 MT Reading Scoresheet'!D15,"") -> Male | E12: ='G1 MT Reading Scoresheet'!J15 -> Light Refresher | F12: =IF($C12<>"",'G1 MT Reading Scoresheet'!$I15/30,"") -> 0.73333333 | G12: =IF(AND($C12<>"",$E12<>"Full Refresher"),'G1 MT Reading Scoresheet'!$Q15,"") -> 0.6 | H12: =IF(AND($C12<>"",$E12<>"Full Refresher"),'G1 MT Reading Scoresheet'!$R15/5,"") -> 0.4 | I12: =IF(AND($C12<>"",$E12<>"Full Refresher"),'G1 MT Reading Scoresheet'!$P15,"") -> 30 | J12: ='G1 MT Reading Scoresheet'!$U15 -> Transitioning Reader | K12: =IF('G1 MT Reading Scoresheet'!V15<>"",'G1 MT Reading Scoresheet'!V15,"")
A13: 6 | B13: =IF('G1 MT Reading Scoresheet'!B16<>"",'G1 MT Reading Scoresheet'!B16,"") -> 117443240004 | C13: =IF('G1 MT Reading Scoresheet'!C16<>"",'G1 MT Reading Scoresheet'!C16,"") -> GARDOSE,KIETH DION, CADUCOY | D13: =IF('G1 MT Reading Scoresheet'!D16<>"",'G1 MT Reading Scoresheet'!D16,"") -> Male | E13: ='G1 MT Reading Scoresheet'!J16 -> Light Refresher | F13: =IF($C13<>"",'G1 MT Reading Scoresheet'!$I16/30,"") -> 0.66666667 | G13: =IF(AND($C13<>"",$E13<>"Full Refresher"),'G1 MT Reading Scoresheet'!$Q16,"") -> 0.5 | H13: =IF(AND($C13<>"",$E13<>"Full Refresher"),'G1 MT Reading Scoresheet'!$R16/5,"") -> 0.4 | I13: =IF(AND($C13<>"",$E13<>"Full Refresher"),'G1 MT Reading Scoresheet'!$P16,"") -> 25 | J13: ='G1 MT Reading Scoresheet'!$U16 -> Developing Reader | K13: =IF('G1 MT Reading Scoresheet'!V16<>"",'G1 MT Reading Scoresheet'!V16,"")
A14: 7 | B14: =IF('G1 MT Reading Scoresheet'!B17<>"",'G1 MT Reading Scoresheet'!B17,"") -> 117443240007 | C14: =IF('G1 MT Reading Scoresheet'!C17<>"",'G1 MT Reading Scoresheet'!C17,"") -> GILUA,ARON JAMES, SUNDAYON | D14: =IF('G1 MT Reading Scoresheet'!D17<>"",'G1 MT Reading Scoresheet'!D17,"") -> Male | E14: ='G1 MT Reading Scoresheet'!J17 -> Grade Ready | F14: =IF($C14<>"",'G1 MT Reading Scoresheet'!$I17/30,"") -> 0.93333333 | G14: =IF(AND($C14<>"",$E14<>"Full Refresher"),'G1 MT Reading Scoresheet'!$Q17,"") -> 0.8 | H14: =IF(AND($C14<>"",$E14<>"Full Refresher"),'G1 MT Reading Scoresheet'!$R17/5,"") -> 0.8 | I14: =IF(AND($C14<>"",$E14<>"Full Refresher"),'G1 MT Reading Scoresheet'!$P17,"") -> 40 | J14: ='G1 MT Reading Scoresheet'!$U17 -> Reading At Grade Level | K14: =IF('G1 MT Reading Scoresheet'!V17<>"",'G1 MT Reading Scoresheet'!V17,"")
A15: 8 | B15: =IF('G1 MT Reading Scoresheet'!B18<>"",'G1 MT Reading Scoresheet'!B18,"") -> 117443240008 | C15: =IF('G1 MT Reading Scoresheet'!C18<>"",'G1 MT Reading Scoresheet'!C18,"") -> LABANZA,DAVID RHON, PALACIO | D15: =IF('G1 MT Reading Scoresheet'!D18<>"",'G1 MT Reading Scoresheet'!D18,"") -> Male | E15: ='G1 MT Reading Scoresheet'!J18 -> Grade Ready | F15: =IF($C15<>"",'G1 MT Reading Scoresheet'!$I18/30,"") -> 0.93333333 | G15: =IF(AND($C15<>"",$E15<>"Full Refresher"),'G1 MT Reading Scoresheet'!$Q18,"") -> 0.6 | H15: =IF(AND($C15<>"",$E15<>"Full Refresher"),'G1 MT Reading Scoresheet'!$R18/5,"") -> 0.8 | I15: =IF(AND($C15<>"",$E15<>"Full Refresher"),'G1 MT Reading Scoresheet'!$P18,"") -> 30 | J15: ='G1 MT Reading Scoresheet'!$U18 -> Transitioning Reader | K15: =IF('G1 MT Reading Scoresheet'!V18<>"",'G1 MT Reading Scoresheet'!V18,"")
A16: 9 | B16: =IF('G1 MT Reading Scoresheet'!B19<>"",'G1 MT Reading Scoresheet'!B19,"") -> 117443240009 | C16: =IF('G1 MT Reading Scoresheet'!C19<>"",'G1 MT Reading Scoresheet'!C19,"") -> LABANZA,JAY-K, NOBLE | D16: =IF('G1 MT Reading Scoresheet'!D19<>"",'G1 MT Reading Scoresheet'!D19,"") -> Male | E16: ='G1 MT Reading Scoresheet'!J19 -> Full Refresher | F16: =IF($C16<>"",'G1 MT Reading Scoresheet'!$I19/30,"") -> 0.23333333 | G16: =IF(AND($C16<>"",$E16<>"Full Refresher"),'G1 MT Reading Scoresheet'!$Q19,"") | H16: =IF(AND($C16<>"",$E16<>"Full Refresher"),'G1 MT Reading Scoresheet'!$R19/5,"") | I16: =IF(AND($C16<>"",$E16<>"Full Refresher"),'G1 MT Reading Scoresheet'!$P19,"") | J16: ='G1 MT Reading Scoresheet'!$U19 -> Low Emerging Reader | K16: =IF('G1 MT Reading Scoresheet'!V19<>"",'G1 MT Reading Scoresheet'!V19,"")
A17: 10 | B17: =IF('G1 MT Reading Scoresheet'!B20<>"",'G1 MT Reading Scoresheet'!B20,"") -> 117443240010 | C17: =IF('G1 MT Reading Scoresheet'!C20<>"",'G1 MT Reading Scoresheet'!C20,"") -> LANGYON,JOHN KENNETH, ESTOCADA | D17: =IF('G1 MT Reading Scoresheet'!D20<>"",'G1 MT Reading Scoresheet'!D20,"") -> Male | E17: ='G1 MT Reading Scoresheet'!J20 -> Full Refresher | F17: =IF($C17<>"",'G1 MT Reading Scoresheet'!$I20/30,"") -> 0 | G17: =IF(AND($C17<>"",$E17<>"Full Refresher"),'G1 MT Reading Scoresheet'!$Q20,"") | H17: =IF(AND($C17<>"",$E17<>"Full Refresher"),'G1 MT Reading Scoresheet'!$R20/5,"") | I17: =IF(AND($C17<>"",$E17<>"Full Refresher"),'G1 MT Reading Scoresheet'!$P20,"") | J17: ='G1 MT Reading Scoresheet'!$U20 -> Low Emerging Reader | K17: =IF('G1 MT Reading Scoresheet'!V20<>"",'G1 MT Reading Scoresheet'!V20,"")
A18: 11 | B18: =IF('G1 MT Reading Scoresheet'!B21<>"",'G1 MT Reading Scoresheet'!B21,"") -> 117443240012 | C18: =IF('G1 MT Reading Scoresheet'!C21<>"",'G1 MT Reading Scoresheet'!C21,"") -> ESLANA,SHANEL, JACOMILLA | D18: =IF('G1 MT Reading Scoresheet'!D21<>"",'G1 MT Reading Scoresheet'!D21,"") -> Female | E18: ='G1 MT Reading Scoresheet'!J21 -> Grade Ready | F18: =IF($C18<>"",'G1 MT Reading Scoresheet'!$I21/30,"") -> 1 | G18: =IF(AND($C18<>"",$E18<>"Full Refresher"),'G1 MT Reading Scoresheet'!$Q21,"") -> 1 | H18: =IF(AND($C18<>"",$E18<>"Full Refresher"),'G1 MT Reading Scoresheet'!$R21/5,"") -> 1 | I18: =IF(AND($C18<>"",$E18<>"Full Refresher"),'G1 MT Reading Scoresheet'!$P21,"") -> 50 | J18: ='G1 MT Reading Scoresheet'!$U21 -> Reading At Grade Level | K18: =IF('G1 MT Reading Scoresheet'!V21<>"",'G1 MT Reading Scoresheet'!V21,"")
A19: 12 | B19: =IF('G1 MT Reading Scoresheet'!B22<>"",'G1 MT Reading Scoresheet'!B22,"") -> 117443240013 | C19: =IF('G1 MT Reading Scoresheet'!C22<>"",'G1 MT Reading Scoresheet'!C22,"") -> JUMBAS,JHANEZZA KAYE, ARCENAL | D19: =IF('G1 MT Reading Scoresheet'!D22<>"",'G1 MT Reading Scoresheet'!D22,"") -> Female | E19: ='G1 MT Reading Scoresheet'!J22 -> Grade Ready | F19: =IF($C19<>"",'G1 MT Reading Scoresheet'!$I22/30,"") -> 1 | G19: =IF(AND($C19<>"",$E19<>"Full Refresher"),'G1 MT Reading Scoresheet'!$Q22,"") -> 1 | H19: =IF(AND($C19<>"",$E19<>"Full Refresher"),'G1 MT Reading Scoresheet'!$R22/5,"") -> 1 | I19: =IF(AND($C19<>"",$E19<>"Full Refresher"),'G1 MT Reading Scoresheet'!$P22,"") -> 50 | J19: ='G1 MT Reading Scoresheet'!$U22 -> Reading At Grade Level | K19: =IF('G1 MT Reading Scoresheet'!V22<>"",'G1 MT Reading Scoresheet'!V22,"")
... A66: 59 | B66: =IF('G1 MT Reading Scoresheet'!B69<>"",'G1 MT Reading Scoresheet'!B69,"") | C66: =IF('G1 MT Reading Scoresheet'!C69<>"",'G1 MT Reading Scoresheet'!C69,"") | D66: =IF('G1 MT Reading Scoresheet'!D69<>"",'G1 MT Reading Scoresheet'!D69,"") | E66: ='G1 MT Reading Scoresheet'!J69 | F66: =IF($C66<>"",'G1 MT Reading Scoresheet'!$I69/30,"") | G66: =IF(AND($C66<>"",$E66<>"Full Refresher"),'G1 MT Reading Scoresheet'!$Q69,"") | H66: =IF(AND($C66<>"",$E66<>"Full Refresher"),'G1 MT Reading Scoresheet'!$R69/5,"") | I66: =IF(AND($C66<>"",$E66<>"Full Refresher"),'G1 MT Reading Scoresheet'!$P69,"") | J66: ='G1 MT Reading Scoresheet'!$U69 | K66: =IF('G1 MT Reading Scoresheet'!V69<>"",'G1 MT Reading Scoresheet'!V69,"")
A67: =A66+1 -> 60 | B67: =IF('G1 MT Reading Scoresheet'!B70<>"",'G1 MT Reading Scoresheet'!B70,"") | C67: =IF('G1 MT Reading Scoresheet'!C70<>"",'G1 MT Reading Scoresheet'!C70,"") | D67: =IF('G1 MT Reading Scoresheet'!D70<>"",'G1 MT Reading Scoresheet'!D70,"") | E67: ='G1 MT Reading Scoresheet'!J70 | F67: =IF($C67<>"",'G1 MT Reading Scoresheet'!$I70/30,"") | G67: =IF(AND($C67<>"",$E67<>"Full Refresher"),'G1 MT Reading Scoresheet'!$Q70,"") | H67: =IF(AND($C67<>"",$E67<>"Full Refresher"),'G1 MT Reading Scoresheet'!$R70/5,"") | I67: =IF(AND($C67<>"",$E67<>"Full Refresher"),'G1 MT Reading Scoresheet'!$P70,"") | J67: ='G1 MT Reading Scoresheet'!$U70 | K67: =IF('G1 MT Reading Scoresheet'!V70<>"",'G1 MT Reading Scoresheet'!V70,"")
A68: =A67+1 -> 61 | B68: =IF('G1 MT Reading Scoresheet'!B71<>"",'G1 MT Reading Scoresheet'!B71,"") | C68: =IF('G1 MT Reading Scoresheet'!C71<>"",'G1 MT Reading Scoresheet'!C71,"") | D68: =IF('G1 MT Reading Scoresheet'!D71<>"",'G1 MT Reading Scoresheet'!D71,"") | E68: ='G1 MT Reading Scoresheet'!J71 | F68: =IF($C68<>"",'G1 MT Reading Scoresheet'!$I71/30,"") | G68: =IF(AND($C68<>"",$E68<>"Full Refresher"),'G1 MT Reading Scoresheet'!$Q71,"") | H68: =IF(AND($C68<>"",$E68<>"Full Refresher"),'G1 MT Reading Scoresheet'!$R71/5,"") | I68: =IF(AND($C68<>"",$E68<>"Full Refresher"),'G1 MT Reading Scoresheet'!$P71,"") | J68: ='G1 MT Reading Scoresheet'!$U71 | K68: =IF('G1 MT Reading Scoresheet'!V71<>"",'G1 MT Reading Scoresheet'!V71,"")
A69: =A68+1 -> 62 | B69: =IF('G1 MT Reading Scoresheet'!B72<>"",'G1 MT Reading Scoresheet'!B72,"") | C69: =IF('G1 MT Reading Scoresheet'!C72<>"",'G1 MT Reading Scoresheet'!C72,"") | D69: =IF('G1 MT Reading Scoresheet'!D72<>"",'G1 MT Reading Scoresheet'!D72,"") | E69: ='G1 MT Reading Scoresheet'!J72 | F69: =IF($C69<>"",'G1 MT Reading Scoresheet'!$I72/30,"") | G69: =IF(AND($C69<>"",$E69<>"Full Refresher"),'G1 MT Reading Scoresheet'!$Q72,"") | H69: =IF(AND($C69<>"",$E69<>"Full Refresher"),'G1 MT Reading Scoresheet'!$R72/5,"") | I69: =IF(AND($C69<>"",$E69<>"Full Refresher"),'G1 MT Reading Scoresheet'!$P72,"") | J69: ='G1 MT Reading Scoresheet'!$U72 | K69: =IF('G1 MT Reading Scoresheet'!V72<>"",'G1 MT Reading Scoresheet'!V72,"")
A70: =A69+1 -> 63 | B70: =IF('G1 MT Reading Scoresheet'!B73<>"",'G1 MT Reading Scoresheet'!B73,"") | C70: =IF('G1 MT Reading Scoresheet'!C73<>"",'G1 MT Reading Scoresheet'!C73,"") | D70: =IF('G1 MT Reading Scoresheet'!D73<>"",'G1 MT Reading Scoresheet'!D73,"") | E70: ='G1 MT Reading Scoresheet'!J73 | F70: =IF($C70<>"",'G1 MT Reading Scoresheet'!$I73/30,"") | G70: =IF(AND($C70<>"",$E70<>"Full Refresher"),'G1 MT Reading Scoresheet'!$Q73,"") | H70: =IF(AND($C70<>"",$E70<>"Full Refresher"),'G1 MT Reading Scoresheet'!$R73/5,"") | I70: =IF(AND($C70<>"",$E70<>"Full Refresher"),'G1 MT Reading Scoresheet'!$P73,"") | J70: ='G1 MT Reading Scoresheet'!$U73 | K70: =IF('G1 MT Reading Scoresheet'!V73<>"",'G1 MT Reading Scoresheet'!V73,"")
A71: =A70+1 -> 64 | B71: =IF('G1 MT Reading Scoresheet'!B74<>"",'G1 MT Reading Scoresheet'!B74,"") | C71: =IF('G1 MT Reading Scoresheet'!C74<>"",'G1 MT Reading Scoresheet'!C74,"") | D71: =IF('G1 MT Reading Scoresheet'!D74<>"",'G1 MT Reading Scoresheet'!D74,"") | E71: ='G1 MT Reading Scoresheet'!J74 | F71: =IF($C71<>"",'G1 MT Reading Scoresheet'!$I74/30,"") | G71: =IF(AND($C71<>"",$E71<>"Full Refresher"),'G1 MT Reading Scoresheet'!$Q74,"") | H71: =IF(AND($C71<>"",$E71<>"Full Refresher"),'G1 MT Reading Scoresheet'!$R74/5,"") | I71: =IF(AND($C71<>"",$E71<>"Full Refresher"),'G1 MT Reading Scoresheet'!$P74,"") | J71: ='G1 MT Reading Scoresheet'!$U74 | K71: =IF('G1 MT Reading Scoresheet'!V74<>"",'G1 MT Reading Scoresheet'!V74,"")
A72: =A71+1 -> 65 | B72: =IF('G1 MT Reading Scoresheet'!B75<>"",'G1 MT Reading Scoresheet'!B75,"") | C72: =IF('G1 MT Reading Scoresheet'!C75<>"",'G1 MT Reading Scoresheet'!C75,"") | D72: =IF('G1 MT Reading Scoresheet'!D75<>"",'G1 MT Reading Scoresheet'!D75,"") | E72: ='G1 MT Reading Scoresheet'!J75 | F72: =IF($C72<>"",'G1 MT Reading Scoresheet'!$I75/30,"") | G72: =IF(AND($C72<>"",$E72<>"Full Refresher"),'G1 MT Reading Scoresheet'!$Q75,"") | H72: =IF(AND($C72<>"",$E72<>"Full Refresher"),'G1 MT Reading Scoresheet'!$R75/5,"") | I72: =IF(AND($C72<>"",$E72<>"Full Refresher"),'G1 MT Reading Scoresheet'!$P75,"") | J72: ='G1 MT Reading Scoresheet'!$U75 | K72: =IF('G1 MT Reading Scoresheet'!V75<>"",'G1 MT Reading Scoresheet'!V75,"")
A73: =A72+1 -> 66 | B73: =IF('G1 MT Reading Scoresheet'!B76<>"",'G1 MT Reading Scoresheet'!B76,"") | C73: =IF('G1 MT Reading Scoresheet'!C76<>"",'G1 MT Reading Scoresheet'!C76,"") | D73: =IF('G1 MT Reading Scoresheet'!D76<>"",'G1 MT Reading Scoresheet'!D76,"") | E73: ='G1 MT Reading Scoresheet'!J76 | F73: =IF($C73<>"",'G1 MT Reading Scoresheet'!$I76/30,"") | G73: =IF(AND($C73<>"",$E73<>"Full Refresher"),'G1 MT Reading Scoresheet'!$Q76,"") | H73: =IF(AND($C73<>"",$E73<>"Full Refresher"),'G1 MT Reading Scoresheet'!$R76/5,"") | I73: =IF(AND($C73<>"",$E73<>"Full Refresher"),'G1 MT Reading Scoresheet'!$P76,"") | J73: ='G1 MT Reading Scoresheet'!$U76 | K73: =IF('G1 MT Reading Scoresheet'!V76<>"",'G1 MT Reading Scoresheet'!V76,"")
A74: =A73+1 -> 67 | B74: =IF('G1 MT Reading Scoresheet'!B77<>"",'G1 MT Reading Scoresheet'!B77,"") | C74: =IF('G1 MT Reading Scoresheet'!C77<>"",'G1 MT Reading Scoresheet'!C77,"") | D74: =IF('G1 MT Reading Scoresheet'!D77<>"",'G1 MT Reading Scoresheet'!D77,"") | E74: ='G1 MT Reading Scoresheet'!J77 | F74: =IF($C74<>"",'G1 MT Reading Scoresheet'!$I77/30,"") | G74: =IF(AND($C74<>"",$E74<>"Full Refresher"),'G1 MT Reading Scoresheet'!$Q77,"") | H74: =IF(AND($C74<>"",$E74<>"Full Refresher"),'G1 MT Reading Scoresheet'!$R77/5,"") | I74: =IF(AND($C74<>"",$E74<>"Full Refresher"),'G1 MT Reading Scoresheet'!$P77,"") | J74: ='G1 MT Reading Scoresheet'!$U77 | K74: =IF('G1 MT Reading Scoresheet'!V77<>"",'G1 MT Reading Scoresheet'!V77,"")
A75: =A74+1 -> 68 | B75: =IF('G1 MT Reading Scoresheet'!B78<>"",'G1 MT Reading Scoresheet'!B78,"") | C75: =IF('G1 MT Reading Scoresheet'!C78<>"",'G1 MT Reading Scoresheet'!C78,"") | D75: =IF('G1 MT Reading Scoresheet'!D78<>"",'G1 MT Reading Scoresheet'!D78,"") | E75: ='G1 MT Reading Scoresheet'!J78 | F75: =IF($C75<>"",'G1 MT Reading Scoresheet'!$I78/30,"") | G75: =IF(AND($C75<>"",$E75<>"Full Refresher"),'G1 MT Reading Scoresheet'!$Q78,"") | H75: =IF(AND($C75<>"",$E75<>"Full Refresher"),'G1 MT Reading Scoresheet'!$R78/5,"") | I75: =IF(AND($C75<>"",$E75<>"Full Refresher"),'G1 MT Reading Scoresheet'!$P78,"") | J75: ='G1 MT Reading Scoresheet'!$U78 | K75: =IF('G1 MT Reading Scoresheet'!V78<>"",'G1 MT Reading Scoresheet'!V78,"")
A76: =A75+1 -> 69 | B76: =IF('G1 MT Reading Scoresheet'!B79<>"",'G1 MT Reading Scoresheet'!B79,"") | C76: =IF('G1 MT Reading Scoresheet'!C79<>"",'G1 MT Reading Scoresheet'!C79,"") | D76: =IF('G1 MT Reading Scoresheet'!D79<>"",'G1 MT Reading Scoresheet'!D79,"") | E76: ='G1 MT Reading Scoresheet'!J79 | F76: =IF($C76<>"",'G1 MT Reading Scoresheet'!$I79/30,"") | G76: =IF(AND($C76<>"",$E76<>"Full Refresher"),'G1 MT Reading Scoresheet'!$Q79,"") | H76: =IF(AND($C76<>"",$E76<>"Full Refresher"),'G1 MT Reading Scoresheet'!$R79/5,"") | I76: =IF(AND($C76<>"",$E76<>"Full Refresher"),'G1 MT Reading Scoresheet'!$P79,"") | J76: ='G1 MT Reading Scoresheet'!$U79 | K76: =IF('G1 MT Reading Scoresheet'!V79<>"",'G1 MT Reading Scoresheet'!V79,"")
A77: =A76+1 -> 70 | B77: =IF('G1 MT Reading Scoresheet'!B80<>"",'G1 MT Reading Scoresheet'!B80,"") | C77: =IF('G1 MT Reading Scoresheet'!C80<>"",'G1 MT Reading Scoresheet'!C80,"") | D77: =IF('G1 MT Reading Scoresheet'!D80<>"",'G1 MT Reading Scoresheet'!D80,"") | E77: ='G1 MT Reading Scoresheet'!J80 | F77: =IF($C77<>"",'G1 MT Reading Scoresheet'!$I80/30,"") | G77: =IF(AND($C77<>"",$E77<>"Full Refresher"),'G1 MT Reading Scoresheet'!$Q80,"") | H77: =IF(AND($C77<>"",$E77<>"Full Refresher"),'G1 MT Reading Scoresheet'!$R80/5,"") | I77: =IF(AND($C77<>"",$E77<>"Full Refresher"),'G1 MT Reading Scoresheet'!$P80,"") | J77: ='G1 MT Reading Scoresheet'!$U80 | K77: =IF('G1 MT Reading Scoresheet'!V80<>"",'G1 MT Reading Scoresheet'!V80,"")
A78: =A77+1 -> 71 | B78: =IF('G1 MT Reading Scoresheet'!B81<>"",'G1 MT Reading Scoresheet'!B81,"") | C78: =IF('G1 MT Reading Scoresheet'!C81<>"",'G1 MT Reading Scoresheet'!C81,"") | D78: =IF('G1 MT Reading Scoresheet'!D81<>"",'G1 MT Reading Scoresheet'!D81,"") | E78: ='G1 MT Reading Scoresheet'!J81 | F78: =IF($C78<>"",'G1 MT Reading Scoresheet'!$I81/30,"") | G78: =IF(AND($C78<>"",$E78<>"Full Refresher"),'G1 MT Reading Scoresheet'!$Q81,"") | H78: =IF(AND($C78<>"",$E78<>"Full Refresher"),'G1 MT Reading Scoresheet'!$R81/5,"") | I78: =IF(AND($C78<>"",$E78<>"Full Refresher"),'G1 MT Reading Scoresheet'!$P81,"") | J78: ='G1 MT Reading Scoresheet'!$U81 | K78: =IF('G1 MT Reading Scoresheet'!V81<>"",'G1 MT Reading Scoresheet'!V81,"")
... A106: =A105+1 -> 99 | B106: =IF('G1 MT Reading Scoresheet'!B109<>"",'G1 MT Reading Scoresheet'!B109,"") | C106: =IF('G1 MT Reading Scoresheet'!C109<>"",'G1 MT Reading Scoresheet'!C109,"") | D106: =IF('G1 MT Reading Scoresheet'!D109<>"",'G1 MT Reading Scoresheet'!D109,"") | E106: ='G1 MT Reading Scoresheet'!J109 | F106: =IF($C106<>"",'G1 MT Reading Scoresheet'!$I109/30,"") | G106: =IF(AND($C106<>"",$E106<>"Full Refresher"),'G1 MT Reading Scoresheet'!$Q109,"") | H106: =IF(AND($C106<>"",$E106<>"Full Refresher"),'G1 MT Reading Scoresheet'!$R109/5,"") | I106: =IF(AND($C106<>"",$E106<>"Full Refresher"),'G1 MT Reading Scoresheet'!$P109,"") | J106: ='G1 MT Reading Scoresheet'!$U109 | K106: =IF('G1 MT Reading Scoresheet'!V109<>"",'G1 MT Reading Scoresheet'!V109,"")
A107: 100 | B107: =IF('G1 MT Reading Scoresheet'!B110<>"",'G1 MT Reading Scoresheet'!B110,"") | C107: =IF('G1 MT Reading Scoresheet'!C110<>"",'G1 MT Reading Scoresheet'!C110,"") | D107: =IF('G1 MT Reading Scoresheet'!D110<>"",'G1 MT Reading Scoresheet'!D110,"") | E107: ='G1 MT Reading Scoresheet'!J110 | F107: =IF($C107<>"",'G1 MT Reading Scoresheet'!$I110/30,"") | G107: =IF(AND($C107<>"",$E107<>"Full Refresher"),'G1 MT Reading Scoresheet'!$Q110,"") | H107: =IF(AND($C107<>"",$E107<>"Full Refresher"),'G1 MT Reading Scoresheet'!$R110/5,"") | I107: =IF(AND($C107<>"",$E107<>"Full Refresher"),'G1 MT Reading Scoresheet'!$P110,"") | J107: ='G1 MT Reading Scoresheet'!$U110 | K107: =IF('G1 MT Reading Scoresheet'!V110<>"",'G1 MT Reading Scoresheet'!V110,"")

Sheet Class Summary
A1: CRLA3v1
A2: GRADE 1 Assessment Scoresheet (CLASS SUMMARY)
A4: SCHOOL ID : | C4: ='G1 MT Reading Scoresheet'!C4 -> 117443
A5: SCHOOL NAME: | C5: ='G1 MT Reading Scoresheet'!C5 -> ROMANA ELEMENTARY SCHOOL
A6: Grade | D6: Language | F6: Number of Learners Enrolled | G6: Number of Learners Assessed | H6: Assessment Part 1 Level | L6: Assessment Part 2 Average Score | O6: READING PROFILE
B7: Section | C7: Teacher | E7: Sex | H7: Full Refresher | I7: Moderate Refresher | J7: Light Refresher | K7: Grade Ready | L7: Reading Fluency | M7: Reading Comprehension | N7: Average Word Per Minute | O7: Low Emerging Reader | P7: High Emerging Reader | Q7: Developing Reader | R7: Transitioning Reader | S7: Reading At Grade Level
A8: Grade 1 | B8: =IF('G1 MT Reading Scoresheet'!$C$8<>"",'G1 MT Reading Scoresheet'!$C$8,"") -> 1 | C8: =IF('G1 MT Reading Scoresheet'!$C$6<>"",'G1 MT Reading Scoresheet'!$C$6," ") -> MARIAN GRACE D. DE LA TORRE | D8: =IF('G1 MT Reading Scoresheet'!C9<>"",'G1 MT Reading Scoresheet'!C9,"") -> Hiligaynon | E8: Male | F8: ='G1 MT Reading Scoresheet'!D6 -> 10 | G8: =COUNTIF('G1 MT Reading Scoresheet'!$D$11:$D$110,$E8) -> 10 | H8: =COUNTIFS('Class Record'!$E$8:$E$107,H$7,'Class Record'!$D$8:$D$107,$E8) -> 3 | I8: =COUNTIFS('Class Record'!$E$8:$E$107,I$7,'Class Record'!$D$8:$D$107,$E8) -> 0 | J8: =COUNTIFS('Class Record'!$E$8:$E$107,J$7,'Class Record'!$D$8:$D$107,$E8) -> 2 | K8: =COUNTIFS('Class Record'!$E$8:$E$107,K$7,'Class Record'!$D$8:$D$107,$E8) -> 5 | L8: =IFERROR(AVERAGEIFS('Class Record'!G$8:G$107,'Class Record'!$D$8:$D$107,$E8),"") -> 0.74285714 | M8: =IFERROR(AVERAGEIFS('Class Record'!H$8:H$107,'Class Record'!$D$8:$D$107,$E8),"") -> 0.68571429 | N8: =IFERROR(AVERAGEIFS('Class Record'!I$8:I$107,'Class Record'!$D$8:$D$107,$E8),"") -> 37.142857 | O8: =COUNTIFS('Class Record'!$J$8:$J$107,O$7,'Class Record'!$D$8:$D$107,$E8) -> 3 | P8: =COUNTIFS('Class Record'!$J$8:$J$107,P$7,'Class Record'!$D$8:$D$107,$E8) -> 0 | Q8: =COUNTIFS('Class Record'!$J$8:$J$107,Q$7,'Class Record'!$D$8:$D$107,$E8) -> 1 | R8: =COUNTIFS('Class Record'!$J$8:$J$107,R$7,'Class Record'!$D$8:$D$107,$E8) -> 3 | S8: =COUNTIFS('Class Record'!$J$8:$J$107,S$7,'Class Record'!$D$8:$D$107,$E8) -> 3
