Workbook

Sheet Class Results
A1: RMA2v2 | V1: =X1 -> RMA2v2 | X1: RMA2v2
A2: School Rapid Mathematics Assessment Results
A4: SCHOOL ID : | B4: 117443 | G4: Medium of Instruction (MOI)
A5: SCHOOL NAME: | B5: Romana Elementary School | G5: Grade 1 | I5: Grade 2 | K5: Grade 3
G6: English | I6: English | K6: English
A8: Grade | D8: Language Matched ( LOI vs Learners) | E8: Number of Learners Assessed | F8: Total Enrolment | G8: Number of Learners Assessed | L8: Number of Learners with Correct Answers >=75 | X8: Status
B9: Section | C9: Sex | G9: Emerging (Not Proficient) | H9: Emerging (Low Proficient) | I9: Developing (Nearly Proficient) | J9: Transitioning (Proficient) | K9: At Grade Level (Highly Proficient) | L9: Task A | M9: Task B | N9: Task C | O9: Task D | P9: Task E | Q9: Task F | R9: Task G | S9: Task H | T9: Task I | U9: Task J | V9: Task K | W9: Average Overall Score
A10: Grade 1 | B10: 1 | C10: Male | E10: 10 | F10: 10 | G10: 6 | H10: 1 | I10: 1 | J10: 1 | K10: 1 | L10: 4 | M10: 1 | N10: 4 | O10: 1 | P10: 2 | Q10: 4 | R10: 0 | S10: 1 | W10: =IFERROR(AVERAGEIFS('[1]G1 RMA Scoresheet'!Q$10:Q$109,'[1]G1 RMA Scoresheet'!$D$10:$D$109,$C10),"") -> 10.7 | X10: =IF(ISBLANK(A10)," ",IF(SUM(G10:K10)=E10,"Data Validated","Data with Error")) -> Data Validated | AA10: Language
A11: Grade 1 | B11: 1 | C11: Female | E11: 4 | F11: 4 | G11: 0 | H11: 0 | I11: 2 | J11: 2 | K11: 0 | L11: 3 | M11: 1 | N11: 3 | O11: 3 | P11: 3 | Q11: 3 | R11: 0 | S11: 0 | W11: =IFERROR(AVERAGEIFS('[1]G1 RMA Scoresheet'!Q$10:Q$109,'[1]G1 RMA Scoresheet'!$D$10:$D$109,$C11),"") -> 27.25 | X11: =IF(ISBLANK(A11)," ",IF(SUM(G11:K11)=E11,"Data Validated","Data with Error")) -> Data Validated | AA11: Akeanon
A12: Grade 2 | B12: 1 | C12: Male | E12: 7 | F12: 7 | G12: 6 | H12: 1 | I12: 0 | J12: 0 | K12: 0 | L12: 0 | M12: 1 | N12: 0 | O12: 1 | P12: 0 | Q12: 0 | R12: 0 | S12: 0 | T12: 2 | U12: 0 | V12: 6 | W12: =IFERROR(AVERAGEIFS('[2]G2 RMA Scoresheet'!T$10:T$109,'[2]G2 RMA Scoresheet'!$D$10:$D$109,$C12),"") | X12: =IF(ISBLANK(A12)," ",IF(SUM(G12:K12)=E12,"Data Validated","Data with Error")) -> Data Validated | AA12: Bahasa Sug
A13: Grade 2 | B13: 1 | C13: Female | E13: 8 | F13: 8 | G13: 3 | H13: 5 | I13: 0 | J13: 0 | K13: 0 | L13: 0 | M13: 5 | N13: 0 | O13: 2 | P13: 0 | Q13: 0 | R13: 0 | S13: 0 | T13: 5 | U13: 4 | V13: 6 | W13: =IFERROR(AVERAGEIFS('[2]G2 RMA Scoresheet'!T$10:T$109,'[2]G2 RMA Scoresheet'!$D$10:$D$109,$C13),"") | X13: =IF(ISBLANK(A13)," ",IF(SUM(G13:K13)=E13,"Data Validated","Data with Error")) -> Data Validated | AA13: Bikol Libon
A14: Grade 3 | B14: 1 | C14: Male | E14: 10 | F14: 10 | G14: 0 | H14: 0 | I14: 2 | J14: 2 | K14: 6 | L14: 10 | M14: 10 | N14: 10 | O14: 6 | P14: 7 | Q14: 6 | R14: 4 | S14: 7 | W14: 16.6 | X14: =IF(ISBLANK(A14)," ",IF(SUM(G14:K14)=E14,"Data Validated","Data with Error")) -> Data Validated | AA14: Buhi-non
A15: Grade 3 | B15: 1 | C15: Female | E15: 15 | F15: 15 | G15: 0 | H15: 0 | I15: 2 | J15: 3 | K15: 10 | L15: 13 | M15: 15 | N15: 13 | O15: 13 | P15: 13 | Q15: 12 | R15: 5 | S15: 10 | W15: 17.133333 | X15: =IF(ISBLANK(A15)," ",IF(SUM(G15:K15)=E15,"Data Validated","Data with Error")) -> Data Validated | AA15: Central Bikol
X16: =IF(ISBLANK(A16)," ",IF(SUM(G16:K16)=E16,"Data Validated","Data with Error")) | AA16: Chavacano
X17: =IF(ISBLANK(A17)," ",IF(SUM(G17:K17)=E17,"Data Validated","Data with Error")) | AA17: Caluyanen
X18: =IF(ISBLANK(A18)," ",IF(SUM(G18:K18)=E18,"Data Validated","Data with Error")) | AA18: Cuyonon
X19: =IF(ISBLANK(A19)," ",IF(SUM(G19:K19)=E19,"Data Validated","Data with Error")) | AA19: English
X20: =IF(ISBLANK(A20)," ",IF(SUM(G20:K20)=E20,"Data Validated","Data with Error")) | AA20: Hiligaynon
X21: =IF(ISBLANK(A21)," ",IF(SUM(G21:K21)=E21,"Data Validated","Data with Error")) | AA21: Ibanag
X22: =IF(ISBLANK(A22)," ",IF(SUM(G22:K22)=E22,"Data Validated","Data with Error")) | AA22: Ilocano
X23: =IF(ISBLANK(A23)," ",IF(SUM(G23:K23)=E23,"Data Validated","Data with Error")) | AA23: Inabaknon
X24: =IF(ISBLANK(A24)," ",IF(SUM(G24:K24)=E24,"Data Validated","Data with Error")) | AA24: Ivatan
X25: =IF(ISBLANK(A25)," ",IF(SUM(G25:K25)=E25,"Data Validated","Data with Error")) | AA25: Kapampangan
X26: =IF(ISBLANK(A26)," ",IF(SUM(G26:K26)=E26,"Data Validated","Data with Error")) | AA26: Kinaray-a - Antique
X27: =IF(ISBLANK(A27)," ",IF(SUM(G27:K27)=E27,"Data Validated","Data with Error")) | AA27: Kinaray-a - Iloilo
... X38: =IF(ISBLANK(A38)," ",IF(SUM(G38:K38)=E38,"Data Validated","Data with Error")) | AA38: Northern Sorsoganon
W39: {=IF(A39<>"",_xlfn.IFS(A39="Grade 1",SUM(L39:S39),A39="Grade 2",SUM(L39:V39),A39="Grade 3",SUM(L39:S39)),"")} | X39: =IF(ISBLANK(A39)," ",IF(SUM(G39:K39)=E39,"Data Validated","Data with Error")) | AA39: Southern Sorsoganon
W40: {=IF(A40<>"",_xlfn.IFS(A40="Grade 1",SUM(L40:S40),A40="Grade 2",SUM(L40:V40),A40="Grade 3",SUM(L40:S40)),"")} | X40: =IF(ISBLANK(A40)," ",IF(SUM(G40:K40)=E40,"Data Validated","Data with Error")) | AA40: Surigaonon
W41: {=IF(A41<>"",_xlfn.IFS(A41="Grade 1",SUM(L41:S41),A41="Grade 2",SUM(L41:V41),A41="Grade 3",SUM(L41:S41)),"")} | X41: =IF(ISBLANK(A41)," ",IF(SUM(G41:K41)=E41,"Data Validated","Data with Error")) | AA41: Tagalog
W42: {=IF(A42<>"",_xlfn.IFS(A42="Grade 1",SUM(L42:S42),A42="Grade 2",SUM(L42:V42),A42="Grade 3",SUM(L42:S42)),"")} | X42: =IF(ISBLANK(A42)," ",IF(SUM(G42:K42)=E42,"Data Validated","Data with Error")) | AA42: Waray
W43: {=IF(A43<>"",_xlfn.IFS(A43="Grade 1",SUM(L43:S43),A43="Grade 2",SUM(L43:V43),A43="Grade 3",SUM(L43:S43)),"")} | X43: =IF(ISBLANK(A43)," ",IF(SUM(G43:K43)=E43,"Data Validated","Data with Error")) | AA43: West Albay Bikol
W44: {=IF(A44<>"",_xlfn.IFS(A44="Grade 1",SUM(L44:S44),A44="Grade 2",SUM(L44:V44),A44="Grade 3",SUM(L44:S44)),"")} | X44: =IF(ISBLANK(A44)," ",IF(SUM(G44:K44)=E44,"Data Validated","Data with Error")) | AA44: Yakan
W45: {=IF(A45<>"",_xlfn.IFS(A45="Grade 1",SUM(L45:S45),A45="Grade 2",SUM(L45:V45),A45="Grade 3",SUM(L45:S45)),"")} | X45: =IF(ISBLANK(A45)," ",IF(SUM(G45:K45)=E45,"Data Validated","Data with Error")) | AA45: Other MT
W46: {=IF(A46<>"",_xlfn.IFS(A46="Grade 1",SUM(L46:S46),A46="Grade 2",SUM(L46:V46),A46="Grade 3",SUM(L46:S46)),"")} | X46: =IF(ISBLANK(A46)," ",IF(SUM(G46:K46)=E46,"Data Validated","Data with Error"))
W47: {=IF(A47<>"",_xlfn.IFS(A47="Grade 1",SUM(L47:S47),A47="Grade 2",SUM(L47:V47),A47="Grade 3",SUM(L47:S47)),"")} | X47: =IF(ISBLANK(A47)," ",IF(SUM(G47:K47)=E47,"Data Validated","Data with Error"))
W48: {=IF(A48<>"",_xlfn.IFS(A48="Grade 1",SUM(L48:S48),A48="Grade 2",SUM(L48:V48),A48="Grade 3",SUM(L48:S48)),"")} | X48: =IF(ISBLANK(A48)," ",IF(SUM(G48:K48)=E48,"Data Validated","Data with Error"))
W49: {=IF(A49<>"",_xlfn.IFS(A49="Grade 1",SUM(L49:S49),A49="Grade 2",SUM(L49:V49),A49="Grade 3",SUM(L49:S49)),"")} | X49: =IF(ISBLANK(A49)," ",IF(SUM(G49:K49)=E49,"Data Validated","Data with Error"))
W50: {=IF(A50<>"",_xlfn.IFS(A50="Grade 1",SUM(L50:S50),A50="Grade 2",SUM(L50:V50),A50="Grade 3",SUM(L50:S50)),"")} | X50: =IF(ISBLANK(A50)," ",IF(SUM(G50:K50)=E50,"Data Validated","Data with Error"))
W51: {=IF(A51<>"",_xlfn.IFS(A51="Grade 1",SUM(L51:S51),A51="Grade 2",SUM(L51:V51),A51="Grade 3",SUM(L51:S51)),"")} | X51: =IF(ISBLANK(A51)," ",IF(SUM(G51:K51)=E51,"Data Validated","Data with Error"))
W52: {=IF(A52<>"",_xlfn.IFS(A52="Grade 1",SUM(L52:S52),A52="Grade 2",SUM(L52:V52),A52="Grade 3",SUM(L52:S52)),"")} | X52: =IF(ISBLANK(A52)," ",IF(SUM(G52:K52)=E52,"Data Validated","Data with Error"))
...

Sheet School Summary
X1: ='Class Results'!$X$1 -> RMA2v2
A2: School Rapid Mathematics Assessment Summary
I3: Male | J3: =D11+D13+D15 -> 27
I4: Female | J4: =D12+D14+D16 -> 27
A5: SCHOOL ID : | B5: ='Class Results'!B4 -> 117443 | G5: Medium of Instruction (MOI)
A6: SCHOOL NAME | B6: ='Class Results'!$B$5 -> Romana Elementary School | G6: Grade 1 | I6: Grade 2 | K6: Grade 3 | BC6: Total Score
G7: ='Class Results'!G6 -> English | I7: ='Class Results'!I6 -> English | K7: ='Class Results'!K6 -> English | BC7: Grade 1 | BD7: 35
BC8: Grade 2 | BD8: 25
C9: Language Matched ( LOI vs Learners) | D9: Number of Learners Assessed | E9: Total Enrolment | F9: Number of Learners Assessed | L9: Number of Learners Who Passed 75% Per Task by Grade Level | W9: Average Overall Score | AD9: Total Items | BC9: Grade 3 | BD9: 20
A10: Grade | B10: Sex | F10: Emerging (Not Proficient) | G10: Emerging (Low Proficient) | H10: Developing (Nearly Proficient) | I10: Transitioning (Proficient) | J10: At Grade Level (Highly Proficient) | L10: Task A | M10: Task B | N10: Task C | O10: Task D | P10: Task E | Q10: Task F | R10: Task G | S10: Task H | T10: Task I | U10: Task J | V10: Task K | AD10: Task A | AE10: Task B | AF10: Task C | AG10: Task D | AH10: Task E | AI10: Task F | AJ10: Task G | AK10: Task H | AL10: Task I | AM10: Task J | AN10: Task K | AO10: Total
A11: Grade 1 | B11: Male | C11: =SUMIFS('Class Results'!D$10:D$362,'Class Results'!$A$10:$A$362,$A11, 'Class Results'!$C$10:$C$362,$B11) -> 0 | D11: =SUMIFS('Class Results'!E$10:E$362,'Class Results'!$A$10:$A$362,$A11, 'Class Results'!$C$10:$C$362,$B11) -> 10 | E11: =SUMIFS('Class Results'!F$10:F$362,'Class Results'!$A$10:$A$362,$A11, 'Class Results'!$C$10:$C$362,$B11) -> 10 | F11: =SUMIFS('Class Results'!G$10:G$362,'Class Results'!$A$10:$A$362,$A11, 'Class Results'!$C$10:$C$362,$B11) -> 6 | G11: =SUMIFS('Class Results'!H$10:H$362,'Class Results'!$A$10:$A$362,$A11, 'Class Results'!$C$10:$C$362,$B11) -> 1 | H11: =SUMIFS('Class Results'!I$10:I$362,'Class Results'!$A$10:$A$362,$A11, 'Class Results'!$C$10:$C$362,$B11) -> 1 | I11: =SUMIFS('Class Results'!J$10:J$362,'Class Results'!$A$10:$A$362,$A11, 'Class Results'!$C$10:$C$362,$B11) -> 1 | J11: =SUMIFS('Class Results'!K$10:K$362,'Class Results'!$A$10:$A$362,$A11, 'Class Results'!$C$10:$C$362,$B11) -> 1 | L11: =SUMIFS('Class Results'!L$10:L$362,'Class Results'!$A$10:$A$362,$A11, 'Class Results'!$C$10:$C$362,$B11) -> 4 | M11: =SUMIFS('Class Results'!M$10:M$362,'Class Results'!$A$10:$A$362,$A11, 'Class Results'!$C$10:$C$362,$B11) -> 1 | N11: =SUMIFS('Class Results'!N$10:N$362,'Class Results'!$A$10:$A$362,$A11, 'Class Results'!$C$10:$C$362,$B11) -> 4 | O11: =SUMIFS('Class Results'!O$10:O$362,'Class Results'!$A$10:$A$362,$A11, 'Class Results'!$C$10:$C$362,$B11) -> 1 | P11: =SUMIFS('Class Results'!P$10:P$362,'Class Results'!$A$10:$A$362,$A11, 'Class Results'!$C$10:$C$362,$B11) -> 2 | Q11: =SUMIFS('Class Results'!Q$10:Q$362,'Class Results'!$A$10:$A$362,$A11, 'Class Results'!$C$10:$C$362,$B11) -> 4 | R11: =SUMIFS('Class Results'!R$10:R$362,'Class Results'!$A$10:$A$362,$A11, 'Class Results'!$C$10:$C$362,$B11) -> 0 | S11: =SUMIFS('Class Results'!S$10:S$362,'Class Results'!$A$10:$A$362,$A11, 'Class Results'!$C$10:$C$362,$B11) -> 1 | W11: =IFERROR(AVERAGEIFS('Class Results'!W$10:W$362,'Class Results'!$A$10:$A$362,$A11, 'Class Results'!$C$10:$C$362,$B11),"") -> 10.7 | AD11: 8 | AE11: 2 | AF11: 8 | AG11: 6 | AH11: 4 | AI11: 1 | AJ11: 3 | AK11: 3 | AO11: =SUM(AD11:AL11) -> 35
A12: Grade 1 | B12: Female | C12: =SUMIFS('Class Results'!D$10:D$362,'Class Results'!$A$10:$A$362,$A12, 'Class Results'!$C$10:$C$362,$B12) -> 0 | D12: =SUMIFS('Class Results'!E$10:E$362,'Class Results'!$A$10:$A$362,$A12, 'Class Results'!$C$10:$C$362,$B12) -> 4 | E12: =SUMIFS('Class Results'!F$10:F$362,'Class Results'!$A$10:$A$362,$A12, 'Class Results'!$C$10:$C$362,$B12) -> 4 | F12: =SUMIFS('Class Results'!G$10:G$362,'Class Results'!$A$10:$A$362,$A12, 'Class Results'!$C$10:$C$362,$B12) -> 0 | G12: =SUMIFS('Class Results'!H$10:H$362,'Class Results'!$A$10:$A$362,$A12, 'Class Results'!$C$10:$C$362,$B12) -> 0 | H12: =SUMIFS('Class Results'!I$10:I$362,'Class Results'!$A$10:$A$362,$A12, 'Class Results'!$C$10:$C$362,$B12) -> 2 | I12: =SUMIFS('Class Results'!J$10:J$362,'Class Results'!$A$10:$A$362,$A12, 'Class Results'!$C$10:$C$362,$B12) -> 2 | J12: =SUMIFS('Class Results'!K$10:K$362,'Class Results'!$A$10:$A$362,$A12, 'Class Results'!$C$10:$C$362,$B12) -> 0 | L12: =SUMIFS('Class Results'!L$10:L$362,'Class Results'!$A$10:$A$362,$A12, 'Class Results'!$C$10:$C$362,$B12) -> 3 | M12: =SUMIFS('Class Results'!M$10:M$362,'Class Results'!$A$10:$A$362,$A12, 'Class Results'!$C$10:$C$362,$B12) -> 1 | N12: =SUMIFS('Class Results'!N$10:N$362,'Class Results'!$A$10:$A$362,$A12, 'Class Results'!$C$10:$C$362,$B12) -> 3 | O12: =SUMIFS('Class Results'!O$10:O$362,'Class Results'!$A$10:$A$362,$A12, 'Class Results'!$C$10:$C$362,$B12) -> 3 | P12: =SUMIFS('Class Results'!P$10:P$362,'Class Results'!$A$10:$A$362,$A12, 'Class Results'!$C$10:$C$362,$B12) -> 3 | Q12: =SUMIFS('Class Results'!Q$10:Q$362,'Class Results'!$A$10:$A$362,$A12, 'Class Results'!$C$10:$C$362,$B12) -> 3 | R12: =SUMIFS('Class Results'!R$10:R$362,'Class Results'!$A$10:$A$362,$A12, 'Class Results'!$C$10:$C$362,$B12) -> 0 | S12: =SUMIFS('Class Results'!S$10:S$362,'Class Results'!$A$10:$A$362,$A12, 'Class Results'!$C$10:$C$362,$B12) -> 0 | W12: =IFERROR(AVERAGEIFS('Class Results'!W$10:W$362,'Class Results'!$A$10:$A$362,$A12, 'Class Results'!$C$10:$C$362,$B12),"") -> 27.25 | AD12: 3 | AE12: 1 | AF12: 2 | AG12: 1 | AH12: 4 | AI12: 3 | AJ12: 3 | AK12: 4 | AL12: 2 | AM12: 1 | AN12: 1 | AO12: =SUM(AD12:AN12) -> 25
A13: Grade 2 | B13: =B11 -> Male | C13: =SUMIFS('Class Results'!D$10:D$362,'Class Results'!$A$10:$A$362,$A13, 'Class Results'!$C$10:$C$362,$B13) -> 0 | D13: =SUMIFS('Class Results'!E$10:E$362,'Class Results'!$A$10:$A$362,$A13, 'Class Results'!$C$10:$C$362,$B13) -> 7 | E13: =SUMIFS('Class Results'!F$10:F$362,'Class Results'!$A$10:$A$362,$A13, 'Class Results'!$C$10:$C$362,$B13) -> 7 | F13: =SUMIFS('Class Results'!G$10:G$362,'Class Results'!$A$10:$A$362,$A13, 'Class Results'!$C$10:$C$362,$B13) -> 6 | G13: =SUMIFS('Class Results'!H$10:H$362,'Class Results'!$A$10:$A$362,$A13, 'Class Results'!$C$10:$C$362,$B13) -> 1 | H13: =SUMIFS('Class Results'!I$10:I$362,'Class Results'!$A$10:$A$362,$A13, 'Class Results'!$C$10:$C$362,$B13) -> 0 | I13: =SUMIFS('Class Results'!J$10:J$362,'Class Results'!$A$10:$A$362,$A13, 'Class Results'!$C$10:$C$362,$B13) -> 0 | J13: =SUMIFS('Class Results'!K$10:K$362,'Class Results'!$A$10:$A$362,$A13, 'Class Results'!$C$10:$C$362,$B13) -> 0 | L13: =SUMIFS('Class Results'!L$10:L$362,'Class Results'!$A$10:$A$362,$A13, 'Class Results'!$C$10:$C$362,$B13) -> 0 | M13: =SUMIFS('Class Results'!M$10:M$362,'Class Results'!$A$10:$A$362,$A13, 'Class Results'!$C$10:$C$362,$B13) -> 1 | N13: =SUMIFS('Class Results'!N$10:N$362,'Class Results'!$A$10:$A$362,$A13, 'Class Results'!$C$10:$C$362,$B13) -> 0 | O13: =SUMIFS('Class Results'!O$10:O$362,'Class Results'!$A$10:$A$362,$A13, 'Class Results'!$C$10:$C$362,$B13) -> 1 | P13: =SUMIFS('Class Results'!P$10:P$362,'Class Results'!$A$10:$A$362,$A13, 'Class Results'!$C$10:$C$362,$B13) -> 0 | Q13: =SUMIFS('Class Results'!Q$10:Q$362,'Class Results'!$A$10:$A$362,$A13, 'Class Results'!$C$10:$C$362,$B13) -> 0 | R13: =SUMIFS('Class Results'!R$10:R$362,'Class Results'!$A$10:$A$362,$A13, 'Class Results'!$C$10:$C$362,$B13) -> 0 | S13: =SUMIFS('Class Results'!S$10:S$362,'Class Results'!$A$10:$A$362,$A13, 'Class Results'!$C$10:$C$362,$B13) -> 0 | ... V13: =SUMIFS('Class Results'!V$10:V$362,'Class Results'!$A$10:$A$362,$A13, 'Class Results'!$C$10:$C$362,$B13) -> 6 | W13: =IFERROR(AVERAGEIFS('Class Results'!W$10:W$362,'Class Results'!$A$10:$A$362,$A13, 'Class Results'!$C$10:$C$362,$B13),"") | AD13: 2 | AE13: 1 | AF13: 2 | AG13: 3 | AH13: 3 | AI13: 2 | AJ13: 3 | AK13: 4 | AO13: =SUM(AD13:AN13) -> 20
A14: Grade 2 | B14: Female | C14: =SUMIFS('Class Results'!D$10:D$362,'Class Results'!$A$10:$A$362,$A14, 'Class Results'!$C$10:$C$362,$B14) -> 0 | D14: =SUMIFS('Class Results'!E$10:E$362,'Class Results'!$A$10:$A$362,$A14, 'Class Results'!$C$10:$C$362,$B14) -> 8 | E14: =SUMIFS('Class Results'!F$10:F$362,'Class Results'!$A$10:$A$362,$A14, 'Class Results'!$C$10:$C$362,$B14) -> 8 | F14: =SUMIFS('Class Results'!G$10:G$362,'Class Results'!$A$10:$A$362,$A14, 'Class Results'!$C$10:$C$362,$B14) -> 3 | G14: =SUMIFS('Class Results'!H$10:H$362,'Class Results'!$A$10:$A$362,$A14, 'Class Results'!$C$10:$C$362,$B14) -> 5 | H14: =SUMIFS('Class Results'!I$10:I$362,'Class Results'!$A$10:$A$362,$A14, 'Class Results'!$C$10:$C$362,$B14) -> 0 | I14: =SUMIFS('Class Results'!J$10:J$362,'Class Results'!$A$10:$A$362,$A14, 'Class Results'!$C$10:$C$362,$B14) -> 0 | J14: =SUMIFS('Class Results'!K$10:K$362,'Class Results'!$A$10:$A$362,$A14, 'Class Results'!$C$10:$C$362,$B14) -> 0 | L14: =SUMIFS('Class Results'!L$10:L$362,'Class Results'!$A$10:$A$362,$A14, 'Class Results'!$C$10:$C$362,$B14) -> 0 | M14: =SUMIFS('Class Results'!M$10:M$362,'Class Results'!$A$10:$A$362,$A14, 'Class Results'!$C$10:$C$362,$B14) -> 5 | N14: =SUMIFS('Class Results'!N$10:N$362,'Class Results'!$A$10:$A$362,$A14, 'Class Results'!$C$10:$C$362,$B14) -> 0 | O14: =SUMIFS('Class Results'!O$10:O$362,'Class Results'!$A$10:$A$362,$A14, 'Class Results'!$C$10:$C$362,$B14) -> 2 | P14: =SUMIFS('Class Results'!P$10:P$362,'Class Results'!$A$10:$A$362,$A14, 'Class Results'!$C$10:$C$362,$B14) -> 0 | Q14: =SUMIFS('Class Results'!Q$10:Q$362,'Class Results'!$A$10:$A$362,$A14, 'Class Results'!$C$10:$C$362,$B14) -> 0 | R14: =SUMIFS('Class Results'!R$10:R$362,'Class Results'!$A$10:$A$362,$A14, 'Class Results'!$C$10:$C$362,$B14) -> 0 | S14: =SUMIFS('Class Results'!S$10:S$362,'Class Results'!$A$10:$A$362,$A14, 'Class Results'!$C$10:$C$362,$B14) -> 0 | ... V14: =SUMIFS('Class Results'!V$10:V$362,'Class Results'!$A$10:$A$362,$A14, 'Class Results'!$C$10:$C$362,$B14) -> 6 | W14: =IFERROR(AVERAGEIFS('Class Results'!W$10:W$362,'Class Results'!$A$10:$A$362,$A14, 'Class Results'!$C$10:$C$362,$B14),"")
A15: Grade 3 | B15: =B11 -> Male | C15: =SUMIFS('Class Results'!D$10:D$362,'Class Results'!$A$10:$A$362,$A15, 'Class Results'!$C$10:$C$362,$B15) -> 0 | D15: =SUMIFS('Class Results'!E$10:E$362,'Class Results'!$A$10:$A$362,$A15, 'Class Results'!$C$10:$C$362,$B15) -> 10 | E15: =SUMIFS('Class Results'!F$10:F$362,'Class Results'!$A$10:$A$362,$A15, 'Class Results'!$C$10:$C$362,$B15) -> 10 | F15: =SUMIFS('Class Results'!G$10:G$362,'Class Results'!$A$10:$A$362,$A15, 'Class Results'!$C$10:$C$362,$B15) -> 0 | G15: =SUMIFS('Class Results'!H$10:H$362,'Class Results'!$A$10:$A$362,$A15, 'Class Results'!$C$10:$C$362,$B15) -> 0 | H15: =SUMIFS('Class Results'!I$10:I$362,'Class Results'!$A$10:$A$362,$A15, 'Class Results'!$C$10:$C$362,$B15) -> 2 | I15: =SUMIFS('Class Results'!J$10:J$362,'Class Results'!$A$10:$A$362,$A15, 'Class Results'!$C$10:$C$362,$B15) -> 2 | J15: =SUMIFS('Class Results'!K$10:K$362,'Class Results'!$A$10:$A$362,$A15, 'Class Results'!$C$10:$C$362,$B15) -> 6 | L15: =SUMIFS('Class Results'!L$10:L$362,'Class Results'!$A$10:$A$362,$A15, 'Class Results'!$C$10:$C$362,$B15) -> 10 | M15: =SUMIFS('Class Results'!M$10:M$362,'Class Results'!$A$10:$A$362,$A15, 'Class Results'!$C$10:$C$362,$B15) -> 10 | N15: =SUMIFS('Class Results'!N$10:N$362,'Class Results'!$A$10:$A$362,$A15, 'Class Results'!$C$10:$C$362,$B15) -> 10 | O15: =SUMIFS('Class Results'!O$10:O$362,'Class Results'!$A$10:$A$362,$A15, 'Class Results'!$C$10:$C$362,$B15) -> 6 | P15: =SUMIFS('Class Results'!P$10:P$362,'Class Results'!$A$10:$A$362,$A15, 'Class Results'!$C$10:$C$362,$B15) -> 7 | Q15: =SUMIFS('Class Results'!Q$10:Q$362,'Class Results'!$A$10:$A$362,$A15, 'Class Results'!$C$10:$C$362,$B15) -> 6 | R15: =SUMIFS('Class Results'!R$10:R$362,'Class Results'!$A$10:$A$362,$A15, 'Class Results'!$C$10:$C$362,$B15) -> 4 | S15: =SUMIFS('Class Results'!S$10:S$362,'Class Results'!$A$10:$A$362,$A15, 'Class Results'!$C$10:$C$362,$B15) -> 7 | T15: =IFERROR(AVERAGEIFS('Class Results'!T$10:T$362,'Class Results'!$A$10:$A$362,$A15, 'Class Results'!$C$10:$C$362,$B15),"") | W15: =IFERROR(AVERAGEIFS('Class Results'!W$10:W$362,'Class Results'!$A$10:$A$362,$A15, 'Class Results'!$C$10:$C$362,$B15),"") -> 16.6
A16: Grade 3 | B16: Female | C16: =SUMIFS('Class Results'!D$10:D$362,'Class Results'!$A$10:$A$362,$A16, 'Class Results'!$C$10:$C$362,$B16) -> 0 | D16: =SUMIFS('Class Results'!E$10:E$362,'Class Results'!$A$10:$A$362,$A16, 'Class Results'!$C$10:$C$362,$B16) -> 15 | E16: =SUMIFS('Class Results'!F$10:F$362,'Class Results'!$A$10:$A$362,$A16, 'Class Results'!$C$10:$C$362,$B16) -> 15 | F16: =SUMIFS('Class Results'!G$10:G$362,'Class Results'!$A$10:$A$362,$A16, 'Class Results'!$C$10:$C$362,$B16) -> 0 | G16: =SUMIFS('Class Results'!H$10:H$362,'Class Results'!$A$10:$A$362,$A16, 'Class Results'!$C$10:$C$362,$B16) -> 0 | H16: =SUMIFS('Class Results'!I$10:I$362,'Class Results'!$A$10:$A$362,$A16, 'Class Results'!$C$10:$C$362,$B16) -> 2 | I16: =SUMIFS('Class Results'!J$10:J$362,'Class Results'!$A$10:$A$362,$A16, 'Class Results'!$C$10:$C$362,$B16) -> 3 | J16: =SUMIFS('Class Results'!K$10:K$362,'Class Results'!$A$10:$A$362,$A16, 'Class Results'!$C$10:$C$362,$B16) -> 10 | L16: =SUMIFS('Class Results'!L$10:L$362,'Class Results'!$A$10:$A$362,$A16, 'Class Results'!$C$10:$C$362,$B16) -> 13 | M16: =SUMIFS('Class Results'!M$10:M$362,'Class Results'!$A$10:$A$362,$A16, 'Class Results'!$C$10:$C$362,$B16) -> 15 | N16: =SUMIFS('Class Results'!N$10:N$362,'Class Results'!$A$10:$A$362,$A16, 'Class Results'!$C$10:$C$362,$B16) -> 13 | O16: =SUMIFS('Class Results'!O$10:O$362,'Class Results'!$A$10:$A$362,$A16, 'Class Results'!$C$10:$C$362,$B16) -> 13 | P16: =SUMIFS('Class Results'!P$10:P$362,'Class Results'!$A$10:$A$362,$A16, 'Class Results'!$C$10:$C$362,$B16) -> 13 | Q16: =SUMIFS('Class Results'!Q$10:Q$362,'Class Results'!$A$10:$A$362,$A16, 'Class Results'!$C$10:$C$362,$B16) -> 12 | R16: =SUMIFS('Class Results'!R$10:R$362,'Class Results'!$A$10:$A$362,$A16, 'Class Results'!$C$10:$C$362,$B16) -> 5 | S16: =SUMIFS('Class Results'!S$10:S$362,'Class Results'!$A$10:$A$362,$A16, 'Class Results'!$C$10:$C$362,$B16) -> 10 | T16: =IFERROR(AVERAGEIFS('Class Results'!T$10:T$362,'Class Results'!$A$10:$A$362,$A16, 'Class Results'!$C$10:$C$362,$B16),"") | W16: =IFERROR(AVERAGEIFS('Class Results'!W$10:W$362,'Class Results'!$A$10:$A$362,$A16, 'Class Results'!$C$10:$C$362,$B16),"") -> 17.133333
A18: TOTAL | C18: Language Matched ( LOI vs Learners) | D18: Number of Learners Assessed | E18: Total Enrolment | F18: Number of Learners Assessed | L18: Percentage of Learners Who Passed 75% Per Task by Grade Level | W18: Average Overall Score
F19: Emerging (Not Proficient) | G19: Emerging (Low Proficient) | H19: Developing (Nearly Proficient) | I19: Transitioning (Proficient) | J19: At Grade Level (Highly Proficient) | L19: Task A | M19: Task B | N19: Task C | O19: Task D | P19: Task E | Q19: Task F | R19: Task G | S19: Task H | T19: Task I | U19: Task J | V19: Task K
A20: Total Grade 1 | C20: =C11+C12 -> 0 | D20: =D11+D12 -> 14 | E20: =E11+E12 -> 14 | F20: =F11+F12 -> 6 | G20: =G11+G12 -> 1 | H20: =H11+H12 -> 3 | I20: =I11+I12 -> 3 | J20: =J11+J12 -> 1 | L20: =L11+L12 -> 7 | M20: =M11+M12 -> 2 | N20: =N11+N12 -> 7 | O20: =O11+O12 -> 4 | P20: =P11+P12 -> 5 | Q20: =Q11+Q12 -> 7 | R20: =R11+R12 -> 0 | S20: =S11+S12 -> 1 | ... V20: =V11+V12 -> 0 | W20: =IFERROR(AVERAGE(W11:W12),"") -> 18.975
A21: Total Grade 2 | C21: =C13+C14 -> 0 | D21: =D13+D14 -> 15 | E21: =E13+E14 -> 15 | F21: =F13+F14 -> 9 | G21: =G13+G14 -> 6 | H21: =H13+H14 -> 0 | I21: =I13+I14 -> 0 | J21: =J13+J14 -> 0 | L21: =L13+L14 -> 0 | M21: =M13+M14 -> 6 | N21: =N13+N14 -> 0 | O21: =O13+O14 -> 3 | P21: =P13+P14 -> 0 | Q21: =Q13+Q14 -> 0 | R21: =R13+R14 -> 0 | S21: =S13+S14 -> 0 | ... V21: =V13+V14 -> 12 | W21: =IFERROR(AVERAGE(W13:W14),"")
A22: Total Grade 3 | C22: =C15+C16 -> 0 | D22: =D15+D16 -> 25 | E22: =E15+E16 -> 25 | F22: =F15+F16 -> 0 | G22: =G15+G16 -> 0 | H22: =H15+H16 -> 4 | I22: =I15+I16 -> 5 | J22: =J15+J16 -> 16 | L22: =L15+L16 -> 23 | M22: =M15+M16 -> 25 | N22: =N15+N16 -> 23 | O22: =O15+O16 -> 19 | P22: =P15+P16 -> 20 | Q22: =Q15+Q16 -> 18 | R22: =R15+R16 -> 9 | S22: =S15+S16 -> 17 | T22: 0 | U22: =U15+U16 -> 0 | V22: =V15+V16 -> 0 | W22: =IFERROR(AVERAGE(W15:W16),"") -> 16.866667
A23: Total Learners | C23: =SUM(C20:C22) -> 0 | D23: =SUM(D20:D22) -> 54 | E23: =SUM(E20:E22) -> 54 | F23: =SUM(F20:F22) -> 15 | G23: =SUM(G20:G22) -> 7 | H23: =SUM(H20:H22) -> 7 | I23: =SUM(I20:I22) -> 8 | J23: =SUM(J20:J22) -> 17 | L23: =L20+L21+L22 -> 30 | M23: =M20+M21+M22 -> 33 | N23: =N20+N21+N22 -> 30 | O23: =O20+O21+O22 -> 26 | P23: =P20+P21+P22 -> 25 | Q23: =Q20+Q21+Q22 -> 25 | R23: =R20+R21+R22 -> 9 | S23: =S20+S21+S22 -> 18 | ... V23: =V20+V21+V22 -> 12 | W23: =IFERROR(AVERAGE(W20:W22),"") -> 17.920833
F25: % of Learners Assessed | L25: % of Leaners who Passed 75% per Task by Grade Level
D26: Grade | E26: Sex | F26: Emerging (Not Proficient) | G26: Emerging (Low Proficient) | H26: Developing (Nearly Proficient) | I26: Transitioning (Proficient) | J26: At Grade Level (Highly Proficient) | L26: Task A | M26: Task B | N26: Task C | O26: Task D | P26: Task E | Q26: Task F | R26: Task G | S26: Task H | T26: Task I | U26: Task J | V26: Task K | W26: OverAll Score
D27: Grade 1 | E27: Male | F27: =IFERROR(F11/$D11,"") -> 0.6 | G27: =IFERROR(G11/$D11,"") -> 0.1 | H27: =IFERROR(H11/$D11,"") -> 0.1 | I27: =IFERROR(I11/$D11,"") -> 0.1 | J27: =IFERROR(J11/$D11,"") -> 0.1 | L27: =IFERROR(L11/$D11,"") -> 0.4 | M27: =IFERROR(M11/$D11,"") -> 0.1 | N27: =IFERROR(N11/$D11,"") -> 0.4 | O27: =IFERROR(O11/$D11,"") -> 0.1 | P27: =IFERROR(P11/$D11,"") -> 0.2 | Q27: =IFERROR(Q11/$D11,"") -> 0.4 | R27: =IFERROR(R11/$D11,"") -> 0 | S27: =IFERROR(S11/$D11,"") -> 0.1 | W27: =IFERROR(W11/$BD$7,"") -> 0.30571429
E28: Female | F28: =IFERROR(F12/$D12,"") -> 0 | G28: =IFERROR(G12/$D12,"") -> 0 | H28: =IFERROR(H12/$D12,"") -> 0.5 | I28: =IFERROR(I12/$D12,"") -> 0.5 | J28: =IFERROR(J12/$D12,"") -> 0 | L28: =IFERROR(L12/$D12,"") -> 0.75 | M28: =IFERROR(M12/$D12,"") -> 0.25 | N28: =IFERROR(N12/$D12,"") -> 0.75 | O28: =IFERROR(O12/$D12,"") -> 0.75 | P28: =IFERROR(P12/$D12,"") -> 0.75 | Q28: =IFERROR(Q12/$D12,"") -> 0.75 | R28: =IFERROR(R12/$D12,"") -> 0 | S28: =IFERROR(S12/$D12,"") -> 0 | T28: =IFERROR(T12/$D12,"") -> 0 | W28: =IFERROR(W12/$BD$7,"") -> 0.77857143
D29: Grade 2 | E29: Male | F29: =IFERROR(F13/$D13,"") -> 0.85714286 | G29: =IFERROR(G13/$D13,"") -> 0.14285714 | H29: =IFERROR(H13/$D13,"") -> 0 | I29: =IFERROR(I13/$D13,"") -> 0 | J29: =IFERROR(J13/$D13,"") -> 0 | L29: =IFERROR(L13/$D13,"") -> 0 | M29: =IFERROR(M13/$D13,"") -> 0.14285714 | N29: =IFERROR(N13/$D13,"") -> 0 | O29: =IFERROR(O13/$D13,"") -> 0.14285714 | P29: =IFERROR(P13/$D13,"") -> 0 | Q29: =IFERROR(Q13/$D13,"") -> 0 | R29: =IFERROR(R13/$D13,"") -> 0 | S29: =IFERROR(S13/$D13,"") -> 0 | ... V29: =IFERROR(V13/$D13,"") -> 0.85714286 | W29: =IFERROR(W13/$BD$8,"")
E30: Female | F30: =IFERROR(F14/$D14,"") -> 0.375 | G30: =IFERROR(G14/$D14,"") -> 0.625 | H30: =IFERROR(H14/$D14,"") -> 0 | I30: =IFERROR(I14/$D14,"") -> 0 | J30: =IFERROR(J14/$D14,"") -> 0 | L30: =IFERROR(L14/$D14,"") -> 0 | M30: =IFERROR(M14/$D14,"") -> 0.625 | N30: =IFERROR(N14/$D14,"") -> 0 | O30: =IFERROR(O14/$D14,"") -> 0.25 | P30: =IFERROR(P14/$D14,"") -> 0 | Q30: =IFERROR(Q14/$D14,"") -> 0 | R30: =IFERROR(R14/$D14,"") -> 0 | S30: =IFERROR(S14/$D14,"") -> 0 | ... V30: =IFERROR(V14/$D14,"") -> 0.75 | W30: =IFERROR(W14/$BD$8,"")
D31: Grade 3 | E31: Male | F31: =IFERROR(F15/$D15,"") -> 0 | G31: =IFERROR(G15/$D15,"") -> 0 | H31: =IFERROR(H15/$D15,"") -> 0.2 | I31: =IFERROR(I15/$D15,"") -> 0.2 | J31: =IFERROR(J15/$D15,"") -> 0.6 | L31: =IFERROR(L15/$D15,"") -> 1 | M31: =IFERROR(M15/$D15,"") -> 1 | N31: =IFERROR(N15/$D15,"") -> 1 | O31: =IFERROR(O15/$D15,"") -> 0.6 | P31: =IFERROR(P15/$D15,"") -> 0.7 | Q31: =IFERROR(Q15/$D15,"") -> 0.6 | R31: =IFERROR(R15/$D15,"") -> 0.4 | S31: =IFERROR(S15/$D15,"") -> 0.7 | T31: =IFERROR(T15/AL$13,"") | W31: =IFERROR(W15/$BD$9,"") -> 0.83
E32: Female | F32: =IFERROR(F16/$D16,"") -> 0 | G32: =IFERROR(G16/$D16,"") -> 0 | H32: =IFERROR(H16/$D16,"") -> 0.13333333 | I32: =IFERROR(I16/$D16,"") -> 0.2 | J32: =IFERROR(J16/$D16,"") -> 0.66666667 | L32: =IFERROR(L16/$D16,"") -> 0.86666667 | M32: =IFERROR(M16/$D16,"") -> 1 | N32: =IFERROR(N16/$D16,"") -> 0.86666667 | O32: =IFERROR(O16/$D16,"") -> 0.86666667 | P32: =IFERROR(P16/$D16,"") -> 0.86666667 | Q32: =IFERROR(Q16/$D16,"") -> 0.8 | R32: =IFERROR(R16/$D16,"") -> 0.33333333 | S32: =IFERROR(S16/$D16,"") -> 0.66666667 | T32: =IFERROR(T16/AL$13,"") | W32: =IFERROR(W16/$BD$9,"") -> 0.85666667
AH48: =IFERROR(#REF!/$H$14,"") | AI48: =IFERROR(#REF!/$H$14,"")
