Workbook

Sheet G1 RMA Scoresheet
T1: RMA2v2
A4: Assement Type | C4: BoSY
A5: Region | C5: Region VI | D5: GRADE 1 Rapid Mathematics Assessment (RMA) Scoresheets
A6: School ID: | C6: 117443 | D6: School Name: | F6: ROMANA ELEMENTARY SCHOOL | I6: LOI/MOI | K6: Hiligaynon | M6: Enrolment (Male) : | O6: 10 | P6: Number Assessed | R6: =COUNTA(C10:C108) -> 14
A7: Grade: | C7: Grade 1 | D7: Teacher : | F7: RAMONA B. PUNZALAN | I7: Section: | K7: 1 | M7: Enrolment (Female) : | O7: 4
A8: S/N | B8: LRN | C8: Name of Learner | D8: Sex | E8: Birthdate | F8: Date of Asessment | G8: Age | H8: Mother Tongue | I8: Task A: No. Identification & Discrimination (8) | J8: Task B: Fractions (2) | K8: Task C: Addition (8) | L8: Task D: Subtraction (6) | M8: Task E: Geometric Representation (4) | N8: Task F: Missing Shapes in Patterns (1) | O8: Task G: Time Measurement (3) | P8: Task H: Linear Measurement (3) | Q8: TOTAL SCORE (35) | R8: % of Correct Answer | S8: Levelling of Learners | T8: Remarks | Y8: Task A: No. Identification & Discrimination (8) | Z8: Task B: Fractions (2) | AA8: Task C: Addition (8) | AB8: Task D: Subtraction (6) | AC8: Task E: Geometric Representation (4) | AD8: Task F: Missing Shapes in Patterns (1) | AE8: Task G: Time Measurement (3) | AF8: Task H: Linear Measurement (3)
I9: 8 | J9: 2 | K9: 8 | L9: 6 | M9: 4 | N9: 1 | O9: 3 | P9: 3 | Q9: =SUM(I9:P9) -> 35 | Y9: =IF(I10/I$9>=75%,1,0) -> 1 | Z9: =IF(J10/J$9>=75%,1,0) -> 0 | AA9: =IF(K10/K$9>=75%,1,0) -> 1 | AB9: =IF(L10/L$9>=75%,1,0) -> 1 | AC9: =IF(M10/M$9>=75%,1,0) -> 1 | AD9: =IF(N10/N$9>=75%,1,0) -> 1 | AE9: =IF(O10/O$9>=75%,1,0) -> 0 | AF9: =IF(P10/P$9>=75%,1,0) -> 1
A10: 1 | B10: 117443240002 | C10: CARDINAL,CIAN, DEMIAR | D10: Male | E10: 43456 | F10: 45826 | G10: =IF(C10<>"",(F10-E10)/365,"") -> 6.4931507 | H10: Hiligaynon | I10: 6 | J10: 1 | K10: 8 | L10: 5 | M10: 3 | N10: 1 | O10: 1 | P10: 3 | Q10: =IF(C10<>"",SUM(I10:P10),"") -> 28 | R10: =IF(AND(Q10>0,C10<>""),Q10/Q$9,"") -> 0.8 | S10: =IF(R10<>"",IF($R10<25%,"Emerging (Not Proficient)",IF(AND($R10>=25%,$R10<50%),"Emerging (Low Proficient)",IF(AND($R10>=50%,$R10<75%),"Developing (Nearly Proficient)",IF(AND($R10>=75%,$R10<85%),"Transitioning (Proficient)","At Grade Level (Highly Proficient)")))),"") -> Transitioning (Proficient) | Y10: =IF(I11/I$9>=75%,1,0) -> 1 | Z10: =IF(J11/J$9>=75%,1,0) -> 0 | AA10: =IF(K11/K$9>=75%,1,0) -> 1 | AB10: =IF(L11/L$9>=75%,1,0) -> 1 | AC10: =IF(M11/M$9>=75%,1,0) -> 1 | AD10: =IF(N11/N$9>=75%,1,0) -> 1 | AE10: =IF(O11/O$9>=75%,1,0) -> 0 | AF10: =IF(P11/P$9>=75%,1,0) -> 1
A11: 2 | B11: 117443240003 | C11: CARDINAL,REY ROES, PANGANTIHON | D11: Male | E11: 43503 | F11: 45826 | G11: =IF(C11<>"",(F11-E11)/365,"") -> 6.3643836 | H11: Hiligaynon | I11: 8 | J11: 1 | K11: 8 | L11: 5 | M11: 3 | N11: 1 | O11: 2 | P11: 3 | Q11: =IF(C11<>"",SUM(I11:P11),"") -> 31 | R11: =IF(AND(Q11>0,C11<>""),Q11/Q$9,"") -> 0.88571429 | S11: =IF(R11<>"",IF($R11<25%,"Emerging (Not Proficient)",IF(AND($R11>=25%,$R11<50%),"Emerging (Low Proficient)",IF(AND($R11>=50%,$R11<75%),"Developing (Nearly Proficient)",IF(AND($R11>=75%,$R11<85%),"Transitioning (Proficient)","At Grade Level (Highly Proficient)")))),"") -> At Grade Level (Highly Proficient) | Y11: =IF(I12/I$9>=75%,1,0) -> 0 | Z11: =IF(J12/J$9>=75%,1,0) -> 0 | AA11: =IF(K12/K$9>=75%,1,0) -> 0 | AB11: =IF(L12/L$9>=75%,1,0) -> 0 | AC11: =IF(M12/M$9>=75%,1,0) -> 0 | AD11: =IF(N12/N$9>=75%,1,0) -> 0 | AE11: =IF(O12/O$9>=75%,1,0) -> 0 | AF11: =IF(P12/P$9>=75%,1,0) -> 0
A12: 3 | B12: 117443240005 | C12: FRANTE,ARK JAY, CABALLERO | D12: Male | E12: 43431 | F12: 45827 | G12: =IF(C12<>"",(F12-E12)/365,"") -> 6.5643836 | H12: Hiligaynon | I12: 0 | J12: 0 | K12: 0 | L12: 0 | M12: 1 | N12: 0 | O12: 1 | P12: 1 | Q12: =IF(C12<>"",SUM(I12:P12),"") -> 3 | R12: =IF(AND(Q12>0,C12<>""),Q12/Q$9,"") -> 0.085714286 | S12: =IF(R12<>"",IF($R12<25%,"Emerging (Not Proficient)",IF(AND($R12>=25%,$R12<50%),"Emerging (Low Proficient)",IF(AND($R12>=50%,$R12<75%),"Developing (Nearly Proficient)",IF(AND($R12>=75%,$R12<85%),"Transitioning (Proficient)","At Grade Level (Highly Proficient)")))),"") -> Emerging (Not Proficient) | Y12: =IF(I13/I$9>=75%,1,0) -> 0 | Z12: =IF(J13/J$9>=75%,1,0) -> 0 | AA12: =IF(K13/K$9>=75%,1,0) -> 0 | AB12: =IF(L13/L$9>=75%,1,0) -> 0 | AC12: =IF(M13/M$9>=75%,1,0) -> 0 | AD12: =IF(N13/N$9>=75%,1,0) -> 0 | AE12: =IF(O13/O$9>=75%,1,0) -> 0 | AF12: =IF(P13/P$9>=75%,1,0) -> 0
A13: 4 | B13: 117443240006 | C13: GANCIA,JELLO, GIER | D13: Male | E13: 43677 | F13: 45826 | G13: =IF(C13<>"",(F13-E13)/365,"") -> 5.8876712 | H13: Hiligaynon | Q13: =IF(C13<>"",SUM(I13:P13),"") -> 0 | R13: =IF(AND(Q13>0,C13<>""),Q13/Q$9,"") | S13: =IF(R13<>"",IF($R13<25%,"Emerging (Not Proficient)",IF(AND($R13>=25%,$R13<50%),"Emerging (Low Proficient)",IF(AND($R13>=50%,$R13<75%),"Developing (Nearly Proficient)",IF(AND($R13>=75%,$R13<85%),"Transitioning (Proficient)","At Grade Level (Highly Proficient)")))),"") | Y13: =IF(I14/I$9>=75%,1,0) -> 0 | Z13: =IF(J14/J$9>=75%,1,0) -> 0 | AA13: =IF(K14/K$9>=75%,1,0) -> 0 | AB13: =IF(L14/L$9>=75%,1,0) -> 0 | AC13: =IF(M14/M$9>=75%,1,0) -> 0 | AD13: =IF(N14/N$9>=75%,1,0) -> 0 | AE13: =IF(O14/O$9>=75%,1,0) -> 0 | AF13: =IF(P14/P$9>=75%,1,0) -> 0
A14: 5 | B14: 117443230006 | C14: GANCIA, RHAYCO, NARCISO | D14: Male | E14: 43294 | F14: 45826 | G14: =IF(C14<>"",(F14-E14)/365,"") -> 6.9369863 | H14: Hiligaynon | I14: 0 | J14: 0 | K14: 1 | L14: 0 | M14: 1 | N14: 0 | O14: 0 | P14: 0 | Q14: =IF(C14<>"",SUM(I14:P14),"") -> 2 | R14: =IF(AND(Q14>0,C14<>""),Q14/Q$9,"") -> 0.057142857 | S14: =IF(R14<>"",IF($R14<25%,"Emerging (Not Proficient)",IF(AND($R14>=25%,$R14<50%),"Emerging (Low Proficient)",IF(AND($R14>=50%,$R14<75%),"Developing (Nearly Proficient)",IF(AND($R14>=75%,$R14<85%),"Transitioning (Proficient)","At Grade Level (Highly Proficient)")))),"") -> Emerging (Not Proficient) | Y14: =IF(I15/I$9>=75%,1,0) -> 0 | Z14: =IF(J15/J$9>=75%,1,0) -> 0 | AA14: =IF(K15/K$9>=75%,1,0) -> 0 | AB14: =IF(L15/L$9>=75%,1,0) -> 0 | AC14: =IF(M15/M$9>=75%,1,0) -> 0 | AD14: =IF(N15/N$9>=75%,1,0) -> 0 | AE14: =IF(O15/O$9>=75%,1,0) -> 0 | AF14: =IF(P15/P$9>=75%,1,0) -> 0
A15: 6 | B15: 117443240004 | C15: GARDOSE,KIETH DION, CADUCOY | D15: Male | E15: 43522 | F15: 45827 | G15: =IF(C15<>"",(F15-E15)/365,"") -> 6.3150685 | H15: Hiligaynon | I15: 0 | J15: 0 | K15: 2 | L15: 1 | M15: 1 | N15: 0 | O15: 0 | P15: 0 | Q15: =IF(C15<>"",SUM(I15:P15),"") -> 4 | R15: =IF(AND(Q15>0,C15<>""),Q15/Q$9,"") -> 0.11428571 | S15: =IF(R15<>"",IF($R15<25%,"Emerging (Not Proficient)",IF(AND($R15>=25%,$R15<50%),"Emerging (Low Proficient)",IF(AND($R15>=50%,$R15<75%),"Developing (Nearly Proficient)",IF(AND($R15>=75%,$R15<85%),"Transitioning (Proficient)","At Grade Level (Highly Proficient)")))),"") -> Emerging (Not Proficient) | Y15: =IF(I16/I$9>=75%,1,0) -> 1 | Z15: =IF(J16/J$9>=75%,1,0) -> 0 | AA15: =IF(K16/K$9>=75%,1,0) -> 1 | AB15: =IF(L16/L$9>=75%,1,0) -> 0 | AC15: =IF(M16/M$9>=75%,1,0) -> 0 | AD15: =IF(N16/N$9>=75%,1,0) -> 0 | AE15: =IF(O16/O$9>=75%,1,0) -> 0 | AF15: =IF(P16/P$9>=75%,1,0) -> 0
A16: 7 | B16: 117443240007 | C16: GILUA,ARON JAMES, SUNDAYON | D16: Male | E16: 43428 | F16: 45827 | G16: =IF(C16<>"",(F16-E16)/365,"") -> 6.5726027 | H16: Hiligaynon | I16: 6 | J16: 0 | K16: 6 | L16: 0 | M16: 1 | N16: 0 | O16: 1 | P16: 1 | Q16: =IF(C16<>"",SUM(I16:P16),"") -> 15 | R16: =IF(AND(Q16>0,C16<>""),Q16/Q$9,"") -> 0.42857143 | S16: =IF(R16<>"",IF($R16<25%,"Emerging (Not Proficient)",IF(AND($R16>=25%,$R16<50%),"Emerging (Low Proficient)",IF(AND($R16>=50%,$R16<75%),"Developing (Nearly Proficient)",IF(AND($R16>=75%,$R16<85%),"Transitioning (Proficient)","At Grade Level (Highly Proficient)")))),"") -> Emerging (Low Proficient) | Y16: =IF(I17/I$9>=75%,1,0) -> 1 | Z16: =IF(J17/J$9>=75%,1,0) -> 0 | AA16: =IF(K17/K$9>=75%,1,0) -> 1 | AB16: =IF(L17/L$9>=75%,1,0) -> 0 | AC16: =IF(M17/M$9>=75%,1,0) -> 1 | AD16: =IF(N17/N$9>=75%,1,0) -> 1 | AE16: =IF(O17/O$9>=75%,1,0) -> 0 | AF16: =IF(P17/P$9>=75%,1,0) -> 0
A17: 8 | B17: 117443240008 | C17: LABANZA,DAVID RHON, PALACIO | D17: Male | E17: 43440 | F17: 45827 | G17: =IF(C17<>"",(F17-E17)/365,"") -> 6.539726 | H17: Hiligaynon | I17: 6 | J17: 0 | K17: 6 | L17: 2 | M17: 3 | N17: 1 | O17: 1 | P17: 2 | Q17: =IF(C17<>"",SUM(I17:P17),"") -> 21 | R17: =IF(AND(Q17>0,C17<>""),Q17/Q$9,"") -> 0.6 | S17: =IF(R17<>"",IF($R17<25%,"Emerging (Not Proficient)",IF(AND($R17>=25%,$R17<50%),"Emerging (Low Proficient)",IF(AND($R17>=50%,$R17<75%),"Developing (Nearly Proficient)",IF(AND($R17>=75%,$R17<85%),"Transitioning (Proficient)","At Grade Level (Highly Proficient)")))),"") -> Developing (Nearly Proficient) | Y17: =IF(I18/I$9>=75%,1,0) -> 0 | Z17: =IF(J18/J$9>=75%,1,0) -> 0 | AA17: =IF(K18/K$9>=75%,1,0) -> 0 | AB17: =IF(L18/L$9>=75%,1,0) -> 0 | AC17: =IF(M18/M$9>=75%,1,0) -> 0 | AD17: =IF(N18/N$9>=75%,1,0) -> 0 | AE17: =IF(O18/O$9>=75%,1,0) -> 0 | AF17: =IF(P18/P$9>=75%,1,0) -> 0
A18: 9 | B18: 117443240009 | C18: LABANZA,JAY-K, NOBLE | D18: Male | E18: 43723 | F18: 45827 | G18: =IF(C18<>"",(F18-E18)/365,"") -> 5.7643836 | H18: Hiligaynon | I18: 0 | J18: 0 | K18: 0 | L18: 1 | M18: 0 | N18: 0 | O18: 0 | P18: 0 | Q18: =IF(C18<>"",SUM(I18:P18),"") -> 1 | R18: =IF(AND(Q18>0,C18<>""),Q18/Q$9,"") -> 0.028571429 | S18: =IF(R18<>"",IF($R18<25%,"Emerging (Not Proficient)",IF(AND($R18>=25%,$R18<50%),"Emerging (Low Proficient)",IF(AND($R18>=50%,$R18<75%),"Developing (Nearly Proficient)",IF(AND($R18>=75%,$R18<85%),"Transitioning (Proficient)","At Grade Level (Highly Proficient)")))),"") -> Emerging (Not Proficient) | Y18: =IF(I19/I$9>=75%,1,0) -> 0 | Z18: =IF(J19/J$9>=75%,1,0) -> 0 | AA18: =IF(K19/K$9>=75%,1,0) -> 0 | AB18: =IF(L19/L$9>=75%,1,0) -> 0 | AC18: =IF(M19/M$9>=75%,1,0) -> 0 | AD18: =IF(N19/N$9>=75%,1,0) -> 0 | AE18: =IF(O19/O$9>=75%,1,0) -> 0 | AF18: =IF(P19/P$9>=75%,1,0) -> 0
A19: 10 | B19: 117443240010 | C19: LANGYON,JOHN KENNETH, ESTOCADA | D19: Male | E19: 43640 | F19: 45826 | G19: =IF(C19<>"",(F19-E19)/365,"") -> 5.9890411 | H19: Hiligaynon | I19: 0 | J19: 0 | K19: 0 | L19: 0 | M19: 0 | N19: 0 | O19: 0 | P19: 0 | Q19: =IF(C19<>"",SUM(I19:P19),"") -> 0 | R19: =IF(AND(Q19>0,C19<>""),Q19/Q$9,"") | S19: =IF(R19<>"",IF($R19<25%,"Emerging (Not Proficient)",IF(AND($R19>=25%,$R19<50%),"Emerging (Low Proficient)",IF(AND($R19>=50%,$R19<75%),"Developing (Nearly Proficient)",IF(AND($R19>=75%,$R19<85%),"Transitioning (Proficient)","At Grade Level (Highly Proficient)")))),"") | Y19: =IF(I20/I$9>=75%,1,0) -> 1 | Z19: =IF(J20/J$9>=75%,1,0) -> 1 | AA19: =IF(K20/K$9>=75%,1,0) -> 1 | AB19: =IF(L20/L$9>=75%,1,0) -> 0 | AC19: =IF(M20/M$9>=75%,1,0) -> 0 | AD19: =IF(N20/N$9>=75%,1,0) -> 0 | AE19: =IF(O20/O$9>=75%,1,0) -> 0 | AF19: =IF(P20/P$9>=75%,1,0) -> 0
A20: 11 | B20: 117443240012 | C20: ESLANA,SHANEL, JACOMILLA | D20: Female | E20: 43664 | F20: 45826 | G20: =IF(C20<>"",(F20-#REF!)/365,"") -> #REF! | H20: Hiligaynon | I20: 8 | J20: 2 | K20: 8 | L20: 4 | M20: 2 | N20: 0 | O20: 1 | P20: 2 | Q20: =IF(C20<>"",SUM(I20:P20),"") -> 27 | R20: =IF(AND(Q20>0,C20<>""),Q20/Q$9,"") -> 0.77142857 | S20: =IF(R20<>"",IF($R20<25%,"Emerging (Not Proficient)",IF(AND($R20>=25%,$R20<50%),"Emerging (Low Proficient)",IF(AND($R20>=50%,$R20<75%),"Developing (Nearly Proficient)",IF(AND($R20>=75%,$R20<85%),"Transitioning (Proficient)","At Grade Level (Highly Proficient)")))),"") -> Transitioning (Proficient) | Y20: =IF(I21/I$9>=75%,1,0) -> 1 | Z20: =IF(J21/J$9>=75%,1,0) -> 0 | AA20: =IF(K21/K$9>=75%,1,0) -> 1 | AB20: =IF(L21/L$9>=75%,1,0) -> 1 | AC20: =IF(M21/M$9>=75%,1,0) -> 1 | AD20: =IF(N21/N$9>=75%,1,0) -> 1 | AE20: =IF(O21/O$9>=75%,1,0) -> 0 | AF20: =IF(P21/P$9>=75%,1,0) -> 0
A21: 12 | B21: 117443240013 | C21: JUMBAS,JHANEZZA KAYE, ARCENAL | D21: Female | E21: 43698 | F21: 45826 | G21: =IF(C21<>"",(F21-E20)/365,"") -> 5.9232877 | H21: Hiligaynon | I21: 8 | J21: 1 | K21: 8 | L21: 5 | M21: 4 | N21: 1 | O21: 1 | P21: 1 | Q21: =IF(C21<>"",SUM(I21:P21),"") -> 29 | R21: =IF(AND(Q21>0,C21<>""),Q21/Q$9,"") -> 0.82857143 | S21: =IF(R21<>"",IF($R21<25%,"Emerging (Not Proficient)",IF(AND($R21>=25%,$R21<50%),"Emerging (Low Proficient)",IF(AND($R21>=50%,$R21<75%),"Developing (Nearly Proficient)",IF(AND($R21>=75%,$R21<85%),"Transitioning (Proficient)","At Grade Level (Highly Proficient)")))),"") -> Transitioning (Proficient) | Y21: =IF(I22/I$9>=75%,1,0) -> 1 | Z21: =IF(J22/J$9>=75%,1,0) -> 0 | AA21: =IF(K22/K$9>=75%,1,0) -> 1 | AB21: =IF(L22/L$9>=75%,1,0) -> 1 | AC21: =IF(M22/M$9>=75%,1,0) -> 1 | AD21: =IF(N22/N$9>=75%,1,0) -> 1 | AE21: =IF(O22/O$9>=75%,1,0) -> 0 | AF21: =IF(P22/P$9>=75%,1,0) -> 0
A22: 13 | B22: 117443240014 | C22: LLAGOSO,PAULA JADE, RICABO | D22: Female | E22: 43475 | F22: 45826 | G22: =IF(C22<>"",(F22-E22)/365,"") -> 6.4410959 | H22: Hiligaynon | I22: 6 | J22: 1 | K22: 7 | L22: 5 | M22: 4 | N22: 1 | O22: 1 | P22: 1 | Q22: =IF(C22<>"",SUM(I22:P22),"") -> 26 | R22: =IF(AND(Q22>0,C22<>""),Q22/Q$9,"") -> 0.74285714 | S22: =IF(R22<>"",IF($R22<25%,"Emerging (Not Proficient)",IF(AND($R22>=25%,$R22<50%),"Emerging (Low Proficient)",IF(AND($R22>=50%,$R22<75%),"Developing (Nearly Proficient)",IF(AND($R22>=75%,$R22<85%),"Transitioning (Proficient)","At Grade Level (Highly Proficient)")))),"") -> Developing (Nearly Proficient) | Y22: =IF(I23/I$9>=75%,1,0) -> 1 | Z22: =IF(J23/J$9>=75%,1,0) -> 1 | AA22: =IF(K23/K$9>=75%,1,0) -> 1 | AB22: =IF(L23/L$9>=75%,1,0) -> 1 | AC22: =IF(M23/M$9>=75%,1,0) -> 1 | AD22: =IF(N23/N$9>=75%,1,0) -> 1 | AE22: =IF(O23/O$9>=75%,1,0) -> 0 | AF22: =IF(P23/P$9>=75%,1,0) -> 0
A23: 14 | B23: 117441240034 | C23: MESIAS, SAVINNAH DOMINIQUE, GARDOSE | D23: Female | F23: 45827 | G23: =IF(C23<>"",(F23-E23)/365,"") -> 125.55342 | H23: Hiligaynon | I23: 6 | J23: 2 | K23: 8 | L23: 5 | M23: 3 | N23: 1 | O23: 1 | P23: 2 | Q23: =IF(C23<>"",SUM(I23:P23),"") -> 28 | R23: =IF(AND(Q23>0,C23<>""),Q23/Q$9,"") -> 0.8 | S23: =IF(R23<>"",IF($R23<25%,"Emerging (Not Proficient)",IF(AND($R23>=25%,$R23<50%),"Emerging (Low Proficient)",IF(AND($R23>=50%,$R23<75%),"Developing (Nearly Proficient)",IF(AND($R23>=75%,$R23<85%),"Transitioning (Proficient)","At Grade Level (Highly Proficient)")))),"") -> Transitioning (Proficient) | Y23: =IF(I24/I$9>=75%,1,0) -> 0 | Z23: =IF(J24/J$9>=75%,1,0) -> 0 | AA23: =IF(K24/K$9>=75%,1,0) -> 0 | AB23: =IF(L24/L$9>=75%,1,0) -> 0 | AC23: =IF(M24/M$9>=75%,1,0) -> 0 | AD23: =IF(N24/N$9>=75%,1,0) -> 0 | AE23: =IF(O24/O$9>=75%,1,0) -> 0 | AF23: =IF(P24/P$9>=75%,1,0) -> 0
A24: 15 | G24: =IF(C24<>"",(F24-E24)/365,"") | Q24: =IF(C24<>"",SUM(I24:P24),"") | R24: =IF(AND(Q24>0,C24<>""),Q24/Q$9,"") | S24: =IF(R24<>"",IF($R24<25%,"Emerging (Not Proficient)",IF(AND($R24>=25%,$R24<50%),"Emerging (Low Proficient)",IF(AND($R24>=50%,$R24<75%),"Developing (Nearly Proficient)",IF(AND($R24>=75%,$R24<85%),"Transitioning (Proficient)","At Grade Level (Highly Proficient)")))),"") | Y24: =IF(I25/I$9>=75%,1,0) -> 0 | Z24: =IF(J25/J$9>=75%,1,0) -> 0 | AA24: =IF(K25/K$9>=75%,1,0) -> 0 | AB24: =IF(L25/L$9>=75%,1,0) -> 0 | AC24: =IF(M25/M$9>=75%,1,0) -> 0 | AD24: =IF(N25/N$9>=75%,1,0) -> 0 | AE24: =IF(O25/O$9>=75%,1,0) -> 0 | AF24: =IF(P25/P$9>=75%,1,0) -> 0
A25: 16 | G25: =IF(C25<>"",(F25-E25)/365,"") | Q25: =IF(C25<>"",SUM(I25:P25),"") | R25: =IF(AND(Q25>0,C25<>""),Q25/Q$9,"") | S25: =IF(R25<>"",IF($R25<25%,"Emerging (Not Proficient)",IF(AND($R25>=25%,$R25<50%),"Emerging (Low Proficient)",IF(AND($R25>=50%,$R25<75%),"Developing (Nearly Proficient)",IF(AND($R25>=75%,$R25<85%),"Transitioning (Proficient)","At Grade Level (Highly Proficient)")))),"") | Y25: =IF(I26/I$9>=75%,1,0) -> 0 | Z25: =IF(J26/J$9>=75%,1,0) -> 0 | AA25: =IF(K26/K$9>=75%,1,0) -> 0 | AB25: =IF(L26/L$9>=75%,1,0) -> 0 | AC25: =IF(M26/M$9>=75%,1,0) -> 0 | AD25: =IF(N26/N$9>=75%,1,0) -> 0 | AE25: =IF(O26/O$9>=75%,1,0) -> 0 | AF25: =IF(P26/P$9>=75%,1,0) -> 0
A26: 17 | G26: =IF(C26<>"",(F26-E26)/365,"") | Q26: =IF(C26<>"",SUM(I26:P26),"") | R26: =IF(AND(Q26>0,C26<>""),Q26/Q$9,"") | S26: =IF(R26<>"",IF($R26<25%,"Emerging (Not Proficient)",IF(AND($R26>=25%,$R26<50%),"Emerging (Low Proficient)",IF(AND($R26>=50%,$R26<75%),"Developing (Nearly Proficient)",IF(AND($R26>=75%,$R26<85%),"Transitioning (Proficient)","At Grade Level (Highly Proficient)")))),"") | Y26: =IF(I27/I$9>=75%,1,0) -> 0 | Z26: =IF(J27/J$9>=75%,1,0) -> 0 | AA26: =IF(K27/K$9>=75%,1,0) -> 0 | AB26: =IF(L27/L$9>=75%,1,0) -> 0 | AC26: =IF(M27/M$9>=75%,1,0) -> 0 | AD26: =IF(N27/N$9>=75%,1,0) -> 0 | AE26: =IF(O27/O$9>=75%,1,0) -> 0 | AF26: =IF(P27/P$9>=75%,1,0) -> 0
A27: 18 | G27: =IF(C27<>"",(F27-E27)/365,"") | Q27: =IF(C27<>"",SUM(I27:P27),"") | R27: =IF(AND(Q27>0,C27<>""),Q27/Q$9,"") | S27: =IF(R27<>"",IF($R27<25%,"Emerging (Not Proficient)",IF(AND($R27>=25%,$R27<50%),"Emerging (Low Proficient)",IF(AND($R27>=50%,$R27<75%),"Developing (Nearly Proficient)",IF(AND($R27>=75%,$R27<85%),"Transitioning (Proficient)","At Grade Level (Highly Proficient)")))),"") | Y27: =IF(I28/I$9>=75%,1,0) -> 0 | Z27: =IF(J28/J$9>=75%,1,0) -> 0 | AA27: =IF(K28/K$9>=75%,1,0) -> 0 | AB27: =IF(L28/L$9>=75%,1,0) -> 0 | AC27: =IF(M28/M$9>=75%,1,0) -> 0 | AD27: =IF(N28/N$9>=75%,1,0) -> 0 | AE27: =IF(O28/O$9>=75%,1,0) -> 0 | AF27: =IF(P28/P$9>=75%,1,0) -> 0
A28: 19 | G28: =IF(C28<>"",(F28-E28)/365,"") | Q28: =IF(C28<>"",SUM(I28:P28),"") | R28: =IF(AND(Q28>0,C28<>""),Q28/Q$9,"") | S28: =IF(R28<>"",IF($R28<25%,"Emerging (Not Proficient)",IF(AND($R28>=25%,$R28<50%),"Emerging (Low Proficient)",IF(AND($R28>=50%,$R28<75%),"Developing (Nearly Proficient)",IF(AND($R28>=75%,$R28<85%),"Transitioning (Proficient)","At Grade Level (Highly Proficient)")))),"") | Y28: =IF(I29/I$9>=75%,1,0) -> 0 | Z28: =IF(J29/J$9>=75%,1,0) -> 0 | AA28: =IF(K29/K$9>=75%,1,0) -> 0 | AB28: =IF(L29/L$9>=75%,1,0) -> 0 | AC28: =IF(M29/M$9>=75%,1,0) -> 0 | AD28: =IF(N29/N$9>=75%,1,0) -> 0 | AE28: =IF(O29/O$9>=75%,1,0) -> 0 | AF28: =IF(P29/P$9>=75%,1,0) -> 0
A29: 20 | G29: =IF(C29<>"",(F29-E29)/365,"") | Q29: =IF(C29<>"",SUM(I29:P29),"") | R29: =IF(AND(Q29>0,C29<>""),Q29/Q$9,"") | S29: =IF(R29<>"",IF($R29<25%,"Emerging (Not Proficient)",IF(AND($R29>=25%,$R29<50%),"Emerging (Low Proficient)",IF(AND($R29>=50%,$R29<75%),"Developing (Nearly Proficient)",IF(AND($R29>=75%,$R29<85%),"Transitioning (Proficient)","At Grade Level (Highly Proficient)")))),"") | Y29: =IF(I30/I$9>=75%,1,0) -> 0 | Z29: =IF(J30/J$9>=75%,1,0) -> 0 | AA29: =IF(K30/K$9>=75%,1,0) -> 0 | AB29: =IF(L30/L$9>=75%,1,0) -> 0 | AC29: =IF(M30/M$9>=75%,1,0) -> 0 | AD29: =IF(N30/N$9>=75%,1,0) -> 0 | AE29: =IF(O30/O$9>=75%,1,0) -> 0 | AF29: =IF(P30/P$9>=75%,1,0) -> 0
A30: 21 | G30: =IF(C30<>"",(F30-E30)/365,"") | Q30: =IF(C30<>"",SUM(I30:P30),"") | R30: =IF(AND(Q30>0,C30<>""),Q30/Q$9,"") | S30: =IF(R30<>"",IF($R30<25%,"Emerging (Not Proficient)",IF(AND($R30>=25%,$R30<50%),"Emerging (Low Proficient)",IF(AND($R30>=50%,$R30<75%),"Developing (Nearly Proficient)",IF(AND($R30>=75%,$R30<85%),"Transitioning (Proficient)","At Grade Level (Highly Proficient)")))),"") | Y30: =IF(I31/I$9>=75%,1,0) -> 0 | Z30: =IF(J31/J$9>=75%,1,0) -> 0 | AA30: =IF(K31/K$9>=75%,1,0) -> 0 | AB30: =IF(L31/L$9>=75%,1,0) -> 0 | AC30: =IF(M31/M$9>=75%,1,0) -> 0 | AD30: =IF(N31/N$9>=75%,1,0) -> 0 | AE30: =IF(O31/O$9>=75%,1,0) -> 0 | AF30: =IF(P31/P$9>=75%,1,0) -> 0
A31: 22 | G31: =IF(C31<>"",(F31-E31)/365,"") | Q31: =IF(C31<>"",SUM(I31:P31),"") | R31: =IF(AND(Q31>0,C31<>""),Q31/Q$9,"") | S31: =IF(R31<>"",IF($R31<25%,"Emerging (Not Proficient)",IF(AND($R31>=25%,$R31<50%),"Emerging (Low Proficient)",IF(AND($R31>=50%,$R31<75%),"Developing (Nearly Proficient)",IF(AND($R31>=75%,$R31<85%),"Transitioning (Proficient)","At Grade Level (Highly Proficient)")))),"") | Y31: =IF(I32/I$9>=75%,1,0) -> 0 | Z31: =IF(J32/J$9>=75%,1,0) -> 0 | AA31: =IF(K32/K$9>=75%,1,0) -> 0 | AB31: =IF(L32/L$9>=75%,1,0) -> 0 | AC31: =IF(M32/M$9>=75%,1,0) -> 0 | AD31: =IF(N32/N$9>=75%,1,0) -> 0 | AE31: =IF(O32/O$9>=75%,1,0) -> 0 | AF31: =IF(P32/P$9>=75%,1,0) -> 0
A32: 23 | G32: =IF(C32<>"",(F32-E32)/365,"") | Q32: =IF(C32<>"",SUM(I32:P32),"") | R32: =IF(AND(Q32>0,C32<>""),Q32/Q$9,"") | S32: =IF(R32<>"",IF($R32<25%,"Emerging (Not Proficient)",IF(AND($R32>=25%,$R32<50%),"Emerging (Low Proficient)",IF(AND($R32>=50%,$R32<75%),"Developing (Nearly Proficient)",IF(AND($R32>=75%,$R32<85%),"Transitioning (Proficient)","At Grade Level (Highly Proficient)")))),"") | Y32: =IF(I33/I$9>=75%,1,0) -> 0 | Z32: =IF(J33/J$9>=75%,1,0) -> 0 | AA32: =IF(K33/K$9>=75%,1,0) -> 0 | AB32: =IF(L33/L$9>=75%,1,0) -> 0 | AC32: =IF(M33/M$9>=75%,1,0) -> 0 | AD32: =IF(N33/N$9>=75%,1,0) -> 0 | AE32: =IF(O33/O$9>=75%,1,0) -> 0 | AF32: =IF(P33/P$9>=75%,1,0) -> 0
A33: 24 | G33: =IF(C33<>"",(F33-E33)/365,"") | Q33: =IF(C33<>"",SUM(I33:P33),"") | R33: =IF(AND(Q33>0,C33<>""),Q33/Q$9,"") | S33: =IF(R33<>"",IF($R33<25%,"Emerging (Not Proficient)",IF(AND($R33>=25%,$R33<50%),"Emerging (Low Proficient)",IF(AND($R33>=50%,$R33<75%),"Developing (Nearly Proficient)",IF(AND($R33>=75%,$R33<85%),"Transitioning (Proficient)","At Grade Level (Highly Proficient)")))),"") | Y33: =IF(I34/I$9>=75%,1,0) -> 0 | Z33: =IF(J34/J$9>=75%,1,0) -> 0 | AA33: =IF(K34/K$9>=75%,1,0) -> 0 | AB33: =IF(L34/L$9>=75%,1,0) -> 0 | AC33: =IF(M34/M$9>=75%,1,0) -> 0 | AD33: =IF(N34/N$9>=75%,1,0) -> 0 | AE33: =IF(O34/O$9>=75%,1,0) -> 0 | AF33: =IF(P34/P$9>=75%,1,0) -> 0
A34: 25 | G34: =IF(C34<>"",(F34-E34)/365,"") | Q34: =IF(C34<>"",SUM(I34:P34),"") | R34: =IF(AND(Q34>0,C34<>""),Q34/Q$9,"") | S34: =IF(R34<>"",IF($R34<25%,"Emerging (Not Proficient)",IF(AND($R34>=25%,$R34<50%),"Emerging (Low Proficient)",IF(AND($R34>=50%,$R34<75%),"Developing (Nearly Proficient)",IF(AND($R34>=75%,$R34<85%),"Transitioning (Proficient)","At Grade Level (Highly Proficient)")))),"") | Y34: =IF(I35/I$9>=75%,1,0) -> 0 | Z34: =IF(J35/J$9>=75%,1,0) -> 0 | AA34: =IF(K35/K$9>=75%,1,0) -> 0 | AB34: =IF(L35/L$9>=75%,1,0) -> 0 | AC34: =IF(M35/M$9>=75%,1,0) -> 0 | AD34: =IF(N35/N$9>=75%,1,0) -> 0 | AE34: =IF(O35/O$9>=75%,1,0) -> 0 | AF34: =IF(P35/P$9>=75%,1,0) -> 0
A35: 26 | G35: =IF(C35<>"",(F35-E35)/365,"") | Q35: =IF(C35<>"",SUM(I35:P35),"") | R35: =IF(AND(Q35>0,C35<>""),Q35/Q$9,"") | S35: =IF(R35<>"",IF($R35<25%,"Emerging (Not Proficient)",IF(AND($R35>=25%,$R35<50%),"Emerging (Low Proficient)",IF(AND($R35>=50%,$R35<75%),"Developing (Nearly Proficient)",IF(AND($R35>=75%,$R35<85%),"Transitioning (Proficient)","At Grade Level (Highly Proficient)")))),"") | Y35: =IF(I36/I$9>=75%,1,0) -> 0 | Z35: =IF(J36/J$9>=75%,1,0) -> 0 | AA35: =IF(K36/K$9>=75%,1,0) -> 0 | AB35: =IF(L36/L$9>=75%,1,0) -> 0 | AC35: =IF(M36/M$9>=75%,1,0) -> 0 | AD35: =IF(N36/N$9>=75%,1,0) -> 0 | AE35: =IF(O36/O$9>=75%,1,0) -> 0 | AF35: =IF(P36/P$9>=75%,1,0) -> 0
... A68: 59 | G68: =IF(C68<>"",(F68-E68)/365,"") | Q68: =IF(C68<>"",SUM(I68:P68),"") | R68: =IF(AND(Q68>0,C68<>""),Q68/Q$9,"") | S68: =IF(R68<>"",IF($R68<25%,"Emerging (Not Proficient)",IF(AND($R68>=25%,$R68<50%),"Emerging (Low Proficient)",IF(AND($R68>=50%,$R68<75%),"Developing (Nearly Proficient)",IF(AND($R68>=75%,$R68<85%),"Transitioning (Proficient)","At Grade Level (Highly Proficient)")))),"") | Y68: =IF(I69/I$9>=75%,1,0) -> 0 | Z68: =IF(J69/J$9>=75%,1,0) -> 0 | AA68: =IF(K69/K$9>=75%,1,0) -> 0 | AB68: =IF(L69/L$9>=75%,1,0) -> 0 | AC68: =IF(M69/M$9>=75%,1,0) -> 0 | AD68: =IF(N69/N$9>=75%,1,0) -> 0 | AE68: =IF(O69/O$9>=75%,1,0) -> 0 | AF68: =IF(P69/P$9>=75%,1,0) -> 0
A69: =A68+1 -> 60 | G69: =IF(C69<>"",(F69-E69)/365,"") | Q69: =IF(C69<>"",SUM(I69:P69),"") | R69: =IF(AND(Q69>0,C69<>""),Q69/Q$9,"") | S69: =IF(R69<>"",IF($R69<25%,"Emerging (Not Proficient)",IF(AND($R69>=25%,$R69<50%),"Emerging (Low Proficient)",IF(AND($R69>=50%,$R69<75%),"Developing (Nearly Proficient)",IF(AND($R69>=75%,$R69<85%),"Transitioning (Proficient)","At Grade Level (Highly Proficient)")))),"") | Y69: =IF(I70/I$9>=75%,1,0) -> 0 | Z69: =IF(J70/J$9>=75%,1,0) -> 0 | AA69: =IF(K70/K$9>=75%,1,0) -> 0 | AB69: =IF(L70/L$9>=75%,1,0) -> 0 | AC69: =IF(M70/M$9>=75%,1,0) -> 0 | AD69: =IF(N70/N$9>=75%,1,0) -> 0 | AE69: =IF(O70/O$9>=75%,1,0) -> 0 | AF69: =IF(P70/P$9>=75%,1,0) -> 0
A70: =A69+1 -> 61 | G70: =IF(C70<>"",(F70-E70)/365,"") | Q70: =IF(C70<>"",SUM(I70:P70),"") | R70: =IF(AND(Q70>0,C70<>""),Q70/Q$9,"") | S70: =IF(R70<>"",IF($R70<25%,"Emerging (Not Proficient)",IF(AND($R70>=25%,$R70<50%),"Emerging (Low Proficient)",IF(AND($R70>=50%,$R70<75%),"Developing (Nearly Proficient)",IF(AND($R70>=75%,$R70<85%),"Transitioning (Proficient)","At Grade Level (Highly Proficient)")))),"") | Y70: =IF(I71/I$9>=75%,1,0) -> 0 | Z70: =IF(J71/J$9>=75%,1,0) -> 0 | AA70: =IF(K71/K$9>=75%,1,0) -> 0 | AB70: =IF(L71/L$9>=75%,1,0) -> 0 | AC70: =IF(M71/M$9>=75%,1,0) -> 0 | AD70: =IF(N71/N$9>=75%,1,0) -> 0 | AE70: =IF(O71/O$9>=75%,1,0) -> 0 | AF70: =IF(P71/P$9>=75%,1,0) -> 0
A71: =A70+1 -> 62 | G71: =IF(C71<>"",(F71-E71)/365,"") | Q71: =IF(C71<>"",SUM(I71:P71),"") | R71: =IF(AND(Q71>0,C71<>""),Q71/Q$9,"") | S71: =IF(R71<>"",IF($R71<25%,"Emerging (Not Proficient)",IF(AND($R71>=25%,$R71<50%),"Emerging (Low Proficient)",IF(AND($R71>=50%,$R71<75%),"Developing (Nearly Proficient)",IF(AND($R71>=75%,$R71<85%),"Transitioning (Proficient)","At Grade Level (Highly Proficient)")))),"") | Y71: =IF(I72/I$9>=75%,1,0) -> 0 | Z71: =IF(J72/J$9>=75%,1,0) -> 0 | AA71: =IF(K72/K$9>=75%,1,0) -> 0 | AB71: =IF(L72/L$9>=75%,1,0) -> 0 | AC71: =IF(M72/M$9>=75%,1,0) -> 0 | AD71: =IF(N72/N$9>=75%,1,0) -> 0 | AE71: =IF(O72/O$9>=75%,1,0) -> 0 | AF71: =IF(P72/P$9>=75%,1,0) -> 0
A72: =A71+1 -> 63 | G72: =IF(C72<>"",(F72-E72)/365,"") | Q72: =IF(C72<>"",SUM(I72:P72),"") | R72: =IF(AND(Q72>0,C72<>""),Q72/Q$9,"") | S72: =IF(R72<>"",IF($R72<25%,"Emerging (Not Proficient)",IF(AND($R72>=25%,$R72<50%),"Emerging (Low Proficient)",IF(AND($R72>=50%,$R72<75%),"Developing (Nearly Proficient)",IF(AND($R72>=75%,$R72<85%),"Transitioning (Proficient)","At Grade Level (Highly Proficient)")))),"") | Y72: =IF(I73/I$9>=75%,1,0) -> 0 | Z72: =IF(J73/J$9>=75%,1,0) -> 0 | AA72: =IF(K73/K$9>=75%,1,0) -> 0 | AB72: =IF(L73/L$9>=75%,1,0) -> 0 | AC72: =IF(M73/M$9>=75%,1,0) -> 0 | AD72: =IF(N73/N$9>=75%,1,0) -> 0 | AE72: =IF(O73/O$9>=75%,1,0) -> 0 | AF72: =IF(P73/P$9>=75%,1,0) -> 0
A73: =A72+1 -> 64 | G73: =IF(C73<>"",(F73-E73)/365,"") | Q73: =IF(C73<>"",SUM(I73:P73),"") | R73: =IF(AND(Q73>0,C73<>""),Q73/Q$9,"") | S73: =IF(R73<>"",IF($R73<25%,"Emerging (Not Proficient)",IF(AND($R73>=25%,$R73<50%),"Emerging (Low Proficient)",IF(AND($R73>=50%,$R73<75%),"Developing (Nearly Proficient)",IF(AND($R73>=75%,$R73<85%),"Transitioning (Proficient)","At Grade Level (Highly Proficient)")))),"") | Y73: =IF(I74/I$9>=75%,1,0) -> 0 | Z73: =IF(J74/J$9>=75%,1,0) -> 0 | AA73: =IF(K74/K$9>=75%,1,0) -> 0 | AB73: =IF(L74/L$9>=75%,1,0) -> 0 | AC73: =IF(M74/M$9>=75%,1,0) -> 0 | AD73: =IF(N74/N$9>=75%,1,0) -> 0 | AE73: =IF(O74/O$9>=75%,1,0) -> 0 | AF73: =IF(P74/P$9>=75%,1,0) -> 0
A74: =A73+1 -> 65 | G74: =IF(C74<>"",(F74-E74)/365,"") | Q74: =IF(C74<>"",SUM(I74:P74),"") | R74: =IF(AND(Q74>0,C74<>""),Q74/Q$9,"") | S74: =IF(R74<>"",IF($R74<25%,"Emerging (Not Proficient)",IF(AND($R74>=25%,$R74<50%),"Emerging (Low Proficient)",IF(AND($R74>=50%,$R74<75%),"Developing (Nearly Proficient)",IF(AND($R74>=75%,$R74<85%),"Transitioning (Proficient)","At Grade Level (Highly Proficient)")))),"") | Y74: =IF(I75/I$9>=75%,1,0) -> 0 | Z74: =IF(J75/J$9>=75%,1,0) -> 0 | AA74: =IF(K75/K$9>=75%,1,0) -> 0 | AB74: =IF(L75/L$9>=75%,1,0) -> 0 | AC74: =IF(M75/M$9>=75%,1,0) -> 0 | AD74: =IF(N75/N$9>=75%,1,0) -> 0 | AE74: =IF(O75/O$9>=75%,1,0) -> 0 | AF74: =IF(P75/P$9>=75%,1,0) -> 0
...

Sheet List
B1: Region | C1: Language
B2: NCR | C2: Agta | F2: Akeanon
B3: CAR | C3: Akeanon | F3: Bahasa Sug
B4: Region I | C4: Bahasa Sug | F4: Central Bikol
B5: Region II | C5: Bikol Libon | F5: Chavacano
B6: Region III | C6: Buhi-non | F6: Hiligaynon
B7: Region IV-A | C7: Caluyanen | F7: Ibanag
B8: Region IV-B | C8: Central Bikol | F8: Ilocano
B9: Region V | C9: Chavacano | F9: Ivatan
B10: Region VI | C10: Cuyonon | F10: Kapampangan
B11: Region VII | C11: English | F11: Kinaray-a
B12: Region VIII | C12: Hiligaynon | F12: Magindanawn
B13: Region IX | C13: Ibanag | F13: Meranaw
... B18: BARMM | C18: Ivatan | F18: Tagalog
C19: Kankanaey | F19: Waray
C20: Kapampangan | F20: Yakan
C21: Kinaray-a
C22: Magindanawn
C23: Meranaw
C24: Minasbate
C25: Miraya
C26: Northern Catanduanes
C27: Northern Sorsoganon
C28: Pangasinan
C29: Rinconada
C30: Sambal
C31: Sinama
C32: Sinugbuanong Binisaya
... C40: Other MT

Sheet Class Summary
A2: GRADE 1 Assessment Scoresheet (CLASS SUMMARY)
A5: SCHOOL ID : | B5: ='G1 RMA Scoresheet'!$C$6 -> 117443 | D5: Total Enrolment : | E5: =F14 -> 14 | F5: Total Assessed : | H5: =$E$14 -> 14
A6: SCHOOL NAME: | B6: ='G1 RMA Scoresheet'!$F$6 -> ROMANA ELEMENTARY SCHOOL | D6: LOI / MOI | E6: {='G1 RMA Scoresheet'!$K$6:$K$6} -> Hiligaynon
A8: Grade | D8: Language Matched ( LOI vs Learners) | E8: Number of Learners Assessed | F8: Total Enrolment | G8: Number of Learners Assessed | L8: Number of Learners with Correct Answer > 50% | W8: Overall Score
B9: Section | C9: Sex | G9: Emerging (Not Proficient) | H9: Emerging (Low Proficient) | I9: Developing (Nearly Proficient) | J9: Transitioning (Proficient) | K9: At Grade Level (Highly Proficient) | L9: Task A | M9: Task B | N9: Task C | O9: Task D | P9: Task E | Q9: Task F | R9: Task G | S9: Task H
L10: 8 | M10: 2 | N10: 8 | O10: ='G1 RMA Scoresheet'!L9 -> 6 | P10: 4 | Q10: 1 | R10: 3 | S10: ='G1 RMA Scoresheet'!P9 -> 3 | W10: =SUM(L10:S10) -> 35
A11: Grade 1 | B11: =IF('G1 RMA Scoresheet'!K7<>"",'G1 RMA Scoresheet'!K7,"") -> 1 | C11: Male | D11: =COUNTIFS('G1 RMA Scoresheet'!$D$10:$D$109,$C11,'G1 RMA Scoresheet'!$H$10:$H$109,$E$6) -> 10 | E11: =COUNTIF('G1 RMA Scoresheet'!$D$10:$D$109,"Male") -> 10 | F11: ='G1 RMA Scoresheet'!$O$6 -> 10 | G11: =COUNTIFS('G1 RMA Scoresheet'!$D$10:$D$109,"Male",'G1 RMA Scoresheet'!$S$10:$S$109,G$9) -> 4 | H11: =COUNTIFS('G1 RMA Scoresheet'!$D$10:$D$109,"Male",'G1 RMA Scoresheet'!$S$10:$S$109,H$9) -> 1 | I11: =COUNTIFS('G1 RMA Scoresheet'!$D$10:$D$109,"Male",'G1 RMA Scoresheet'!$S$10:$S$109,I$9) -> 1 | J11: =COUNTIFS('G1 RMA Scoresheet'!$D$10:$D$109,"Male",'G1 RMA Scoresheet'!$S$10:$S$109,J$9) -> 1 | K11: =COUNTIFS('G1 RMA Scoresheet'!$D$10:$D$109,"Male",'G1 RMA Scoresheet'!$S$10:$S$109,K$9) -> 1 | L11: =COUNTIFS('G1 RMA Scoresheet'!$D$10:$D$109,"Male",'G1 RMA Scoresheet'!Y$10:Y$109,1) -> 4 | M11: =COUNTIFS('G1 RMA Scoresheet'!$D$10:$D$109,"Male",'G1 RMA Scoresheet'!Z$10:Z$109,1) -> 1 | N11: =COUNTIFS('G1 RMA Scoresheet'!$D$10:$D$109,"Male",'G1 RMA Scoresheet'!AA$10:AA$109,1) -> 4 | O11: =COUNTIFS('G1 RMA Scoresheet'!$D$10:$D$109,"Male",'G1 RMA Scoresheet'!AB$10:AB$109,1) -> 1 | P11: =COUNTIFS('G1 RMA Scoresheet'!$D$10:$D$109,"Male",'G1 RMA Scoresheet'!AC$10:AC$109,1) -> 2 | Q11: =COUNTIFS('G1 RMA Scoresheet'!$D$10:$D$109,"Male",'G1 RMA Scoresheet'!AD$10:AD$109,1) -> 2 | R11: =COUNTIFS('G1 RMA Scoresheet'!$D$10:$D$109,"Male",'G1 RMA Scoresheet'!AE$10:AE$109,1) -> 0 | S11: =COUNTIFS('G1 RMA Scoresheet'!$D$10:$D$109,"Male",'G1 RMA Scoresheet'!AF$10:AF$109,1) -> 1 | W11: =IFERROR(AVERAGEIFS('G1 RMA Scoresheet'!Q$10:Q$109,'G1 RMA Scoresheet'!$D$10:$D$109,$C11),"") -> 10.5
A12: =A11 -> Grade 1 | B12: =B11 -> 1 | C12: Female | D12: =COUNTIFS('G1 RMA Scoresheet'!$D$10:$D$109,$C12,'G1 RMA Scoresheet'!$H$10:$H$109,$E$6) -> 4 | E12: =COUNTIF('G1 RMA Scoresheet'!$D$10:$D$109,"Female") -> 4 | F12: ='G1 RMA Scoresheet'!$O$7 -> 4 | G12: =COUNTIFS('G1 RMA Scoresheet'!$D$10:$D$109,"Female",'G1 RMA Scoresheet'!$S$10:$S$109,G$9) -> 0 | H12: =COUNTIFS('G1 RMA Scoresheet'!$D$10:$D$109,"Female",'G1 RMA Scoresheet'!$S$10:$S$109,H$9) -> 0 | I12: =COUNTIFS('G1 RMA Scoresheet'!$D$10:$D$109,"Female",'G1 RMA Scoresheet'!$S$10:$S$109,I$9) -> 1 | J12: =COUNTIFS('G1 RMA Scoresheet'!$D$10:$D$109,"Female",'G1 RMA Scoresheet'!$S$10:$S$109,J$9) -> 3 | K12: =COUNTIFS('G1 RMA Scoresheet'!$D$10:$D$109,"Female",'G1 RMA Scoresheet'!$S$10:$S$109,K$9) -> 0 | L12: =COUNTIFS('G1 RMA Scoresheet'!$D$10:$D$109,"Female",'G1 RMA Scoresheet'!Y$10:Y$109,1) -> 3 | M12: =COUNTIFS('G1 RMA Scoresheet'!$D$10:$D$109,"Female",'G1 RMA Scoresheet'!Z$10:Z$109,1) -> 1 | N12: =COUNTIFS('G1 RMA Scoresheet'!$D$10:$D$109,"Female",'G1 RMA Scoresheet'!AA$10:AA$109,1) -> 3 | O12: =COUNTIFS('G1 RMA Scoresheet'!$D$10:$D$109,"Female",'G1 RMA Scoresheet'!AB$10:AB$109,1) -> 3 | P12: =COUNTIFS('G1 RMA Scoresheet'!$D$10:$D$109,"Female",'G1 RMA Scoresheet'!AC$10:AC$109,1) -> 3 | Q12: =COUNTIFS('G1 RMA Scoresheet'!$D$10:$D$109,"Female",'G1 RMA Scoresheet'!AD$10:AD$109,1) -> 3 | R12: =COUNTIFS('G1 RMA Scoresheet'!$D$10:$D$109,"Female",'G1 RMA Scoresheet'!AE$10:AE$109,1) -> 0 | S12: =COUNTIFS('G1 RMA Scoresheet'!$D$10:$D$109,"Female",'G1 RMA Scoresheet'!AF$10:AF$109,1) -> 0 | W12: =IFERROR(AVERAGEIFS('G1 RMA Scoresheet'!Q$10:Q$109,'G1 RMA Scoresheet'!$D$10:$D$109,$C12),"") -> 27.5
A14: =A12 -> Grade 1 | B14: =B12 -> 1 | C14: Total | D14: =D11+D12 -> 14 | E14: =E11+E12 -> 14 | F14: =F11+F12 -> 14 | G14: =G11+G12 -> 4 | H14: =H11+H12 -> 1 | I14: =I11+I12 -> 2 | J14: =J11+J12 -> 4 | K14: =K11+K12 -> 1 | ... S14: =S11+S12 -> 1 | W14: =IFERROR(AVERAGE('G1 RMA Scoresheet'!Q$10:Q$109),"") -> 15.357143
A17: Dashboard | C17: Percent (%) of Learners at each proficiency level | L17: Percentage of Learners Who Passed 75% Per Task by Grade Level
A18: Sex | B18: Percent of Learners assessed | C18: Emerging (Not Proficient) | D18: Emerging (Low Proficient) | E18: Developing (Nearly Proficient) | F18: Transitioning (Proficient) | G18: At Grade Level (Highly Proficient) | K18: Sex | L18: Task A | M18: Task B | N18: Task C | O18: Task D | P18: Task E | Q18: Task F | R18: Task G | S18: Task H | W18: Overall Score
A19: Male | B19: =IFERROR(E11/$E$5,"") -> 0.71428571 | C19: =IFERROR(G11/$E$11,"") -> 0.4 | D19: =IFERROR(H11/$E$11,"") -> 0.1 | E19: =IFERROR(I11/$E$11,"") -> 0.1 | F19: =IFERROR(J11/$E$11,"") -> 0.1 | G19: =IFERROR(K11/$E$11,"") -> 0.1 | I19: =IFERROR(#REF!/$I$11,"") | K19: Male | L19: =IFERROR(L11/$E11,"") -> 0.4 | M19: =IFERROR(M11/$E11,"") -> 0.1 | N19: =IFERROR(N11/$E11,"") -> 0.4 | O19: =IFERROR(O11/$E11,"") -> 0.1 | P19: =IFERROR(P11/$E11,"") -> 0.2 | Q19: =IFERROR(Q11/$E11,"") -> 0.2 | R19: =IFERROR(R11/$E11,"") -> 0 | S19: =IFERROR(S11/$E11,"") -> 0.1 | W19: =IFERROR(W11/W$10,"") -> 0.3
A20: Female | B20: =IFERROR(E12/$E$5,"") -> 0.28571429 | C20: =IFERROR(G12/$E$12,"") -> 0 | D20: =IFERROR(H12/$E$12,"") -> 0 | E20: =IFERROR(I12/$E$12,"") -> 0.25 | F20: =IFERROR(J12/$E$12,"") -> 0.75 | G20: =IFERROR(K12/$E$12,"") -> 0 | K20: Female | L20: =IFERROR(L12/$E12,"") -> 0.75 | M20: =IFERROR(M12/$E12,"") -> 0.25 | N20: =IFERROR(N12/$E12,"") -> 0.75 | O20: =IFERROR(O12/$E12,"") -> 0.75 | P20: =IFERROR(P12/$E12,"") -> 0.75 | Q20: =IFERROR(Q12/$E12,"") -> 0.75 | R20: =IFERROR(R12/$E12,"") -> 0 | S20: =IFERROR(S12/$E12,"") -> 0 | W20: =IFERROR(W12/W$10,"") -> 0.78571429
A21: Total | B21: =IFERROR(B19+B20,"") -> 1 | C21: =IFERROR(G14/$E14,"") -> 0.28571429 | D21: =IFERROR(H14/$E14,"") -> 0.071428571 | E21: =IFERROR(I14/$E14,"") -> 0.14285714 | F21: =IFERROR(J14/$E14,"") -> 0.28571429 | G21: =IFERROR(K14/$E14,"") -> 0.071428571 | K21: Total | L21: =IFERROR(L14/$E14,"") -> 0.5 | M21: =IFERROR(M14/$E14,"") -> 0.14285714 | N21: =IFERROR(N14/$E14,"") -> 0.5 | O21: =IFERROR(O14/$E14,"") -> 0.28571429 | P21: =IFERROR(P14/$E14,"") -> 0.35714286 | Q21: =IFERROR(Q14/$E14,"") -> 0.35714286 | R21: =IFERROR(R14/$E14,"") -> 0 | S21: =IFERROR(S14/$E14,"") -> 0.071428571 | W21: =IFERROR(W14/W$10,"") -> 0.43877551
