Workbook

Sheet G2 RMA Scoresheet
T1: =W1 -> RMA2v2 | W1: RMA2v2
A4: Assessment Type | C4: BoSY
A5: Region | C5: Region VI | D5: GRADE 2 Rapid Mathematics Scoresheets
A6: School ID: | C6: 117443 | D6: School Name: | F6: Romana Elementary School | I6: LOI/MOI | K6: Hiligaynon | M6: Enrolment (Male): | O6: 7 | P6: Number Assessed | R6: =COUNTA(C10:C108) -> 15
A7: Grade: | C7: Grade 2 | D7: Teacher : | F7: Maricar F. Joaquin | I7: Section: | K7: 1 | M7: Enrolment (Female): | O7: 8
A8: S/N | B8: LRN | C8: Name of Learner | D8: Sex | E8: Birthdate | F8: Date of Asessment | G8: Age | H8: Mother Tongue | I8: Task A: Number Identification (3) | J8: Task B: Number Discrimination (1) | K8: Task C: Missing Numbers In Patterns (2) | L8: Task D: Missing Unit Fractions (1) | M8: Task E: Addition (4) | N8: Task F: Subtraction (3) | O8: Task G: Multiplication (3) | P8: Task H: Division (4) | Q8: Task I: Geometric Pattern (2) | R8: Task J: Geometric Visulization (1) | S8: Task K: Linear Measurement (1) | T8: TOTAL SCORE (25) | U8: % of Correct Answer | V8: Levelling of Learners | W8: Remarks | AB8: Task A: Number Identification (3) | AC8: Task B: Number Discrimination (1) | AD8: Task C: Missing Numbers In Patterns (2) | AE8: Task D: Missing Unit Fractions (1) | AF8: Task E: Addition (4) | AG8: Task F: Subtraction (3) | AH8: Task G: Multiplication (3) | AI8: Task H: Division (4) | AJ8: Task I: Geometric Pattern (2) | AK8: Task J: Geometric Visulization (1) | AL8: Task K: Linear Measurement (1)
I9: 3 | J9: 1 | K9: 2 | L9: 1 | M9: 4 | N9: 3 | O9: 3 | P9: 4 | Q9: 2 | R9: 1 | S9: 1 | T9: =SUM(I9:S9) -> 25
A10: 1 | C10: BARGASA, REY JOHN V. | D10: Male | E10: 43146 | F10: 45831 | G10: =IF(C10<>"",(F10-E10)/365,"") -> 7.3561644 | H10: Hiligaynon | I10: 0 | J10: 0 | K10: 0 | L10: 1 | M10: 1 | N10: 0 | O10: 0 | P10: 0 | Q10: 1 | R10: 0 | S10: 0 | T10: =IF(C10<>"",SUM(I10:S10),"") -> 3 | U10: =IF(AND(T10>0,C10<>""),T10/T$9,"") -> 0.12 | V10: =IF(U10<>"",IF($U10<25%,"Emerging (Not Proficient)", IF(AND($U10 >=25%, $U10 <50%), "Emerging (Low Proficient)", IF(AND($U10 >=50%, $U10 <75%),"Developing (Nearly Proficient)",IF(AND($U10 >=75%, $U10 <85%),"Transitioning (Proficient)","At Grade Level (Highly Proficient)")))),"") -> Emerging (Not Proficient) | AB10: =IF(I10/I$9>=75%,1,0) -> 0 | AC10: =IF(J10/J$9>=75%,1,0) -> 0 | AD10: =IF(K10/K$9>=75%,1,0) -> 0 | AE10: =IF(L10/L$9>=75%,1,0) -> 1 | AF10: =IF(M10/M$9>=75%,1,0) -> 0 | AG10: =IF(N10/N$9>=75%,1,0) -> 0 | AH10: =IF(O10/O$9>=75%,1,0) -> 0 | AI10: =IF(P10/P$9>=75%,1,0) -> 0 | ... AL10: =IF(S10/S$9>=75%,1,0) -> 0
A11: 2 | C11: BESANES, ZANDER G. | D11: Male | E11: 42759 | F11: 45828 | G11: =IF(C11<>"",(F11-E11)/365,"") -> 8.4082192 | H11: Hiligaynon | I11: 0 | J11: 0 | K11: 0 | L11: 0 | M11: 0 | N11: 0 | O11: 0 | P11: 0 | Q11: 0 | R11: 0 | S11: 1 | T11: =IF(C11<>"",SUM(I11:S11),"") -> 1 | U11: =IF(AND(T11>0,C11<>""),T11/T$9,"") -> 0.04 | V11: =IF(U11<>"",IF($U11<25%,"Emerging (Not Proficient)", IF(AND($U11 >=25%, $U11 <50%), "Emerging (Low Proficient)", IF(AND($U11 >=50%, $U11 <75%),"Developing (Nearly Proficient)",IF(AND($U11 >=75%, $U11 <85%),"Transitioning (Proficient)","At Grade Level (Highly Proficient)")))),"") -> Emerging (Not Proficient) | AB11: =IF(I11/I$9>=75%,1,0) -> 0 | AC11: =IF(J11/J$9>=75%,1,0) -> 0 | AD11: =IF(K11/K$9>=75%,1,0) -> 0 | AE11: =IF(L11/L$9>=75%,1,0) -> 0 | AF11: =IF(M11/M$9>=75%,1,0) -> 0 | AG11: =IF(N11/N$9>=75%,1,0) -> 0 | AH11: =IF(O11/O$9>=75%,1,0) -> 0 | AI11: =IF(P11/P$9>=75%,1,0) -> 0 | ... AL11: =IF(S11/S$9>=75%,1,0) -> 1
A12: 3 | C12: BERIZAL, KENT ANGELO C. | D12: Male | E12: 43310 | F12: 45828 | G12: =IF(C12<>"",(F12-E12)/365,"") -> 6.8986301 | H12: Hiligaynon | I12: 0 | J12: 0 | K12: 0 | L12: 0 | M12: 1 | N12: 1 | O12: 1 | P12: 0 | Q12: 0 | R12: 0 | S12: 1 | T12: =IF(C12<>"",SUM(I12:S12),"") -> 4 | U12: =IF(AND(T12>0,C12<>""),T12/T$9,"") -> 0.16 | V12: =IF(U12<>"",IF($U12<25%,"Emerging (Not Proficient)", IF(AND($U12 >=25%, $U12 <50%), "Emerging (Low Proficient)", IF(AND($U12 >=50%, $U12 <75%),"Developing (Nearly Proficient)",IF(AND($U12 >=75%, $U12 <85%),"Transitioning (Proficient)","At Grade Level (Highly Proficient)")))),"") -> Emerging (Not Proficient) | AB12: =IF(I12/I$9>=75%,1,0) -> 0 | AC12: =IF(J12/J$9>=75%,1,0) -> 0 | AD12: =IF(K12/K$9>=75%,1,0) -> 0 | AE12: =IF(L12/L$9>=75%,1,0) -> 0 | AF12: =IF(M12/M$9>=75%,1,0) -> 0 | AG12: =IF(N12/N$9>=75%,1,0) -> 0 | AH12: =IF(O12/O$9>=75%,1,0) -> 0 | AI12: =IF(P12/P$9>=75%,1,0) -> 0 | ... AL12: =IF(S12/S$9>=75%,1,0) -> 1
A13: 4 | C13: DARAS, REYNASH R. | D13: Male | E13: 43141 | F13: 45827 | G13: =IF(C13<>"",(F13-E13)/365,"") -> 7.3589041 | H13: Hiligaynon | I13: 1 | J13: 1 | K13: 1 | L13: 0 | M13: 2 | N13: 1 | O13: 2 | P13: 1 | Q13: 2 | R13: 0 | S13: 1 | T13: =IF(C13<>"",SUM(I13:S13),"") -> 12 | U13: =IF(AND(T13>0,C13<>""),T13/T$9,"") -> 0.48 | V13: =IF(U13<>"",IF($U13<25%,"Emerging (Not Proficient)", IF(AND($U13 >=25%, $U13 <50%), "Emerging (Low Proficient)", IF(AND($U13 >=50%, $U13 <75%),"Developing (Nearly Proficient)",IF(AND($U13 >=75%, $U13 <85%),"Transitioning (Proficient)","At Grade Level (Highly Proficient)")))),"") -> Emerging (Low Proficient) | AB13: =IF(I13/I$9>=75%,1,0) -> 0 | AC13: =IF(J13/J$9>=75%,1,0) -> 1 | AD13: =IF(K13/K$9>=75%,1,0) -> 0 | AE13: =IF(L13/L$9>=75%,1,0) -> 0 | AF13: =IF(M13/M$9>=75%,1,0) -> 0 | AG13: =IF(N13/N$9>=75%,1,0) -> 0 | AH13: =IF(O13/O$9>=75%,1,0) -> 0 | AI13: =IF(P13/P$9>=75%,1,0) -> 0 | ... AL13: =IF(S13/S$9>=75%,1,0) -> 1
A14: 5 | C14: ORTILANO, KLENT Y. | D14: Male | E14: 43385 | F14: 45828 | G14: =IF(C14<>"",(F14-E14)/365,"") -> 6.6931507 | H14: Hiligaynon | I14: 0 | J14: 0 | K14: 0 | L14: 0 | M14: 1 | N14: 0 | O14: 1 | P14: 1 | Q14: 2 | R14: 0 | S14: 1 | T14: =IF(C14<>"",SUM(I14:S14),"") -> 6 | U14: =IF(AND(T14>0,C14<>""),T14/T$9,"") -> 0.24 | V14: =IF(U14<>"",IF($U14<25%,"Emerging (Not Proficient)", IF(AND($U14 >=25%, $U14 <50%), "Emerging (Low Proficient)", IF(AND($U14 >=50%, $U14 <75%),"Developing (Nearly Proficient)",IF(AND($U14 >=75%, $U14 <85%),"Transitioning (Proficient)","At Grade Level (Highly Proficient)")))),"") -> Emerging (Not Proficient) | AB14: =IF(I14/I$9>=75%,1,0) -> 0 | AC14: =IF(J14/J$9>=75%,1,0) -> 0 | AD14: =IF(K14/K$9>=75%,1,0) -> 0 | AE14: =IF(L14/L$9>=75%,1,0) -> 0 | AF14: =IF(M14/M$9>=75%,1,0) -> 0 | AG14: =IF(N14/N$9>=75%,1,0) -> 0 | AH14: =IF(O14/O$9>=75%,1,0) -> 0 | AI14: =IF(P14/P$9>=75%,1,0) -> 0 | ... AL14: =IF(S14/S$9>=75%,1,0) -> 1
A15: 6 | C15: PATRICIO, SEAN E. | D15: Male | E15: 43310 | F15: 45828 | G15: =IF(C15<>"",(F15-E15)/365,"") -> 6.8986301 | H15: Hiligaynon | I15: 0 | J15: 0 | K15: 0 | L15: 0 | M15: 0 | N15: 0 | O15: 0 | P15: 0 | Q15: 0 | R15: 0 | S15: 1 | T15: =IF(C15<>"",SUM(I15:S15),"") -> 1 | U15: =IF(AND(T15>0,C15<>""),T15/T$9,"") -> 0.04 | V15: =IF(U15<>"",IF($U15<25%,"Emerging (Not Proficient)", IF(AND($U15 >=25%, $U15 <50%), "Emerging (Low Proficient)", IF(AND($U15 >=50%, $U15 <75%),"Developing (Nearly Proficient)",IF(AND($U15 >=75%, $U15 <85%),"Transitioning (Proficient)","At Grade Level (Highly Proficient)")))),"") -> Emerging (Not Proficient) | AB15: =IF(I15/I$9>=75%,1,0) -> 0 | AC15: =IF(J15/J$9>=75%,1,0) -> 0 | AD15: =IF(K15/K$9>=75%,1,0) -> 0 | AE15: =IF(L15/L$9>=75%,1,0) -> 0 | AF15: =IF(M15/M$9>=75%,1,0) -> 0 | AG15: =IF(N15/N$9>=75%,1,0) -> 0 | AH15: =IF(O15/O$9>=75%,1,0) -> 0 | AI15: =IF(P15/P$9>=75%,1,0) -> 0 | ... AL15: =IF(S15/S$9>=75%,1,0) -> 1
A16: 7 | C16: ZONITA, NELJOHN E. | D16: Male | E16: 43009 | F16: 45828 | G16: =IF(C16<>"",(F16-E16)/365,"") -> 7.7232877 | H16: Hiligaynon | I16: 0 | J16: 0 | K16: 0 | L16: 0 | M16: 0 | N16: 0 | O16: 0 | P16: 0 | Q16: 0 | R16: 0 | S16: 1 | T16: =IF(C16<>"",SUM(I16:S16),"") -> 1 | U16: =IF(AND(T16>0,C16<>""),T16/T$9,"") -> 0.04 | V16: =IF(U16<>"",IF($U16<25%,"Emerging (Not Proficient)", IF(AND($U16 >=25%, $U16 <50%), "Emerging (Low Proficient)", IF(AND($U16 >=50%, $U16 <75%),"Developing (Nearly Proficient)",IF(AND($U16 >=75%, $U16 <85%),"Transitioning (Proficient)","At Grade Level (Highly Proficient)")))),"") -> Emerging (Not Proficient) | AB16: =IF(I16/I$9>=75%,1,0) -> 0 | AC16: =IF(J16/J$9>=75%,1,0) -> 0 | AD16: =IF(K16/K$9>=75%,1,0) -> 0 | AE16: =IF(L16/L$9>=75%,1,0) -> 0 | AF16: =IF(M16/M$9>=75%,1,0) -> 0 | AG16: =IF(N16/N$9>=75%,1,0) -> 0 | AH16: =IF(O16/O$9>=75%,1,0) -> 0 | AI16: =IF(P16/P$9>=75%,1,0) -> 0 | ... AL16: =IF(S16/S$9>=75%,1,0) -> 1
A17: 8 | C17: ANTONIO, JELAISA JEAN P. | D17: Female | E17: 43285 | F17: 45828 | G17: =IF(C17<>"",(F17-E17)/365,"") -> 6.9671233 | H17: Hiligaynon | I17: 0 | J17: 0 | K17: 0 | L17: 0 | M17: 0 | N17: 0 | O17: 0 | P17: 0 | Q17: 0 | R17: 1 | S17: 0 | T17: =IF(C17<>"",SUM(I17:S17),"") -> 1 | U17: =IF(AND(T17>0,C17<>""),T17/T$9,"") -> 0.04 | V17: =IF(U17<>"",IF($U17<25%,"Emerging (Not Proficient)", IF(AND($U17 >=25%, $U17 <50%), "Emerging (Low Proficient)", IF(AND($U17 >=50%, $U17 <75%),"Developing (Nearly Proficient)",IF(AND($U17 >=75%, $U17 <85%),"Transitioning (Proficient)","At Grade Level (Highly Proficient)")))),"") -> Emerging (Not Proficient) | AB17: =IF(I17/I$9>=75%,1,0) -> 0 | AC17: =IF(J17/J$9>=75%,1,0) -> 0 | AD17: =IF(K17/K$9>=75%,1,0) -> 0 | AE17: =IF(L17/L$9>=75%,1,0) -> 0 | AF17: =IF(M17/M$9>=75%,1,0) -> 0 | AG17: =IF(N17/N$9>=75%,1,0) -> 0 | AH17: =IF(O17/O$9>=75%,1,0) -> 0 | AI17: =IF(P17/P$9>=75%,1,0) -> 0 | ... AL17: =IF(S17/S$9>=75%,1,0) -> 0
A18: 9 | C18: CUSTODIO, MARICAR C. | D18: Female | E18: 43239 | F18: 45828 | G18: =IF(C18<>"",(F18-E18)/365,"") -> 7.0931507 | H18: Hiligaynon | I18: 1 | J18: 0 | K18: 1 | L18: 0 | M18: 1 | N18: 0 | O18: 1 | P18: 0 | Q18: 2 | R18: 1 | S18: 1 | T18: =IF(C18<>"",SUM(I18:S18),"") -> 8 | U18: =IF(AND(T18>0,C18<>""),T18/T$9,"") -> 0.32 | V18: =IF(U18<>"",IF($U18<25%,"Emerging (Not Proficient)", IF(AND($U18 >=25%, $U18 <50%), "Emerging (Low Proficient)", IF(AND($U18 >=50%, $U18 <75%),"Developing (Nearly Proficient)",IF(AND($U18 >=75%, $U18 <85%),"Transitioning (Proficient)","At Grade Level (Highly Proficient)")))),"") -> Emerging (Low Proficient) | AB18: =IF(I18/I$9>=75%,1,0) -> 0 | AC18: =IF(J18/J$9>=75%,1,0) -> 0 | AD18: =IF(K18/K$9>=75%,1,0) -> 0 | AE18: =IF(L18/L$9>=75%,1,0) -> 0 | AF18: =IF(M18/M$9>=75%,1,0) -> 0 | AG18: =IF(N18/N$9>=75%,1,0) -> 0 | AH18: =IF(O18/O$9>=75%,1,0) -> 0 | AI18: =IF(P18/P$9>=75%,1,0) -> 0 | ... AL18: =IF(S18/S$9>=75%,1,0) -> 1
A19: 10 | C19: DUMAICOS, NOVELYN F. | D19: Female | E19: 43358 | F19: 45828 | G19: =IF(C19<>"",(F19-E19)/365,"") -> 6.7671233 | H19: Hiligaynon | I19: 0 | J19: 1 | K19: 1 | L19: 0 | M19: 1 | N19: 1 | O19: 0 | P19: 0 | Q19: 1 | R19: 1 | S19: 1 | T19: =IF(C19<>"",SUM(I19:S19),"") -> 7 | U19: =IF(AND(T19>0,C19<>""),T19/T$9,"") -> 0.28 | V19: =IF(U19<>"",IF($U19<25%,"Emerging (Not Proficient)", IF(AND($U19 >=25%, $U19 <50%), "Emerging (Low Proficient)", IF(AND($U19 >=50%, $U19 <75%),"Developing (Nearly Proficient)",IF(AND($U19 >=75%, $U19 <85%),"Transitioning (Proficient)","At Grade Level (Highly Proficient)")))),"") -> Emerging (Low Proficient) | AB19: =IF(I19/I$9>=75%,1,0) -> 0 | AC19: =IF(J19/J$9>=75%,1,0) -> 1 | AD19: =IF(K19/K$9>=75%,1,0) -> 0 | AE19: =IF(L19/L$9>=75%,1,0) -> 0 | AF19: =IF(M19/M$9>=75%,1,0) -> 0 | AG19: =IF(N19/N$9>=75%,1,0) -> 0 | AH19: =IF(O19/O$9>=75%,1,0) -> 0 | AI19: =IF(P19/P$9>=75%,1,0) -> 0 | ... AL19: =IF(S19/S$9>=75%,1,0) -> 1
A20: 11 | C20: DUMANIEL, SHANAYA A. | D20: Female | E20: 43390 | F20: 45828 | G20: =IF(C20<>"",(F20-E20)/365,"") -> 6.6794521 | H20: Hiligaynon | I20: 0 | J20: 1 | K20: 1 | L20: 1 | M20: 1 | N20: 0 | O20: 0 | P20: 0 | Q20: 2 | R20: 1 | S20: 1 | T20: =IF(C20<>"",SUM(I20:S20),"") -> 8 | U20: =IF(AND(T20>0,C20<>""),T20/T$9,"") -> 0.32 | V20: =IF(U20<>"",IF($U20<25%,"Emerging (Not Proficient)", IF(AND($U20 >=25%, $U20 <50%), "Emerging (Low Proficient)", IF(AND($U20 >=50%, $U20 <75%),"Developing (Nearly Proficient)",IF(AND($U20 >=75%, $U20 <85%),"Transitioning (Proficient)","At Grade Level (Highly Proficient)")))),"") -> Emerging (Low Proficient) | AB20: =IF(I20/I$9>=75%,1,0) -> 0 | AC20: =IF(J20/J$9>=75%,1,0) -> 1 | AD20: =IF(K20/K$9>=75%,1,0) -> 0 | AE20: =IF(L20/L$9>=75%,1,0) -> 1 | AF20: =IF(M20/M$9>=75%,1,0) -> 0 | AG20: =IF(N20/N$9>=75%,1,0) -> 0 | AH20: =IF(O20/O$9>=75%,1,0) -> 0 | AI20: =IF(P20/P$9>=75%,1,0) -> 0 | ... AL20: =IF(S20/S$9>=75%,1,0) -> 1
A21: 12 | C21: ESTOCADA, JULIANA Q. | D21: Female | E21: 43052 | F21: 45828 | G21: =IF(C21<>"",(F21-E21)/365,"") -> 7.6054795 | H21: Hiligaynon | I21: 0 | J21: 1 | K21: 0 | L21: 0 | M21: 1 | N21: 1 | O21: 0 | P21: 0 | Q21: 2 | R21: 0 | S21: 1 | T21: =IF(C21<>"",SUM(I21:S21),"") -> 6 | U21: =IF(AND(T21>0,C21<>""),T21/T$9,"") -> 0.24 | V21: =IF(U21<>"",IF($U21<25%,"Emerging (Not Proficient)", IF(AND($U21 >=25%, $U21 <50%), "Emerging (Low Proficient)", IF(AND($U21 >=50%, $U21 <75%),"Developing (Nearly Proficient)",IF(AND($U21 >=75%, $U21 <85%),"Transitioning (Proficient)","At Grade Level (Highly Proficient)")))),"") -> Emerging (Not Proficient) | AB21: =IF(I21/I$9>=75%,1,0) -> 0 | AC21: =IF(J21/J$9>=75%,1,0) -> 1 | AD21: =IF(K21/K$9>=75%,1,0) -> 0 | AE21: =IF(L21/L$9>=75%,1,0) -> 0 | AF21: =IF(M21/M$9>=75%,1,0) -> 0 | AG21: =IF(N21/N$9>=75%,1,0) -> 0 | AH21: =IF(O21/O$9>=75%,1,0) -> 0 | AI21: =IF(P21/P$9>=75%,1,0) -> 0 | ... AL21: =IF(S21/S$9>=75%,1,0) -> 1
... A24: 15 | C24: LABANZA, ALEJANDRINE AMIAH G. | D24: Female | E24: 43220 | F24: 45828 | G24: =IF(C24<>"",(F24-E24)/365,"") -> 7.1452055 | H24: Hiligaynon | I24: 0 | J24: 1 | K24: 0 | L24: 1 | M24: 1 | N24: 1 | O24: 1 | P24: 0 | Q24: 2 | R24: 0 | S24: 0 | T24: =IF(C24<>"",SUM(I24:S24),"") -> 7 | U24: =IF(AND(T24>0,C24<>""),T24/T$9,"") -> 0.28 | V24: =IF(U24<>"",IF($U24<25%,"Emerging (Not Proficient)", IF(AND($U24 >=25%, $U24 <50%), "Emerging (Low Proficient)", IF(AND($U24 >=50%, $U24 <75%),"Developing (Nearly Proficient)",IF(AND($U24 >=75%, $U24 <85%),"Transitioning (Proficient)","At Grade Level (Highly Proficient)")))),"") -> Emerging (Low Proficient) | AB24: =IF(I24/I$9>=75%,1,0) -> 0 | AC24: =IF(J24/J$9>=75%,1,0) -> 1 | AD24: =IF(K24/K$9>=75%,1,0) -> 0 | AE24: =IF(L24/L$9>=75%,1,0) -> 1 | AF24: =IF(M24/M$9>=75%,1,0) -> 0 | AG24: =IF(N24/N$9>=75%,1,0) -> 0 | AH24: =IF(O24/O$9>=75%,1,0) -> 0 | AI24: =IF(P24/P$9>=75%,1,0) -> 0 | ... AL24: =IF(S24/S$9>=75%,1,0) -> 0
A25: 16 | G25: =IF(C25<>"",(F25-E25)/365,"") | H25: Agta | T25: =IF(C25<>"",SUM(I25:S25),"") | U25: =IF(AND(T25>0,C25<>""),T25/T$9,"") | V25: =IF(U25<>"",IF($U25<25%,"Emerging (Not Proficient)", IF(AND($U25 >=25%, $U25 <50%), "Emerging (Low Proficient)", IF(AND($U25 >=50%, $U25 <75%),"Developing (Nearly Proficient)",IF(AND($U25 >=75%, $U25 <85%),"Transitioning (Proficient)","At Grade Level (Highly Proficient)")))),"") | AB25: =IF(I25/I$9>=75%,1,0) -> 0 | AC25: =IF(J25/J$9>=75%,1,0) -> 0 | AD25: =IF(K25/K$9>=75%,1,0) -> 0 | AE25: =IF(L25/L$9>=75%,1,0) -> 0 | AF25: =IF(M25/M$9>=75%,1,0) -> 0 | AG25: =IF(N25/N$9>=75%,1,0) -> 0 | AH25: =IF(O25/O$9>=75%,1,0) -> 0 | AI25: =IF(P25/P$9>=75%,1,0) -> 0 | ... AL25: =IF(S25/S$9>=75%,1,0) -> 0
A26: 17 | G26: =IF(C26<>"",(F26-E26)/365,"") | T26: =IF(C26<>"",SUM(I26:S26),"") | U26: =IF(AND(T26>0,C26<>""),T26/T$9,"") | V26: =IF(U26<>"",IF($U26<25%,"Emerging (Not Proficient)", IF(AND($U26 >=25%, $U26 <50%), "Emerging (Low Proficient)", IF(AND($U26 >=50%, $U26 <75%),"Developing (Nearly Proficient)",IF(AND($U26 >=75%, $U26 <85%),"Transitioning (Proficient)","At Grade Level (Highly Proficient)")))),"") | AB26: =IF(I26/I$9>=75%,1,0) -> 0 | AC26: =IF(J26/J$9>=75%,1,0) -> 0 | AD26: =IF(K26/K$9>=75%,1,0) -> 0 | AE26: =IF(L26/L$9>=75%,1,0) -> 0 | AF26: =IF(M26/M$9>=75%,1,0) -> 0 | AG26: =IF(N26/N$9>=75%,1,0) -> 0 | AH26: =IF(O26/O$9>=75%,1,0) -> 0 | AI26: =IF(P26/P$9>=75%,1,0) -> 0 | ... AL26: =IF(S26/S$9>=75%,1,0) -> 0
A27: 18 | G27: =IF(C27<>"",(F27-E27)/365,"") | T27: =IF(C27<>"",SUM(I27:S27),"") | U27: =IF(AND(T27>0,C27<>""),T27/T$9,"") | V27: =IF(U27<>"",IF($U27<25%,"Emerging (Not Proficient)", IF(AND($U27 >=25%, $U27 <50%), "Emerging (Low Proficient)", IF(AND($U27 >=50%, $U27 <75%),"Developing (Nearly Proficient)",IF(AND($U27 >=75%, $U27 <85%),"Transitioning (Proficient)","At Grade Level (Highly Proficient)")))),"") | AB27: =IF(I27/I$9>=75%,1,0) -> 0 | AC27: =IF(J27/J$9>=75%,1,0) -> 0 | AD27: =IF(K27/K$9>=75%,1,0) -> 0 | AE27: =IF(L27/L$9>=75%,1,0) -> 0 | AF27: =IF(M27/M$9>=75%,1,0) -> 0 | AG27: =IF(N27/N$9>=75%,1,0) -> 0 | AH27: =IF(O27/O$9>=75%,1,0) -> 0 | AI27: =IF(P27/P$9>=75%,1,0) -> 0 | ... AL27: =IF(S27/S$9>=75%,1,0) -> 0
A28: 19 | G28: =IF(C28<>"",(F28-E28)/365,"") | T28: =IF(C28<>"",SUM(I28:S28),"") | U28: =IF(AND(T28>0,C28<>""),T28/T$9,"") | V28: =IF(U28<>"",IF($U28<25%,"Emerging (Not Proficient)", IF(AND($U28 >=25%, $U28 <50%), "Emerging (Low Proficient)", IF(AND($U28 >=50%, $U28 <75%),"Developing (Nearly Proficient)",IF(AND($U28 >=75%, $U28 <85%),"Transitioning (Proficient)","At Grade Level (Highly Proficient)")))),"") | AB28: =IF(I28/I$9>=75%,1,0) -> 0 | AC28: =IF(J28/J$9>=75%,1,0) -> 0 | AD28: =IF(K28/K$9>=75%,1,0) -> 0 | AE28: =IF(L28/L$9>=75%,1,0) -> 0 | AF28: =IF(M28/M$9>=75%,1,0) -> 0 | AG28: =IF(N28/N$9>=75%,1,0) -> 0 | AH28: =IF(O28/O$9>=75%,1,0) -> 0 | AI28: =IF(P28/P$9>=75%,1,0) -> 0 | ... AL28: =IF(S28/S$9>=75%,1,0) -> 0
A29: 20 | G29: =IF(C29<>"",(F29-E29)/365,"") | T29: =IF(C29<>"",SUM(I29:S29),"") | U29: =IF(AND(T29>0,C29<>""),T29/T$9,"") | V29: =IF(U29<>"",IF($U29<25%,"Emerging (Not Proficient)", IF(AND($U29 >=25%, $U29 <50%), "Emerging (Low Proficient)", IF(AND($U29 >=50%, $U29 <75%),"Developing (Nearly Proficient)",IF(AND($U29 >=75%, $U29 <85%),"Transitioning (Proficient)","At Grade Level (Highly Proficient)")))),"") | AB29: =IF(I29/I$9>=75%,1,0) -> 0 | AC29: =IF(J29/J$9>=75%,1,0) -> 0 | AD29: =IF(K29/K$9>=75%,1,0) -> 0 | AE29: =IF(L29/L$9>=75%,1,0) -> 0 | AF29: =IF(M29/M$9>=75%,1,0) -> 0 | AG29: =IF(N29/N$9>=75%,1,0) -> 0 | AH29: =IF(O29/O$9>=75%,1,0) -> 0 | AI29: =IF(P29/P$9>=75%,1,0) -> 0 | ... AL29: =IF(S29/S$9>=75%,1,0) -> 0
A30: 21 | G30: =IF(C30<>"",(F30-E30)/365,"") | T30: =IF(C30<>"",SUM(I30:S30),"") | U30: =IF(AND(T30>0,C30<>""),T30/T$9,"") | V30: =IF(U30<>"",IF($U30<25%,"Emerging (Not Proficient)", IF(AND($U30 >=25%, $U30 <50%), "Emerging (Low Proficient)", IF(AND($U30 >=50%, $U30 <75%),"Developing (Nearly Proficient)",IF(AND($U30 >=75%, $U30 <85%),"Transitioning (Proficient)","At Grade Level (Highly Proficient)")))),"") | AB30: =IF(I30/I$9>=75%,1,0) -> 0 | AC30: =IF(J30/J$9>=75%,1,0) -> 0 | AD30: =IF(K30/K$9>=75%,1,0) -> 0 | AE30: =IF(L30/L$9>=75%,1,0) -> 0 | AF30: =IF(M30/M$9>=75%,1,0) -> 0 | AG30: =IF(N30/N$9>=75%,1,0) -> 0 | AH30: =IF(O30/O$9>=75%,1,0) -> 0 | AI30: =IF(P30/P$9>=75%,1,0) -> 0 | ... AL30: =IF(S30/S$9>=75%,1,0) -> 0
A31: 22 | G31: =IF(C31<>"",(F31-E31)/365,"") | T31: =IF(C31<>"",SUM(I31:S31),"") | U31: =IF(AND(T31>0,C31<>""),T31/T$9,"") | V31: =IF(U31<>"",IF($U31<25%,"Emerging (Not Proficient)", IF(AND($U31 >=25%, $U31 <50%), "Emerging (Low Proficient)", IF(AND($U31 >=50%, $U31 <75%),"Developing (Nearly Proficient)",IF(AND($U31 >=75%, $U31 <85%),"Transitioning (Proficient)","At Grade Level (Highly Proficient)")))),"") | AB31: =IF(I31/I$9>=75%,1,0) -> 0 | AC31: =IF(J31/J$9>=75%,1,0) -> 0 | AD31: =IF(K31/K$9>=75%,1,0) -> 0 | AE31: =IF(L31/L$9>=75%,1,0) -> 0 | AF31: =IF(M31/M$9>=75%,1,0) -> 0 | AG31: =IF(N31/N$9>=75%,1,0) -> 0 | AH31: =IF(O31/O$9>=75%,1,0) -> 0 | AI31: =IF(P31/P$9>=75%,1,0) -> 0 | ... AL31: =IF(S31/S$9>=75%,1,0) -> 0
A32: 23 | G32: =IF(C32<>"",(F32-E32)/365,"") | T32: =IF(C32<>"",SUM(I32:S32),"") | U32: =IF(AND(T32>0,C32<>""),T32/T$9,"") | V32: =IF(U32<>"",IF($U32<25%,"Emerging (Not Proficient)", IF(AND($U32 >=25%, $U32 <50%), "Emerging (Low Proficient)", IF(AND($U32 >=50%, $U32 <75%),"Developing (Nearly Proficient)",IF(AND($U32 >=75%, $U32 <85%),"Transitioning (Proficient)","At Grade Level (Highly Proficient)")))),"") | AB32: =IF(I32/I$9>=75%,1,0) -> 0 | AC32: =IF(J32/J$9>=75%,1,0) -> 0 | AD32: =IF(K32/K$9>=75%,1,0) -> 0 | AE32: =IF(L32/L$9>=75%,1,0) -> 0 | AF32: =IF(M32/M$9>=75%,1,0) -> 0 | AG32: =IF(N32/N$9>=75%,1,0) -> 0 | AH32: =IF(O32/O$9>=75%,1,0) -> 0 | AI32: =IF(P32/P$9>=75%,1,0) -> 0 | ... AL32: =IF(S32/S$9>=75%,1,0) -> 0
A33: 24 | G33: =IF(C33<>"",(F33-E33)/365,"") | T33: =IF(C33<>"",SUM(I33:S33),"") | U33: =IF(AND(T33>0,C33<>""),T33/T$9,"") | V33: =IF(U33<>"",IF($U33<25%,"Emerging (Not Proficient)", IF(AND($U33 >=25%, $U33 <50%), "Emerging (Low Proficient)", IF(AND($U33 >=50%, $U33 <75%),"Developing (Nearly Proficient)",IF(AND($U33 >=75%, $U33 <85%),"Transitioning (Proficient)","At Grade Level (Highly Proficient)")))),"") | AB33: =IF(I33/I$9>=75%,1,0) -> 0 | AC33: =IF(J33/J$9>=75%,1,0) -> 0 | AD33: =IF(K33/K$9>=75%,1,0) -> 0 | AE33: =IF(L33/L$9>=75%,1,0) -> 0 | AF33: =IF(M33/M$9>=75%,1,0) -> 0 | AG33: =IF(N33/N$9>=75%,1,0) -> 0 | AH33: =IF(O33/O$9>=75%,1,0) -> 0 | AI33: =IF(P33/P$9>=75%,1,0) -> 0 | ... AL33: =IF(S33/S$9>=75%,1,0) -> 0
A34: 25 | G34: =IF(C34<>"",(F34-E34)/365,"") | T34: =IF(C34<>"",SUM(I34:S34),"") | U34: =IF(AND(T34>0,C34<>""),T34/T$9,"") | V34: =IF(U34<>"",IF($U34<25%,"Emerging (Not Proficient)", IF(AND($U34 >=25%, $U34 <50%), "Emerging (Low Proficient)", IF(AND($U34 >=50%, $U34 <75%),"Developing (Nearly Proficient)",IF(AND($U34 >=75%, $U34 <85%),"Transitioning (Proficient)","At Grade Level (Highly Proficient)")))),"") | AB34: =IF(I34/I$9>=75%,1,0) -> 0 | AC34: =IF(J34/J$9>=75%,1,0) -> 0 | AD34: =IF(K34/K$9>=75%,1,0) -> 0 | AE34: =IF(L34/L$9>=75%,1,0) -> 0 | AF34: =IF(M34/M$9>=75%,1,0) -> 0 | AG34: =IF(N34/N$9>=75%,1,0) -> 0 | AH34: =IF(O34/O$9>=75%,1,0) -> 0 | AI34: =IF(P34/P$9>=75%,1,0) -> 0 | ... AL34: =IF(S34/S$9>=75%,1,0) -> 0
A35: 26 | G35: =IF(C35<>"",(F35-E35)/365,"") | T35: =IF(C35<>"",SUM(I35:S35),"") | U35: =IF(AND(T35>0,C35<>""),T35/T$9,"") | V35: =IF(U35<>"",IF($U35<25%,"Emerging (Not Proficient)", IF(AND($U35 >=25%, $U35 <50%), "Emerging (Low Proficient)", IF(AND($U35 >=50%, $U35 <75%),"Developing (Nearly Proficient)",IF(AND($U35 >=75%, $U35 <85%),"Transitioning (Proficient)","At Grade Level (Highly Proficient)")))),"") | AB35: =IF(I35/I$9>=75%,1,0) -> 0 | AC35: =IF(J35/J$9>=75%,1,0) -> 0 | AD35: =IF(K35/K$9>=75%,1,0) -> 0 | AE35: =IF(L35/L$9>=75%,1,0) -> 0 | AF35: =IF(M35/M$9>=75%,1,0) -> 0 | AG35: =IF(N35/N$9>=75%,1,0) -> 0 | AH35: =IF(O35/O$9>=75%,1,0) -> 0 | AI35: =IF(P35/P$9>=75%,1,0) -> 0 | ... AL35: =IF(S35/S$9>=75%,1,0) -> 0
A36: 27 | G36: =IF(C36<>"",(F36-E36)/365,"") | T36: =IF(C36<>"",SUM(I36:S36),"") | U36: =IF(AND(T36>0,C36<>""),T36/T$9,"") | V36: =IF(U36<>"",IF($U36<25%,"Emerging (Not Proficient)", IF(AND($U36 >=25%, $U36 <50%), "Emerging (Low Proficient)", IF(AND($U36 >=50%, $U36 <75%),"Developing (Nearly Proficient)",IF(AND($U36 >=75%, $U36 <85%),"Transitioning (Proficient)","At Grade Level (Highly Proficient)")))),"") | AB36: =IF(I36/I$9>=75%,1,0) -> 0 | AC36: =IF(J36/J$9>=75%,1,0) -> 0 | AD36: =IF(K36/K$9>=75%,1,0) -> 0 | AE36: =IF(L36/L$9>=75%,1,0) -> 0 | AF36: =IF(M36/M$9>=75%,1,0) -> 0 | AG36: =IF(N36/N$9>=75%,1,0) -> 0 | AH36: =IF(O36/O$9>=75%,1,0) -> 0 | AI36: =IF(P36/P$9>=75%,1,0) -> 0 | ... AL36: =IF(S36/S$9>=75%,1,0) -> 0
A37: 28 | G37: =IF(C37<>"",(F37-E37)/365,"") | T37: =IF(C37<>"",SUM(I37:S37),"") | U37: =IF(AND(T37>0,C37<>""),T37/T$9,"") | V37: =IF(U37<>"",IF($U37<25%,"Emerging (Not Proficient)", IF(AND($U37 >=25%, $U37 <50%), "Emerging (Low Proficient)", IF(AND($U37 >=50%, $U37 <75%),"Developing (Nearly Proficient)",IF(AND($U37 >=75%, $U37 <85%),"Transitioning (Proficient)","At Grade Level (Highly Proficient)")))),"") | AB37: =IF(I37/I$9>=75%,1,0) -> 0 | AC37: =IF(J37/J$9>=75%,1,0) -> 0 | AD37: =IF(K37/K$9>=75%,1,0) -> 0 | AE37: =IF(L37/L$9>=75%,1,0) -> 0 | AF37: =IF(M37/M$9>=75%,1,0) -> 0 | AG37: =IF(N37/N$9>=75%,1,0) -> 0 | AH37: =IF(O37/O$9>=75%,1,0) -> 0 | AI37: =IF(P37/P$9>=75%,1,0) -> 0 | ... AL37: =IF(S37/S$9>=75%,1,0) -> 0
... A68: 59 | G68: =IF(C68<>"",(F68-E68)/365,"") | T68: =IF(C68<>"",SUM(I68:S68),"") | U68: =IF(AND(T68>0,C68<>""),T68/T$9,"") | V68: =IF(U68<>"",IF($U68<25%,"Emerging (Not Proficient)", IF(AND($U68 >=25%, $U68 <50%), "Emerging (Low Proficient)", IF(AND($U68 >=50%, $U68 <75%),"Developing (Nearly Proficient)",IF(AND($U68 >=75%, $U68 <85%),"Transitioning (Proficient)","At Grade Level (Highly Proficient)")))),"") | AB68: =IF(I68/I$9>=75%,1,0) -> 0 | AC68: =IF(J68/J$9>=75%,1,0) -> 0 | AD68: =IF(K68/K$9>=75%,1,0) -> 0 | AE68: =IF(L68/L$9>=75%,1,0) -> 0 | AF68: =IF(M68/M$9>=75%,1,0) -> 0 | AG68: =IF(N68/N$9>=75%,1,0) -> 0 | AH68: =IF(O68/O$9>=75%,1,0) -> 0 | AI68: =IF(P68/P$9>=75%,1,0) -> 0 | ... AL68: =IF(S68/S$9>=75%,1,0) -> 0
A69: =A68+1 -> 60 | G69: =IF(C69<>"",(F69-E69)/365,"") | T69: =IF(C69<>"",SUM(I69:S69),"") | U69: =IF(AND(T69>0,C69<>""),T69/T$9,"") | V69: =IF(U69<>"",IF($U69<25%,"Emerging (Not Proficient)", IF(AND($U69 >=25%, $U69 <50%), "Emerging (Low Proficient)", IF(AND($U69 >=50%, $U69 <75%),"Developing (Nearly Proficient)",IF(AND($U69 >=75%, $U69 <85%),"Transitioning (Proficient)","At Grade Level (Highly Proficient)")))),"") | AB69: =IF(I69/I$9>=75%,1,0) -> 0 | AC69: =IF(J69/J$9>=75%,1,0) -> 0 | AD69: =IF(K69/K$9>=75%,1,0) -> 0 | AE69: =IF(L69/L$9>=75%,1,0) -> 0 | AF69: =IF(M69/M$9>=75%,1,0) -> 0 | AG69: =IF(N69/N$9>=75%,1,0) -> 0 | AH69: =IF(O69/O$9>=75%,1,0) -> 0 | AI69: =IF(P69/P$9>=75%,1,0) -> 0 | ... AL69: =IF(S69/S$9>=75%,1,0) -> 0
A70: =A69+1 -> 61 | G70: =IF(C70<>"",(F70-E70)/365,"") | T70: =IF(C70<>"",SUM(I70:S70),"") | U70: =IF(AND(T70>0,C70<>""),T70/T$9,"") | V70: =IF(U70<>"",IF($U70<25%,"Emerging (Not Proficient)", IF(AND($U70 >=25%, $U70 <50%), "Emerging (Low Proficient)", IF(AND($U70 >=50%, $U70 <75%),"Developing (Nearly Proficient)",IF(AND($U70 >=75%, $U70 <85%),"Transitioning (Proficient)","At Grade Level (Highly Proficient)")))),"") | AB70: =IF(I70/I$9>=75%,1,0) -> 0 | AC70: =IF(J70/J$9>=75%,1,0) -> 0 | AD70: =IF(K70/K$9>=75%,1,0) -> 0 | AE70: =IF(L70/L$9>=75%,1,0) -> 0 | AF70: =IF(M70/M$9>=75%,1,0) -> 0 | AG70: =IF(N70/N$9>=75%,1,0) -> 0 | AH70: =IF(O70/O$9>=75%,1,0) -> 0 | AI70: =IF(P70/P$9>=75%,1,0) -> 0 | ... AL70: =IF(S70/S$9>=75%,1,0) -> 0
A71: =A70+1 -> 62 | G71: =IF(C71<>"",(F71-E71)/365,"") | T71: =IF(C71<>"",SUM(I71:S71),"") | U71: =IF(AND(T71>0,C71<>""),T71/T$9,"") | V71: =IF(U71<>"",IF($U71<25%,"Emerging (Not Proficient)", IF(AND($U71 >=25%, $U71 <50%), "Emerging (Low Proficient)", IF(AND($U71 >=50%, $U71 <75%),"Developing (Nearly Proficient)",IF(AND($U71 >=75%, $U71 <85%),"Transitioning (Proficient)","At Grade Level (Highly Proficient)")))),"") | AB71: =IF(I71/I$9>=75%,1,0) -> 0 | AC71: =IF(J71/J$9>=75%,1,0) -> 0 | AD71: =IF(K71/K$9>=75%,1,0) -> 0 | AE71: =IF(L71/L$9>=75%,1,0) -> 0 | AF71: =IF(M71/M$9>=75%,1,0) -> 0 | AG71: =IF(N71/N$9>=75%,1,0) -> 0 | AH71: =IF(O71/O$9>=75%,1,0) -> 0 | AI71: =IF(P71/P$9>=75%,1,0) -> 0 | ... AL71: =IF(S71/S$9>=75%,1,0) -> 0
A72: =A71+1 -> 63 | G72: =IF(C72<>"",(F72-E72)/365,"") | T72: =IF(C72<>"",SUM(I72:S72),"") | U72: =IF(AND(T72>0,C72<>""),T72/T$9,"") | V72: =IF(U72<>"",IF($U72<25%,"Emerging (Not Proficient)", IF(AND($U72 >=25%, $U72 <50%), "Emerging (Low Proficient)", IF(AND($U72 >=50%, $U72 <75%),"Developing (Nearly Proficient)",IF(AND($U72 >=75%, $U72 <85%),"Transitioning (Proficient)","At Grade Level (Highly Proficient)")))),"") | AB72: =IF(I72/I$9>=75%,1,0) -> 0 | AC72: =IF(J72/J$9>=75%,1,0) -> 0 | AD72: =IF(K72/K$9>=75%,1,0) -> 0 | AE72: =IF(L72/L$9>=75%,1,0) -> 0 | AF72: =IF(M72/M$9>=75%,1,0) -> 0 | AG72: =IF(N72/N$9>=75%,1,0) -> 0 | AH72: =IF(O72/O$9>=75%,1,0) -> 0 | AI72: =IF(P72/P$9>=75%,1,0) -> 0 | ... AL72: =IF(S72/S$9>=75%,1,0) -> 0
A73: =A72+1 -> 64 | G73: =IF(C73<>"",(F73-E73)/365,"") | T73: =IF(C73<>"",SUM(I73:S73),"") | U73: =IF(AND(T73>0,C73<>""),T73/T$9,"") | V73: =IF(U73<>"",IF($U73<25%,"Emerging (Not Proficient)", IF(AND($U73 >=25%, $U73 <50%), "Emerging (Low Proficient)", IF(AND($U73 >=50%, $U73 <75%),"Developing (Nearly Proficient)",IF(AND($U73 >=75%, $U73 <85%),"Transitioning (Proficient)","At Grade Level (Highly Proficient)")))),"") | AB73: =IF(I73/I$9>=75%,1,0) -> 0 | AC73: =IF(J73/J$9>=75%,1,0) -> 0 | AD73: =IF(K73/K$9>=75%,1,0) -> 0 | AE73: =IF(L73/L$9>=75%,1,0) -> 0 | AF73: =IF(M73/M$9>=75%,1,0) -> 0 | AG73: =IF(N73/N$9>=75%,1,0) -> 0 | AH73: =IF(O73/O$9>=75%,1,0) -> 0 | AI73: =IF(P73/P$9>=75%,1,0) -> 0 | ... AL73: =IF(S73/S$9>=75%,1,0) -> 0
A74: =A73+1 -> 65 | G74: =IF(C74<>"",(F74-E74)/365,"") | T74: =IF(C74<>"",SUM(I74:S74),"") | U74: =IF(AND(T74>0,C74<>""),T74/T$9,"") | V74: =IF(U74<>"",IF($U74<25%,"Emerging (Not Proficient)", IF(AND($U74 >=25%, $U74 <50%), "Emerging (Low Proficient)", IF(AND($U74 >=50%, $U74 <75%),"Developing (Nearly Proficient)",IF(AND($U74 >=75%, $U74 <85%),"Transitioning (Proficient)","At Grade Level (Highly Proficient)")))),"") | AB74: =IF(I74/I$9>=75%,1,0) -> 0 | AC74: =IF(J74/J$9>=75%,1,0) -> 0 | AD74: =IF(K74/K$9>=75%,1,0) -> 0 | AE74: =IF(L74/L$9>=75%,1,0) -> 0 | AF74: =IF(M74/M$9>=75%,1,0) -> 0 | AG74: =IF(N74/N$9>=75%,1,0) -> 0 | AH74: =IF(O74/O$9>=75%,1,0) -> 0 | AI74: =IF(P74/P$9>=75%,1,0) -> 0 | ... AL74: =IF(S74/S$9>=75%,1,0) -> 0
...

Sheet List
B1: Region | C1: Language
B2: NCR | C2: Agta | F2: Akeanon
B3: CAR | C3: Akeanon | F3: Bahasa Sug
B4: Region I | C4: Bahasa Sug | F4: Central Bikol
B5: Region II | C5: Bikol Libon | F5: Chavacano
B6: Region III | C6: Buhi-non | F6: Hiligaynon
B7: Region IV-A | C7: Caluyanen | F7: Ibanag
B8: Region IV-B | C8: Central Bikol | F8: Ilocano
B9: Region V | C9: Chavacano | F9: Ivatan
B10: Region VI | C10: Cuyonon | F10: Kapampangan
B11: Region VII | C11: English | F11: Kinaray-a
B12: Region VIII | C12: Hiligaynon | F12: Magindanawn
B13: Region IX | C13: Ibanag | F13: Meranaw
... B18: BARMM | C18: Ivatan | F18: Tagalog
C19: Kankanaey | F19: Waray
C20: Kapampangan | F20: Yakan
C21: Kinaray-a
C22: Magindanawn
C23: Meranaw
C24: Minasbate
C25: Miraya
C26: Northern Catanduanes
C27: Northern Sorsoganon
C28: Pangasinan
C29: Rinconada
C30: Sambal
C31: Sinama
C32: Sinugbuanong Binisaya
... C40: Other MT

Sheet Class Summary
A2: GRADE 2 Assessment Scoresheet (CLASS SUMMARY)
A5: SCHOOL ID : | B5: ='G2 RMA Scoresheet'!$C$6 -> 117443 | D5: Total Enrolment | E5: =F14 -> 15 | F5: Total Assessed : | I5: =E14 -> 15
A6: SCHOOL NAME: | B6: ='G2 RMA Scoresheet'!$F$6 -> Romana Elementary School | D6: LOI / MOI | E6: {='G2 RMA Scoresheet'!$K$6:$K$6} -> Hiligaynon
A8: Grade | D8: Language Matched ( LOI vs Learners) | E8: Number of Learners Assessed | F8: Total Enrolment | G8: Number of Learners Assessed | L8: Number of Learners with Correct Answers >=75% | W8: OverAll Average
B9: Section | C9: Sex | G9: Emerging (Not Proficient) | H9: Emerging (Low Proficient) | I9: Developing (Nearly Proficient) | J9: Transitioning (Proficient) | K9: At Grade Level (Highly Proficient) | L9: Task A | M9: Task B | N9: Task C | O9: Task D | P9: Task E | Q9: Task F | R9: Task G | S9: Task H | T9: Task I | U9: Task J | V9: Task K
L10: ='G2 RMA Scoresheet'!I9 -> 3 | M10: ='G2 RMA Scoresheet'!J9 -> 1 | N10: ='G2 RMA Scoresheet'!K9 -> 2 | O10: ='G2 RMA Scoresheet'!L9 -> 1 | P10: ='G2 RMA Scoresheet'!M9 -> 4 | Q10: ='G2 RMA Scoresheet'!N9 -> 3 | R10: ='G2 RMA Scoresheet'!O9 -> 3 | S10: ='G2 RMA Scoresheet'!P9 -> 4 | ... V10: ='G2 RMA Scoresheet'!S9 -> 1 | W10: =SUM(L10:V10) -> 25
A11: Grade 2 | B11: =IF('G2 RMA Scoresheet'!K7<>"",'G2 RMA Scoresheet'!K7,"") -> 1 | C11: Male | D11: =COUNTIFS('G2 RMA Scoresheet'!$D$10:$D$109,$C11,'G2 RMA Scoresheet'!$H$10:$H$109,$E$6) -> 7 | E11: =COUNTIF('G2 RMA Scoresheet'!$D$10:$D$109,"Male") -> 7 | F11: ='G2 RMA Scoresheet'!$O$6 -> 7 | G11: =COUNTIFS('G2 RMA Scoresheet'!$D$10:$D$109,"Male",'G2 RMA Scoresheet'!$V$10:$V$109,G$9) -> 6 | H11: =COUNTIFS('G2 RMA Scoresheet'!$D$10:$D$109,"Male",'G2 RMA Scoresheet'!$V$10:$V$109,H$9) -> 1 | I11: =COUNTIFS('G2 RMA Scoresheet'!$D$10:$D$109,"Male",'G2 RMA Scoresheet'!$V$10:$V$109,I$9) -> 0 | J11: =COUNTIFS('G2 RMA Scoresheet'!$D$10:$D$109,"Male",'G2 RMA Scoresheet'!$V$10:$V$109,J$9) -> 0 | K11: =COUNTIFS('G2 RMA Scoresheet'!$D$10:$D$109,"Male",'G2 RMA Scoresheet'!$V$10:$V$109,K$9) -> 0 | L11: =COUNTIFS('G2 RMA Scoresheet'!$D$10:$D$109,"Male",'G2 RMA Scoresheet'!AB$10:AB$109,1) -> 0 | M11: =COUNTIFS('G2 RMA Scoresheet'!$D$10:$D$109,"Male",'G2 RMA Scoresheet'!AC$10:AC$109,1) -> 1 | N11: =COUNTIFS('G2 RMA Scoresheet'!$D$10:$D$109,"Male",'G2 RMA Scoresheet'!AD$10:AD$109,1) -> 0 | O11: =COUNTIFS('G2 RMA Scoresheet'!$D$10:$D$109,"Male",'G2 RMA Scoresheet'!AE$10:AE$109,1) -> 1 | P11: =COUNTIFS('G2 RMA Scoresheet'!$D$10:$D$109,"Male",'G2 RMA Scoresheet'!AF$10:AF$109,1) -> 0 | Q11: =COUNTIFS('G2 RMA Scoresheet'!$D$10:$D$109,"Male",'G2 RMA Scoresheet'!AG$10:AG$109,1) -> 0 | R11: =COUNTIFS('G2 RMA Scoresheet'!$D$10:$D$109,"Male",'G2 RMA Scoresheet'!AH$10:AH$109,1) -> 0 | S11: =COUNTIFS('G2 RMA Scoresheet'!$D$10:$D$109,"Male",'G2 RMA Scoresheet'!AI$10:AI$109,1) -> 0 | ... V11: =COUNTIFS('G2 RMA Scoresheet'!$D$10:$D$109,"Male",'G2 RMA Scoresheet'!AL$10:AL$109,1) -> 6 | W11: =IFERROR(AVERAGEIFS('G2 RMA Scoresheet'!T$10:T$109,'G2 RMA Scoresheet'!$D$10:$D$109,$C11),"") -> 4
A12: =A11 -> Grade 2 | B12: =B11 -> 1 | C12: Female | D12: =COUNTIFS('G2 RMA Scoresheet'!$D$10:$D$109,$C12,'G2 RMA Scoresheet'!$H$10:$H$109,$E$6) -> 8 | E12: =COUNTIF('G2 RMA Scoresheet'!$D$10:$D$109,"Female") -> 8 | F12: ='G2 RMA Scoresheet'!O7 -> 8 | G12: =COUNTIFS('G2 RMA Scoresheet'!$D$10:$D$109,"Female",'G2 RMA Scoresheet'!$V$10:$V$109,G$9) -> 3 | H12: =COUNTIFS('G2 RMA Scoresheet'!$D$10:$D$109,"Female",'G2 RMA Scoresheet'!$V$10:$V$109,H$9) -> 5 | I12: =COUNTIFS('G2 RMA Scoresheet'!$D$10:$D$109,"Female",'G2 RMA Scoresheet'!$V$10:$V$109,I$9) -> 0 | J12: =COUNTIFS('G2 RMA Scoresheet'!$D$10:$D$109,"Female",'G2 RMA Scoresheet'!$V$10:$V$109,J$9) -> 0 | K12: =COUNTIFS('G2 RMA Scoresheet'!$D$10:$D$109,"Female",'G2 RMA Scoresheet'!$V$10:$V$109,K$9) -> 0 | L12: =COUNTIFS('G2 RMA Scoresheet'!$D$10:$D$109,"Female",'G2 RMA Scoresheet'!AB$10:AB$109,1) -> 0 | M12: =COUNTIFS('G2 RMA Scoresheet'!$D$10:$D$109,"Female",'G2 RMA Scoresheet'!AC$10:AC$109,1) -> 5 | N12: =COUNTIFS('G2 RMA Scoresheet'!$D$10:$D$109,"Female",'G2 RMA Scoresheet'!AD$10:AD$109,1) -> 0 | O12: =COUNTIFS('G2 RMA Scoresheet'!$D$10:$D$109,"Female",'G2 RMA Scoresheet'!AE$10:AE$109,1) -> 2 | P12: =COUNTIFS('G2 RMA Scoresheet'!$D$10:$D$109,"Female",'G2 RMA Scoresheet'!AF$10:AF$109,1) -> 0 | Q12: =COUNTIFS('G2 RMA Scoresheet'!$D$10:$D$109,"Female",'G2 RMA Scoresheet'!AG$10:AG$109,1) -> 0 | R12: =COUNTIFS('G2 RMA Scoresheet'!$D$10:$D$109,"Female",'G2 RMA Scoresheet'!AH$10:AH$109,1) -> 0 | S12: =COUNTIFS('G2 RMA Scoresheet'!$D$10:$D$109,"Female",'G2 RMA Scoresheet'!AI$10:AI$109,1) -> 0 | ... V12: =COUNTIFS('G2 RMA Scoresheet'!$D$10:$D$109,"Female",'G2 RMA Scoresheet'!AL$10:AL$109,1) -> 6 | W12: =IFERROR(AVERAGEIFS('G2 RMA Scoresheet'!T$10:T$109,'G2 RMA Scoresheet'!$D$10:$D$109,$C12),"") -> 6
A14: =A12 -> Grade 2 | B14: =B12 -> 1 | C14: Total | D14: =D11+D12 -> 15 | E14: =E11+E12 -> 15 | F14: =F11+F12 -> 15 | G14: =G11+G12 -> 9 | H14: =H11+H12 -> 6 | I14: =I11+I12 -> 0 | J14: =J11+J12 -> 0 | K14: =K11+K12 -> 0 | ... V14: =V11+V12 -> 12 | W14: =IFERROR(AVERAGE('G2 RMA Scoresheet'!T$10:T$109),"") -> 5.0666667
A18: Dashboard | C18: Percent (%) of Learners at each proficiency level | L18: Percentage of Learners with Correct Answers >=75%
A19: Sex | B19: Percent of Learners assessed | C19: Emerging (Not Proficient) | D19: Emerging (Low Proficient) | E19: Developing (Nearly Proficient) | F19: Transitioning (Proficient) | G19: At Grade Level (Highly Proficient) | K19: Sex | L19: Task A | M19: Task B | N19: Task C | O19: Task D | P19: Task E | Q19: Task F | R19: Task G | S19: Task H | T19: Task I | U19: Task J | V19: Task K | W19: Overall Average
A20: Male | B20: =IFERROR(E11/$E$5,"") -> 0.46666667 | C20: =IFERROR(G11/$E$11,"") -> 0.85714286 | D20: =IFERROR(H11/$E$11,"") -> 0.14285714 | E20: =IFERROR(I11/$E$11,"") -> 0 | F20: =IFERROR(J11/$E$11,"") -> 0 | G20: =IFERROR(K11/$E$11,"") -> 0 | I20: =IFERROR(#REF!/$I$11,"") | K20: Male | L20: =IFERROR(L11/$E11,"") -> 0 | M20: =IFERROR(M11/$E11,"") -> 0.14285714 | N20: =IFERROR(N11/$E11,"") -> 0 | O20: =IFERROR(O11/$E11,"") -> 0.14285714 | P20: =IFERROR(P11/$E11,"") -> 0 | Q20: =IFERROR(Q11/$E11,"") -> 0 | R20: =IFERROR(R11/$E11,"") -> 0 | S20: =IFERROR(S11/$E11,"") -> 0 | ... V20: =IFERROR(V11/$E11,"") -> 0.85714286 | W20: =IFERROR(W11/W$10,"") -> 0.16
A21: Female | B21: =IFERROR(E12/$E$5,"") -> 0.53333333 | C21: =IFERROR(G12/$E$12,"") -> 0.375 | D21: =IFERROR(H12/$E$12,"") -> 0.625 | E21: =IFERROR(I12/$E$12,"") -> 0 | F21: =IFERROR(J12/$E$12,"") -> 0 | G21: =IFERROR(K12/$E$12,"") -> 0 | K21: Female | L21: =IFERROR(L12/$E12,"") -> 0 | M21: =IFERROR(M12/$E12,"") -> 0.625 | N21: =IFERROR(N12/$E12,"") -> 0 | O21: =IFERROR(O12/$E12,"") -> 0.25 | P21: =IFERROR(P12/$E12,"") -> 0 | Q21: =IFERROR(Q12/$E12,"") -> 0 | R21: =IFERROR(R12/$E12,"") -> 0 | S21: =IFERROR(S12/$E12,"") -> 0 | ... V21: =IFERROR(V12/$E12,"") -> 0.75 | W21: =IFERROR(W12/W$10,"") -> 0.24
A22: Total | B22: =IFERROR(B20+B21,"") -> 1 | C22: =IFERROR(G14/$E$14,"") -> 0.6 | D22: =IFERROR(H14/$E$14,"") -> 0.4 | E22: =IFERROR(I14/$E$14,"") -> 0 | F22: =IFERROR(J14/$E$14,"") -> 0 | G22: =IFERROR(K14/$E$14,"") -> 0 | K22: Total | L22: =IFERROR(L14/$E14,"") -> 0 | M22: =IFERROR(M14/$E14,"") -> 0.4 | N22: =IFERROR(N14/$E14,"") -> 0 | O22: =IFERROR(O14/$E14,"") -> 0.2 | P22: =IFERROR(P14/$E14,"") -> 0 | Q22: =IFERROR(Q14/$E14,"") -> 0 | R22: =IFERROR(R14/$E14,"") -> 0 | S22: =IFERROR(S14/$E14,"") -> 0 | ... V22: =IFERROR(V14/$E14,"") -> 0.8 | W22: =IFERROR(W14/W$10,"") -> 0.20266667
