Workbook

Sheet G3 RMA Scoresheet
T1: RMA2v2
A4: Assessment Type
A5: Region | C5: Region VI | D5: GRADE 3 Rapid Mathematics Scoresheets
A6: School ID: | C6: 117443 | D6: School Name: | F6: ROMANA ELEMENTARY SCHOOL | I6: LOI/MOI | M6: Enrolment (Male): | O6: 10 | P6: Number Assessed | R6: =COUNTA(D10:D109) -> 25
A7: Grade: | C7: Grade 3 | D7: Teacher : | F7: KEMBERLY G. BELMIS | I7: Section: | K7: 1 | M7: Enrolment (Female): | O7: 15
A8: S/N | B8: LRN | C8: Name of Learner | D8: Sex | E8: Birthdate | F8: Date of Asessment | G8: Age | H8: Mother Tongue | I8: Task A: Fractions (2) | J8: Task B: Mass Measurement (1) | K8: Task C: Missing Number in Patterns (2) | L8: Task D: Addition (3) | M8: Task E: Subtraction (3) | N8: Task F: Multiplication (2) | O8: Task G: Division (3) | P8: Task H: Geometric Representation (4) | Q8: TOTAL SCORE (20) | R8: % of Correct Answer | S8: Levelling of Learners | T8: Remarks | Y8: Task A: Fractions (2) | Z8: Task B: Mass Measurement (1) | AA8: Task C: Missing Number in Patterns (2) | AB8: Task D: Addition (3) | AC8: Task E: Subtraction (3) | AD8: Task F: Multiplication (2) | AE8: Task G: Division (3) | AF8: Task H: Geometric Representation (4)
I9: 2 | J9: 1 | K9: 2 | L9: 3 | M9: 3 | N9: 2 | O9: 3 | P9: 4 | Q9: =SUM(I9:P9) -> 20
A10: 1 | B10: 117443220001 | C10: ABAY, KENNETH ALEXANDER, NALONAN | D10: Male | E10: 03-23-2016 | F10: 45719 | G10: =IF(C10<>"",(F10-E10)/365,"") -> #VALUE! | H10: Hiligaynon | I10: 2 | J10: 1 | K10: 2 | L10: 3 | M10: 3 | N10: 2 | O10: 1 | P10: 3 | Q10: =IF(C10<>"",SUM(I10:P10),"") -> 17 | R10: =IF(AND(Q10>0,C10<>""),Q10/Q$9,"") -> 0.85 | S10: =IF(R10<>"",IF($R10<25%,"Emerging (Not Proficient)", IF(AND($R10 >=25%, $R10 <50%), "Emerging (Low Proficient)", IF(AND($R10 >=50%, $R10 <75%),"Developing (Nearly Proficient)",IF(AND($R10 >=75%, $R10 <85%),"Transitioning (Proficient)","At Grade Level (Highly Proficient)")))),"") -> At Grade Level (Highly Proficient) | Y10: =IF(I10/I$9>=75%,1,0) -> 1 | Z10: =IF(J10/J$9>=75%,1,0) -> 1 | AA10: =IF(K10/K$9>=75%,1,0) -> 1 | AB10: =IF(L10/L$9>=75%,1,0) -> 1 | AC10: =IF(M10/M$9>=75%,1,0) -> 1 | AD10: =IF(N10/N$9>=75%,1,0) -> 1 | AE10: =IF(O10/O$9>=75%,1,0) -> 0 | AF10: =IF(P10/P$9>=75%,1,0) -> 1
A11: 2 | B11: 117443220002 | C11: BANARIA, KEEPER, ABAY | D11: Male | E11: 10-28-2015 | F11: 45719 | G11: =IF(C11<>"",(F11-E11)/365,"") -> #VALUE! | H11: Hiligaynon | I11: 2 | J11: 1 | K11: 2 | L11: 2 | M11: 3 | N11: 2 | O11: 1 | P11: 3 | Q11: =IF(C11<>"",SUM(I11:P11),"") -> 16 | R11: =IF(AND(Q11>0,C11<>""),Q11/Q$9,"") -> 0.8 | S11: =IF(R11<>"",IF($R11<25%,"Emerging (Not Proficient)", IF(AND($R11 >=25%, $R11 <50%), "Emerging (Low Proficient)", IF(AND($R11 >=50%, $R11 <75%),"Developing (Nearly Proficient)",IF(AND($R11 >=75%, $R11 <85%),"Transitioning (Proficient)","At Grade Level (Highly Proficient)")))),"") -> Transitioning (Proficient) | Y11: =IF(I11/I$9>=75%,1,0) -> 1 | Z11: =IF(J11/J$9>=75%,1,0) -> 1 | AA11: =IF(K11/K$9>=75%,1,0) -> 1 | AB11: =IF(L11/L$9>=75%,1,0) -> 0 | AC11: =IF(M11/M$9>=75%,1,0) -> 1 | AD11: =IF(N11/N$9>=75%,1,0) -> 1 | AE11: =IF(O11/O$9>=75%,1,0) -> 0 | AF11: =IF(P11/P$9>=75%,1,0) -> 1
A12: 3 | B12: 117443220017 | C12: BARGASA, EDSEL JOHN. P | D12: Male | E12: 42488 | F12: 45719 | G12: =IF(C12<>"",(F12-E12)/365,"") -> 8.8520548 | H12: Hiligaynon | I12: 2 | J12: 1 | K12: 2 | L12: 3 | M12: 3 | N12: 2 | O12: 3 | P12: 3 | Q12: =IF(C12<>"",SUM(I12:P12),"") -> 19 | R12: =IF(AND(Q12>0,C12<>""),Q12/Q$9,"") -> 0.95 | S12: =IF(R12<>"",IF($R12<25%,"Emerging (Not Proficient)", IF(AND($R12 >=25%, $R12 <50%), "Emerging (Low Proficient)", IF(AND($R12 >=50%, $R12 <75%),"Developing (Nearly Proficient)",IF(AND($R12 >=75%, $R12 <85%),"Transitioning (Proficient)","At Grade Level (Highly Proficient)")))),"") -> At Grade Level (Highly Proficient) | Y12: =IF(I12/I$9>=75%,1,0) -> 1 | Z12: =IF(J12/J$9>=75%,1,0) -> 1 | AA12: =IF(K12/K$9>=75%,1,0) -> 1 | AB12: =IF(L12/L$9>=75%,1,0) -> 1 | AC12: =IF(M12/M$9>=75%,1,0) -> 1 | AD12: =IF(N12/N$9>=75%,1,0) -> 1 | AE12: =IF(O12/O$9>=75%,1,0) -> 1 | AF12: =IF(P12/P$9>=75%,1,0) -> 1
A13: 4 | B13: 117443220006 | C13: DUMANIEL, KEVIN JOHN ALVAREZ | D13: Male | E13: 10-13-2015 | F13: 45719 | G13: =IF(C13<>"",(F13-E13)/365,"") -> #VALUE! | H13: Hiligaynon | I13: 2 | J13: 1 | K13: 2 | L13: 3 | M13: 3 | N13: 2 | O13: 3 | P13: 3 | Q13: =IF(C13<>"",SUM(I13:P13),"") -> 19 | R13: =IF(AND(Q13>0,C13<>""),Q13/Q$9,"") -> 0.95 | S13: =IF(R13<>"",IF($R13<25%,"Emerging (Not Proficient)", IF(AND($R13 >=25%, $R13 <50%), "Emerging (Low Proficient)", IF(AND($R13 >=50%, $R13 <75%),"Developing (Nearly Proficient)",IF(AND($R13 >=75%, $R13 <85%),"Transitioning (Proficient)","At Grade Level (Highly Proficient)")))),"") -> At Grade Level (Highly Proficient) | Y13: =IF(I13/I$9>=75%,1,0) -> 1 | Z13: =IF(J13/J$9>=75%,1,0) -> 1 | AA13: =IF(K13/K$9>=75%,1,0) -> 1 | AB13: =IF(L13/L$9>=75%,1,0) -> 1 | AC13: =IF(M13/M$9>=75%,1,0) -> 1 | AD13: =IF(N13/N$9>=75%,1,0) -> 1 | AE13: =IF(O13/O$9>=75%,1,0) -> 1 | AF13: =IF(P13/P$9>=75%,1,0) -> 1
A14: 5 | B14: 117443220018 | C14: ESTOCADA, JOEMARIE III, OMPAD | D14: Male | E14: 05-20-2016 | F14: 45719 | G14: =IF(C14<>"",(F14-E14)/365,"") -> #VALUE! | H14: Hiligaynon | I14: 2 | J14: 1 | K14: 2 | L14: 2 | M14: 2 | N14: 1 | O14: 2 | P14: 3 | Q14: =IF(C14<>"",SUM(I14:P14),"") -> 15 | R14: =IF(AND(Q14>0,C14<>""),Q14/Q$9,"") -> 0.75 | S14: =IF(R14<>"",IF($R14<25%,"Emerging (Not Proficient)", IF(AND($R14 >=25%, $R14 <50%), "Emerging (Low Proficient)", IF(AND($R14 >=50%, $R14 <75%),"Developing (Nearly Proficient)",IF(AND($R14 >=75%, $R14 <85%),"Transitioning (Proficient)","At Grade Level (Highly Proficient)")))),"") -> Transitioning (Proficient) | Y14: =IF(I14/I$9>=75%,1,0) -> 1 | Z14: =IF(J14/J$9>=75%,1,0) -> 1 | AA14: =IF(K14/K$9>=75%,1,0) -> 1 | AB14: =IF(L14/L$9>=75%,1,0) -> 0 | AC14: =IF(M14/M$9>=75%,1,0) -> 0 | AD14: =IF(N14/N$9>=75%,1,0) -> 0 | AE14: =IF(O14/O$9>=75%,1,0) -> 0 | AF14: =IF(P14/P$9>=75%,1,0) -> 1
A15: 6 | B15: 117542220012 | C15: GO, NEAL XANDRIE, DOMANIEL | D15: Male | E15: 11-06-2015 | F15: 45720 | G15: =IF(C15<>"",(F15-E15)/365,"") -> 9.7369863 | H15: Hiligaynon | I15: 2 | J15: 1 | K15: 2 | L15: 3 | M15: 3 | N15: 2 | O15: 3 | P15: 2 | Q15: =IF(C15<>"",SUM(I15:P15),"") -> 18 | R15: =IF(AND(Q15>0,C15<>""),Q15/Q$9,"") -> 0.9 | S15: =IF(R15<>"",IF($R15<25%,"Emerging (Not Proficient)", IF(AND($R15 >=25%, $R15 <50%), "Emerging (Low Proficient)", IF(AND($R15 >=50%, $R15 <75%),"Developing (Nearly Proficient)",IF(AND($R15 >=75%, $R15 <85%),"Transitioning (Proficient)","At Grade Level (Highly Proficient)")))),"") -> At Grade Level (Highly Proficient) | Y15: =IF(I15/I$9>=75%,1,0) -> 1 | Z15: =IF(J15/J$9>=75%,1,0) -> 1 | AA15: =IF(K15/K$9>=75%,1,0) -> 1 | AB15: =IF(L15/L$9>=75%,1,0) -> 1 | AC15: =IF(M15/M$9>=75%,1,0) -> 1 | AD15: =IF(N15/N$9>=75%,1,0) -> 1 | AE15: =IF(O15/O$9>=75%,1,0) -> 1 | AF15: =IF(P15/P$9>=75%,1,0) -> 0
A16: 7 | B16: 117443220003 | C16: GREGORIO, JOHN MARK, ABELLAR | D16: Male | E16: 02-19-2015 | F16: 45720 | G16: =IF(C16<>"",(F16-E16)/365,"") -> #VALUE! | H16: Hiligaynon | I16: 2 | J16: 1 | K16: 2 | L16: 2 | M16: 2 | N16: 1 | O16: 2 | P16: 2 | Q16: =IF(C16<>"",SUM(I16:P16),"") -> 14 | R16: =IF(AND(Q16>0,C16<>""),Q16/Q$9,"") -> 0.7 | S16: =IF(R16<>"",IF($R16<25%,"Emerging (Not Proficient)", IF(AND($R16 >=25%, $R16 <50%), "Emerging (Low Proficient)", IF(AND($R16 >=50%, $R16 <75%),"Developing (Nearly Proficient)",IF(AND($R16 >=75%, $R16 <85%),"Transitioning (Proficient)","At Grade Level (Highly Proficient)")))),"") -> Developing (Nearly Proficient) | Y16: =IF(I16/I$9>=75%,1,0) -> 1 | Z16: =IF(J16/J$9>=75%,1,0) -> 1 | AA16: =IF(K16/K$9>=75%,1,0) -> 1 | AB16: =IF(L16/L$9>=75%,1,0) -> 0 | AC16: =IF(M16/M$9>=75%,1,0) -> 0 | AD16: =IF(N16/N$9>=75%,1,0) -> 0 | AE16: =IF(O16/O$9>=75%,1,0) -> 0 | AF16: =IF(P16/P$9>=75%,1,0) -> 0
A17: 8 | B17: 117443220005 | C17: JUMBAS, CYREL JAY, BARILLO | D17: Male | E17: 02-07-2016 | F17: 45720 | G17: =IF(C17<>"",(F17-E17)/365,"") -> 8.6767123 | H17: Hiligaynon | I17: 2 | J17: 1 | K17: 2 | L17: 3 | M17: 3 | N17: 1 | O17: 2 | P17: 3 | Q17: =IF(C17<>"",SUM(I17:P17),"") -> 17 | R17: =IF(AND(Q17>0,C17<>""),Q17/Q$9,"") -> 0.85 | S17: =IF(R17<>"",IF($R17<25%,"Emerging (Not Proficient)", IF(AND($R17 >=25%, $R17 <50%), "Emerging (Low Proficient)", IF(AND($R17 >=50%, $R17 <75%),"Developing (Nearly Proficient)",IF(AND($R17 >=75%, $R17 <85%),"Transitioning (Proficient)","At Grade Level (Highly Proficient)")))),"") -> At Grade Level (Highly Proficient) | Y17: =IF(I17/I$9>=75%,1,0) -> 1 | Z17: =IF(J17/J$9>=75%,1,0) -> 1 | AA17: =IF(K17/K$9>=75%,1,0) -> 1 | AB17: =IF(L17/L$9>=75%,1,0) -> 1 | AC17: =IF(M17/M$9>=75%,1,0) -> 1 | AD17: =IF(N17/N$9>=75%,1,0) -> 0 | AE17: =IF(O17/O$9>=75%,1,0) -> 0 | AF17: =IF(P17/P$9>=75%,1,0) -> 1
A18: 9 | B18: 117443220007 | C18: LEMORINAS, ARTHUR, BAYLON | D18: Male | E18: 03-30-2016 | F18: 45720 | G18: =IF(C18<>"",(F18-E18)/365,"") -> #VALUE! | H18: Hiligaynon | I18: 2 | J18: 1 | K18: 2 | L18: 1 | M18: 1 | N18: 1 | O18: 1 | P18: 2 | Q18: =IF(C18<>"",SUM(I18:P18),"") -> 11 | R18: =IF(AND(Q18>0,C18<>""),Q18/Q$9,"") -> 0.55 | S18: =IF(R18<>"",IF($R18<25%,"Emerging (Not Proficient)", IF(AND($R18 >=25%, $R18 <50%), "Emerging (Low Proficient)", IF(AND($R18 >=50%, $R18 <75%),"Developing (Nearly Proficient)",IF(AND($R18 >=75%, $R18 <85%),"Transitioning (Proficient)","At Grade Level (Highly Proficient)")))),"") -> Developing (Nearly Proficient) | Y18: =IF(I18/I$9>=75%,1,0) -> 1 | Z18: =IF(J18/J$9>=75%,1,0) -> 1 | AA18: =IF(K18/K$9>=75%,1,0) -> 1 | AB18: =IF(L18/L$9>=75%,1,0) -> 0 | AC18: =IF(M18/M$9>=75%,1,0) -> 0 | AD18: =IF(N18/N$9>=75%,1,0) -> 0 | AE18: =IF(O18/O$9>=75%,1,0) -> 0 | AF18: =IF(P18/P$9>=75%,1,0) -> 0
A19: 10 | B19: 117443220008 | C19: MARASIGAN,ZHENKIE NATHAN, DELA CRUZ | D19: Male | E19: 11-17-2015 | F19: 45720 | G19: =IF(C19<>"",(F19-E19)/365,"") -> #VALUE! | H19: Hiligaynon | I19: 2 | J19: 1 | K19: 2 | L19: 3 | M19: 3 | N19: 2 | O19: 3 | P19: 4 | Q19: =IF(C19<>"",SUM(I19:P19),"") -> 20 | R19: =IF(AND(Q19>0,C19<>""),Q19/Q$9,"") -> 1 | S19: =IF(R19<>"",IF($R19<25%,"Emerging (Not Proficient)", IF(AND($R19 >=25%, $R19 <50%), "Emerging (Low Proficient)", IF(AND($R19 >=50%, $R19 <75%),"Developing (Nearly Proficient)",IF(AND($R19 >=75%, $R19 <85%),"Transitioning (Proficient)","At Grade Level (Highly Proficient)")))),"") -> At Grade Level (Highly Proficient) | Y19: =IF(I19/I$9>=75%,1,0) -> 1 | Z19: =IF(J19/J$9>=75%,1,0) -> 1 | AA19: =IF(K19/K$9>=75%,1,0) -> 1 | AB19: =IF(L19/L$9>=75%,1,0) -> 1 | AC19: =IF(M19/M$9>=75%,1,0) -> 1 | AD19: =IF(N19/N$9>=75%,1,0) -> 1 | AE19: =IF(O19/O$9>=75%,1,0) -> 1 | AF19: =IF(P19/P$9>=75%,1,0) -> 1
A20: 11 | B20: 136651220284 | C20: ABRINILLO, VERONICA, SIASAT | D20: Female | E20: 09-25-2016 | F20: 45721 | G20: =IF(C20<>"",(F20-E20)/365,"") -> #VALUE! | H20: Hiligaynon | I20: 2 | J20: 1 | K20: 2 | L20: 3 | M20: 3 | N20: 2 | O20: 2 | P20: 3 | Q20: =IF(C20<>"",SUM(I20:P20),"") -> 18 | R20: =IF(AND(Q20>0,C20<>""),Q20/Q$9,"") -> 0.9 | S20: =IF(R20<>"",IF($R20<25%,"Emerging (Not Proficient)", IF(AND($R20 >=25%, $R20 <50%), "Emerging (Low Proficient)", IF(AND($R20 >=50%, $R20 <75%),"Developing (Nearly Proficient)",IF(AND($R20 >=75%, $R20 <85%),"Transitioning (Proficient)","At Grade Level (Highly Proficient)")))),"") -> At Grade Level (Highly Proficient) | Y20: =IF(I20/I$9>=75%,1,0) -> 1 | Z20: =IF(J20/J$9>=75%,1,0) -> 1 | AA20: =IF(K20/K$9>=75%,1,0) -> 1 | AB20: =IF(L20/L$9>=75%,1,0) -> 1 | AC20: =IF(M20/M$9>=75%,1,0) -> 1 | AD20: =IF(N20/N$9>=75%,1,0) -> 1 | AE20: =IF(O20/O$9>=75%,1,0) -> 0 | AF20: =IF(P20/P$9>=75%,1,0) -> 1
A21: 12 | B21: 117443220019 | C21: CARDINAL, KISHIA, - | D21: Female | E21: 01-22-2016 | F21: 45721 | G21: =IF(C21<>"",(F21-E21)/365,"") -> #VALUE! | H21: Hiligaynon | I21: 2 | J21: 1 | K21: 2 | L21: 3 | M21: 3 | N21: 2 | O21: 2 | P21: 4 | Q21: =IF(C21<>"",SUM(I21:P21),"") -> 19 | R21: =IF(AND(Q21>0,C21<>""),Q21/Q$9,"") -> 0.95 | S21: =IF(R21<>"",IF($R21<25%,"Emerging (Not Proficient)", IF(AND($R21 >=25%, $R21 <50%), "Emerging (Low Proficient)", IF(AND($R21 >=50%, $R21 <75%),"Developing (Nearly Proficient)",IF(AND($R21 >=75%, $R21 <85%),"Transitioning (Proficient)","At Grade Level (Highly Proficient)")))),"") -> At Grade Level (Highly Proficient) | Y21: =IF(I21/I$9>=75%,1,0) -> 1 | Z21: =IF(J21/J$9>=75%,1,0) -> 1 | AA21: =IF(K21/K$9>=75%,1,0) -> 1 | AB21: =IF(L21/L$9>=75%,1,0) -> 1 | AC21: =IF(M21/M$9>=75%,1,0) -> 1 | AD21: =IF(N21/N$9>=75%,1,0) -> 1 | AE21: =IF(O21/O$9>=75%,1,0) -> 0 | AF21: =IF(P21/P$9>=75%,1,0) -> 1
A22: 13 | B22: 117443220009 | C22: Cardinal, LEXIE, SUNDAYON | D22: Female | E22: 02-07-2016 | F22: 45721 | G22: =IF(C22<>"",(F22-E22)/365,"") -> 8.6794521 | H22: Hiligaynon | I22: 2 | J22: 1 | K22: 2 | L22: 3 | M22: 3 | N22: 2 | O22: 3 | P22: 4 | Q22: =IF(C22<>"",SUM(I22:P22),"") -> 20 | R22: =IF(AND(Q22>0,C22<>""),Q22/Q$9,"") -> 1 | S22: =IF(R22<>"",IF($R22<25%,"Emerging (Not Proficient)", IF(AND($R22 >=25%, $R22 <50%), "Emerging (Low Proficient)", IF(AND($R22 >=50%, $R22 <75%),"Developing (Nearly Proficient)",IF(AND($R22 >=75%, $R22 <85%),"Transitioning (Proficient)","At Grade Level (Highly Proficient)")))),"") -> At Grade Level (Highly Proficient) | Y22: =IF(I22/I$9>=75%,1,0) -> 1 | Z22: =IF(J22/J$9>=75%,1,0) -> 1 | AA22: =IF(K22/K$9>=75%,1,0) -> 1 | AB22: =IF(L22/L$9>=75%,1,0) -> 1 | AC22: =IF(M22/M$9>=75%,1,0) -> 1 | AD22: =IF(N22/N$9>=75%,1,0) -> 1 | AE22: =IF(O22/O$9>=75%,1,0) -> 1 | AF22: =IF(P22/P$9>=75%,1,0) -> 1
A23: 14 | B23: 117443220021 | C23: DIONSON, AIRA, BAUTISTA | D23: Female | E23: 04-07-2014 | F23: 45721 | G23: =IF(C23<>"",(F23-E23)/365,"") -> 10.676712 | H23: Hiligaynon | I23: 2 | J23: 1 | K23: 1 | L23: 1 | M23: 2 | N23: 2 | O23: 2 | P23: 2 | Q23: =IF(C23<>"",SUM(I23:P23),"") -> 13 | R23: =IF(AND(Q23>0,C23<>""),Q23/Q$9,"") -> 0.65 | S23: =IF(R23<>"",IF($R23<25%,"Emerging (Not Proficient)", IF(AND($R23 >=25%, $R23 <50%), "Emerging (Low Proficient)", IF(AND($R23 >=50%, $R23 <75%),"Developing (Nearly Proficient)",IF(AND($R23 >=75%, $R23 <85%),"Transitioning (Proficient)","At Grade Level (Highly Proficient)")))),"") -> Developing (Nearly Proficient) | Y23: =IF(I23/I$9>=75%,1,0) -> 1 | Z23: =IF(J23/J$9>=75%,1,0) -> 1 | AA23: =IF(K23/K$9>=75%,1,0) -> 0 | AB23: =IF(L23/L$9>=75%,1,0) -> 0 | AC23: =IF(M23/M$9>=75%,1,0) -> 0 | AD23: =IF(N23/N$9>=75%,1,0) -> 1 | AE23: =IF(O23/O$9>=75%,1,0) -> 0 | AF23: =IF(P23/P$9>=75%,1,0) -> 0
A24: 15 | C24: ESTOCADA, ANGEL, B. | D24: Female | E24: 01-14-2016 | F24: 45721 | G24: =IF(C24<>"",(F24-E24)/365,"") -> #VALUE! | H24: Hiligaynon | I24: 2 | J24: 1 | K24: 1 | L24: 3 | M24: 3 | N24: 2 | O24: 2 | P24: 3 | Q24: =IF(C24<>"",SUM(I24:P24),"") -> 17 | R24: =IF(AND(Q24>0,C24<>""),Q24/Q$9,"") -> 0.85 | S24: =IF(R24<>"",IF($R24<25%,"Emerging (Not Proficient)", IF(AND($R24 >=25%, $R24 <50%), "Emerging (Low Proficient)", IF(AND($R24 >=50%, $R24 <75%),"Developing (Nearly Proficient)",IF(AND($R24 >=75%, $R24 <85%),"Transitioning (Proficient)","At Grade Level (Highly Proficient)")))),"") -> At Grade Level (Highly Proficient) | Y24: =IF(I24/I$9>=75%,1,0) -> 1 | Z24: =IF(J24/J$9>=75%,1,0) -> 1 | AA24: =IF(K24/K$9>=75%,1,0) -> 0 | AB24: =IF(L24/L$9>=75%,1,0) -> 1 | AC24: =IF(M24/M$9>=75%,1,0) -> 1 | AD24: =IF(N24/N$9>=75%,1,0) -> 1 | AE24: =IF(O24/O$9>=75%,1,0) -> 0 | AF24: =IF(P24/P$9>=75%,1,0) -> 1
A25: 16 | B25: 117443220010 | C25: ESTOCADA, GENYZA, BACARO | D25: Female | E25: 01-04-2016 | F25: 45721 | G25: =IF(C25<>"",(F25-E25)/365,"") -> 8.9315068 | H25: Hiligaynon | I25: 2 | J25: 1 | K25: 2 | L25: 3 | M25: 3 | N25: 2 | O25: 2 | P25: 2 | Q25: =IF(C25<>"",SUM(I25:P25),"") -> 17 | R25: =IF(AND(Q25>0,C25<>""),Q25/Q$9,"") -> 0.85 | S25: =IF(R25<>"",IF($R25<25%,"Emerging (Not Proficient)", IF(AND($R25 >=25%, $R25 <50%), "Emerging (Low Proficient)", IF(AND($R25 >=50%, $R25 <75%),"Developing (Nearly Proficient)",IF(AND($R25 >=75%, $R25 <85%),"Transitioning (Proficient)","At Grade Level (Highly Proficient)")))),"") -> At Grade Level (Highly Proficient) | Y25: =IF(I25/I$9>=75%,1,0) -> 1 | Z25: =IF(J25/J$9>=75%,1,0) -> 1 | AA25: =IF(K25/K$9>=75%,1,0) -> 1 | AB25: =IF(L25/L$9>=75%,1,0) -> 1 | AC25: =IF(M25/M$9>=75%,1,0) -> 1 | AD25: =IF(N25/N$9>=75%,1,0) -> 1 | AE25: =IF(O25/O$9>=75%,1,0) -> 0 | AF25: =IF(P25/P$9>=75%,1,0) -> 0
A26: 17 | B26: 117443220011 | C26: ESTOCADA, JERCEL JANE, SIASET | D26: Female | E26: 12-05-2015 | F26: 45722 | G26: =IF(C26<>"",(F26-E26)/365,"") -> 9.8246575 | H26: Hiligaynon | I26: 2 | J26: 1 | K26: 2 | L26: 3 | M26: 3 | N26: 2 | O26: 3 | P26: 3 | Q26: =IF(C26<>"",SUM(I26:P26),"") -> 19 | R26: =IF(AND(Q26>0,C26<>""),Q26/Q$9,"") -> 0.95 | S26: =IF(R26<>"",IF($R26<25%,"Emerging (Not Proficient)", IF(AND($R26 >=25%, $R26 <50%), "Emerging (Low Proficient)", IF(AND($R26 >=50%, $R26 <75%),"Developing (Nearly Proficient)",IF(AND($R26 >=75%, $R26 <85%),"Transitioning (Proficient)","At Grade Level (Highly Proficient)")))),"") -> At Grade Level (Highly Proficient) | Y26: =IF(I26/I$9>=75%,1,0) -> 1 | Z26: =IF(J26/J$9>=75%,1,0) -> 1 | AA26: =IF(K26/K$9>=75%,1,0) -> 1 | AB26: =IF(L26/L$9>=75%,1,0) -> 1 | AC26: =IF(M26/M$9>=75%,1,0) -> 1 | AD26: =IF(N26/N$9>=75%,1,0) -> 1 | AE26: =IF(O26/O$9>=75%,1,0) -> 1 | AF26: =IF(P26/P$9>=75%,1,0) -> 1
A27: 18 | B27: 120637200024 | C27: ESTOCAD, REANNA, LLAGOSA | D27: Female | E27: 02-18-2016 | F27: 45722 | G27: =IF(C27<>"",(F27-E27)/365,"") -> #VALUE! | H27: Hiligaynon | I27: 2 | J27: 1 | K27: 2 | L27: 3 | M27: 3 | N27: 2 | O27: 2 | P27: 3 | Q27: =IF(C27<>"",SUM(I27:P27),"") -> 18 | R27: =IF(AND(Q27>0,C27<>""),Q27/Q$9,"") -> 0.9 | S27: =IF(R27<>"",IF($R27<25%,"Emerging (Not Proficient)", IF(AND($R27 >=25%, $R27 <50%), "Emerging (Low Proficient)", IF(AND($R27 >=50%, $R27 <75%),"Developing (Nearly Proficient)",IF(AND($R27 >=75%, $R27 <85%),"Transitioning (Proficient)","At Grade Level (Highly Proficient)")))),"") -> At Grade Level (Highly Proficient) | Y27: =IF(I27/I$9>=75%,1,0) -> 1 | Z27: =IF(J27/J$9>=75%,1,0) -> 1 | AA27: =IF(K27/K$9>=75%,1,0) -> 1 | AB27: =IF(L27/L$9>=75%,1,0) -> 1 | AC27: =IF(M27/M$9>=75%,1,0) -> 1 | AD27: =IF(N27/N$9>=75%,1,0) -> 1 | AE27: =IF(O27/O$9>=75%,1,0) -> 0 | AF27: =IF(P27/P$9>=75%,1,0) -> 1
A28: 19 | B28: 117443220012 | C28: ESTOCADA, RHEAN SHAN, DEMAFILES | D28: Female | E28: 02-27-2016 | F28: 45722 | G28: =IF(C28<>"",(F28-E28)/365,"") -> #VALUE! | H28: Hiligaynon | I28: 1 | J28: 1 | K28: 2 | L28: 3 | M28: 3 | N28: 1 | O28: 1 | P28: 3 | Q28: =IF(C28<>"",SUM(I28:P28),"") -> 15 | R28: =IF(AND(Q28>0,C28<>""),Q28/Q$9,"") -> 0.75 | S28: =IF(R28<>"",IF($R28<25%,"Emerging (Not Proficient)", IF(AND($R28 >=25%, $R28 <50%), "Emerging (Low Proficient)", IF(AND($R28 >=50%, $R28 <75%),"Developing (Nearly Proficient)",IF(AND($R28 >=75%, $R28 <85%),"Transitioning (Proficient)","At Grade Level (Highly Proficient)")))),"") -> Transitioning (Proficient) | Y28: =IF(I28/I$9>=75%,1,0) -> 0 | Z28: =IF(J28/J$9>=75%,1,0) -> 1 | AA28: =IF(K28/K$9>=75%,1,0) -> 1 | AB28: =IF(L28/L$9>=75%,1,0) -> 1 | AC28: =IF(M28/M$9>=75%,1,0) -> 1 | AD28: =IF(N28/N$9>=75%,1,0) -> 0 | AE28: =IF(O28/O$9>=75%,1,0) -> 0 | AF28: =IF(P28/P$9>=75%,1,0) -> 1
A29: 20 | B29: 117443220020 | C29: LABANZA, HOPE ANGELAINE, - | D29: Female | E29: 08-30-2016 | F29: 45722 | G29: =IF(C29<>"",(F29-E29)/365,"") -> #VALUE! | H29: Hiligaynon | I29: 1 | J29: 1 | K29: 2 | L29: 3 | M29: 3 | N29: 1 | O29: 2 | P29: 1 | Q29: =IF(C29<>"",SUM(I29:P29),"") -> 14 | R29: =IF(AND(Q29>0,C29<>""),Q29/Q$9,"") -> 0.7 | S29: =IF(R29<>"",IF($R29<25%,"Emerging (Not Proficient)", IF(AND($R29 >=25%, $R29 <50%), "Emerging (Low Proficient)", IF(AND($R29 >=50%, $R29 <75%),"Developing (Nearly Proficient)",IF(AND($R29 >=75%, $R29 <85%),"Transitioning (Proficient)","At Grade Level (Highly Proficient)")))),"") -> Developing (Nearly Proficient) | Y29: =IF(I29/I$9>=75%,1,0) -> 0 | Z29: =IF(J29/J$9>=75%,1,0) -> 1 | AA29: =IF(K29/K$9>=75%,1,0) -> 1 | AB29: =IF(L29/L$9>=75%,1,0) -> 1 | AC29: =IF(M29/M$9>=75%,1,0) -> 1 | AD29: =IF(N29/N$9>=75%,1,0) -> 0 | AE29: =IF(O29/O$9>=75%,1,0) -> 0 | AF29: =IF(P29/P$9>=75%,1,0) -> 0
A30: 21 | B30: 117443220013 | C30: LABANZA, JESEL, PARBA | D30: Female | E30: 02-23-2016 | F30: 45722 | G30: =IF(C30<>"",(F30-E30)/365,"") -> #VALUE! | H30: Hiligaynon | I30: 2 | J30: 1 | K30: 2 | L30: 3 | M30: 3 | N30: 1 | O30: 1 | P30: 3 | Q30: =IF(C30<>"",SUM(I30:P30),"") -> 16 | R30: =IF(AND(Q30>0,C30<>""),Q30/Q$9,"") -> 0.8 | S30: =IF(R30<>"",IF($R30<25%,"Emerging (Not Proficient)", IF(AND($R30 >=25%, $R30 <50%), "Emerging (Low Proficient)", IF(AND($R30 >=50%, $R30 <75%),"Developing (Nearly Proficient)",IF(AND($R30 >=75%, $R30 <85%),"Transitioning (Proficient)","At Grade Level (Highly Proficient)")))),"") -> Transitioning (Proficient) | Y30: =IF(I30/I$9>=75%,1,0) -> 1 | Z30: =IF(J30/J$9>=75%,1,0) -> 1 | AA30: =IF(K30/K$9>=75%,1,0) -> 1 | AB30: =IF(L30/L$9>=75%,1,0) -> 1 | AC30: =IF(M30/M$9>=75%,1,0) -> 1 | AD30: =IF(N30/N$9>=75%,1,0) -> 0 | AE30: =IF(O30/O$9>=75%,1,0) -> 0 | AF30: =IF(P30/P$9>=75%,1,0) -> 1
A31: 22 | B31: 117443220014 | C31: LANOJAN, JASHLYN KATE, JADIA | D31: Female | E31: 05-02-2016 | F31: 45722 | G31: =IF(C31<>"",(F31-E31)/365,"") -> 9.0876712 | H31: Hiligaynon | I31: 2 | J31: 1 | K31: 2 | L31: 3 | M31: 3 | N31: 2 | O31: 3 | P31: 3 | Q31: =IF(C31<>"",SUM(I31:P31),"") -> 19 | R31: =IF(AND(Q31>0,C31<>""),Q31/Q$9,"") -> 0.95 | S31: =IF(R31<>"",IF($R31<25%,"Emerging (Not Proficient)", IF(AND($R31 >=25%, $R31 <50%), "Emerging (Low Proficient)", IF(AND($R31 >=50%, $R31 <75%),"Developing (Nearly Proficient)",IF(AND($R31 >=75%, $R31 <85%),"Transitioning (Proficient)","At Grade Level (Highly Proficient)")))),"") -> At Grade Level (Highly Proficient) | Y31: =IF(I31/I$9>=75%,1,0) -> 1 | Z31: =IF(J31/J$9>=75%,1,0) -> 1 | AA31: =IF(K31/K$9>=75%,1,0) -> 1 | AB31: =IF(L31/L$9>=75%,1,0) -> 1 | AC31: =IF(M31/M$9>=75%,1,0) -> 1 | AD31: =IF(N31/N$9>=75%,1,0) -> 1 | AE31: =IF(O31/O$9>=75%,1,0) -> 1 | AF31: =IF(P31/P$9>=75%,1,0) -> 1
A32: 23 | B32: 117443220015 | C32: MANGUBAT, AMARAH DENISE, LABANZA | D32: Female | F32: 45811 | G32: =IF(C32<>"",(F32-E32)/365,"") -> 125.50959 | I32: 2 | J32: 1 | K32: 2 | L32: 3 | M32: 3 | N32: 2 | O32: 2 | P32: 2 | Q32: =IF(C32<>"",SUM(I32:P32),"") -> 17 | R32: =IF(AND(Q32>0,C32<>""),Q32/Q$9,"") -> 0.85 | S32: =IF(R32<>"",IF($R32<25%,"Emerging (Not Proficient)", IF(AND($R32 >=25%, $R32 <50%), "Emerging (Low Proficient)", IF(AND($R32 >=50%, $R32 <75%),"Developing (Nearly Proficient)",IF(AND($R32 >=75%, $R32 <85%),"Transitioning (Proficient)","At Grade Level (Highly Proficient)")))),"") -> At Grade Level (Highly Proficient) | Y32: =IF(I32/I$9>=75%,1,0) -> 1 | Z32: =IF(J32/J$9>=75%,1,0) -> 1 | AA32: =IF(K32/K$9>=75%,1,0) -> 1 | AB32: =IF(L32/L$9>=75%,1,0) -> 1 | AC32: =IF(M32/M$9>=75%,1,0) -> 1 | AD32: =IF(N32/N$9>=75%,1,0) -> 1 | AE32: =IF(O32/O$9>=75%,1,0) -> 0 | AF32: =IF(P32/P$9>=75%,1,0) -> 0
A33: 24 | B33: 117443220016 | C33: SUMOLAY, GRACE ANN, ESPARTERO | D33: Female | E33: 42319 | G33: =IF(C33<>"",(F33-E33)/365,"") -> -115.94247 | I33: 2 | J33: 1 | K33: 2 | L33: 3 | M33: 3 | N33: 2 | O33: 3 | P33: 3 | Q33: =IF(C33<>"",SUM(I33:P33),"") -> 19 | R33: =IF(AND(Q33>0,C33<>""),Q33/Q$9,"") -> 0.95 | S33: =IF(R33<>"",IF($R33<25%,"Emerging (Not Proficient)", IF(AND($R33 >=25%, $R33 <50%), "Emerging (Low Proficient)", IF(AND($R33 >=50%, $R33 <75%),"Developing (Nearly Proficient)",IF(AND($R33 >=75%, $R33 <85%),"Transitioning (Proficient)","At Grade Level (Highly Proficient)")))),"") -> At Grade Level (Highly Proficient) | Y33: =IF(I33/I$9>=75%,1,0) -> 1 | Z33: =IF(J33/J$9>=75%,1,0) -> 1 | AA33: =IF(K33/K$9>=75%,1,0) -> 1 | AB33: =IF(L33/L$9>=75%,1,0) -> 1 | AC33: =IF(M33/M$9>=75%,1,0) -> 1 | AD33: =IF(N33/N$9>=75%,1,0) -> 1 | AE33: =IF(O33/O$9>=75%,1,0) -> 1 | AF33: =IF(P33/P$9>=75%,1,0) -> 1
A34: 25 | B34: 117692220048 | C34: TAPIC, KYZYL ZYNN MJ.- | D34: Female | E34: 42957 | G34: =IF(C34<>"",(F34-E34)/365,"") -> -117.69041 | I34: 2 | J34: 1 | K34: 2 | L34: 2 | M34: 2 | N34: 2 | O34: 3 | P34: 2 | Q34: =IF(C34<>"",SUM(I34:P34),"") -> 16 | R34: =IF(AND(Q34>0,C34<>""),Q34/Q$9,"") -> 0.8 | S34: =IF(R34<>"",IF($R34<25%,"Emerging (Not Proficient)", IF(AND($R34 >=25%, $R34 <50%), "Emerging (Low Proficient)", IF(AND($R34 >=50%, $R34 <75%),"Developing (Nearly Proficient)",IF(AND($R34 >=75%, $R34 <85%),"Transitioning (Proficient)","At Grade Level (Highly Proficient)")))),"") -> Transitioning (Proficient) | Y34: =IF(I34/I$9>=75%,1,0) -> 1 | Z34: =IF(J34/J$9>=75%,1,0) -> 1 | AA34: =IF(K34/K$9>=75%,1,0) -> 1 | AB34: =IF(L34/L$9>=75%,1,0) -> 0 | AC34: =IF(M34/M$9>=75%,1,0) -> 0 | AD34: =IF(N34/N$9>=75%,1,0) -> 1 | AE34: =IF(O34/O$9>=75%,1,0) -> 1 | AF34: =IF(P34/P$9>=75%,1,0) -> 0
A35: 26 | G35: =IF(C35<>"",(F35-E35)/365,"") | Q35: =IF(C35<>"",SUM(I35:P35),"") | R35: =IF(AND(Q35>0,C35<>""),Q35/Q$9,"") | S35: =IF(R35<>"",IF($R35<25%,"Emerging (Not Proficient)", IF(AND($R35 >=25%, $R35 <50%), "Emerging (Low Proficient)", IF(AND($R35 >=50%, $R35 <75%),"Developing (Nearly Proficient)",IF(AND($R35 >=75%, $R35 <85%),"Transitioning (Proficient)","At Grade Level (Highly Proficient)")))),"") | Y35: =IF(I35/I$9>=75%,1,0) -> 0 | Z35: =IF(J35/J$9>=75%,1,0) -> 0 | AA35: =IF(K35/K$9>=75%,1,0) -> 0 | AB35: =IF(L35/L$9>=75%,1,0) -> 0 | AC35: =IF(M35/M$9>=75%,1,0) -> 0 | AD35: =IF(N35/N$9>=75%,1,0) -> 0 | AE35: =IF(O35/O$9>=75%,1,0) -> 0 | AF35: =IF(P35/P$9>=75%,1,0) -> 0
A36: 27 | G36: =IF(C36<>"",(F36-E36)/365,"") | Q36: =IF(C36<>"",SUM(I36:P36),"") | R36: =IF(AND(Q36>0,C36<>""),Q36/Q$9,"") | S36: =IF(R36<>"",IF($R36<25%,"Emerging (Not Proficient)", IF(AND($R36 >=25%, $R36 <50%), "Emerging (Low Proficient)", IF(AND($R36 >=50%, $R36 <75%),"Developing (Nearly Proficient)",IF(AND($R36 >=75%, $R36 <85%),"Transitioning (Proficient)","At Grade Level (Highly Proficient)")))),"") | Y36: =IF(I36/I$9>=75%,1,0) -> 0 | Z36: =IF(J36/J$9>=75%,1,0) -> 0 | AA36: =IF(K36/K$9>=75%,1,0) -> 0 | AB36: =IF(L36/L$9>=75%,1,0) -> 0 | AC36: =IF(M36/M$9>=75%,1,0) -> 0 | AD36: =IF(N36/N$9>=75%,1,0) -> 0 | AE36: =IF(O36/O$9>=75%,1,0) -> 0 | AF36: =IF(P36/P$9>=75%,1,0) -> 0
A37: 28 | G37: =IF(C37<>"",(F37-E37)/365,"") | Q37: =IF(C37<>"",SUM(I37:P37),"") | R37: =IF(AND(Q37>0,C37<>""),Q37/Q$9,"") | S37: =IF(R37<>"",IF($R37<25%,"Emerging (Not Proficient)", IF(AND($R37 >=25%, $R37 <50%), "Emerging (Low Proficient)", IF(AND($R37 >=50%, $R37 <75%),"Developing (Nearly Proficient)",IF(AND($R37 >=75%, $R37 <85%),"Transitioning (Proficient)","At Grade Level (Highly Proficient)")))),"") | Y37: =IF(I37/I$9>=75%,1,0) -> 0 | Z37: =IF(J37/J$9>=75%,1,0) -> 0 | AA37: =IF(K37/K$9>=75%,1,0) -> 0 | AB37: =IF(L37/L$9>=75%,1,0) -> 0 | AC37: =IF(M37/M$9>=75%,1,0) -> 0 | AD37: =IF(N37/N$9>=75%,1,0) -> 0 | AE37: =IF(O37/O$9>=75%,1,0) -> 0 | AF37: =IF(P37/P$9>=75%,1,0) -> 0
A38: 29 | G38: =IF(C38<>"",(F38-E38)/365,"") | Q38: =IF(C38<>"",SUM(I38:P38),"") | R38: =IF(AND(Q38>0,C38<>""),Q38/Q$9,"") | S38: =IF(R38<>"",IF($R38<25%,"Emerging (Not Proficient)", IF(AND($R38 >=25%, $R38 <50%), "Emerging (Low Proficient)", IF(AND($R38 >=50%, $R38 <75%),"Developing (Nearly Proficient)",IF(AND($R38 >=75%, $R38 <85%),"Transitioning (Proficient)","At Grade Level (Highly Proficient)")))),"") | Y38: =IF(I38/I$9>=75%,1,0) -> 0 | Z38: =IF(J38/J$9>=75%,1,0) -> 0 | AA38: =IF(K38/K$9>=75%,1,0) -> 0 | AB38: =IF(L38/L$9>=75%,1,0) -> 0 | AC38: =IF(M38/M$9>=75%,1,0) -> 0 | AD38: =IF(N38/N$9>=75%,1,0) -> 0 | AE38: =IF(O38/O$9>=75%,1,0) -> 0 | AF38: =IF(P38/P$9>=75%,1,0) -> 0
A39: 30 | G39: =IF(C39<>"",(F39-E39)/365,"") | Q39: =IF(C39<>"",SUM(I39:P39),"") | R39: =IF(AND(Q39>0,C39<>""),Q39/Q$9,"") | S39: =IF(R39<>"",IF($R39<25%,"Emerging (Not Proficient)", IF(AND($R39 >=25%, $R39 <50%), "Emerging (Low Proficient)", IF(AND($R39 >=50%, $R39 <75%),"Developing (Nearly Proficient)",IF(AND($R39 >=75%, $R39 <85%),"Transitioning (Proficient)","At Grade Level (Highly Proficient)")))),"") | Y39: =IF(I39/I$9>=75%,1,0) -> 0 | Z39: =IF(J39/J$9>=75%,1,0) -> 0 | AA39: =IF(K39/K$9>=75%,1,0) -> 0 | AB39: =IF(L39/L$9>=75%,1,0) -> 0 | AC39: =IF(M39/M$9>=75%,1,0) -> 0 | AD39: =IF(N39/N$9>=75%,1,0) -> 0 | AE39: =IF(O39/O$9>=75%,1,0) -> 0 | AF39: =IF(P39/P$9>=75%,1,0) -> 0
A40: 31 | G40: =IF(C40<>"",(F40-E40)/365,"") | Q40: =IF(C40<>"",SUM(I40:P40),"") | R40: =IF(AND(Q40>0,C40<>""),Q40/Q$9,"") | S40: =IF(R40<>"",IF($R40<25%,"Emerging (Not Proficient)", IF(AND($R40 >=25%, $R40 <50%), "Emerging (Low Proficient)", IF(AND($R40 >=50%, $R40 <75%),"Developing (Nearly Proficient)",IF(AND($R40 >=75%, $R40 <85%),"Transitioning (Proficient)","At Grade Level (Highly Proficient)")))),"") | Y40: =IF(I40/I$9>=75%,1,0) -> 0 | Z40: =IF(J40/J$9>=75%,1,0) -> 0 | AA40: =IF(K40/K$9>=75%,1,0) -> 0 | AB40: =IF(L40/L$9>=75%,1,0) -> 0 | AC40: =IF(M40/M$9>=75%,1,0) -> 0 | AD40: =IF(N40/N$9>=75%,1,0) -> 0 | AE40: =IF(O40/O$9>=75%,1,0) -> 0 | AF40: =IF(P40/P$9>=75%,1,0) -> 0
A41: 32 | G41: =IF(C41<>"",(F41-E41)/365,"") | Q41: =IF(C41<>"",SUM(I41:P41),"") | R41: =IF(AND(Q41>0,C41<>""),Q41/Q$9,"") | S41: =IF(R41<>"",IF($R41<25%,"Emerging (Not Proficient)", IF(AND($R41 >=25%, $R41 <50%), "Emerging (Low Proficient)", IF(AND($R41 >=50%, $R41 <75%),"Developing (Nearly Proficient)",IF(AND($R41 >=75%, $R41 <85%),"Transitioning (Proficient)","At Grade Level (Highly Proficient)")))),"") | Y41: =IF(I41/I$9>=75%,1,0) -> 0 | Z41: =IF(J41/J$9>=75%,1,0) -> 0 | AA41: =IF(K41/K$9>=75%,1,0) -> 0 | AB41: =IF(L41/L$9>=75%,1,0) -> 0 | AC41: =IF(M41/M$9>=75%,1,0) -> 0 | AD41: =IF(N41/N$9>=75%,1,0) -> 0 | AE41: =IF(O41/O$9>=75%,1,0) -> 0 | AF41: =IF(P41/P$9>=75%,1,0) -> 0
A42: 33 | G42: =IF(C42<>"",(F42-E42)/365,"") | Q42: =IF(C42<>"",SUM(I42:P42),"") | R42: =IF(AND(Q42>0,C42<>""),Q42/Q$9,"") | S42: =IF(R42<>"",IF($R42<25%,"Emerging (Not Proficient)", IF(AND($R42 >=25%, $R42 <50%), "Emerging (Low Proficient)", IF(AND($R42 >=50%, $R42 <75%),"Developing (Nearly Proficient)",IF(AND($R42 >=75%, $R42 <85%),"Transitioning (Proficient)","At Grade Level (Highly Proficient)")))),"") | Y42: =IF(I42/I$9>=75%,1,0) -> 0 | Z42: =IF(J42/J$9>=75%,1,0) -> 0 | AA42: =IF(K42/K$9>=75%,1,0) -> 0 | AB42: =IF(L42/L$9>=75%,1,0) -> 0 | AC42: =IF(M42/M$9>=75%,1,0) -> 0 | AD42: =IF(N42/N$9>=75%,1,0) -> 0 | AE42: =IF(O42/O$9>=75%,1,0) -> 0 | AF42: =IF(P42/P$9>=75%,1,0) -> 0
...

Sheet List
B1: Region | C1: Language
B2: NCR | C2: Agta | F2: Akeanon
B3: CAR | C3: Akeanon | F3: Bahasa Sug
B4: Region I | C4: Bahasa Sug | F4: Central Bikol
B5: Region II | C5: Bikol Libon | F5: Chavacano
B6: Region III | C6: Buhi-non | F6: Hiligaynon
B7: Region IV-A | C7: Caluyanen | F7: Ibanag
B8: Region IV-B | C8: Central Bikol | F8: Ilocano
B9: Region V | C9: Chavacano | F9: Ivatan
B10: Region VI | C10: Cuyonon | F10: Kapampangan
B11: Region VII | C11: English | F11: Kinaray-a
B12: Region VIII | C12: Hiligaynon | F12: Magindanawn
B13: Region IX | C13: Ibanag | F13: Meranaw
... B18: BARMM | C18: Ivatan | F18: Tagalog
C19: Kankanaey | F19: Waray
C20: Kapampangan | F20: Yakan
C21: Kinaray-a
C22: Magindanawn
C23: Meranaw
C24: Minasbate
C25: Miraya
C26: Northern Catanduanes
C27: Northern Sorsoganon
C28: Pangasinan
C29: Rinconada
C30: Sambal
C31: Sinama
C32: Sinugbuanong Binisaya
... C40: Other MT

Sheet Class Summary
A2: GRADE 3 Assessment Scoresheet (CLASS SUMMARY)
A5: SCHOOL ID : | B5: ='G3 RMA Scoresheet'!$C$6 -> 117443 | D5: Total Enrolment : | E5: =F14 -> 25 | G5: Total Assessed : | H5: =E14 -> 25
A6: SCHOOL NAME: | B6: ='G3 RMA Scoresheet'!$F$6 -> ROMANA ELEMENTARY SCHOOL | D6: LOI / MOI | E6: {='G3 RMA Scoresheet'!$K$6:$K$6} -> 0
A8: Grade | D8: Language Matched ( LOI vs Learners) | E8: Number of Learners Assessed | F8: Total Enrolment | G8: Number of Learners Assessed | L8: Number of Learners with Percentage Score >=75% | W8: Overall Score Average
B9: Section | C9: Sex | G9: Emerging (Not Proficient) | H9: Emerging (Low Proficient) | I9: Developing (Nearly Proficient) | J9: Transitioning (Proficient) | K9: At Grade Level (Highly Proficient) | L9: Task A | M9: Task B | N9: Task C | O9: Task D | P9: Task E | Q9: Task F | R9: Task G | S9: Task H
L10: ='G3 RMA Scoresheet'!I9 -> 2 | M10: ='G3 RMA Scoresheet'!J9 -> 1 | N10: ='G3 RMA Scoresheet'!K9 -> 2 | O10: ='G3 RMA Scoresheet'!L9 -> 3 | P10: ='G3 RMA Scoresheet'!M9 -> 3 | Q10: ='G3 RMA Scoresheet'!N9 -> 2 | R10: ='G3 RMA Scoresheet'!O9 -> 3 | S10: ='G3 RMA Scoresheet'!P9 -> 4 | W10: ='G3 RMA Scoresheet'!Q9 -> 20
A11: Grade 3 | B11: =IF('G3 RMA Scoresheet'!K7<>"",'G3 RMA Scoresheet'!K7,"") -> 1 | C11: Male | D11: =COUNTIFS('G3 RMA Scoresheet'!$D$10:$D$109,$C11,'G3 RMA Scoresheet'!$H$10:$H$109,$E$6) -> 0 | E11: =COUNTIF('G3 RMA Scoresheet'!$D$10:$D$109,"Male") -> 10 | F11: ='G3 RMA Scoresheet'!O6 -> 10 | G11: =COUNTIFS('G3 RMA Scoresheet'!$D$10:$D$109,"Male",'G3 RMA Scoresheet'!$S$10:$S$109,G$9) -> 0 | H11: =COUNTIFS('G3 RMA Scoresheet'!$D$10:$D$109,"Male",'G3 RMA Scoresheet'!$S$10:$S$109,H$9) -> 0 | I11: =COUNTIFS('G3 RMA Scoresheet'!$D$10:$D$109,"Male",'G3 RMA Scoresheet'!$S$10:$S$109,I$9) -> 2 | J11: =COUNTIFS('G3 RMA Scoresheet'!$D$10:$D$109,"Male",'G3 RMA Scoresheet'!$S$10:$S$109,J$9) -> 2 | K11: =COUNTIFS('G3 RMA Scoresheet'!$D$10:$D$109,"Male",'G3 RMA Scoresheet'!$S$10:$S$109,K$9) -> 6 | L11: =COUNTIFS('G3 RMA Scoresheet'!$D$10:$D$109,"Male",'G3 RMA Scoresheet'!Y$10:Y$109,1) -> 10 | M11: =COUNTIFS('G3 RMA Scoresheet'!$D$10:$D$109,"Male",'G3 RMA Scoresheet'!Z$10:Z$109,1) -> 10 | N11: =COUNTIFS('G3 RMA Scoresheet'!$D$10:$D$109,"Male",'G3 RMA Scoresheet'!AA$10:AA$109,1) -> 10 | O11: =COUNTIFS('G3 RMA Scoresheet'!$D$10:$D$109,"Male",'G3 RMA Scoresheet'!AB$10:AB$109,1) -> 6 | P11: =COUNTIFS('G3 RMA Scoresheet'!$D$10:$D$109,"Male",'G3 RMA Scoresheet'!AC$10:AC$109,1) -> 7 | Q11: =COUNTIFS('G3 RMA Scoresheet'!$D$10:$D$109,"Male",'G3 RMA Scoresheet'!AD$10:AD$109,1) -> 6 | R11: =COUNTIFS('G3 RMA Scoresheet'!$D$10:$D$109,"Male",'G3 RMA Scoresheet'!AE$10:AE$109,1) -> 4 | S11: =COUNTIFS('G3 RMA Scoresheet'!$D$10:$D$109,"Male",'G3 RMA Scoresheet'!AF$10:AF$109,1) -> 7 | W11: =IFERROR(AVERAGEIFS('G3 RMA Scoresheet'!Q$10:Q$109,'G3 RMA Scoresheet'!$D$10:$D$109,$C11),"") -> 16.6
A12: =A11 -> Grade 3 | B12: =B11 -> 1 | C12: Female | D12: =COUNTIFS('G3 RMA Scoresheet'!$D$10:$D$109,$C12,'G3 RMA Scoresheet'!$H$10:$H$109,$E$6) -> 0 | E12: =COUNTIF('G3 RMA Scoresheet'!$D$10:$D$109,"Female") -> 15 | F12: ='G3 RMA Scoresheet'!O7 -> 15 | G12: =COUNTIFS('G3 RMA Scoresheet'!$D$10:$D$109,"Female",'G3 RMA Scoresheet'!$S$10:$S$109,G$9) -> 0 | H12: =COUNTIFS('G3 RMA Scoresheet'!$D$10:$D$109,"Female",'G3 RMA Scoresheet'!$S$10:$S$109,H$9) -> 0 | I12: =COUNTIFS('G3 RMA Scoresheet'!$D$10:$D$109,"Female",'G3 RMA Scoresheet'!$S$10:$S$109,I$9) -> 2 | J12: =COUNTIFS('G3 RMA Scoresheet'!$D$10:$D$109,"Female",'G3 RMA Scoresheet'!$S$10:$S$109,J$9) -> 3 | K12: =COUNTIFS('G3 RMA Scoresheet'!$D$10:$D$109,"Female",'G3 RMA Scoresheet'!$S$10:$S$109,K$9) -> 10 | L12: =COUNTIFS('G3 RMA Scoresheet'!$D$10:$D$109,"Female",'G3 RMA Scoresheet'!Y$10:Y$109,1) -> 13 | M12: =COUNTIFS('G3 RMA Scoresheet'!$D$10:$D$109,"Female",'G3 RMA Scoresheet'!Z$10:Z$109,1) -> 15 | N12: =COUNTIFS('G3 RMA Scoresheet'!$D$10:$D$109,"Female",'G3 RMA Scoresheet'!AA$10:AA$109,1) -> 13 | O12: =COUNTIFS('G3 RMA Scoresheet'!$D$10:$D$109,"Female",'G3 RMA Scoresheet'!AB$10:AB$109,1) -> 13 | P12: =COUNTIFS('G3 RMA Scoresheet'!$D$10:$D$109,"Female",'G3 RMA Scoresheet'!AC$10:AC$109,1) -> 13 | Q12: =COUNTIFS('G3 RMA Scoresheet'!$D$10:$D$109,"Female",'G3 RMA Scoresheet'!AD$10:AD$109,1) -> 12 | R12: =COUNTIFS('G3 RMA Scoresheet'!$D$10:$D$109,"Female",'G3 RMA Scoresheet'!AE$10:AE$109,1) -> 5 | S12: =COUNTIFS('G3 RMA Scoresheet'!$D$10:$D$109,"Female",'G3 RMA Scoresheet'!AF$10:AF$109,1) -> 10 | W12: =IFERROR(AVERAGEIFS('G3 RMA Scoresheet'!Q$10:Q$109,'G3 RMA Scoresheet'!$D$10:$D$109,$C12),"") -> 17.133333
A14: =A12 -> Grade 3 | B14: =B12 -> 1 | C14: Total | D14: =D11+D12 -> 0 | E14: =E11+E12 -> 25 | F14: =F11+F12 -> 25 | G14: =G11+G12 -> 0 | H14: =H11+H12 -> 0 | I14: =I11+I12 -> 4 | J14: =J11+J12 -> 5 | K14: =K11+K12 -> 16 | ... S14: =S11+S12 -> 17 | W14: =IFERROR(AVERAGE('G3 RMA Scoresheet'!Q$10:Q$109),"") -> 16.92
A17: Dashboard | C17: Percent (%) of Learners at each proficiency level | L17: Percentage of Learners Who Passed 75% (Proficient) by Grade Level
A18: Sex | B18: Percent of Learners assessed | C18: Emerging (Not Proficient) | D18: Emerging (Low Proficient) | E18: Developing (Nearly Proficient) | F18: Transitioning (Proficient) | G18: At Grade Level (Highly Proficient) | K18: Sex | L18: Task A | M18: Task B | N18: Task C | O18: Task D | P18: Task E | Q18: Task F | R18: Task G | S18: Task H | W18: Overall Score
A19: Male | B19: =IFERROR(E11/$E$5,"") -> 0.4 | C19: =IFERROR(G11/$E$11,"") -> 0 | D19: =IFERROR(H11/$E$11,"") -> 0 | E19: =IFERROR(I11/$E$11,"") -> 0.2 | F19: =IFERROR(J11/$E$11,"") -> 0.2 | G19: =IFERROR(K11/$E$11,"") -> 0.6 | I19: =IFERROR(#REF!/$I$11,"") | K19: Male | L19: =IFERROR(L11/$E$11,"") -> 1 | M19: =IFERROR(M11/$E$11,"") -> 1 | N19: =IFERROR(N11/$E$11,"") -> 1 | O19: =IFERROR(O11/$E$11,"") -> 0.6 | P19: =IFERROR(P11/$E$11,"") -> 0.7 | Q19: =IFERROR(Q11/$E$11,"") -> 0.6 | R19: =IFERROR(R11/$E$11,"") -> 0.4 | S19: =IFERROR(S11/$E$11,"") -> 0.7 | W19: =IFERROR(W11/W$10,"") -> 0.83 | X19: =IFERROR(X11/X$10,"") | Y19: =IFERROR(Y11/Y$10,"")
A20: Female | B20: =IFERROR(E12/$E$5,"") -> 0.6 | C20: =IFERROR(G12/$E$12,"") -> 0 | D20: =IFERROR(H12/$E$12,"") -> 0 | E20: =IFERROR(I12/$E$12,"") -> 0.13333333 | F20: =IFERROR(J12/$E$12,"") -> 0.2 | G20: =IFERROR(K12/$E$12,"") -> 0.66666667 | K20: Female | L20: =IFERROR(L12/$E$12,"") -> 0.86666667 | M20: =IFERROR(M12/$E$12,"") -> 1 | N20: =IFERROR(N12/$E$12,"") -> 0.86666667 | O20: =IFERROR(O12/$E$12,"") -> 0.86666667 | P20: =IFERROR(P12/$E$12,"") -> 0.86666667 | Q20: =IFERROR(Q12/$E$12,"") -> 0.8 | R20: =IFERROR(R12/$E$12,"") -> 0.33333333 | S20: =IFERROR(S12/$E$12,"") -> 0.66666667 | W20: =IFERROR(W12/W$10,"") -> 0.85666667 | X20: =IFERROR(X12/X$10,"") | Y20: =IFERROR(Y12/Y$10,"")
A21: Total | B21: =IFERROR(B19+B20,"") -> 1 | C21: =IFERROR(G14/$E14,"") -> 0 | D21: =IFERROR(H14/$E14,"") -> 0 | E21: =IFERROR(I14/$E14,"") -> 0.16 | F21: =IFERROR(J14/$E14,"") -> 0.2 | G21: =IFERROR(K14/$E14,"") -> 0.64 | K21: Total | L21: =IFERROR(L14/$E$14,"") -> 0.92 | M21: =IFERROR(M14/$E$14,"") -> 1 | N21: =IFERROR(N14/$E$14,"") -> 0.92 | O21: =IFERROR(O14/$E$14,"") -> 0.76 | P21: =IFERROR(P14/$E$14,"") -> 0.8 | Q21: =IFERROR(Q14/$E$14,"") -> 0.72 | R21: =IFERROR(R14/$E$14,"") -> 0.36 | S21: =IFERROR(S14/$E$14,"") -> 0.68 | W21: =IFERROR(W14/W$10,"") -> 0.846 | X21: =IFERROR(X14/X$10,"") | Y21: =IFERROR(Y14/Y$10,"")
