Workbook

Sheet Group 1
A1: UPSKILLING SCHOOL LEADERS FOR STRATEGIC PERFORMANCE PLANNING AND RESULTS MONITORING
B3: KRA
B4: Organizational Outcomes Alignment
B5: GAA
B6: BDEP Pillar
B7: MATATAG Pillar
A9: Objective No. ___ :
B11: Timeline
B12: Weight Allocation
B13: Performance Target
B14: Value
B15: Description
B16: Performance Measure
B17: Quality
B18: 5
B19: 4
B20: 3
B21: 2
B22: 1
B23: Efficiency
B24: 5
B25: 4
B26: 3
B27: 2
B28: 1
B29: Timeliness
B30: 5
B31: 4
B32: 3
B33: 2
B34: 1

Sheet PART I (CY 2024&SY2024-2025)
B2: OFFICE PERFORMANCE COMMITMENT AND REVIEW FORM (OPCRF) ver.Feb2025
B4: Name of Employee: | N4: Name of Rater:
B5: Position/Designation: | N5: Position:
B6: Review Period: | N6: Approving Authority:
B7: Strand/Bureau/Center/Service/Region/Division: | N7: Date of Review:
B8: Strand/Bureau/Center/Service/Region/Division Statement of Purpose:
B10: PART I-A: COMMITMENT TO ORGANIZATIONAL OUTCOMES (60%) Part I-A. Commitment to Organizational Outcomes shall capture office commitments, performance, and accomplishments based on office mandates and KRAs as reflected in the official issuance on the Compendium of Office Functions. This part shall capture the contributions of the office directly targeting the Organizational Outcomes indicated in the General Appropriation Act (GAA) Programs/Subprograms, Basic Education Development Plan (BEDP) Pillars, MATATAG Agenda priority deliverables, and other national level commitments that are aligned with and relevant to the office KRAs. Clear attribution shall be made to ensure such alignment.
B12: TO BE ACCOMPLISHED DURING PLANNING | S12: TO BE FILLED DURING EVALUATION
B13: Organizational Outcomes Alignment | F13: Objectives (based on Office Functions) | H13: Timeline | I13: Weight Allocation | J13: Performance Targets (Target Outcome/Ouput of the Bureau/Center/Service/Division aligned with the Outcome/Output Indicators in the Organizational Outcomes) | L13: Performance Measure (Quality, Efficiency, Timeliness) | M13: Rating Scale | R13: Means of Verification (MOVs) | S13: Actual Accomplishments | T13: RATING (Q,E,T) | U13: AVERAGE (QET) | V13: WEIGHTED AVERAGE
B14: Key Result Areas (KRA) (Based on Office Mandate and Functions) | C14: Organizational Outcome Attribution (Refer to the GAA Programs/Subprogram and BEDP Pillars) | J14: Value (numerical, statistical, trend) | K14: Description (expected outcome/ output/service) | M14: 5 (Outstanding) | N14: 4 (Very Satisfactory) | O14: 3 (Satisfactory) | P14: 2 (Unsatisfactory) | Q14: 1 (Poor)
C15: GAA Programs/ Subprograms | D15: BEDP Pillars | E15: MATATAG Pillars
B16: Education Human Resource Development Program | E16: X number of policies formulated, reviewed, and issued | F16: Human Resource Development | G16: Objective 1: Ensured preparation of HR policies, guidelines, and standards that are Bureau-initiated, or may be assigned by the EXECOM for issuance; compliant with PRIME-HRM standards and national guidelines geared towards competency-based HR system within the set scheduled deadline. | H16: January to December 2024 | I16: 0.35 | L16: Quality | M16: Met all 5 indicators based on the established standards in policy formulation: a. Consistent with existing laws, policies, guidelines, requirements, and data/information as may be required by law, oversight agencies, and/or DepEd b. Consistent with agency strategic directions and appropriate with DepEd context c. Compliant with DepEd guidelines on policy development process and underwent consultations and involvement of relevant management officials, personnel, and stakeholders at all governance levels d. Provided presentation materials, press release(as needed), and briefers for Directors and Executive sponsors e. Provided with complete staff work, to include implications/scenario analysis and recommendations | N16: Met 4 out of 5 indicators based on the established standards in policy formulation | O16: Met 3 out of 5 indicators based on the established standards in policy formulation | P16: Met 2 out of 5 indicators based on the established standards in policy formulation | Q16: Only 1 out of 5 indicators is met based on the established standards in policy formulation | S16: Policy deliverables submitted followed the set standards in policy formulation and met all 5 indicators | T16: 5 | U16: =AVERAGE(T16:T18) -> 4.6666667
L17: Efficiency | M17: 100% of total number of policy deliverables submitted and/or presented to the Director for approval; commented upon by such and provided responses to said comments; and/or integrated into the proposed policy action document. | N17: 76-99% of total number of policy deliverables submitted and/or presented to the Director for approval; commented upon by such and provided responses to said comments; and/or integrated into the proposed policy action document. | O17: 51-75% of total number of policy deliverables submitted and/or presented to the Director for approval; commented upon by such and provided responses to said comments; and/or integrated into the proposed policy action document. | P17: 26-50% of total number of policy deliverables submitted and/or presented to the Director for approval; commented upon by such and provided responses to said comments; and/or integrated into the proposed policy action document. | Q17: 25 %and below of total number of policy deliverables submitted and/or presented to the Director for approval; commented upon by such and provided responses to said comments; and/or integrated into the proposed policy action document. | S17: 13 out of 15 (87%) policy deliverables were submitted and/or presented to the Director and/or EXECOM for approval | T17: 4
L18: Timeliness | M18: Endorsed to the Office of the Director before the deadline set | N18: Endorsed to the Office of the Director on the deadline set | O18: Endorsed to the Office of the Director two weeks after the deadline | P18: Endorsed to the Office of the Director one month after the deadline | Q18: Endorsed to the Office of the Director more than one month | S18: 13 policy deliberables endorsed to the Office of the Director before the deadline set | T18: 5
C19: Refer to Accountability Matrix (PREXC Indicators) | D19: Refer to BMEF and BEDP 2030 | L19: Quality | U19: =AVERAGE(T19:T21) -> #DIV/0! | V19: =U19*I19 -> #DIV/0!
L20: Efficiency
L21: Timeliness
L22: Quality | U22: =AVERAGE(T22:T24) -> #DIV/0! | V22: =U22*I22 -> #DIV/0!
L23: Efficiency
L24: Timeliness
L25: Quality | U25: =AVERAGE(T25:T27) -> #DIV/0! | V25: =U25*I25 -> #DIV/0!
L26: Efficiency
L27: Timeliness
R37: Part I-A Total Score | V37: =SUM(V19:V27) -> #DIV/0!
B40: PART I-B: INNOVATING AND INTERVENING ACCOMPLISHMENTS (20%) Part I-B. Innovating and Intervening Accomplishments shall capture the outcomes/outputs of the office that are enabling, supportive, and/or contributory to the achievement of the organizational commitments and KRAs in Part I-A. Accomplishments can be innovations, interventions, and enhancements on the processes, services, and/or outputs.
B41: TO BE FILLED IN DURING PLANNING | S41: TO BE FILLED DURING EVALUATION
B42: Key Result Areas (KRA) | F42: Objectives | H42: Timeline | I42: Weight Allocation | J42: Performance Targets (Target Outcome/Ouput of the Bureau/Center/Service/Division that are enabling, supportive, and/or contributory to the achievement of the organizational outcomes and KRAs (Part I-A)) | L42: Performance Measure (Quality, Efficiency, Timeliness) | M42: RATING SCALE | R42: Means of Verification (MOVs) | S42: Actual Results/ Accomplishments | T42: RATING (Q,E,T) | U42: AVERAGE (QET) | V42: WEIGHTED AVERAGE
J43: Value (numerical, statistical, trend) | K43: Description (expected outcome/ output/service) | M43: 5 (Outstanding) | N43: 4 (Very Satisfactory) | O43: 3 (Satisfactory) | P43: 2 (Unsatisfactory) | Q43: 1 (Poor)
L44: Quality | U44: =AVERAGE(T44:T46) -> #DIV/0! | V44: =U44*I44 -> #DIV/0!
L45: Efficiency
L46: Timeliness
L47: Quality | U47: =AVERAGE(T47:T49) -> #DIV/0! | V47: =U47*I47 -> #DIV/0!
L48: Efficiency
L49: Timeliness
L50: Quality | U50: =AVERAGE(T50:T52) -> #DIV/0! | V50: =U50*I50 -> #DIV/0!
L51: Efficiency
L52: Timeliness
B71: Part I-B Total Score | V71: =SUM(V44:V52) -> #DIV/0!
B73: PART I-C: ORGANIZATIONAL EFFECTIVENESS (15%) Part I-C. Organizational Effectiveness shall capture accomplishments/outputs produced or attained on the aspects of Financial Stewardship, Process Improvement, and Client Satisfaction. It shall focus on the results achieved by the office that are aligned with the Performance-based Bonus (PBB) oversight requirements.
B75: TO BE FILLED IN DURING PLANNING | S75: TO BE FILLED DURING EVALUATION
...

Sheet PART I (CY 2025&SY2025-2026)
A2: OFFICE PERFORMANCE COMMITMENT AND REVIEW FORM (OPCRF) ver.Feb2025
A4: Name of Employee: | E4: MC WELSON C. SOLOMON | M4: Name of Rater: | N4: ROGER Z. ROCHAR, PhD
A5: Position/Designation: | E5: Head Teacher III | M5: Position: | N5: OIC-ASDS
A6: Review Period: | E6: June 2025-July 2026 | M6: Approving Authority: | N6: PORTIA MISSION MALLORCA, PhD CESO V
A7: Division: | E7: City Schools Division of Victorias | M7: Date of Rating:
A8: Division Statement of Purpose: | E8: To improve the learning outcomes of the schools in SDO Victorias City
A10: PART I-A: COMMITMENT TO ORGANIZATIONAL OUTCOMES (60%) Part I-A. Commitment to Organizational Outcomes shall capture office commitments, performance, and accomplishments based on office mandates and KRAs as reflected in the official issuance on the Compendium of Office Functions. This part shall capture the contributions of the office directly targeting the Organizational Outcomes indicated in the General Appropriation Act (GAA) Programs/Subprograms, Basic Education Development Plan (BEDP) Pillars, Current Administration Agenda, and other national level commitments that are aligned with and relevant to the office KRAs. Clear attribution shall be made to ensure such alignment.
A12: TO BE ACCOMPLISHED DURING PLANNING | R12: TO BE FILLED DURING EVALUATION
A13: Organizational Outcomes Alignment | E13: Objectives (based on Office Functions) | G13: Timeline | H13: Weight Allocation | I13: Performance Targets (Target Outcome/ Ouput of the Bureau/ Center/Service/ Division aligned with the Outcome/Output Indicators in the Organizational Outcomes) | K13: Performance Measure (Quality, Efficiency, Timeliness) | L13: Rating Scale | Q13: Means of Verification (MOVs) | R13: Actual Accomplishments | S13: RATING (Q,E,T) | T13: AVERAGE (QET) | U13: WEIGHTED AVERAGE
A14: Key Result Areas (KRA) (Based on Office Mandate and Functions) | B14: gOrganizational Outcome Attribution (Refer to the GAA Programs/Subprogram and BEDP Pillars) | I14: Value (numerical, statistical, trend) | J14: Description (expected outcome/ output/service) | L14: 5 (Outstanding) | M14: 4 (Very Satisfactory) | N14: 3 (Satisfactory) | O14: 2 (Unsatisfactory) | P14: 1 (Poor)
B15: GAA Programs/ Subprograms | C15: BEDP Pillars | D15: Current Administration Agenda
A16: KRA 1: Curriculum and Teaching | B16: *Education Policy Development Program | C16: Quality | D16: High Quality of Education | E16: 1. Accounted for learning outcomes of school vis-a-vis goals and targets (Reduced Frustration Level Learners, Reduce Non-Numerates) ----------------------- 1.1. Achieved 50% of learners At Grade Level on CRLA results | G16: June 2025-March 2026 | H16: 0.04 | I16: 1 | J16: KPI Targets, KPI within National Standard | K16: Quality | L16: Achieved 50% and above of learners At Grade Level on CRLA results | M16: Achieved 40-50% of learners At Grade Level on CRLA results | N16: Achieved 30-40% of learners At Grade Level on CRLA results | O16: Achieved 20-30% of learners At Grade Level on CRLA results | P16: Achieved 20% and below of learners At Grade Level on CRLA results | Q16: 1. CRLA Consolidated BOSY Results 2. CRLA Consolidated EOSY Results 3. CRLA Grade Level BOSY Results 4. CRLA Grade Level EOSY Results | S16: 5 | T16: =AVERAGE(S16:S21) -> 5 | U16: =T16*SUM(H16:H21) -> 0.2
K20: Efficiency | L20: Submitted CRLA results and supported by all of the MOVs | M20: Submitted CRLA results and supported by any 4 of the MOVs | N20: Submitted CRLA results and supported by any 3 of the MOV | O20: Submitted CRLA results and supported by any 2 of the MOV | P20: Submitted CRLA results and supported by any 1 of the MOVs | S20: 5
K21: Timeliness | L21: Submitted on or before due date | M21: Submitted 1–2 days working days after due date | N21: Submitted 3–4 days working days after due date | O21: Submitted 5–6 days working days after due date | P21: Submitted 7–8 days working days after due date | S21: 5
E22: 1.2. Achieved 50% of learners at Independent Level in Phil-IRI Filipino Results | H22: 0.03 | K22: Quality | L22: Achieved 50% and above of learners at Independent Level in Phil-IRI Filipino Results. | M22: Achieved 40-50% of learners at Independent Level in Phil-IRI Filipino Results. | N22: Achieved 30-40% of learners at Independent Level in Phil-IRI Filipino Results. | O22: Achieved 20-30% of learners at Independent Level in Phil-IRI Filipino Results. | P22: Achieved 20% and below of learners at Independent Level in Phil-IRI Filipino Results. | Q22: 1. Phil-IRI Filipino Consolidated BOSY Results 2.Phil-IRI Filipino Consolidated EOSY Results 3. Phil-IRI Filipino Grade Level BOSY Results 4. Phil-IRI Filipino Grade Level EOSY Results | T22: =AVERAGE(S22:S24) -> #DIV/0! | U22: =T22*SUM(H22:H24) -> #DIV/0!
K23: Efficiency | L23: Submitted Phil-IRI Filipino results and supported by all of the MOVs | M23: Submitted Phil-IRI Filipino results and supported by any 4 of the MOVs | N23: Submitted Phil-IRI Filipino results and supported by any 3 of the MOV | O23: Submitted Phil-IRI Filipino results and supported by any 2 of the MOV | P23: Submitted Phil-IRI Filipino results and supported by any 1 of the MOVs
K24: Timeliness | L24: Submitted on or before due date | M24: Submitted 1–2 days working days after due date | N24: Submitted 3–4 days working days after due date | O24: Submitted 5–6 days working days after due date | P24: Submitted 7–8 days working days after due date
E25: 1.3. Achieved 50% of learners at Independent Level in Phil-IRI English Results | H25: 0.03 | K25: Quality | L25: Achieved 50% and above of learners at Independent Level in Phil-IRI English Results. | M25: Achieved 40-50% of learners at Independent Level in Phil-IRI English Results. | N25: Achieved 30-40% of learners at Independent Level in Phil-IRI English Results. | O25: Achieved 20-30% of learners at Independent Level in Phil-IRI English Results. | P25: Achieved 20% and below of learners at Independent Level in Phil-IRI English Results. | Q25: 1. Phil-IRI English Consolidated BOSY Results 2. Phil-IRI English Consolidated EOSY Results 3. Phil-IRI English Grade Level BOSY Results 4. Phil-IRI English Grade Level EOSY Results | T25: =AVERAGE(S25:S27) -> #DIV/0! | U25: =T25*SUM(H25:H27) -> #DIV/0!
K26: Efficiency | L26: Submitted Phil-IRI English results and supported by all of the MOVs | M26: Submitted Phil-IRI English results and supported by any 4 of the MOVs | N26: Submitted Phil-IRI English results and supported by any 3 of the MOV | O26: Submitted Phil-IRI English results and supported by any 2 of the MOV | P26: Submitted Phil-IRI English results and supported by any 1 of the MOVs
K27: Timeliness | L27: Submitted on or before due date | M27: Submitted 1–2 days working days after due date | N27: Submitted 3–4 days working days after due date | O27: Submitted 5–6 days working days after due date | P27: Submitted 7–8 days working days after due date
E28: 1.4. Achieved 50% of learners at Proficient and Highly Proficient Level in RMA Results | H28: 0.02 | K28: Quality | L28: Achieved 50% and above of learners at Proficient and Highly Proficient Level in RMA Results | M28: Achieved 40-50% of learners at Proficient and Highly Proficient Level in RMA Results | N28: Achieved 30-40% of learners at Proficient and Highly Proficient Level in RMA Results | O28: Achieved 20-30% and of learners at Proficient and Highly Proficient Level in RMA Results | P28: Achieved 20% and below of learners at Proficient and Highly Proficient Level in RMA Results | Q28: 1. RMA Consolidated BOSY Results 2. RMA Consolidated EOSY Results 3. RMA Grade Level BOSY Results 4. RMA Grade Level EOSY Results | T28: =AVERAGE(S28:S30) -> #DIV/0! | U28: =T28*SUM(H28:H30) -> #DIV/0!
K29: Efficiency | L29: Submitted RMA results and supported by all of the MOVs | M29: Submitted RMA results and supported by any 4 of the MOVs | N29: Submitted RMA results and supported by any 3 of the MOV | O29: Submitted RMA results and supported by any 2 of the MOV | P29: Submitted RMA results and supported by any 1 of the MOVs
K30: Timeliness | L30: Submitted on or before due date | M30: Submitted 1–2 days working days after due date | N30: Submitted 3–4 days working days after due date | O30: Submitted 5–6 days working days after due date | P30: Submitted 7–8 days working days after due date
B31: *Education Policy Development Program *Education Human Resource Development Program | C31: Quality | D31: *High Quality of Education *High Performing Teacher | E31: 2. Performed Instructional Supervision | G31: June 2025-March 2026 | H31: 0.04 | I31: 1 | J31: Teachers Observation | K31: Quality | L31: 100% of planned instructional supervision reflected in the ISEAP is performed. | M31: 91-99% of planned instructional supervision reflected in the ISEAP is performed. | N31: 81-90% of planned instructional supervision reflected in the ISEAP is performed. | O31: 71-80% of planned instructional supervision reflected in the ISEAP is performed. | P31: 70% and below of planned instructional supervision reflected in the ISEAP is performed. | Q31: 1. ISEAP 2. ISEAR 3. COT 4. Observation Notes/ STAR Notes | T31: =AVERAGE(S31:S33) -> #DIV/0! | U31: =T31*H31 -> #DIV/0!
K32: Efficiency | L32: Submitted ISEAP Report and supported by all of the MOVs | M32: Submitted ISEAP Report and supported by any 4 of the MOVs | N32: Submitted ISEAP Report and supported by any 3 of the MOVs | O32: Submitted ISEAP Report and supported by any 2 of the MOVs | P32: Submitted ISEAP Report and supported by any 1 of the MOVs
K33: Timeliness | L33: Submitted a week before due date | M33: Submitted 1–2 days working days after due date | N33: Submitted 3–4 days working days after due date | O33: Submitted 5–6 days working days after due date | P33: Submitted 7–8 days working days after due date
B34: *Education Policy Development Program *Inclusive Education Program | D34: *Efficient and Supportive Governance Structure | E34: 3. Achieved target learner enrolled in Kindergarten | G34: June-July 2025 | H34: 0.04 | I34: 0.18 | J34: Learners enrolled in Kindergarten | K34: Quality | L34: 9% and above increase in enrollment | M34: 7-8% increase in enrollment | N34: 5-6% increase in enrollment | O34: 3-4% increase in enrollment | P34: 1-2% increase in enrollment | Q34: 1. SF1 2. SF4 | T34: =AVERAGE(S34:S36) -> #DIV/0! | U34: =T34*H34 -> #DIV/0!
K35: Efficiency | L35: Increased 9 and above learners enrolled over the previous year | M35: Increased 7-8 learners enrolled over the previous year | N35: Increased 5-6 learners enrolled over the previous year | O35: Increased 3-4 learners enrolled over the previous year | P35: Increased 1-2 learners enrolled over the previous year
K36: Timeliness | L36: Enrolled on-time | M36: Enrolled 1 day after the scheduled date | N36: Enrolled 2 days after the scheduled date | O36: Enrolled 3 days after the scheduled date | P36: Enrolled 4 days and beyond after the scheduled date
A37: KRA 2: Learning Environment | B37: *Basic Education Input Program | C37: Enabling Mechanism/Access | D37: Learners physical and Mental well-being protected | E37: Implemented and promoted Safe and Child friendly learning and school environment for learners. | G37: January – December 2026 | H37: 0.04 | I37: 1 | J37: PAPS on Learning Environment in WFP were accomplished | K37: Quality | L37: 91% and above of the PAPS on Learning Environment in WFP were accomplished | M37: 81-90% of the PAPS on Learning Environment in WFP were accomplished | N37: 71-80% of the PAPS on Learning Environment in WFP were accomplished | O37: 61-70% of the PAPS on Learning Environment in WFP were accomplished | P37: 60% and below of the PAPS on Learning Environment in WFP were accomplished | Q37: Approved Program of Works WFP Pictures (before and after repair) | T37: =AVERAGE(S37:S39) -> #DIV/0! | U37: =T37*H37 -> #DIV/0!
K38: Efficiency | L38: 91% and above compliance with the approved Program of Works | M38: 81-90% compliance with the approved Program of Works | N38: 71-80% compliance with the approved Program of Works | O38: 61-70% compliance with the approved Program of Works | P38: 60% and below compliance with the approved Program of Works
K39: Timeliness | L39: Accomplished on time based on the target date | M39: Accomplished 15 days after the target date | N39: Accomplished 30 days after the target date | O39: Accomplished 45 days after the target date | P39: Accomplished 60 days after the target date
E40: Provided safe and child-friendly learning and school environment through the implementation of the Child Protection Policy | G40: June 2025-March 2026 | H40: 0.03 | I40: 1 | J40: Implemented the Child Protection Policy of the school | K40: Quality | L40: 91-100% resolution of cases in the CPC/Zero CPC case | M40: 86-90% resolution of cases in the CPC | N40: 81-85% resolution of cases in the CPC; | O40: 76-80% resolution of cases in the CPC | P40: 71-75% resolution of cases in the CPC | Q40: List of CPC Members Minutes of the Meeting CPC Intake Sheet Accomplishment Report | T40: =AVERAGE(S40:S42) -> #DIV/0! | U40: =T40*H40 -> #DIV/0!
K41: Efficiency | L41: All MOVs are present | M41: 3 MOVs are present | N41: 2 MOVs are present | O41: 1 MOV is present | P41: No MOV
K42: Timeliness | L42: The was implemented as scheduled | M42: The program was implemented 1 month after the scheduled date | N42: The program was implemented 2 months after the scheduled date | O42: The program was implemented 3 months after the scheduled date | P42: The program was implemented 4 months after the scheduled date
B43: Education Policy Development Program | E43: Increased the participation of learners in school activities( Intramural, Galaw Pilipinas, Nestle Wellness, Boy Scout, Girl Scout, SELG, SSG) | G43: June 2025-March 2026 | H43: 0.03 | I43: 1 | J43: Participated in school activities | K43: Quality | L43: 90%-100% learners’ participation in school activities | M43: 80%-89% learners’ participation in school activities | N43: 70%-79% learners’ participation in school activities | O43: 60%-69% learners’ participation in school activities | P43: 50%-59% learners’ participation in school activities | Q43: School Calendar of Activities Pictures (Documentation) Attendance Sheet | T43: =AVERAGE(S43:S45) -> #DIV/0! | U43: =T43*H43 -> #DIV/0!
K44: Efficiency | L44: 90%-100% learners participated actively in school activities | M44: 80%-89% learners participated actively in school activities | N44: 70%-79% learners participated actively in school activities | O44: 60%-69% learners participated actively in school activities | P44: 50%-59% learners participated actively in school activities
K45: Timeliness | L45: All school activities done without delay and on scheduled date | M45: 2-3 days delay after the scheduled date | N45: 4-5 days delay after the scheduled date | O45: 6-7 days delay after the scheduled date | P45: 8-10 days delay after the scheduled date
A46: KRA 3: Leadership | B46: Education Policy Development Program | C46: Enabling Mechanisms: Governance and Management | D46: *Efficient and Supportive Governance Structures | E46: Ensured implementation of SIP and WFP | G46: Whole year-round | H46: 0.03 | I46: 100 | J46: Number of DepEd policies and issuances implemented | K46: Quality | L46: 90-100% of the items of SIP and WFP were implemented | M46: 80-89% of the policies and issuances implemented/disseminated to 90% of teachers after a week after its release. | N46: 70-79 % of the policies and issuances implemented/disseminated to 80% of teachers after two weeks after its release. | O46: 60-69% of the policies and issuances implemented/disseminated to 70% of teachers three weeks after its release. | P46: 50% and below of the policies and issuances implemented/disseminated to 60% and below of teachers four weeks after its release. | Q46: 1. Division Issuances and Policies 2. Minutes of the Meeting 3. Attendance of the Participants 4. Supervisory Plan | T46: =AVERAGE(S46:S48) -> #DIV/0! | U46: =T46*H46 -> #DIV/0!
K47: Efficiency | L47: Policies and issuances implemented to 100% of teachers with 0-1 misinterpretation | M47: Policies and issuances implemented 90% of teachers with 2-3 misinterpretation | N47: Policies and issuances implemented 80% of teachers with 4-5 misinterpretation | O47: Policies and issuances implemented 70% of teachers with 6-7 misinterpretation | P47: Policies and issuances implemented 50% and below of teachers with 8 and above misinterpretation
...

Sheet PART II
B2: DepEd OPCRF (ver.Feb2025), page 2 of 4
B3: PART II-A: LEADERSHIP COMPETENCIES (2.5%) Part II-A. Leadership Competencies shall capture competencies expected of heads of functional offices who hold managerial and executive/supervisory positions. The Leadership Competencies expected to be demonstrated include Leading People, People Performance Management, and People Development.
B4: Competencies | C4: Behavioural Indicators | G4: Remarks/ Observations | I4: RATING | J4: AVERAGE | L4: DepEd Competencies Scale
L5: Numerical Rating | M5: Adjectival Rating | N5: Definition
B6: Leading People | C6: 1. Uses basic persuasion techniques in a discussion or presentation e.g., staff mobilization, appeals to reason and/or emotions, uses data and examples, visual aids | J6: =AVERAGE(I6:I10) -> #DIV/0! | L6: 5 | M6: Role Model | N6: Behavioral indicator is consistently exhibited and is worthy of emulation.
C7: 2. Persuades, convinces or influences others, in order to have a specific impact or effect. | L7: 4 | M7: Consistently Demonstrated | N7: Behavioral indicator is constantly shown.
C8: 3. “Sets a good example”, is a credible and respected leader; and demonstrates desired behavior. | L8: 3 | M8: Most of the Time Demonstrated | N8: Behavioral indicator is often shown.
C9: 4. Forwards personal, professional and work unit needs and interests in an issue. | L9: 2 | M9: Sometimes Demonstrated | N9: Behavioral indicator is irregularly shown.
C10: 5. Assumes a pivotal role in promoting the development of an inspiring, relevant vision for the organization and influences others to share ownership of DepEd goals, in order to create an effective work environment. | L10: 1 | M10: Rarely Demonstrated | N10: Behavioral indicator is seldom shown.
B11: People Performance Management | C11: 1. Makes specific changes in the performance management system or in own work methods to improve performance (e.g. does something better, faster, at lower cost, more efficiently; improves quality, customer satisfaction, morale, revenues). | J11: =AVERAGE(I11:I15) -> #DIV/0!
C12: 2. Sets performance standards and measures progress of employees based on office and department targets.
C13: 3. Provides feedback and technical assistance such as coaching for performance improvement and action planning.
C14: 4. States performance expectations clearly and checks understanding and commitment.
C15: 5. Performs all the stages of result-based performance management system supported by evidence and required documents/forms.
B16: People Development | C16: 1. Improves the skills and effectiveness of individuals through employing a range of development strategies. | J16: =AVERAGE(I16:I20) -> #DIV/0!
C17: 2. Facilitates workforce effectiveness through coaching and motivating/developing people within a work environment that promotes mutual trust and respect.
C18: 3. Conceptualizes and implements learning interventions to meet identified training needs.
C19: 4. Does long-term coaching or training by arranging appropriate and helpful assignments, formal training, or other experiences for the purpose of supporting a person’s learning and development.
C20: 5. Cultivates a learning environment by structuring interactive experiences such as looking for future opportunities that are in support of achieving individual career goals.
B21: Part II-A Total Score: Weighted Average (Average x 0.025) | J21: =AVERAGE(J6:J20)*0.025 -> #DIV/0!
B22: PART II-B: CORE BEHAVIOURAL COMPETENCIES (2.5%) Part II-B. Core Behavioral Competencies shall capture competencies required from all DepEd personnel in all job groups within the organization, upholding the DepEd’s core values and the Code of Conduct and Ethical Standards for Public Officials and Employees pursuant to RA 6713. They represent the way individuals embody and live the values of the organization.
B23: Competencies | C23: Behavioural Indicators | G23: Remarks/ Observations | I23: RATING | J23: AVERAGE
B25: Self-Management | C25: 1. Sets personal goals and direction, needs and development. | J25: =AVERAGE(I25:I29) -> #DIV/0!
C26: 2. Understands personal actions and behavior that are clear and purposive and takes into account personal goals and values congruent to that of the organization
C27: 3. Displays emotional maturity and enthusiasm for and is challenged by higher goals
C28: 4. Prioritize work tasks and schedules (through Gantt charts, checklists, etc.) to achieve goals
C29: 5. Sets high quality, challenging, realistic goals for self and others.
B30: Professionalism and Ethics | C30: 1. Demonstrate the values and behavior enshrined in the Norms and Conduct and Ethical Standards for Public Officials and Employees (RA 6713). | J30: =AVERAGE(I30:I34) -> #DIV/0!
C31: 2. Practice ethical and professional behavior and conduct taking into account the impact of his/her actions and decisions.
C32: 3. Maintains a professional image: being trustworthy, regularity of attendance and punctuality, good grooming and communication.
C33: 4. Makes personal sacrifices to meet the organization’s needs.
C34: 5. Act with a sense of urgency and responsibility to meet the organization’s needs, improve system and help others improve their effectiveness.
B35: Results Focus | C35: 1. Achieves results with optimal use of time and resources mist of the time. | J35: =AVERAGE(I35:I39) -> #DIV/0!
C36: 2. Avoids rework, mistakes and wastage through effective work methods by placing organizational needs before personal needs.
C37: 3. Delivers error-free outputs most of the time by conforming to standard operating procedures correctly and consistently. Able to produce very satisfactory quality of work in terms of usefulness/acceptability and completeness with no supervision required.
C38: 4. Expresses a desire to do better and may express frustration at waste or inefficiency. May focus on new or more precise ways of meeting goals set
C39: 5. Makes specific changes in the system or in own work methods to improve performance. Examples may include doing something better, faster, at a lower cost, more efficiently, or improving quality, customer satisfaction, morale, without setting any specific goal.
B40: Teamwork | C40: 1. Willingly does his/her share of responsibility | J40: =AVERAGE(I40:I44) -> #DIV/0!
C41: 2. Promotes collaboration and removes barriers to teamwork and goal accomplishment across the organization.
C42: 3. Applies negotiation principles in arriving at win-win agreements.
...

Sheet PART III
B1: DepEd OPCRF (ver.Feb2025), page 3 of 4
C2: PART III: SUMMARY OF RATINGS
C5: Final Performance Components | E5: Weight Allocation | F5: Obtained Score | G5: Overall Score | H5: RPMS Rating | M5: RPMS Rating Table
H6: Numerical Rating | I6: Adjectival Rating | M6: Range | N6: Numerical Rating | O6: Adjectival Rating
C7: PART I | D7: A. Commitment to Organizational Outcomes | E7: 0.6 | F7: ='PART I (CY 2025&SY2025-2026)'!U82 -> #DIV/0! | G7: =SUM(F$7:F$11) -> #DIV/0! | H7: =G7 -> #DIV/0! | I7: =IF(G7>=4.5, "Outstanding", IF(G7>=3.5, "Very Satisfactory", IF(G7>=2.5, "Satisfactory", IF(G7>=1.5, "Unsatisfactory", "Poor")))) -> #DIV/0! | M7: 4.500-5.000 | N7: 5 | O7: Outstanding
D8: B. Innovating and Intervening Accomplishments | E8: 0.2 | F8: ='PART I (CY 2025&SY2025-2026)'!U107 -> #DIV/0! | M8: 3.500-4.499 | N8: 4 | O8: Very Satisfactory
D9: C. Organizational Effectiveness | E9: 0.15 | F9: ='PART I (CY 2025&SY2025-2026)'!U122 -> #DIV/0! | M9: 2.500-3.499 | N9: 3 | O9: Satisfactory
C10: PART II | D10: A. Leadership Competencies | E10: 2.5% (0.125) | F10: ='PART II'!J21 -> #DIV/0! | M10: 1.500-2.499 | N10: 2 | O10: Unsatisfactory
D11: B. Core Behavioural Competencies | E11: 2.5% (0.125) | F11: ='PART II'!J55 -> #DIV/0! | M11: 1.000-1.499 | N11: 1 | O11: Poor
C13: Ratee-Rater Agreement
C15: The signatures below confirm that the employee and his/her superior have agreed to the contents of the performance as captured in this form.
C17: Name of Employee: | D17: MC WELSON C. SOLOMON | F17: Name of Superior: ROGER Z. ROCHAR, PhD
C19: Signature: | F19: Signature:
C21: Date: | F21: Date:

Sheet Sheet3

Sheet Sheet4

Sheet Sheet5

Sheet Sheet6

Sheet PART I_SampleComp
B2: OFFICE PERFORMANCE COMMITMENT AND REVIEW FORM (OPCRF) ver. Feb2025
B4: Name of Employee: REGINA N. BONDA | N4: Name of Rater: | O4: ROGER Z. ROCHAR PhD.
B5: Position/Designation: OIC PRINCIPAL | N5: Position: | O5: OIC ASDS
B6: Review Period: July 2024; July 2025 | N6: Approving Authority: | O6: PORTIA MISSION MALLORCA PhD. CESOV
B7: Strand/Bureau/Center/Service/Region/Division: SDO VICTORIAS | N7: Date of Rating | O7: 45828
B8: To improve the learning outcomes of the schools in SDO VIctorias City.
B10: PART I-A: COMMITMENT TO ORGANIZATIONAL OUTCOMES (60%) Part I-A. Commitment to Organizational Outcomes shall capture office commitments, performance, and accomplishments based on office mandates and KRAs as reflected in the official issuance on the Compendium of Office Functions. This part shall capture the contributions of the office directly targeting the Organizational Outcomes indicated in the General Appropriation Act (GAA) Programs/Subprograms, Basic Education Development Plan (BEDP) Pillars, Current Administration Agenda, and other national level commitments that are aligned with and relevant to the office KRAs. Clear attribution shall be made to ensure such alignment.
B12: TO BE ACCOMPLISHED DURING PLANNING | S12: TO BE FILLED DURING EVALUATION
B13: Organizational Outcomes Alignment | F13: Objectives (based on Office Functions) | H13: Timeline | I13: Weight Allocation | J13: Performance Targets (Target Outcome/Ouput of the Bureau/Center/Service/Division aligned with the Outcome/Output Indicators in the Organizational Outcomes) | L13: Performance Measure (Quality, Efficiency, Timeliness) | M13: Rating Scale | R13: Means of Verification (MOVs) | S13: Actual Accomplishments | T13: RATING (Q,E,T) | U13: AVERAGE (QET) | V13: WEIGHTED AVERAGE
B14: Key Result Areas (KRA) (Based on Office Mandate and Functions) | C14: Organizational Outcome Attribution (Refer to the GAA Programs/Subprogram and BEDP Pillars) | J14: Value (numerical, statistical, trend) | K14: Description (expected outcome/ output/service) | M14: 5 (Outstanding) | N14: 4 (Very Satisfactory) | O14: 3 (Satisfactory) | P14: 2 (Unsatisfactory) | Q14: 1 (Poor)
C15: GAA Programs/ Subprograms | D15: BEDP Pillars | E15: Current Administration Agenda
B16: Education Human Resource Development Program | E16: X number of policies formulated, reviewed, and issued | F16: Human Resource Development | G16: Objective 1: Ensured preparation of HR policies, guidelines, and standards that are Bureau-initiated, or may be assigned by the EXECOM for issuance; compliant with PRIME-HRM standards and national guidelines geared towards competency-based HR system within the set scheduled deadline. | H16: January to December 2024 | I16: 0.35 | L16: Quality | M16: Met all 5 indicators based on the established standards in policy formulation: a. Consistent with existing laws, policies, guidelines, requirements, and data/information as may be required by law, oversight agencies, and/or DepEd b. Consistent with agency strategic directions and appropriate with DepEd context c. Compliant with DepEd guidelines on policy development process and underwent consultations and involvement of relevant management officials, personnel, and stakeholders at all governance levels d. Provided presentation materials, press release(as needed), and briefers for Directors and Executive sponsors e. Provided with complete staff work, to include implications/scenario analysis and recommendations | N16: Met 4 out of 5 indicators based on the established standards in policy formulation | O16: Met 3 out of 5 indicators based on the established standards in policy formulation | P16: Met 2 out of 5 indicators based on the established standards in policy formulation | Q16: Only 1 out of 5 indicators is met based on the established standards in policy formulation | S16: Policy deliverables submitted followed the set standards in policy formulation and met all 5 indicators | T16: 5 | U16: =AVERAGE(T16:T18) -> 4.6666667
L17: Efficiency | M17: 100% of total number of policy deliverables submitted and/or presented to the Director for approval; commented upon by such and provided responses to said comments; and/or integrated into the proposed policy action document. | N17: 76-99% of total number of policy deliverables submitted and/or presented to the Director for approval; commented upon by such and provided responses to said comments; and/or integrated into the proposed policy action document. | O17: 51-75% of total number of policy deliverables submitted and/or presented to the Director for approval; commented upon by such and provided responses to said comments; and/or integrated into the proposed policy action document. | P17: 26-50% of total number of policy deliverables submitted and/or presented to the Director for approval; commented upon by such and provided responses to said comments; and/or integrated into the proposed policy action document. | Q17: 25 %and below of total number of policy deliverables submitted and/or presented to the Director for approval; commented upon by such and provided responses to said comments; and/or integrated into the proposed policy action document. | S17: 13 out of 15 (87%) policy deliverables were submitted and/or presented to the Director and/or EXECOM for approval | T17: 4
L18: Timeliness | M18: Endorsed to the Office of the Director before the deadline set | N18: Endorsed to the Office of the Director on the deadline set | O18: Endorsed to the Office of the Director two weeks after the deadline | P18: Endorsed to the Office of the Director one month after the deadline | Q18: Endorsed to the Office of the Director more than one month | S18: 13 policy deliberables endorsed to the Office of the Director before the deadline set | T18: 5
C19: Refer to Accountability Matrix (PREXC Indicators) | D19: Refer to Accountability Matrix (PREXC Indicators) | E19: Refer to 5-Point Agenda of the DepEd Secretary | I19: 0.2 | L19: Quality | T19: 5 | U19: =AVERAGE(T19:T21) -> 5 | V19: =U19*I19 -> 1
L20: Efficiency | T20: 5
L21: Timeliness | T21: 5
I22: 0.2 | L22: Quality | T22: 5 | U22: =AVERAGE(T22:T24) -> 5 | V22: =U22*I22 -> 1
L23: Efficiency | T23: 5
L24: Timeliness | T24: 5
I25: 0.2 | L25: Quality | T25: 5 | U25: =AVERAGE(T25:T27) -> 5 | V25: =U25*I25 -> 1
L26: Efficiency | T26: 5
L27: Timeliness | T27: 5
R37: Part I-A Total Score | V37: =SUM(V19:V27) -> 3
B40: PART I-B: INNOVATING AND INTERVENING ACCOMPLISHMENTS (20%) Part I-B. Innovating and Intervening Accomplishments shall capture the outcomes/outputs of the office that are enabling, supportive, and/or contributory to the achievement of the organizational commitments and KRAs in Part I-A. Accomplishments can be innovations, interventions, and enhancements on the processes, services, and/or outputs.
B41: TO BE FILLED IN DURING PLANNING | S41: TO BE FILLED DURING EVALUATION
B42: Key Result Areas (KRA) | F42: Objectives | H42: Timeline | I42: Weight Allocation | J42: Performance Targets (Target Outcome/Ouput of the Bureau/Center/Service/Division that are enabling, supportive, and/or contributory to the achievement of the organizational outcomes and KRAs (Part I-A)) | L42: Performance Measure (Quality, Efficiency, Timeliness) | M42: RATING SCALE | R42: Means of Verification (MOVs) | S42: Actual Results/ Accomplishments | T42: RATING (Q,E,T) | U42: AVERAGE (QET) | V42: WEIGHTED AVERAGE
J43: Value (numerical, statistical, trend) | K43: Description (expected outcome/ output/service) | M43: 5 (Outstanding) | N43: 4 (Very Satisfactory) | O43: 3 (Satisfactory) | P43: 2 (Unsatisfactory) | Q43: 1 (Poor)
B44: 2. LEARNING ENVIRONMENT | F44: : Promoted a safe, clean and healthy learning environment by implementing the following Clean and Green program. | H44: July 2024-April 2025 | I44: 0.05 | J44: 0.01 | K44: Clean and Green program implemented | L44: Quality | M44: 95% -100% implemented and sustained Clean and Green program | N44: 90% - 94% implemented and sustained Clean and Green program | O44: 85% - 89% implemented and sustained Clean and Green program | P44: 80% - 84% implemented and sustained Clean and Green program | Q44: 75% - 79% implemented and sustained Clean and Green program | R44: 1. School Memo | T44: 5 | U44: =AVERAGE(T44:T46) -> 5 | V44: =U44*I44 -> 0.25
L45: Efficiency | M45: All MOVs are submitted | N45: 4-5 MOVs are submitted | O45: 3 MOVs are submitted | P45: 2 MOVs are submitted | Q45: 1 MOV are submitted | T45: 5
F46: 1. Waste Segregation | L46: Timeliness | M46: ( Clean and Green components will be implemented throughout the year) | R46: 2. Minutes of the Meeting | T46: 5
I47: 0.05 | L47: Quality | T47: 5 | U47: =AVERAGE(T47:T49) -> 5 | V47: =U47*I47 -> 0.25
F48: 2. Project SANYOG | L48: Efficiency | R48: 3. M&E tool | T48: 5
L49: Timeliness | T49: 5
F50: 3. Edible Landscaping | I50: 0.1 | L50: Quality | R50: 4. Attendance Sheet | T50: 5 | U50: =AVERAGE(T50:T52) -> 5 | V50: =U50*I50 -> 0.5
L51: Efficiency | T51: 5
F52: 4. Gulayan sa Paaralan | L52: Timeliness | R52: 5. Accomplishment Reports | T52: 5
R54: 6. Pictures
B71: Part I-B Total Score | V71: =SUM(V44:V52) -> 1
B73: PART I-C: ORGANIZATIONAL EFFECTIVENESS (15%) Part I-C. Organizational Effectiveness shall capture accomplishments/outputs produced or attained on the aspects of Financial Stewardship, Process Improvement, and Client Satisfaction. It shall focus on the results achieved by the office that are aligned with the Performance-based Bonus (PBB) oversight requirements.
...

Sheet PART II_SampleCom
B2: DepEd OPCRF (ver.Feb2025), page 2 of 4
B3: PART II-A: LEADERSHIP COMPETENCIES (2.5%) Part II-A. Leadership Competencies shall capture competencies expected of heads of functional offices who hold managerial and executive/supervisory positions. The Leadership Competencies expected to be demonstrated include Leading People, People Performance Management, and People Development.
B4: Competencies | C4: Behavioural Indicators | G4: Remarks/ Observations | I4: RATING | J4: AVERAGE | L4: DepEd Competencies Scale
L5: Numerical Rating | M5: Adjectival Rating | N5: Definition
B6: Leading People | C6: 1. Uses basic persuasion techniques in a discussion or presentation e.g., staff mobilization, appeals to reason and/or emotions, uses data and examples, visual aids | I6: 5 | J6: =AVERAGE(I6:I10) -> 5 | L6: 5 | M6: Role Model | N6: Behavioral indicator is consistently exhibited and is worthy of emulation.
C7: 2. Persuades, convinces or influences others, in order to have a specific impact or effect. | I7: 5 | L7: 4 | M7: Consistently Demonstrated | N7: Behavioral indicator is constantly shown.
C8: 3. “Sets a good example”, is a credible and respected leader; and demonstrates desired behavior. | I8: 5 | L8: 3 | M8: Most of the Time Demonstrated | N8: Behavioral indicator is often shown.
C9: 4. Forwards personal, professional and work unit needs and interests in an issue. | I9: 5 | L9: 2 | M9: Sometimes Demonstrated | N9: Behavioral indicator is irregularly shown.
C10: 5. Assumes a pivotal role in promoting the development of an inspiring, relevant vision for the organization and influences others to share ownership of DepEd goals, in order to create an effective work environment. | I10: 5 | L10: 1 | M10: Rarely Demonstrated | N10: Behavioral indicator is seldom shown.
B11: People Performance Management | C11: 1. Makes specific changes in the performance management system or in own work methods to improve performance (e.g. does something better, faster, at lower cost, more efficiently; improves quality, customer satisfaction, morale, revenues). | I11: 5 | J11: =AVERAGE(I11:I15) -> 5
C12: 2. Sets performance standards and measures progress of employees based on office and department targets. | I12: 5
C13: 3. Provides feedback and technical assistance such as coaching for performance improvement and action planning. | I13: 5
C14: 4. States performance expectations clearly and checks understanding and commitment. | I14: 5
C15: 5. Performs all the stages of result-based performance management system supported by evidence and required documents/forms. | I15: 5
B16: People Development | C16: 1. Improves the skills and effectiveness of individuals through employing a range of development strategies. | I16: 5 | J16: =AVERAGE(I16:I20) -> 5
C17: 2. Facilitates workforce effectiveness through coaching and motivating/developing people within a work environment that promotes mutual trust and respect. | I17: 5
C18: 3. Conceptualizes and implements learning interventions to meet identified training needs. | I18: 5
C19: 4. Does long-term coaching or training by arranging appropriate and helpful assignments, formal training, or other experiences for the purpose of supporting a person’s learning and development. | I19: 5
C20: 5. Cultivates a learning environment by structuring interactive experiences such as looking for future opportunities that are in support of achieving individual career goals. | I20: 5
B21: Part II-A : Weighted Average (Average x 0.025) | J21: =AVERAGE(J6:J20)*0.025 -> 0.125
B22: PART II-B: CORE BEHAVIOURAL COMPETENCIES (2.5%) Part II-B. Core Behavioral Competencies shall capture competencies required from all DepEd personnel in all job groups within the organization, upholding the DepEd’s core values and the Code of Conduct and Ethical Standards for Public Officials and Employees pursuant to RA 6713. They represent the way individuals embody and live the values of the organization.
B23: Competencies | C23: Behavioural Indicators | G23: Remarks/ Observations | I23: RATING | J23: AVERAGE
B25: Self-Management | C25: 1. Sets personal goals and direction, needs and development. | I25: 5 | J25: =AVERAGE(I25:I29) -> 5
C26: 2. Understands personal actions and behavior that are clear and purposive and takes into account personal goals and values congruent to that of the organization | I26: 5
C27: 3. Displays emotional maturity and enthusiasm for and is challenged by higher goals | I27: 5
C28: 4. Prioritize work tasks and schedules (through Gantt charts, checklists, etc.) to achieve goals | I28: 5
C29: 5. Sets high quality, challenging, realistic goals for self and others. | I29: 5
B30: Professionalism and Ethics | C30: 1. Demonstrate the values and behavior enshrined in the Norms and Conduct and Ethical Standards for Public Officials and Employees (RA 6713). | I30: 5 | J30: =AVERAGE(I30:I34) -> 5
C31: 2. Practice ethical and professional behavior and conduct taking into account the impact of his/her actions and decisions. | I31: 5
C32: 3. Maintains a professional image: being trustworthy, regularity of attendance and punctuality, good grooming and communication. | I32: 5
C33: 4. Makes personal sacrifices to meet the organization’s needs. | I33: 5
C34: 5. Act with a sense of urgency and responsibility to meet the organization’s needs, improve system and help others improve their effectiveness. | I34: 5
B35: Results Focus | C35: 1. Achieves results with optimal use of time and resources mist of the time. | I35: 5 | J35: =AVERAGE(I35:I39) -> 5
C36: 2. Avoids rework, mistakes and wastage through effective work methods by placing organizational needs before personal needs. | I36: 5
C37: 3. Delivers error-free outputs most of the time by conforming to standard operating procedures correctly and consistently. Able to produce very satisfactory quality of work in terms of usefulness/acceptability and completeness with no supervision required. | I37: 5
C38: 4. Expresses a desire to do better and may express frustration at waste or inefficiency. May focus on new or more precise ways of meeting goals set | I38: 5
C39: 5. Makes specific changes in the system or in own work methods to improve performance. Examples may include doing something better, faster, at a lower cost, more efficiently, or improving quality, customer satisfaction, morale, without setting any specific goal. | I39: 5
B40: Teamwork | C40: 1. Willingly does his/her share of responsibility | I40: 5 | J40: =AVERAGE(I40:I44) -> 5
C41: 2. Promotes collaboration and removes barriers to teamwork and goal accomplishment across the organization. | I41: 5
C42: 3. Applies negotiation principles in arriving at win-win agreements. | I42: 5
...

Sheet PART III_SampleComp
B1: DepEd OPCRF (ver.Feb2025), page 3 of 4
C2: PART III: SUMMARY OF RATINGS
C5: Final Performance Components | E5: Weight Allocation | F5: Obtained Score | G5: Overall Score | H5: RPMS Rating | M5: RPMS Rating Table
H6: Numerical Rating | I6: Adjectival Rating | M6: Range | N6: Numerical Rating | O6: Adjectival Rating
C7: PART I | D7: A. Commitment to Organizational Outcomes | E7: 0.6 | F7: ='PART I (CY 2025&SY2025-2026)'!U37 -> #DIV/0! | G7: =SUM(F$7:F$11) -> #DIV/0! | M7: 4.500-5.000 | N7: 5 | O7: Outstanding
D8: B. Innovating and Intervening Accomplishments | E8: 0.2 | F8: =#REF! -> #REF! | M8: 3.500-4.499 | N8: 4 | O8: Very Satisfactory
D9: C. Organizational Effectiveness | E9: 0.15 | F9: =#REF! -> #REF! | M9: 2.500-3.499 | N9: 3 | O9: Satisfactory
C10: PART II | D10: A. Leadership Competencies | E10: 2.5% (0.125) | F10: ='PART II'!J21 -> #DIV/0! | M10: 1.500-2.499 | N10: 2 | O10: Unsatisfactory
D11: B. Core Behavioural Competencies | E11: 2.5% (0.125) | F11: ='PART II'!J55 -> #DIV/0! | M11: 1.000-1.499 | N11: 1 | O11: Poor
C13: Ratee-Rater Agreement
C15: The signatures below confirm that the employee and his/her superior have agreed to the contents of the performance as captured in this form.
C17: Name of Employee: | F17: Name of Superior:
C19: Signature: | F19: Signature:
C21: Date: | F21: Date:

Sheet PART IV
C2: DepEd OPCRF (ver.Feb2025), page 4 of 4
C4: PART IV: IMPROVEMENT AND DEVELOPMENT PLANS
C6: Part IV-A: Office Improvement Plan
E7: Action Plan
C8: Gap Analysis (SWOT) | D8: Improvement Area | E8: General Objective | G8: Recommended Improvement Intervention | I8: Timeline | J8: Resources Needed
C12: Feedback:
C14: Part IV-B: Individual Development Plan
E15: Action Plan
C16: Strengths | D16: Improvement Needs | E16: Learning Objective (based on the developmental intervention) | G16: Recommended Developmental Intervention | I16: Timeline | J16: Resources Needed
I17: Whole Year | J17: Human Resource
C20: Feedback:
C22: MC WELSON C. SOLOMON | F22: ROGER Z. ROCHAR, PhD | I22: PORTIA MISSION MALLORCA, PhD CESO V
C23: RATEE | F23: RATER | I23: APPROVING AUTHORITY
