Workbook
Name BoSY: 'RMAKS2 Scoresheet'!$BL$10:$BL$12
Name EoSY: 'RMAKS2 Scoresheet'!$BM$10:$BM$11

Sheet RMAKS2 Scoresheet
BJ1: RMAKS2v4
A4: Assement Type | C4: EoSY
A5: Region | C5: NIR | D5: Rapid Mathematics Assessment (RMA) Scoresheets | BA5: #VALUE! | BD5: Content Domain | BG5: Cognitive Domain | BN5: Content Domain | BR5: Cognitive Domain
A6: School ID: | C6: 117443 | D6: School Name: | F6: ROMANA ES | J6: Teacher : | M6: RAMONA B. PUNZALAN | S6: Enrolment (Male) : | X6: 14 | Z6: Enrolment (Female) : | AE6: 10 | AG6: Total | AJ6: =AE6+X6 -> 24 | AM6: Number Assessed | AS6: =COUNTA(C10:C108) -> 24 | AX6: Grade Level Scores
B7: Grade: | C7: Grade 4 | D7: Section | F7: 1 | H7: ITEM NUMBER | AX7: Grade 4 (13) | AY7: Grade 5 (19) | AZ7: Grade 6 (18) | BD7: No and Algebra | BE7: Meas and Geom | BF7: Data and Prob | BG7: Knowing | BH7: Applying | BI7: Reasoning | BN7: No and Algebra | BO7: Meas and Geom | BP7: Data and Prob | BQ7: Total | BR7: Knowing | BS7: Applying | BT7: Reasoning | BU7: Total
A8: S/N | B8: LRN | C8: Name of Learner | D8: Sex | E8: Birthdate | F8: Date of Asessment | G8: Age | H8: 1 | I8: =H8+1 -> 2 | J8: =I8+1 -> 3 | K8: =J8+1 -> 4 | L8: =K8+1 -> 5 | M8: =L8+1 -> 6 | N8: =M8+1 -> 7 | O8: =N8+1 -> 8 | P8: =O8+1 -> 9 | ... AJ8: =AI8+1 -> 29 | AK8: 30a | AL8: 30b | AM8: 31 | AN8: =AM8+1 -> 32 | AO8: =AN8+1 -> 33 | AP8: =AO8+1 -> 34 | AQ8: =AP8+1 -> 35 | AR8: 36 | AS8: 37a | AT8: 37b | AU8: 38 | AV8: =AU8+1 -> 39 | AW8: =AV8+1 -> 40 | BA8: TOTAL SCORE | BB8: % of Correct Answer | BC8: Levelling of Learners | BJ8: Remarks
A9: Total Points / Scores | H9: 1 | I9: 1 | J9: 1 | K9: 1 | L9: 2 | M9: 1 | N9: 1 | O9: 1 | P9: 1 | Q9: 1 | R9: 1 | S9: 1 | T9: 1 | U9: 1 | V9: 1 | W9: 1 | X9: 3 | Y9: 1 | Z9: 1 | AA9: 1 | AB9: 2 | AC9: 1 | AD9: 2 | AE9: 1 | AF9: 1 | AG9: 1 | AH9: 1 | AI9: 1 | AJ9: 1 | AK9: 1 | AL9: 1 | AM9: 1 | AN9: 2 | AO9: 2 | AP9: 1 | AQ9: 1 | AR9: 1 | AS9: 1 | AT9: 1 | AU9: 1 | AV9: 2 | AW9: 1 | AX9: 13 | AY9: 19 | AZ9: 18 | BA9: =IF($C$7="Grade 4",AX9,IF($C$7="Grade 5",AY9+AX9,IF($C$7="Grade 6",AZ9+AY9+AX9,0))) -> 13 | BD9: =IF($BA9<>0,IF($C$7="Grade 6",SUM(H9:J9)+SUM(M9:O9)+SUM(Q9:S9)+U9+V9+Z9+AB9+AF9+AJ9+SUM(AM9:AQ9)+AU9+AV9,IF($C$7="Grade 5",SUM(H9:J9)+SUM(M9:O9)+SUM(Q9:S9)+U9+V9+Z9+AB9+AF9,IF($C$7="Grade 4",SUM(H9:J9)+SUM(M9:O9)+SUM(Q9:S9),0))),0) -> 9 | BE9: =IF($BA9<>0,IF($C$7="Grade 6",L9+P9+T9+SUM(W9:Y9)+AA9+SUM(AC9:AE9)+AG9+AI9+AT9,IF($C$7="Grade 5",L9+P9+T9+SUM(W9:Y9)+AA9+SUM(AC9:AE9)+AG9,IF($C$7="Grade 4",L9+P9,0))),0) -> 3 | BF9: =IF($BA9<>0,IF($C$7="Grade 6",K9+AH9+AK9+AL9+AR9+AS9+AW9,IF($C$7="Grade 5",K9+AH9,IF($C$7="Grade 4",K9,0))),0) -> 1 | BG9: =IF($BA9<>0,IF($C$7="Grade 6",H9+K9+M9+S9+T9+V9+W9+Z9+AB9+AC9+SUM(AH9:AJ9)+AN9+AP9+AQ9+AS9+AT9,IF($C$7="Grade 5",H9+K9+M9+S9+T9+V9+W9+Z9+AB9+AC9+AH9,IF($C$7="Grade 4",H9+K9+M9+S9,0))),0) -> 4 | BH9: =IF($BA9<>0,IF($C$7="Grade 6",I9+J9+L9+N9+O9+R9+U9+Y9+SUM(AE9:AG9)+AK9+AM9+AO9+AU9+AV9+AW9,IF($C$7="Grade 5",I9+J9+L9+N9+O9+R9+U9+Y9+SUM(AE9:AG9),IF($C$7="Grade 4",I9+J9+L9+N9+O9+R9,0))),0) -> 7 | BI9: =IF($BA9<>0,IF($C$7="Grade 6",P9+Q9+X9+AA9+AD9+AL9+AR9,IF($C$7="Grade 5",P9+Q9+X9+AA9+AD9,IF($C$7="Grade 4",P9+Q9,0))),0) -> 2 | BL9: BoSY | BM9: EoSY | BN9: =BD9 -> 9 | BO9: =BE9 -> 3 | BP9: =BF9 -> 1 | BQ9: =BN9+BO9+BP9 -> 13 | BR9: =BG9 -> 4 | BS9: =BH9 -> 7 | BT9: =BI9 -> 2 | BU9: =BR9+BS9+BT9 -> 13
A10: 1 | B10: 117443210001 | C10: ANDAYA,KURT JOSEPH, LABANZA | D10: Male | E10: 42452 | F10: 46083 | G10: =IF(C10<>"",(F10-E10)/365,"") -> 9.9479452 | H10: 1 | I10: 1 | J10: 0 | K10: 1 | L10: 1 | M10: 1 | N10: 1 | O10: 0 | P10: 1 | Q10: 0 | R10: 0 | S10: 0 | T10: 0 | U10: 0 | V10: 0 | W10: 0 | X10: 0 | Y10: 0 | Z10: 0 | AA10: 0 | AB10: 0 | AC10: 1 | AD10: 0 | AE10: 0 | AF10: 0 | AG10: 0 | AH10: 0 | AI10: 0 | AJ10: 1 | AK10: 0 | AL10: 0 | AM10: 1 | AN10: 0 | AO10: 0 | AP10: 0 | AQ10: 0 | AR10: 0 | AS10: 0 | AT10: 0 | AU10: 0 | AV10: 0 | AW10: 1 | AX10: =IF($C10<>"",SUM(H10:S10),"") -> 7 | AY10: =IF($C10<>"",SUM(T10:AH10),"") -> 1 | AZ10: =IF($C10<>"",SUM(AI10:AW10),"") -> 3 | BA10: =_xlfn.IFNA(IF(AND($C$4<>"",$C$7<>"",C10<>""),IF($C$7="Grade 4",AX10,IF($C$7="Grade 5",AX10+AY10,IF($C$7="Grade 6",AX10+AY10+AZ10,0))),""),"") -> 7 | BB10: =IFERROR(IF(AND(BA10>0,C10<>""),BA10/$BA$9,""),"") -> 0.53846154 | BC10: =IF($BA10="","",IF($BA$9=50,IF($BA10>=45,"At Grade Level (Highly Proficient)",IF($BA10>=39,"Transitioning (Proficient)",IF($BA10>=29,"Developing (Nearly Proficient)",IF($BA10>=15,"Emerging (Low Proficient)","Emerging (Not Proficient)")))),IF($BA$9=32,IF($BA10>=27,"At Grade Level (Highly Proficient)",IF($BA10>=21,"Transitioning (Proficient)",IF($BA10>=14,"Developing (Nearly Proficient)",IF($BA10>=7,"Emerging (Low Proficient)","Emerging (Not Proficient)")))),IF($BA$9=13,IF($BA10>=11,"At Grade Level (Highly Proficient)",IF($BA10>=8,"Transitioning (Proficient)",IF($BA10>=5,"Developing (Nearly Proficient)",IF($BA10>=3,"Emerging (Low Proficient)","Emerging (Not Proficient)")))),"")))) -> Developing (Nearly Proficient) | BD10: =IF($BA10<>0,IF($C$7="Grade 6",SUM(H10:J10)+SUM(M10:O10)+SUM(Q10:S10)+U10+V10+Z10+AB10+AF10+AJ10+SUM(AM10:AQ10)+AU10+AV10,IF($C$7="Grade 5",SUM(H10:J10)+SUM(M10:O10)+SUM(Q10:S10)+U10+V10+Z10+AB10+AF10,IF($C$7="Grade 4",SUM(H10:J10)+SUM(M10:O10)+SUM(Q10:S10),0))),0) -> 4 | BE10: =IF($BA10<>0,IF($C$7="Grade 6",L10+P10+T10+SUM(W10:Y10)+AA10+SUM(AC10:AE10)+AG10+AI10+AT10,IF($C$7="Grade 5",L10+P10+T10+SUM(W10:Y10)+AA10+SUM(AC10:AE10)+AG10,IF($C$7="Grade 4",L10+P10,0))),0) -> 2 | BF10: =IF($BA10<>0,IF($C$7="Grade 6",K10+AH10+AK10+AL10+AR10+AS10+AW10,IF($C$7="Grade 5",K10+AH10,IF($C$7="Grade 4",K10,0))),0) -> 1 | BG10: =IF($BA10<>0,IF($C$7="Grade 6",H10+K10+M10+S10+T10+V10+W10+Z10+AB10+AC10+SUM(AH10:AJ10)+AN10+AP10+AQ10+AS10+AT10,IF($C$7="Grade 5",H10+K10+M10+S10+T10+V10+W10+Z10+AB10+AC10+AH10,IF($C$7="Grade 4",H10+K10+M10+S10,0))),0) -> 3 | BH10: =IF($BA10<>0,IF($C$7="Grade 6",I10+J10+L10+N10+O10+R10+U10+Y10+SUM(AE10:AG10)+AK10+AM10+AO10+AU10+AV10+AW10,IF($C$7="Grade 5",I10+J10+L10+N10+O10+R10+U10+Y10+SUM(AE10:AG10),IF($C$7="Grade 4",I10+J10+L10+N10+O10+R10,0))),0) -> 3 | BI10: =IF($BA10<>0,IF($C$7="Grade 6",P10+Q10+X10+AA10+AD10+AL10+AR10,IF($C$7="Grade 5",P10+Q10+X10+AA10+AD10,IF($C$7="Grade 4",P10+Q10,0))),0) -> 1 | BL10: Grade 4 | BM10: Grade 4 | BN10: =IF($BA10<>"",IF(BD10/BN$9>=0.75,1,0),"") -> 0 | BO10: =IF($BA10<>"",IF(BE10/BO$9>=0.75,1,0),"") -> 0 | BP10: =IF($BA10<>"",IF(BF10/BP$9>=0.75,1,0),"") -> 1 | BQ10: =IF($BA10<>"",IF(SUM(BD10:BF10)/BQ$9>=0.75,1,0),"") -> 0 | BR10: =IF($BA10<>"",IF(BG10/BR$9>=0.75,1,0),"") -> 1 | BS10: =IF($BA10<>"",IF(BH10/BS$9>=0.75,1,0),"") -> 0 | BT10: =IF($BA10<>"",IF(BI10/BT$9>=0.75,1,0),"") -> 0 | BU10: =IF($BA10<>"",IF(SUM(BG10:BI10)/BU$9>=0.75,1,0),"") -> 0
A11: 2 | B11: 117443210002 | C11: ANTONIO,ARNEL, JR PALACIOS | D11: Male | E11: 42305 | F11: 46083 | G11: =IF(C11<>"",(F11-E11)/365,"") -> 10.350685 | H11: 0 | I11: 0 | J11: 1 | K11: 1 | L11: 0 | M11: 1 | N11: 0 | O11: 0 | P11: 1 | Q11: 1 | R11: 0 | S11: 1 | T11: 1 | U11: 0 | V11: 0 | W11: 0 | X11: 0 | Y11: 1 | Z11: 1 | AA11: 0 | AB11: 0 | AC11: 0 | AD11: 0 | AE11: 0 | AF11: 0 | AG11: 0 | AH11: 0 | AI11: 0 | AJ11: 0 | AK11: 0 | AL11: 0 | AM11: 1 | AN11: 0 | AO11: 0 | AP11: 1 | AQ11: 0 | AR11: 0 | AS11: 0 | AT11: 0 | AU11: 1 | AV11: 0 | AW11: 1 | AX11: =IF($C11<>"",SUM(H11:S11),"") -> 6 | AY11: =IF($C11<>"",SUM(T11:AH11),"") -> 3 | AZ11: =IF($C11<>"",SUM(AI11:AW11),"") -> 4 | BA11: =_xlfn.IFNA(IF(AND($C$4<>"",$C$7<>"",C11<>""),IF($C$7="Grade 4",AX11,IF($C$7="Grade 5",AX11+AY11,IF($C$7="Grade 6",AX11+AY11+AZ11,0))),""),"") -> 6 | BB11: =IFERROR(IF(AND(BA11>0,C11<>""),BA11/$BA$9,""),"") -> 0.46153846 | BC11: =IF($BA11="","",IF($BA$9=50,IF($BA11>=45,"At Grade Level (Highly Proficient)",IF($BA11>=39,"Transitioning (Proficient)",IF($BA11>=29,"Developing (Nearly Proficient)",IF($BA11>=15,"Emerging (Low Proficient)","Emerging (Not Proficient)")))),IF($BA$9=32,IF($BA11>=27,"At Grade Level (Highly Proficient)",IF($BA11>=21,"Transitioning (Proficient)",IF($BA11>=14,"Developing (Nearly Proficient)",IF($BA11>=7,"Emerging (Low Proficient)","Emerging (Not Proficient)")))),IF($BA$9=13,IF($BA11>=11,"At Grade Level (Highly Proficient)",IF($BA11>=8,"Transitioning (Proficient)",IF($BA11>=5,"Developing (Nearly Proficient)",IF($BA11>=3,"Emerging (Low Proficient)","Emerging (Not Proficient)")))),"")))) -> Developing (Nearly Proficient) | BD11: =IF($BA11<>0,IF($C$7="Grade 6",SUM(H11:J11)+SUM(M11:O11)+SUM(Q11:S11)+U11+V11+Z11+AB11+AF11+AJ11+SUM(AM11:AQ11)+AU11+AV11,IF($C$7="Grade 5",SUM(H11:J11)+SUM(M11:O11)+SUM(Q11:S11)+U11+V11+Z11+AB11+AF11,IF($C$7="Grade 4",SUM(H11:J11)+SUM(M11:O11)+SUM(Q11:S11),0))),0) -> 4 | BE11: =IF($BA11<>0,IF($C$7="Grade 6",L11+P11+T11+SUM(W11:Y11)+AA11+SUM(AC11:AE11)+AG11+AI11+AT11,IF($C$7="Grade 5",L11+P11+T11+SUM(W11:Y11)+AA11+SUM(AC11:AE11)+AG11,IF($C$7="Grade 4",L11+P11,0))),0) -> 1 | BF11: =IF($BA11<>0,IF($C$7="Grade 6",K11+AH11+AK11+AL11+AR11+AS11+AW11,IF($C$7="Grade 5",K11+AH11,IF($C$7="Grade 4",K11,0))),0) -> 1 | BG11: =IF($BA11<>0,IF($C$7="Grade 6",H11+K11+M11+S11+T11+V11+W11+Z11+AB11+AC11+SUM(AH11:AJ11)+AN11+AP11+AQ11+AS11+AT11,IF($C$7="Grade 5",H11+K11+M11+S11+T11+V11+W11+Z11+AB11+AC11+AH11,IF($C$7="Grade 4",H11+K11+M11+S11,0))),0) -> 3 | BH11: =IF($BA11<>0,IF($C$7="Grade 6",I11+J11+L11+N11+O11+R11+U11+Y11+SUM(AE11:AG11)+AK11+AM11+AO11+AU11+AV11+AW11,IF($C$7="Grade 5",I11+J11+L11+N11+O11+R11+U11+Y11+SUM(AE11:AG11),IF($C$7="Grade 4",I11+J11+L11+N11+O11+R11,0))),0) -> 1 | BI11: =IF($BA11<>0,IF($C$7="Grade 6",P11+Q11+X11+AA11+AD11+AL11+AR11,IF($C$7="Grade 5",P11+Q11+X11+AA11+AD11,IF($C$7="Grade 4",P11+Q11,0))),0) -> 2 | BL11: Grade 5 | BM11: Grade 5 | BN11: =IF($BA11<>"",IF(BD11/BN$9>=0.75,1,0),"") -> 0 | BO11: =IF($BA11<>"",IF(BE11/BO$9>=0.75,1,0),"") -> 0 | BP11: =IF($BA11<>"",IF(BF11/BP$9>=0.75,1,0),"") -> 1 | BQ11: =IF($BA11<>"",IF(SUM(BD11:BF11)/BQ$9>=0.75,1,0),"") -> 0 | BR11: =IF($BA11<>"",IF(BG11/BR$9>=0.75,1,0),"") -> 1 | BS11: =IF($BA11<>"",IF(BH11/BS$9>=0.75,1,0),"") -> 0 | BT11: =IF($BA11<>"",IF(BI11/BT$9>=0.75,1,0),"") -> 1 | BU11: =IF($BA11<>"",IF(SUM(BG11:BI11)/BU$9>=0.75,1,0),"") -> 0
A12: 3 | B12: 117443210004 | C12: BANHAO, ZAYN ETHAN, JUMBAS | D12: Male | E12: 42488 | F12: 46083 | G12: =IF(C12<>"",(F12-E12)/365,"") -> 9.8493151 | H12: 1 | I12: 1 | J12: 1 | K12: 1 | L12: 2 | M12: 1 | N12: 1 | O12: 0 | P12: 0 | Q12: 0 | R12: 1 | S12: 1 | T12: 0 | U12: 0 | V12: 1 | W12: 1 | X12: 1 | Y12: 1 | Z12: 1 | AA12: 0 | AB12: 0 | AC12: 1 | AD12: 0 | AE12: 0 | AF12: 0 | AG12: 0 | AH12: 0 | AI12: 0 | AJ12: 0 | AK12: 0 | AL12: 0 | AM12: 0 | AN12: 0 | AO12: 0 | AP12: 1 | AQ12: 0 | AR12: 0 | AS12: 1 | AT12: 1 | AU12: 0 | AV12: 0 | AW12: 1 | AX12: =IF($C12<>"",SUM(H12:S12),"") -> 10 | AY12: =IF($C12<>"",SUM(T12:AH12),"") -> 6 | AZ12: =IF($C12<>"",SUM(AI12:AW12),"") -> 4 | BA12: =_xlfn.IFNA(IF(AND($C$4<>"",$C$7<>"",C12<>""),IF($C$7="Grade 4",AX12,IF($C$7="Grade 5",AX12+AY12,IF($C$7="Grade 6",AX12+AY12+AZ12,0))),""),"") -> 10 | BB12: =IFERROR(IF(AND(BA12>0,C12<>""),BA12/$BA$9,""),"") -> 0.76923077 | BC12: =IF($BA12="","",IF($BA$9=50,IF($BA12>=45,"At Grade Level (Highly Proficient)",IF($BA12>=39,"Transitioning (Proficient)",IF($BA12>=29,"Developing (Nearly Proficient)",IF($BA12>=15,"Emerging (Low Proficient)","Emerging (Not Proficient)")))),IF($BA$9=32,IF($BA12>=27,"At Grade Level (Highly Proficient)",IF($BA12>=21,"Transitioning (Proficient)",IF($BA12>=14,"Developing (Nearly Proficient)",IF($BA12>=7,"Emerging (Low Proficient)","Emerging (Not Proficient)")))),IF($BA$9=13,IF($BA12>=11,"At Grade Level (Highly Proficient)",IF($BA12>=8,"Transitioning (Proficient)",IF($BA12>=5,"Developing (Nearly Proficient)",IF($BA12>=3,"Emerging (Low Proficient)","Emerging (Not Proficient)")))),"")))) -> Transitioning (Proficient) | BD12: =IF($BA12<>0,IF($C$7="Grade 6",SUM(H12:J12)+SUM(M12:O12)+SUM(Q12:S12)+U12+V12+Z12+AB12+AF12+AJ12+SUM(AM12:AQ12)+AU12+AV12,IF($C$7="Grade 5",SUM(H12:J12)+SUM(M12:O12)+SUM(Q12:S12)+U12+V12+Z12+AB12+AF12,IF($C$7="Grade 4",SUM(H12:J12)+SUM(M12:O12)+SUM(Q12:S12),0))),0) -> 7 | BE12: =IF($BA12<>0,IF($C$7="Grade 6",L12+P12+T12+SUM(W12:Y12)+AA12+SUM(AC12:AE12)+AG12+AI12+AT12,IF($C$7="Grade 5",L12+P12+T12+SUM(W12:Y12)+AA12+SUM(AC12:AE12)+AG12,IF($C$7="Grade 4",L12+P12,0))),0) -> 2 | BF12: =IF($BA12<>0,IF($C$7="Grade 6",K12+AH12+AK12+AL12+AR12+AS12+AW12,IF($C$7="Grade 5",K12+AH12,IF($C$7="Grade 4",K12,0))),0) -> 1 | BG12: =IF($BA12<>0,IF($C$7="Grade 6",H12+K12+M12+S12+T12+V12+W12+Z12+AB12+AC12+SUM(AH12:AJ12)+AN12+AP12+AQ12+AS12+AT12,IF($C$7="Grade 5",H12+K12+M12+S12+T12+V12+W12+Z12+AB12+AC12+AH12,IF($C$7="Grade 4",H12+K12+M12+S12,0))),0) -> 4 | BH12: =IF($BA12<>0,IF($C$7="Grade 6",I12+J12+L12+N12+O12+R12+U12+Y12+SUM(AE12:AG12)+AK12+AM12+AO12+AU12+AV12+AW12,IF($C$7="Grade 5",I12+J12+L12+N12+O12+R12+U12+Y12+SUM(AE12:AG12),IF($C$7="Grade 4",I12+J12+L12+N12+O12+R12,0))),0) -> 6 | BI12: =IF($BA12<>0,IF($C$7="Grade 6",P12+Q12+X12+AA12+AD12+AL12+AR12,IF($C$7="Grade 5",P12+Q12+X12+AA12+AD12,IF($C$7="Grade 4",P12+Q12,0))),0) -> 0 | BL12: Grade 6 | BN12: =IF($BA12<>"",IF(BD12/BN$9>=0.75,1,0),"") -> 1 | BO12: =IF($BA12<>"",IF(BE12/BO$9>=0.75,1,0),"") -> 0 | BP12: =IF($BA12<>"",IF(BF12/BP$9>=0.75,1,0),"") -> 1 | BQ12: =IF($BA12<>"",IF(SUM(BD12:BF12)/BQ$9>=0.75,1,0),"") -> 1 | BR12: =IF($BA12<>"",IF(BG12/BR$9>=0.75,1,0),"") -> 1 | BS12: =IF($BA12<>"",IF(BH12/BS$9>=0.75,1,0),"") -> 1 | BT12: =IF($BA12<>"",IF(BI12/BT$9>=0.75,1,0),"") -> 0 | BU12: =IF($BA12<>"",IF(SUM(BG12:BI12)/BU$9>=0.75,1,0),"") -> 1
A13: 4 | B13: 117443210026 | C13: CUÑADO,TIERENCE, AMARO | D13: Male | E13: 42267 | F13: 46083 | G13: =IF(C13<>"",(F13-E13)/365,"") -> 10.454795 | H13: 1 | I13: 0 | J13: 0 | K13: 0 | L13: 0 | M13: 1 | N13: 0 | O13: 1 | P13: 1 | Q13: 0 | R13: 0 | S13: 0 | T13: 0 | U13: 0 | V13: 0 | W13: 0 | X13: 0 | Y13: 1 | Z13: 0 | AA13: 0 | AB13: 0 | AC13: 0 | AD13: 1 | AE13: 0 | AF13: 0 | AG13: 0 | AH13: 0 | AI13: 0 | AJ13: 0 | AK13: 0 | AL13: 0 | AM13: 0 | AN13: 0 | AO13: 0 | AP13: 0 | AQ13: 0 | AR13: 1 | AS13: 0 | AT13: 0 | AU13: 0 | AV13: 0 | AW13: 1 | AX13: =IF($C13<>"",SUM(H13:S13),"") -> 4 | AY13: =IF($C13<>"",SUM(T13:AH13),"") -> 2 | AZ13: =IF($C13<>"",SUM(AI13:AW13),"") -> 2 | BA13: =_xlfn.IFNA(IF(AND($C$4<>"",$C$7<>"",C13<>""),IF($C$7="Grade 4",AX13,IF($C$7="Grade 5",AX13+AY13,IF($C$7="Grade 6",AX13+AY13+AZ13,0))),""),"") -> 4 | BB13: =IFERROR(IF(AND(BA13>0,C13<>""),BA13/$BA$9,""),"") -> 0.30769231 | BC13: =IF($BA13="","",IF($BA$9=50,IF($BA13>=45,"At Grade Level (Highly Proficient)",IF($BA13>=39,"Transitioning (Proficient)",IF($BA13>=29,"Developing (Nearly Proficient)",IF($BA13>=15,"Emerging (Low Proficient)","Emerging (Not Proficient)")))),IF($BA$9=32,IF($BA13>=27,"At Grade Level (Highly Proficient)",IF($BA13>=21,"Transitioning (Proficient)",IF($BA13>=14,"Developing (Nearly Proficient)",IF($BA13>=7,"Emerging (Low Proficient)","Emerging (Not Proficient)")))),IF($BA$9=13,IF($BA13>=11,"At Grade Level (Highly Proficient)",IF($BA13>=8,"Transitioning (Proficient)",IF($BA13>=5,"Developing (Nearly Proficient)",IF($BA13>=3,"Emerging (Low Proficient)","Emerging (Not Proficient)")))),"")))) -> Emerging (Low Proficient) | BD13: =IF($BA13<>0,IF($C$7="Grade 6",SUM(H13:J13)+SUM(M13:O13)+SUM(Q13:S13)+U13+V13+Z13+AB13+AF13+AJ13+SUM(AM13:AQ13)+AU13+AV13,IF($C$7="Grade 5",SUM(H13:J13)+SUM(M13:O13)+SUM(Q13:S13)+U13+V13+Z13+AB13+AF13,IF($C$7="Grade 4",SUM(H13:J13)+SUM(M13:O13)+SUM(Q13:S13),0))),0) -> 3 | BE13: =IF($BA13<>0,IF($C$7="Grade 6",L13+P13+T13+SUM(W13:Y13)+AA13+SUM(AC13:AE13)+AG13+AI13+AT13,IF($C$7="Grade 5",L13+P13+T13+SUM(W13:Y13)+AA13+SUM(AC13:AE13)+AG13,IF($C$7="Grade 4",L13+P13,0))),0) -> 1 | BF13: =IF($BA13<>0,IF($C$7="Grade 6",K13+AH13+AK13+AL13+AR13+AS13+AW13,IF($C$7="Grade 5",K13+AH13,IF($C$7="Grade 4",K13,0))),0) -> 0 | BG13: =IF($BA13<>0,IF($C$7="Grade 6",H13+K13+M13+S13+T13+V13+W13+Z13+AB13+AC13+SUM(AH13:AJ13)+AN13+AP13+AQ13+AS13+AT13,IF($C$7="Grade 5",H13+K13+M13+S13+T13+V13+W13+Z13+AB13+AC13+AH13,IF($C$7="Grade 4",H13+K13+M13+S13,0))),0) -> 2 | BH13: =IF($BA13<>0,IF($C$7="Grade 6",I13+J13+L13+N13+O13+R13+U13+Y13+SUM(AE13:AG13)+AK13+AM13+AO13+AU13+AV13+AW13,IF($C$7="Grade 5",I13+J13+L13+N13+O13+R13+U13+Y13+SUM(AE13:AG13),IF($C$7="Grade 4",I13+J13+L13+N13+O13+R13,0))),0) -> 1 | BI13: =IF($BA13<>0,IF($C$7="Grade 6",P13+Q13+X13+AA13+AD13+AL13+AR13,IF($C$7="Grade 5",P13+Q13+X13+AA13+AD13,IF($C$7="Grade 4",P13+Q13,0))),0) -> 1 | BN13: =IF($BA13<>"",IF(BD13/BN$9>=0.75,1,0),"") -> 0 | BO13: =IF($BA13<>"",IF(BE13/BO$9>=0.75,1,0),"") -> 0 | BP13: =IF($BA13<>"",IF(BF13/BP$9>=0.75,1,0),"") -> 0 | BQ13: =IF($BA13<>"",IF(SUM(BD13:BF13)/BQ$9>=0.75,1,0),"") -> 0 | BR13: =IF($BA13<>"",IF(BG13/BR$9>=0.75,1,0),"") -> 0 | BS13: =IF($BA13<>"",IF(BH13/BS$9>=0.75,1,0),"") -> 0 | BT13: =IF($BA13<>"",IF(BI13/BT$9>=0.75,1,0),"") -> 0 | BU13: =IF($BA13<>"",IF(SUM(BG13:BI13)/BU$9>=0.75,1,0),"") -> 0
A14: 5 | B14: 117443210007 | C14: DUMAGAT,CLARK YVAN, DOMANIEL | D14: Male | E14: 42290 | F14: 46083 | G14: =IF(C14<>"",(F14-E14)/365,"") -> 10.391781 | H14: 0 | I14: 0 | J14: 0 | K14: 0 | L14: 1 | M14: 1 | N14: 0 | O14: 1 | P14: 0 | Q14: 1 | R14: 1 | S14: 1 | T14: 0 | U14: 0 | V14: 1 | W14: 0 | X14: 0 | Y14: 0 | Z14: 1 | AA14: 0 | AB14: 0 | AC14: 0 | AD14: 0 | AE14: 0 | AF14: 0 | AG14: 0 | AH14: 1 | AI14: 0 | AJ14: 0 | AK14: 0 | AL14: 0 | AM14: 1 | AN14: 0 | AO14: 0 | AP14: 1 | AQ14: 0 | AR14: 1 | AS14: 1 | AT14: 0 | AU14: 0 | AV14: 0 | AW14: 0 | AX14: =IF($C14<>"",SUM(H14:S14),"") -> 6 | AY14: =IF($C14<>"",SUM(T14:AH14),"") -> 3 | AZ14: =IF($C14<>"",SUM(AI14:AW14),"") -> 4 | BA14: =_xlfn.IFNA(IF(AND($C$4<>"",$C$7<>"",C14<>""),IF($C$7="Grade 4",AX14,IF($C$7="Grade 5",AX14+AY14,IF($C$7="Grade 6",AX14+AY14+AZ14,0))),""),"") -> 6 | BB14: =IFERROR(IF(AND(BA14>0,C14<>""),BA14/$BA$9,""),"") -> 0.46153846 | BC14: =IF($BA14="","",IF($BA$9=50,IF($BA14>=45,"At Grade Level (Highly Proficient)",IF($BA14>=39,"Transitioning (Proficient)",IF($BA14>=29,"Developing (Nearly Proficient)",IF($BA14>=15,"Emerging (Low Proficient)","Emerging (Not Proficient)")))),IF($BA$9=32,IF($BA14>=27,"At Grade Level (Highly Proficient)",IF($BA14>=21,"Transitioning (Proficient)",IF($BA14>=14,"Developing (Nearly Proficient)",IF($BA14>=7,"Emerging (Low Proficient)","Emerging (Not Proficient)")))),IF($BA$9=13,IF($BA14>=11,"At Grade Level (Highly Proficient)",IF($BA14>=8,"Transitioning (Proficient)",IF($BA14>=5,"Developing (Nearly Proficient)",IF($BA14>=3,"Emerging (Low Proficient)","Emerging (Not Proficient)")))),"")))) -> Developing (Nearly Proficient) | BD14: =IF($BA14<>0,IF($C$7="Grade 6",SUM(H14:J14)+SUM(M14:O14)+SUM(Q14:S14)+U14+V14+Z14+AB14+AF14+AJ14+SUM(AM14:AQ14)+AU14+AV14,IF($C$7="Grade 5",SUM(H14:J14)+SUM(M14:O14)+SUM(Q14:S14)+U14+V14+Z14+AB14+AF14,IF($C$7="Grade 4",SUM(H14:J14)+SUM(M14:O14)+SUM(Q14:S14),0))),0) -> 5 | BE14: =IF($BA14<>0,IF($C$7="Grade 6",L14+P14+T14+SUM(W14:Y14)+AA14+SUM(AC14:AE14)+AG14+AI14+AT14,IF($C$7="Grade 5",L14+P14+T14+SUM(W14:Y14)+AA14+SUM(AC14:AE14)+AG14,IF($C$7="Grade 4",L14+P14,0))),0) -> 1 | BF14: =IF($BA14<>0,IF($C$7="Grade 6",K14+AH14+AK14+AL14+AR14+AS14+AW14,IF($C$7="Grade 5",K14+AH14,IF($C$7="Grade 4",K14,0))),0) -> 0 | BG14: =IF($BA14<>0,IF($C$7="Grade 6",H14+K14+M14+S14+T14+V14+W14+Z14+AB14+AC14+SUM(AH14:AJ14)+AN14+AP14+AQ14+AS14+AT14,IF($C$7="Grade 5",H14+K14+M14+S14+T14+V14+W14+Z14+AB14+AC14+AH14,IF($C$7="Grade 4",H14+K14+M14+S14,0))),0) -> 2 | BH14: =IF($BA14<>0,IF($C$7="Grade 6",I14+J14+L14+N14+O14+R14+U14+Y14+SUM(AE14:AG14)+AK14+AM14+AO14+AU14+AV14+AW14,IF($C$7="Grade 5",I14+J14+L14+N14+O14+R14+U14+Y14+SUM(AE14:AG14),IF($C$7="Grade 4",I14+J14+L14+N14+O14+R14,0))),0) -> 3 | BI14: =IF($BA14<>0,IF($C$7="Grade 6",P14+Q14+X14+AA14+AD14+AL14+AR14,IF($C$7="Grade 5",P14+Q14+X14+AA14+AD14,IF($C$7="Grade 4",P14+Q14,0))),0) -> 1 | BN14: =IF($BA14<>"",IF(BD14/BN$9>=0.75,1,0),"") -> 0 | BO14: =IF($BA14<>"",IF(BE14/BO$9>=0.75,1,0),"") -> 0 | BP14: =IF($BA14<>"",IF(BF14/BP$9>=0.75,1,0),"") -> 0 | BQ14: =IF($BA14<>"",IF(SUM(BD14:BF14)/BQ$9>=0.75,1,0),"") -> 0 | BR14: =IF($BA14<>"",IF(BG14/BR$9>=0.75,1,0),"") -> 0 | BS14: =IF($BA14<>"",IF(BH14/BS$9>=0.75,1,0),"") -> 0 | BT14: =IF($BA14<>"",IF(BI14/BT$9>=0.75,1,0),"") -> 0 | BU14: =IF($BA14<>"",IF(SUM(BG14:BI14)/BU$9>=0.75,1,0),"") -> 0
A15: 6 | B15: 117443210009 | C15: ESTOCADA,JOSHUA, SIASAT | D15: Male | E15: 42510 | F15: 46083 | G15: =IF(C15<>"",(F15-E15)/365,"") -> 9.7890411 | H15: 1 | I15: 1 | J15: 1 | K15: 1 | L15: 0 | M15: 1 | N15: 0 | O15: 1 | P15: 0 | Q15: 0 | R15: 0 | S15: 0 | T15: 0 | U15: 1 | V15: 0 | W15: 0 | X15: 0 | Y15: 0 | Z15: 0 | AA15: 0 | AB15: 0 | AC15: 0 | AD15: 0 | AE15: 0 | AF15: 0 | AG15: 0 | AH15: 1 | AI15: 0 | AJ15: 0 | AK15: 1 | AL15: 1 | AM15: 1 | AN15: 0 | AO15: 0 | AP15: 0 | AQ15: 0 | AR15: 1 | AS15: 1 | AT15: 1 | AU15: 1 | AV15: 0 | AW15: 0 | AX15: =IF($C15<>"",SUM(H15:S15),"") -> 6 | AY15: =IF($C15<>"",SUM(T15:AH15),"") -> 2 | AZ15: =IF($C15<>"",SUM(AI15:AW15),"") -> 7 | BA15: =_xlfn.IFNA(IF(AND($C$4<>"",$C$7<>"",C15<>""),IF($C$7="Grade 4",AX15,IF($C$7="Grade 5",AX15+AY15,IF($C$7="Grade 6",AX15+AY15+AZ15,0))),""),"") -> 6 | BB15: =IFERROR(IF(AND(BA15>0,C15<>""),BA15/$BA$9,""),"") -> 0.46153846 | BC15: =IF($BA15="","",IF($BA$9=50,IF($BA15>=45,"At Grade Level (Highly Proficient)",IF($BA15>=39,"Transitioning (Proficient)",IF($BA15>=29,"Developing (Nearly Proficient)",IF($BA15>=15,"Emerging (Low Proficient)","Emerging (Not Proficient)")))),IF($BA$9=32,IF($BA15>=27,"At Grade Level (Highly Proficient)",IF($BA15>=21,"Transitioning (Proficient)",IF($BA15>=14,"Developing (Nearly Proficient)",IF($BA15>=7,"Emerging (Low Proficient)","Emerging (Not Proficient)")))),IF($BA$9=13,IF($BA15>=11,"At Grade Level (Highly Proficient)",IF($BA15>=8,"Transitioning (Proficient)",IF($BA15>=5,"Developing (Nearly Proficient)",IF($BA15>=3,"Emerging (Low Proficient)","Emerging (Not Proficient)")))),"")))) -> Developing (Nearly Proficient) | BD15: =IF($BA15<>0,IF($C$7="Grade 6",SUM(H15:J15)+SUM(M15:O15)+SUM(Q15:S15)+U15+V15+Z15+AB15+AF15+AJ15+SUM(AM15:AQ15)+AU15+AV15,IF($C$7="Grade 5",SUM(H15:J15)+SUM(M15:O15)+SUM(Q15:S15)+U15+V15+Z15+AB15+AF15,IF($C$7="Grade 4",SUM(H15:J15)+SUM(M15:O15)+SUM(Q15:S15),0))),0) -> 5 | BE15: =IF($BA15<>0,IF($C$7="Grade 6",L15+P15+T15+SUM(W15:Y15)+AA15+SUM(AC15:AE15)+AG15+AI15+AT15,IF($C$7="Grade 5",L15+P15+T15+SUM(W15:Y15)+AA15+SUM(AC15:AE15)+AG15,IF($C$7="Grade 4",L15+P15,0))),0) -> 0 | BF15: =IF($BA15<>0,IF($C$7="Grade 6",K15+AH15+AK15+AL15+AR15+AS15+AW15,IF($C$7="Grade 5",K15+AH15,IF($C$7="Grade 4",K15,0))),0) -> 1 | BG15: =IF($BA15<>0,IF($C$7="Grade 6",H15+K15+M15+S15+T15+V15+W15+Z15+AB15+AC15+SUM(AH15:AJ15)+AN15+AP15+AQ15+AS15+AT15,IF($C$7="Grade 5",H15+K15+M15+S15+T15+V15+W15+Z15+AB15+AC15+AH15,IF($C$7="Grade 4",H15+K15+M15+S15,0))),0) -> 3 | BH15: =IF($BA15<>0,IF($C$7="Grade 6",I15+J15+L15+N15+O15+R15+U15+Y15+SUM(AE15:AG15)+AK15+AM15+AO15+AU15+AV15+AW15,IF($C$7="Grade 5",I15+J15+L15+N15+O15+R15+U15+Y15+SUM(AE15:AG15),IF($C$7="Grade 4",I15+J15+L15+N15+O15+R15,0))),0) -> 3 | BI15: =IF($BA15<>0,IF($C$7="Grade 6",P15+Q15+X15+AA15+AD15+AL15+AR15,IF($C$7="Grade 5",P15+Q15+X15+AA15+AD15,IF($C$7="Grade 4",P15+Q15,0))),0) -> 0 | BN15: =IF($BA15<>"",IF(BD15/BN$9>=0.75,1,0),"") -> 0 | BO15: =IF($BA15<>"",IF(BE15/BO$9>=0.75,1,0),"") -> 0 | BP15: =IF($BA15<>"",IF(BF15/BP$9>=0.75,1,0),"") -> 1 | BQ15: =IF($BA15<>"",IF(SUM(BD15:BF15)/BQ$9>=0.75,1,0),"") -> 0 | BR15: =IF($BA15<>"",IF(BG15/BR$9>=0.75,1,0),"") -> 1 | BS15: =IF($BA15<>"",IF(BH15/BS$9>=0.75,1,0),"") -> 0 | BT15: =IF($BA15<>"",IF(BI15/BT$9>=0.75,1,0),"") -> 0 | BU15: =IF($BA15<>"",IF(SUM(BG15:BI15)/BU$9>=0.75,1,0),"") -> 0
A16: 7 | B16: 117443210010 | C16: ESTOCADA,LYNWEL, QUIRANTE | D16: Male | E16: 42314 | F16: 46084 | G16: =IF(C16<>"",(F16-E16)/365,"") -> 10.328767 | H16: 0 | I16: 0 | J16: 0 | K16: 0 | L16: 0 | M16: 1 | N16: 0 | O16: 0 | P16: 0 | Q16: 1 | R16: 0 | S16: 1 | T16: 0 | U16: 0 | V16: 0 | W16: 0 | X16: 0 | Y16: 1 | Z16: 0 | AA16: 0 | AB16: 0 | AC16: 0 | AD16: 0 | AE16: 1 | AF16: 0 | AG16: 0 | AH16: 0 | AI16: 0 | AJ16: 0 | AK16: 0 | AL16: 0 | AM16: 0 | AN16: 0 | AO16: 0 | AP16: 1 | AQ16: 0 | AR16: 0 | AS16: 0 | AT16: 0 | AU16: 0 | AV16: 0 | AW16: 1 | AX16: =IF($C16<>"",SUM(H16:S16),"") -> 3 | AY16: =IF($C16<>"",SUM(T16:AH16),"") -> 2 | AZ16: =IF($C16<>"",SUM(AI16:AW16),"") -> 2 | BA16: =_xlfn.IFNA(IF(AND($C$4<>"",$C$7<>"",C16<>""),IF($C$7="Grade 4",AX16,IF($C$7="Grade 5",AX16+AY16,IF($C$7="Grade 6",AX16+AY16+AZ16,0))),""),"") -> 3 | BB16: =IFERROR(IF(AND(BA16>0,C16<>""),BA16/$BA$9,""),"") -> 0.23076923 | BC16: =IF($BA16="","",IF($BA$9=50,IF($BA16>=45,"At Grade Level (Highly Proficient)",IF($BA16>=39,"Transitioning (Proficient)",IF($BA16>=29,"Developing (Nearly Proficient)",IF($BA16>=15,"Emerging (Low Proficient)","Emerging (Not Proficient)")))),IF($BA$9=32,IF($BA16>=27,"At Grade Level (Highly Proficient)",IF($BA16>=21,"Transitioning (Proficient)",IF($BA16>=14,"Developing (Nearly Proficient)",IF($BA16>=7,"Emerging (Low Proficient)","Emerging (Not Proficient)")))),IF($BA$9=13,IF($BA16>=11,"At Grade Level (Highly Proficient)",IF($BA16>=8,"Transitioning (Proficient)",IF($BA16>=5,"Developing (Nearly Proficient)",IF($BA16>=3,"Emerging (Low Proficient)","Emerging (Not Proficient)")))),"")))) -> Emerging (Low Proficient) | BD16: =IF($BA16<>0,IF($C$7="Grade 6",SUM(H16:J16)+SUM(M16:O16)+SUM(Q16:S16)+U16+V16+Z16+AB16+AF16+AJ16+SUM(AM16:AQ16)+AU16+AV16,IF($C$7="Grade 5",SUM(H16:J16)+SUM(M16:O16)+SUM(Q16:S16)+U16+V16+Z16+AB16+AF16,IF($C$7="Grade 4",SUM(H16:J16)+SUM(M16:O16)+SUM(Q16:S16),0))),0) -> 3 | BE16: =IF($BA16<>0,IF($C$7="Grade 6",L16+P16+T16+SUM(W16:Y16)+AA16+SUM(AC16:AE16)+AG16+AI16+AT16,IF($C$7="Grade 5",L16+P16+T16+SUM(W16:Y16)+AA16+SUM(AC16:AE16)+AG16,IF($C$7="Grade 4",L16+P16,0))),0) -> 0 | BF16: =IF($BA16<>0,IF($C$7="Grade 6",K16+AH16+AK16+AL16+AR16+AS16+AW16,IF($C$7="Grade 5",K16+AH16,IF($C$7="Grade 4",K16,0))),0) -> 0 | BG16: =IF($BA16<>0,IF($C$7="Grade 6",H16+K16+M16+S16+T16+V16+W16+Z16+AB16+AC16+SUM(AH16:AJ16)+AN16+AP16+AQ16+AS16+AT16,IF($C$7="Grade 5",H16+K16+M16+S16+T16+V16+W16+Z16+AB16+AC16+AH16,IF($C$7="Grade 4",H16+K16+M16+S16,0))),0) -> 2 | BH16: =IF($BA16<>0,IF($C$7="Grade 6",I16+J16+L16+N16+O16+R16+U16+Y16+SUM(AE16:AG16)+AK16+AM16+AO16+AU16+AV16+AW16,IF($C$7="Grade 5",I16+J16+L16+N16+O16+R16+U16+Y16+SUM(AE16:AG16),IF($C$7="Grade 4",I16+J16+L16+N16+O16+R16,0))),0) -> 0 | BI16: =IF($BA16<>0,IF($C$7="Grade 6",P16+Q16+X16+AA16+AD16+AL16+AR16,IF($C$7="Grade 5",P16+Q16+X16+AA16+AD16,IF($C$7="Grade 4",P16+Q16,0))),0) -> 1 | BN16: =IF($BA16<>"",IF(BD16/BN$9>=0.75,1,0),"") -> 0 | BO16: =IF($BA16<>"",IF(BE16/BO$9>=0.75,1,0),"") -> 0 | BP16: =IF($BA16<>"",IF(BF16/BP$9>=0.75,1,0),"") -> 0 | BQ16: =IF($BA16<>"",IF(SUM(BD16:BF16)/BQ$9>=0.75,1,0),"") -> 0 | BR16: =IF($BA16<>"",IF(BG16/BR$9>=0.75,1,0),"") -> 0 | BS16: =IF($BA16<>"",IF(BH16/BS$9>=0.75,1,0),"") -> 0 | BT16: =IF($BA16<>"",IF(BI16/BT$9>=0.75,1,0),"") -> 0 | BU16: =IF($BA16<>"",IF(SUM(BG16:BI16)/BU$9>=0.75,1,0),"") -> 0
A17: 8 | B17: 117447210030 | C17: ESTOCADA,PRINCE JENMAR, BALONSONG | D17: Male | E17: 42212 | F17: 46084 | G17: =IF(C17<>"",(F17-E17)/365,"") -> 10.608219 | H17: 1 | I17: 1 | J17: 1 | K17: 1 | L17: 0 | M17: 0 | N17: 1 | O17: 0 | P17: 1 | Q17: 0 | R17: 0 | S17: 0 | T17: 0 | U17: 0 | V17: 1 | W17: 0 | X17: 0 | Y17: 0 | Z17: 0 | AA17: 0 | AB17: 0 | AC17: 0 | AD17: 0 | AE17: 0 | AF17: 0 | AG17: 0 | AH17: 0 | AI17: 0 | AJ17: 0 | AK17: 0 | AL17: 0 | AM17: 1 | AN17: 0 | AO17: 0 | AP17: 0 | AQ17: 0 | AR17: 1 | AS17: 1 | AT17: 1 | AU17: 0 | AV17: 0 | AW17: 0 | AX17: =IF($C17<>"",SUM(H17:S17),"") -> 6 | AY17: =IF($C17<>"",SUM(T17:AH17),"") -> 1 | AZ17: =IF($C17<>"",SUM(AI17:AW17),"") -> 4 | BA17: =_xlfn.IFNA(IF(AND($C$4<>"",$C$7<>"",C17<>""),IF($C$7="Grade 4",AX17,IF($C$7="Grade 5",AX17+AY17,IF($C$7="Grade 6",AX17+AY17+AZ17,0))),""),"") -> 6 | BB17: =IFERROR(IF(AND(BA17>0,C17<>""),BA17/$BA$9,""),"") -> 0.46153846 | BC17: =IF($BA17="","",IF($BA$9=50,IF($BA17>=45,"At Grade Level (Highly Proficient)",IF($BA17>=39,"Transitioning (Proficient)",IF($BA17>=29,"Developing (Nearly Proficient)",IF($BA17>=15,"Emerging (Low Proficient)","Emerging (Not Proficient)")))),IF($BA$9=32,IF($BA17>=27,"At Grade Level (Highly Proficient)",IF($BA17>=21,"Transitioning (Proficient)",IF($BA17>=14,"Developing (Nearly Proficient)",IF($BA17>=7,"Emerging (Low Proficient)","Emerging (Not Proficient)")))),IF($BA$9=13,IF($BA17>=11,"At Grade Level (Highly Proficient)",IF($BA17>=8,"Transitioning (Proficient)",IF($BA17>=5,"Developing (Nearly Proficient)",IF($BA17>=3,"Emerging (Low Proficient)","Emerging (Not Proficient)")))),"")))) -> Developing (Nearly Proficient) | BD17: =IF($BA17<>0,IF($C$7="Grade 6",SUM(H17:J17)+SUM(M17:O17)+SUM(Q17:S17)+U17+V17+Z17+AB17+AF17+AJ17+SUM(AM17:AQ17)+AU17+AV17,IF($C$7="Grade 5",SUM(H17:J17)+SUM(M17:O17)+SUM(Q17:S17)+U17+V17+Z17+AB17+AF17,IF($C$7="Grade 4",SUM(H17:J17)+SUM(M17:O17)+SUM(Q17:S17),0))),0) -> 4 | BE17: =IF($BA17<>0,IF($C$7="Grade 6",L17+P17+T17+SUM(W17:Y17)+AA17+SUM(AC17:AE17)+AG17+AI17+AT17,IF($C$7="Grade 5",L17+P17+T17+SUM(W17:Y17)+AA17+SUM(AC17:AE17)+AG17,IF($C$7="Grade 4",L17+P17,0))),0) -> 1 | BF17: =IF($BA17<>0,IF($C$7="Grade 6",K17+AH17+AK17+AL17+AR17+AS17+AW17,IF($C$7="Grade 5",K17+AH17,IF($C$7="Grade 4",K17,0))),0) -> 1 | BG17: =IF($BA17<>0,IF($C$7="Grade 6",H17+K17+M17+S17+T17+V17+W17+Z17+AB17+AC17+SUM(AH17:AJ17)+AN17+AP17+AQ17+AS17+AT17,IF($C$7="Grade 5",H17+K17+M17+S17+T17+V17+W17+Z17+AB17+AC17+AH17,IF($C$7="Grade 4",H17+K17+M17+S17,0))),0) -> 2 | BH17: =IF($BA17<>0,IF($C$7="Grade 6",I17+J17+L17+N17+O17+R17+U17+Y17+SUM(AE17:AG17)+AK17+AM17+AO17+AU17+AV17+AW17,IF($C$7="Grade 5",I17+J17+L17+N17+O17+R17+U17+Y17+SUM(AE17:AG17),IF($C$7="Grade 4",I17+J17+L17+N17+O17+R17,0))),0) -> 3 | BI17: =IF($BA17<>0,IF($C$7="Grade 6",P17+Q17+X17+AA17+AD17+AL17+AR17,IF($C$7="Grade 5",P17+Q17+X17+AA17+AD17,IF($C$7="Grade 4",P17+Q17,0))),0) -> 1 | BN17: =IF($BA17<>"",IF(BD17/BN$9>=0.75,1,0),"") -> 0 | BO17: =IF($BA17<>"",IF(BE17/BO$9>=0.75,1,0),"") -> 0 | BP17: =IF($BA17<>"",IF(BF17/BP$9>=0.75,1,0),"") -> 1 | BQ17: =IF($BA17<>"",IF(SUM(BD17:BF17)/BQ$9>=0.75,1,0),"") -> 0 | BR17: =IF($BA17<>"",IF(BG17/BR$9>=0.75,1,0),"") -> 0 | BS17: =IF($BA17<>"",IF(BH17/BS$9>=0.75,1,0),"") -> 0 | BT17: =IF($BA17<>"",IF(BI17/BT$9>=0.75,1,0),"") -> 0 | BU17: =IF($BA17<>"",IF(SUM(BG17:BI17)/BU$9>=0.75,1,0),"") -> 0
A18: 9 | B18: 117443210011 | C18: GREGORIO,JOSHUA, ABELLAR | D18: Male | E18: 42054 | F18: 46084 | G18: =IF(C18<>"",(F18-E18)/365,"") -> 11.041096 | H18: 1 | I18: 0 | J18: 0 | K18: 0 | L18: 0 | M18: 1 | N18: 1 | O18: 0 | P18: 0 | Q18: 0 | R18: 1 | S18: 0 | T18: 0 | U18: 0 | V18: 0 | W18: 0 | X18: 0 | Y18: 0 | Z18: 0 | AA18: 0 | AB18: 0 | AC18: 1 | AD18: 0 | AE18: 0 | AF18: 0 | AG18: 0 | AH18: 1 | AI18: 0 | AJ18: 0 | AK18: 0 | AL18: 0 | AM18: 0 | AN18: 0 | AO18: 0 | AP18: 0 | AQ18: 0 | AR18: 0 | AS18: 0 | AT18: 0 | AU18: 0 | AV18: 0 | AW18: 1 | AX18: =IF($C18<>"",SUM(H18:S18),"") -> 4 | AY18: =IF($C18<>"",SUM(T18:AH18),"") -> 2 | AZ18: =IF($C18<>"",SUM(AI18:AW18),"") -> 1 | BA18: =_xlfn.IFNA(IF(AND($C$4<>"",$C$7<>"",C18<>""),IF($C$7="Grade 4",AX18,IF($C$7="Grade 5",AX18+AY18,IF($C$7="Grade 6",AX18+AY18+AZ18,0))),""),"") -> 4 | BB18: =IFERROR(IF(AND(BA18>0,C18<>""),BA18/$BA$9,""),"") -> 0.30769231 | BC18: =IF($BA18="","",IF($BA$9=50,IF($BA18>=45,"At Grade Level (Highly Proficient)",IF($BA18>=39,"Transitioning (Proficient)",IF($BA18>=29,"Developing (Nearly Proficient)",IF($BA18>=15,"Emerging (Low Proficient)","Emerging (Not Proficient)")))),IF($BA$9=32,IF($BA18>=27,"At Grade Level (Highly Proficient)",IF($BA18>=21,"Transitioning (Proficient)",IF($BA18>=14,"Developing (Nearly Proficient)",IF($BA18>=7,"Emerging (Low Proficient)","Emerging (Not Proficient)")))),IF($BA$9=13,IF($BA18>=11,"At Grade Level (Highly Proficient)",IF($BA18>=8,"Transitioning (Proficient)",IF($BA18>=5,"Developing (Nearly Proficient)",IF($BA18>=3,"Emerging (Low Proficient)","Emerging (Not Proficient)")))),"")))) -> Emerging (Low Proficient) | BD18: =IF($BA18<>0,IF($C$7="Grade 6",SUM(H18:J18)+SUM(M18:O18)+SUM(Q18:S18)+U18+V18+Z18+AB18+AF18+AJ18+SUM(AM18:AQ18)+AU18+AV18,IF($C$7="Grade 5",SUM(H18:J18)+SUM(M18:O18)+SUM(Q18:S18)+U18+V18+Z18+AB18+AF18,IF($C$7="Grade 4",SUM(H18:J18)+SUM(M18:O18)+SUM(Q18:S18),0))),0) -> 4 | BE18: =IF($BA18<>0,IF($C$7="Grade 6",L18+P18+T18+SUM(W18:Y18)+AA18+SUM(AC18:AE18)+AG18+AI18+AT18,IF($C$7="Grade 5",L18+P18+T18+SUM(W18:Y18)+AA18+SUM(AC18:AE18)+AG18,IF($C$7="Grade 4",L18+P18,0))),0) -> 0 | BF18: =IF($BA18<>0,IF($C$7="Grade 6",K18+AH18+AK18+AL18+AR18+AS18+AW18,IF($C$7="Grade 5",K18+AH18,IF($C$7="Grade 4",K18,0))),0) -> 0 | BG18: =IF($BA18<>0,IF($C$7="Grade 6",H18+K18+M18+S18+T18+V18+W18+Z18+AB18+AC18+SUM(AH18:AJ18)+AN18+AP18+AQ18+AS18+AT18,IF($C$7="Grade 5",H18+K18+M18+S18+T18+V18+W18+Z18+AB18+AC18+AH18,IF($C$7="Grade 4",H18+K18+M18+S18,0))),0) -> 2 | BH18: =IF($BA18<>0,IF($C$7="Grade 6",I18+J18+L18+N18+O18+R18+U18+Y18+SUM(AE18:AG18)+AK18+AM18+AO18+AU18+AV18+AW18,IF($C$7="Grade 5",I18+J18+L18+N18+O18+R18+U18+Y18+SUM(AE18:AG18),IF($C$7="Grade 4",I18+J18+L18+N18+O18+R18,0))),0) -> 2 | BI18: =IF($BA18<>0,IF($C$7="Grade 6",P18+Q18+X18+AA18+AD18+AL18+AR18,IF($C$7="Grade 5",P18+Q18+X18+AA18+AD18,IF($C$7="Grade 4",P18+Q18,0))),0) -> 0 | BN18: =IF($BA18<>"",IF(BD18/BN$9>=0.75,1,0),"") -> 0 | BO18: =IF($BA18<>"",IF(BE18/BO$9>=0.75,1,0),"") -> 0 | BP18: =IF($BA18<>"",IF(BF18/BP$9>=0.75,1,0),"") -> 0 | BQ18: =IF($BA18<>"",IF(SUM(BD18:BF18)/BQ$9>=0.75,1,0),"") -> 0 | BR18: =IF($BA18<>"",IF(BG18/BR$9>=0.75,1,0),"") -> 0 | BS18: =IF($BA18<>"",IF(BH18/BS$9>=0.75,1,0),"") -> 0 | BT18: =IF($BA18<>"",IF(BI18/BT$9>=0.75,1,0),"") -> 0 | BU18: =IF($BA18<>"",IF(SUM(BG18:BI18)/BU$9>=0.75,1,0),"") -> 0
A19: 10 | B19: 117025210065 | C19: JOCSON,JAYSON, ABAY | D19: Male | E19: 42407 | F19: 46084 | G19: =IF(C19<>"",(F19-E19)/365,"") -> 10.073973 | H19: 1 | I19: 0 | J19: 1 | K19: 1 | L19: 0 | M19: 0 | N19: 0 | O19: 1 | P19: 1 | Q19: 0 | R19: 1 | S19: 1 | T19: 0 | U19: 1 | V19: 0 | W19: 0 | X19: 0 | Y19: 0 | Z19: 0 | AA19: 1 | AB19: 0 | AC19: 0 | AD19: 0 | AE19: 0 | AF19: 1 | AG19: 0 | AH19: 0 | AI19: 0 | AJ19: 1 | AK19: 0 | AL19: 0 | AM19: 0 | AN19: 0 | AO19: 0 | AP19: 1 | AQ19: 1 | AR19: 1 | AS19: 1 | AT19: 1 | AU19: 1 | AV19: 0 | AW19: 0 | AX19: =IF($C19<>"",SUM(H19:S19),"") -> 7 | AY19: =IF($C19<>"",SUM(T19:AH19),"") -> 3 | AZ19: =IF($C19<>"",SUM(AI19:AW19),"") -> 7 | BA19: =_xlfn.IFNA(IF(AND($C$4<>"",$C$7<>"",C19<>""),IF($C$7="Grade 4",AX19,IF($C$7="Grade 5",AX19+AY19,IF($C$7="Grade 6",AX19+AY19+AZ19,0))),""),"") -> 7 | BB19: =IFERROR(IF(AND(BA19>0,C19<>""),BA19/$BA$9,""),"") -> 0.53846154 | BC19: =IF($BA19="","",IF($BA$9=50,IF($BA19>=45,"At Grade Level (Highly Proficient)",IF($BA19>=39,"Transitioning (Proficient)",IF($BA19>=29,"Developing (Nearly Proficient)",IF($BA19>=15,"Emerging (Low Proficient)","Emerging (Not Proficient)")))),IF($BA$9=32,IF($BA19>=27,"At Grade Level (Highly Proficient)",IF($BA19>=21,"Transitioning (Proficient)",IF($BA19>=14,"Developing (Nearly Proficient)",IF($BA19>=7,"Emerging (Low Proficient)","Emerging (Not Proficient)")))),IF($BA$9=13,IF($BA19>=11,"At Grade Level (Highly Proficient)",IF($BA19>=8,"Transitioning (Proficient)",IF($BA19>=5,"Developing (Nearly Proficient)",IF($BA19>=3,"Emerging (Low Proficient)","Emerging (Not Proficient)")))),"")))) -> Developing (Nearly Proficient) | BD19: =IF($BA19<>0,IF($C$7="Grade 6",SUM(H19:J19)+SUM(M19:O19)+SUM(Q19:S19)+U19+V19+Z19+AB19+AF19+AJ19+SUM(AM19:AQ19)+AU19+AV19,IF($C$7="Grade 5",SUM(H19:J19)+SUM(M19:O19)+SUM(Q19:S19)+U19+V19+Z19+AB19+AF19,IF($C$7="Grade 4",SUM(H19:J19)+SUM(M19:O19)+SUM(Q19:S19),0))),0) -> 5 | BE19: =IF($BA19<>0,IF($C$7="Grade 6",L19+P19+T19+SUM(W19:Y19)+AA19+SUM(AC19:AE19)+AG19+AI19+AT19,IF($C$7="Grade 5",L19+P19+T19+SUM(W19:Y19)+AA19+SUM(AC19:AE19)+AG19,IF($C$7="Grade 4",L19+P19,0))),0) -> 1 | BF19: =IF($BA19<>0,IF($C$7="Grade 6",K19+AH19+AK19+AL19+AR19+AS19+AW19,IF($C$7="Grade 5",K19+AH19,IF($C$7="Grade 4",K19,0))),0) -> 1 | BG19: =IF($BA19<>0,IF($C$7="Grade 6",H19+K19+M19+S19+T19+V19+W19+Z19+AB19+AC19+SUM(AH19:AJ19)+AN19+AP19+AQ19+AS19+AT19,IF($C$7="Grade 5",H19+K19+M19+S19+T19+V19+W19+Z19+AB19+AC19+AH19,IF($C$7="Grade 4",H19+K19+M19+S19,0))),0) -> 3 | BH19: =IF($BA19<>0,IF($C$7="Grade 6",I19+J19+L19+N19+O19+R19+U19+Y19+SUM(AE19:AG19)+AK19+AM19+AO19+AU19+AV19+AW19,IF($C$7="Grade 5",I19+J19+L19+N19+O19+R19+U19+Y19+SUM(AE19:AG19),IF($C$7="Grade 4",I19+J19+L19+N19+O19+R19,0))),0) -> 3 | BI19: =IF($BA19<>0,IF($C$7="Grade 6",P19+Q19+X19+AA19+AD19+AL19+AR19,IF($C$7="Grade 5",P19+Q19+X19+AA19+AD19,IF($C$7="Grade 4",P19+Q19,0))),0) -> 1 | BN19: =IF($BA19<>"",IF(BD19/BN$9>=0.75,1,0),"") -> 0 | BO19: =IF($BA19<>"",IF(BE19/BO$9>=0.75,1,0),"") -> 0 | BP19: =IF($BA19<>"",IF(BF19/BP$9>=0.75,1,0),"") -> 1 | BQ19: =IF($BA19<>"",IF(SUM(BD19:BF19)/BQ$9>=0.75,1,0),"") -> 0 | BR19: =IF($BA19<>"",IF(BG19/BR$9>=0.75,1,0),"") -> 1 | BS19: =IF($BA19<>"",IF(BH19/BS$9>=0.75,1,0),"") -> 0 | BT19: =IF($BA19<>"",IF(BI19/BT$9>=0.75,1,0),"") -> 0 | BU19: =IF($BA19<>"",IF(SUM(BG19:BI19)/BU$9>=0.75,1,0),"") -> 0
A20: 11 | B20: 117443210012 | C20: JUMBAS,JERRYL, GOLE | D20: Male | E20: 42459 | F20: 46084 | G20: =IF(C20<>"",(F20-E20)/365,"") -> 9.9315068 | H20: 1 | I20: 0 | J20: 1 | K20: 1 | L20: 1 | M20: 0 | N20: 1 | O20: 1 | P20: 1 | Q20: 1 | R20: 0 | S20: 1 | T20: 0 | U20: 0 | V20: 0 | W20: 0 | X20: 0 | Y20: 0 | Z20: 0 | AA20: 0 | AB20: 0 | AC20: 0 | AD20: 0 | AE20: 0 | AF20: 0 | AG20: 0 | AH20: 0 | AI20: 0 | AJ20: 0 | AK20: 0 | AL20: 0 | AM20: 0 | AN20: 0 | AO20: 0 | AP20: 1 | AQ20: 0 | AR20: 1 | AS20: 1 | AT20: 1 | AU20: 1 | AV20: 0 | AW20: 0 | AX20: =IF($C20<>"",SUM(H20:S20),"") -> 9 | AY20: =IF($C20<>"",SUM(T20:AH20),"") -> 0 | AZ20: =IF($C20<>"",SUM(AI20:AW20),"") -> 5 | BA20: =_xlfn.IFNA(IF(AND($C$4<>"",$C$7<>"",C20<>""),IF($C$7="Grade 4",AX20,IF($C$7="Grade 5",AX20+AY20,IF($C$7="Grade 6",AX20+AY20+AZ20,0))),""),"") -> 9 | BB20: =IFERROR(IF(AND(BA20>0,C20<>""),BA20/$BA$9,""),"") -> 0.69230769 | BC20: =IF($BA20="","",IF($BA$9=50,IF($BA20>=45,"At Grade Level (Highly Proficient)",IF($BA20>=39,"Transitioning (Proficient)",IF($BA20>=29,"Developing (Nearly Proficient)",IF($BA20>=15,"Emerging (Low Proficient)","Emerging (Not Proficient)")))),IF($BA$9=32,IF($BA20>=27,"At Grade Level (Highly Proficient)",IF($BA20>=21,"Transitioning (Proficient)",IF($BA20>=14,"Developing (Nearly Proficient)",IF($BA20>=7,"Emerging (Low Proficient)","Emerging (Not Proficient)")))),IF($BA$9=13,IF($BA20>=11,"At Grade Level (Highly Proficient)",IF($BA20>=8,"Transitioning (Proficient)",IF($BA20>=5,"Developing (Nearly Proficient)",IF($BA20>=3,"Emerging (Low Proficient)","Emerging (Not Proficient)")))),"")))) -> Transitioning (Proficient) | BD20: =IF($BA20<>0,IF($C$7="Grade 6",SUM(H20:J20)+SUM(M20:O20)+SUM(Q20:S20)+U20+V20+Z20+AB20+AF20+AJ20+SUM(AM20:AQ20)+AU20+AV20,IF($C$7="Grade 5",SUM(H20:J20)+SUM(M20:O20)+SUM(Q20:S20)+U20+V20+Z20+AB20+AF20,IF($C$7="Grade 4",SUM(H20:J20)+SUM(M20:O20)+SUM(Q20:S20),0))),0) -> 6 | BE20: =IF($BA20<>0,IF($C$7="Grade 6",L20+P20+T20+SUM(W20:Y20)+AA20+SUM(AC20:AE20)+AG20+AI20+AT20,IF($C$7="Grade 5",L20+P20+T20+SUM(W20:Y20)+AA20+SUM(AC20:AE20)+AG20,IF($C$7="Grade 4",L20+P20,0))),0) -> 2 | BF20: =IF($BA20<>0,IF($C$7="Grade 6",K20+AH20+AK20+AL20+AR20+AS20+AW20,IF($C$7="Grade 5",K20+AH20,IF($C$7="Grade 4",K20,0))),0) -> 1 | BG20: =IF($BA20<>0,IF($C$7="Grade 6",H20+K20+M20+S20+T20+V20+W20+Z20+AB20+AC20+SUM(AH20:AJ20)+AN20+AP20+AQ20+AS20+AT20,IF($C$7="Grade 5",H20+K20+M20+S20+T20+V20+W20+Z20+AB20+AC20+AH20,IF($C$7="Grade 4",H20+K20+M20+S20,0))),0) -> 3 | BH20: =IF($BA20<>0,IF($C$7="Grade 6",I20+J20+L20+N20+O20+R20+U20+Y20+SUM(AE20:AG20)+AK20+AM20+AO20+AU20+AV20+AW20,IF($C$7="Grade 5",I20+J20+L20+N20+O20+R20+U20+Y20+SUM(AE20:AG20),IF($C$7="Grade 4",I20+J20+L20+N20+O20+R20,0))),0) -> 4 | BI20: =IF($BA20<>0,IF($C$7="Grade 6",P20+Q20+X20+AA20+AD20+AL20+AR20,IF($C$7="Grade 5",P20+Q20+X20+AA20+AD20,IF($C$7="Grade 4",P20+Q20,0))),0) -> 2 | BN20: =IF($BA20<>"",IF(BD20/BN$9>=0.75,1,0),"") -> 0 | BO20: =IF($BA20<>"",IF(BE20/BO$9>=0.75,1,0),"") -> 0 | BP20: =IF($BA20<>"",IF(BF20/BP$9>=0.75,1,0),"") -> 1 | BQ20: =IF($BA20<>"",IF(SUM(BD20:BF20)/BQ$9>=0.75,1,0),"") -> 0 | BR20: =IF($BA20<>"",IF(BG20/BR$9>=0.75,1,0),"") -> 1 | BS20: =IF($BA20<>"",IF(BH20/BS$9>=0.75,1,0),"") -> 0 | BT20: =IF($BA20<>"",IF(BI20/BT$9>=0.75,1,0),"") -> 1 | BU20: =IF($BA20<>"",IF(SUM(BG20:BI20)/BU$9>=0.75,1,0),"") -> 0
A21: 12 | B21: 117443210024 | C21: LABANZA,DANIEL REY, PALACIO | D21: Male | E21: 42325 | F21: 46084 | G21: =IF(C21<>"",(F21-E21)/365,"") -> 10.29863 | H21: 1 | I21: 0 | J21: 0 | K21: 1 | L21: 1 | M21: 1 | N21: 0 | O21: 1 | P21: 1 | Q21: 1 | R21: 0 | S21: 0 | T21: 0 | U21: 1 | V21: 1 | W21: 0 | X21: 0 | Y21: 0 | Z21: 1 | AA21: 1 | AB21: 0 | AC21: 1 | AD21: 0 | AE21: 0 | AF21: 1 | AG21: 0 | AH21: 0 | AI21: 0 | AJ21: 0 | AK21: 0 | AL21: 0 | AM21: 0 | AN21: 0 | AO21: 0 | AP21: 0 | AQ21: 0 | AR21: 0 | AS21: 0 | AT21: 0 | AU21: 0 | AV21: 0 | AW21: 0 | AX21: =IF($C21<>"",SUM(H21:S21),"") -> 7 | AY21: =IF($C21<>"",SUM(T21:AH21),"") -> 6 | AZ21: =IF($C21<>"",SUM(AI21:AW21),"") -> 0 | BA21: =_xlfn.IFNA(IF(AND($C$4<>"",$C$7<>"",C21<>""),IF($C$7="Grade 4",AX21,IF($C$7="Grade 5",AX21+AY21,IF($C$7="Grade 6",AX21+AY21+AZ21,0))),""),"") -> 7 | BB21: =IFERROR(IF(AND(BA21>0,C21<>""),BA21/$BA$9,""),"") -> 0.53846154 | BC21: =IF($BA21="","",IF($BA$9=50,IF($BA21>=45,"At Grade Level (Highly Proficient)",IF($BA21>=39,"Transitioning (Proficient)",IF($BA21>=29,"Developing (Nearly Proficient)",IF($BA21>=15,"Emerging (Low Proficient)","Emerging (Not Proficient)")))),IF($BA$9=32,IF($BA21>=27,"At Grade Level (Highly Proficient)",IF($BA21>=21,"Transitioning (Proficient)",IF($BA21>=14,"Developing (Nearly Proficient)",IF($BA21>=7,"Emerging (Low Proficient)","Emerging (Not Proficient)")))),IF($BA$9=13,IF($BA21>=11,"At Grade Level (Highly Proficient)",IF($BA21>=8,"Transitioning (Proficient)",IF($BA21>=5,"Developing (Nearly Proficient)",IF($BA21>=3,"Emerging (Low Proficient)","Emerging (Not Proficient)")))),"")))) -> Developing (Nearly Proficient) | BD21: =IF($BA21<>0,IF($C$7="Grade 6",SUM(H21:J21)+SUM(M21:O21)+SUM(Q21:S21)+U21+V21+Z21+AB21+AF21+AJ21+SUM(AM21:AQ21)+AU21+AV21,IF($C$7="Grade 5",SUM(H21:J21)+SUM(M21:O21)+SUM(Q21:S21)+U21+V21+Z21+AB21+AF21,IF($C$7="Grade 4",SUM(H21:J21)+SUM(M21:O21)+SUM(Q21:S21),0))),0) -> 4 | BE21: =IF($BA21<>0,IF($C$7="Grade 6",L21+P21+T21+SUM(W21:Y21)+AA21+SUM(AC21:AE21)+AG21+AI21+AT21,IF($C$7="Grade 5",L21+P21+T21+SUM(W21:Y21)+AA21+SUM(AC21:AE21)+AG21,IF($C$7="Grade 4",L21+P21,0))),0) -> 2 | BF21: =IF($BA21<>0,IF($C$7="Grade 6",K21+AH21+AK21+AL21+AR21+AS21+AW21,IF($C$7="Grade 5",K21+AH21,IF($C$7="Grade 4",K21,0))),0) -> 1 | BG21: =IF($BA21<>0,IF($C$7="Grade 6",H21+K21+M21+S21+T21+V21+W21+Z21+AB21+AC21+SUM(AH21:AJ21)+AN21+AP21+AQ21+AS21+AT21,IF($C$7="Grade 5",H21+K21+M21+S21+T21+V21+W21+Z21+AB21+AC21+AH21,IF($C$7="Grade 4",H21+K21+M21+S21,0))),0) -> 3 | BH21: =IF($BA21<>0,IF($C$7="Grade 6",I21+J21+L21+N21+O21+R21+U21+Y21+SUM(AE21:AG21)+AK21+AM21+AO21+AU21+AV21+AW21,IF($C$7="Grade 5",I21+J21+L21+N21+O21+R21+U21+Y21+SUM(AE21:AG21),IF($C$7="Grade 4",I21+J21+L21+N21+O21+R21,0))),0) -> 2 | BI21: =IF($BA21<>0,IF($C$7="Grade 6",P21+Q21+X21+AA21+AD21+AL21+AR21,IF($C$7="Grade 5",P21+Q21+X21+AA21+AD21,IF($C$7="Grade 4",P21+Q21,0))),0) -> 2 | BN21: =IF($BA21<>"",IF(BD21/BN$9>=0.75,1,0),"") -> 0 | BO21: =IF($BA21<>"",IF(BE21/BO$9>=0.75,1,0),"") -> 0 | BP21: =IF($BA21<>"",IF(BF21/BP$9>=0.75,1,0),"") -> 1 | BQ21: =IF($BA21<>"",IF(SUM(BD21:BF21)/BQ$9>=0.75,1,0),"") -> 0 | BR21: =IF($BA21<>"",IF(BG21/BR$9>=0.75,1,0),"") -> 1 | BS21: =IF($BA21<>"",IF(BH21/BS$9>=0.75,1,0),"") -> 0 | BT21: =IF($BA21<>"",IF(BI21/BT$9>=0.75,1,0),"") -> 1 | BU21: =IF($BA21<>"",IF(SUM(BG21:BI21)/BU$9>=0.75,1,0),"") -> 0
A22: 13 | B22: 117443210013 | C22: LLAGOSO,RENS, PADERNAL | D22: Male | E22: 42279 | F22: 46085 | G22: =IF(C22<>"",(F22-E22)/365,"") -> 10.427397 | H22: 1 | I22: 0 | J22: 1 | K22: 0 | L22: 0 | M22: 0 | N22: 0 | O22: 1 | P22: 1 | Q22: 0 | R22: 0 | S22: 0 | T22: 0 | U22: 0 | V22: 0 | W22: 0 | X22: 0 | Y22: 0 | Z22: 1 | AA22: 1 | AB22: 0 | AC22: 0 | AD22: 0 | AE22: 0 | AF22: 0 | AG22: 0 | AH22: 0 | AI22: 0 | AJ22: 0 | AK22: 0 | AL22: 0 | AM22: 0 | AN22: 0 | AO22: 0 | AP22: 1 | AQ22: 0 | AR22: 0 | AS22: 0 | AT22: 0 | AU22: 0 | AV22: 0 | AW22: 1 | AX22: =IF($C22<>"",SUM(H22:S22),"") -> 4 | AY22: =IF($C22<>"",SUM(T22:AH22),"") -> 2 | AZ22: =IF($C22<>"",SUM(AI22:AW22),"") -> 2 | BA22: =_xlfn.IFNA(IF(AND($C$4<>"",$C$7<>"",C22<>""),IF($C$7="Grade 4",AX22,IF($C$7="Grade 5",AX22+AY22,IF($C$7="Grade 6",AX22+AY22+AZ22,0))),""),"") -> 4 | BB22: =IFERROR(IF(AND(BA22>0,C22<>""),BA22/$BA$9,""),"") -> 0.30769231 | BC22: =IF($BA22="","",IF($BA$9=50,IF($BA22>=45,"At Grade Level (Highly Proficient)",IF($BA22>=39,"Transitioning (Proficient)",IF($BA22>=29,"Developing (Nearly Proficient)",IF($BA22>=15,"Emerging (Low Proficient)","Emerging (Not Proficient)")))),IF($BA$9=32,IF($BA22>=27,"At Grade Level (Highly Proficient)",IF($BA22>=21,"Transitioning (Proficient)",IF($BA22>=14,"Developing (Nearly Proficient)",IF($BA22>=7,"Emerging (Low Proficient)","Emerging (Not Proficient)")))),IF($BA$9=13,IF($BA22>=11,"At Grade Level (Highly Proficient)",IF($BA22>=8,"Transitioning (Proficient)",IF($BA22>=5,"Developing (Nearly Proficient)",IF($BA22>=3,"Emerging (Low Proficient)","Emerging (Not Proficient)")))),"")))) -> Emerging (Low Proficient) | BD22: =IF($BA22<>0,IF($C$7="Grade 6",SUM(H22:J22)+SUM(M22:O22)+SUM(Q22:S22)+U22+V22+Z22+AB22+AF22+AJ22+SUM(AM22:AQ22)+AU22+AV22,IF($C$7="Grade 5",SUM(H22:J22)+SUM(M22:O22)+SUM(Q22:S22)+U22+V22+Z22+AB22+AF22,IF($C$7="Grade 4",SUM(H22:J22)+SUM(M22:O22)+SUM(Q22:S22),0))),0) -> 3 | BE22: =IF($BA22<>0,IF($C$7="Grade 6",L22+P22+T22+SUM(W22:Y22)+AA22+SUM(AC22:AE22)+AG22+AI22+AT22,IF($C$7="Grade 5",L22+P22+T22+SUM(W22:Y22)+AA22+SUM(AC22:AE22)+AG22,IF($C$7="Grade 4",L22+P22,0))),0) -> 1 | BF22: =IF($BA22<>0,IF($C$7="Grade 6",K22+AH22+AK22+AL22+AR22+AS22+AW22,IF($C$7="Grade 5",K22+AH22,IF($C$7="Grade 4",K22,0))),0) -> 0 | BG22: =IF($BA22<>0,IF($C$7="Grade 6",H22+K22+M22+S22+T22+V22+W22+Z22+AB22+AC22+SUM(AH22:AJ22)+AN22+AP22+AQ22+AS22+AT22,IF($C$7="Grade 5",H22+K22+M22+S22+T22+V22+W22+Z22+AB22+AC22+AH22,IF($C$7="Grade 4",H22+K22+M22+S22,0))),0) -> 1 | BH22: =IF($BA22<>0,IF($C$7="Grade 6",I22+J22+L22+N22+O22+R22+U22+Y22+SUM(AE22:AG22)+AK22+AM22+AO22+AU22+AV22+AW22,IF($C$7="Grade 5",I22+J22+L22+N22+O22+R22+U22+Y22+SUM(AE22:AG22),IF($C$7="Grade 4",I22+J22+L22+N22+O22+R22,0))),0) -> 2 | BI22: =IF($BA22<>0,IF($C$7="Grade 6",P22+Q22+X22+AA22+AD22+AL22+AR22,IF($C$7="Grade 5",P22+Q22+X22+AA22+AD22,IF($C$7="Grade 4",P22+Q22,0))),0) -> 1 | BN22: =IF($BA22<>"",IF(BD22/BN$9>=0.75,1,0),"") -> 0 | BO22: =IF($BA22<>"",IF(BE22/BO$9>=0.75,1,0),"") -> 0 | BP22: =IF($BA22<>"",IF(BF22/BP$9>=0.75,1,0),"") -> 0 | BQ22: =IF($BA22<>"",IF(SUM(BD22:BF22)/BQ$9>=0.75,1,0),"") -> 0 | BR22: =IF($BA22<>"",IF(BG22/BR$9>=0.75,1,0),"") -> 0 | BS22: =IF($BA22<>"",IF(BH22/BS$9>=0.75,1,0),"") -> 0 | BT22: =IF($BA22<>"",IF(BI22/BT$9>=0.75,1,0),"") -> 0 | BU22: =IF($BA22<>"",IF(SUM(BG22:BI22)/BU$9>=0.75,1,0),"") -> 0
A23: 14 | B23: 117447210077 | C23: PATRICIO,NOEL, JR ESPINOSA | D23: Male | E23: 42638 | F23: 46085 | G23: =IF(C23<>"",(F23-E23)/365,"") -> 9.4438356 | H23: 0 | I23: 1 | J23: 0 | K23: 0 | L23: 0 | M23: 0 | N23: 1 | O23: 0 | P23: 0 | Q23: 0 | R23: 0 | S23: 0 | T23: 0 | U23: 0 | V23: 0 | W23: 0 | X23: 0 | Y23: 0 | Z23: 0 | AA23: 0 | AB23: 0 | AC23: 0 | AD23: 0 | AE23: 0 | AF23: 0 | AG23: 0 | AH23: 0 | AI23: 0 | AJ23: 0 | AK23: 0 | AL23: 0 | AM23: 0 | AN23: 0 | AO23: 0 | AP23: 0 | AQ23: 0 | AR23: 0 | AS23: 0 | AT23: 0 | AU23: 0 | AV23: 0 | AW23: 1 | AX23: =IF($C23<>"",SUM(H23:S23),"") -> 2 | AY23: =IF($C23<>"",SUM(T23:AH23),"") -> 0 | AZ23: =IF($C23<>"",SUM(AI23:AW23),"") -> 1 | BA23: =_xlfn.IFNA(IF(AND($C$4<>"",$C$7<>"",C23<>""),IF($C$7="Grade 4",AX23,IF($C$7="Grade 5",AX23+AY23,IF($C$7="Grade 6",AX23+AY23+AZ23,0))),""),"") -> 2 | BB23: =IFERROR(IF(AND(BA23>0,C23<>""),BA23/$BA$9,""),"") -> 0.15384615 | BC23: =IF($BA23="","",IF($BA$9=50,IF($BA23>=45,"At Grade Level (Highly Proficient)",IF($BA23>=39,"Transitioning (Proficient)",IF($BA23>=29,"Developing (Nearly Proficient)",IF($BA23>=15,"Emerging (Low Proficient)","Emerging (Not Proficient)")))),IF($BA$9=32,IF($BA23>=27,"At Grade Level (Highly Proficient)",IF($BA23>=21,"Transitioning (Proficient)",IF($BA23>=14,"Developing (Nearly Proficient)",IF($BA23>=7,"Emerging (Low Proficient)","Emerging (Not Proficient)")))),IF($BA$9=13,IF($BA23>=11,"At Grade Level (Highly Proficient)",IF($BA23>=8,"Transitioning (Proficient)",IF($BA23>=5,"Developing (Nearly Proficient)",IF($BA23>=3,"Emerging (Low Proficient)","Emerging (Not Proficient)")))),"")))) -> Emerging (Not Proficient) | BD23: =IF($BA23<>0,IF($C$7="Grade 6",SUM(H23:J23)+SUM(M23:O23)+SUM(Q23:S23)+U23+V23+Z23+AB23+AF23+AJ23+SUM(AM23:AQ23)+AU23+AV23,IF($C$7="Grade 5",SUM(H23:J23)+SUM(M23:O23)+SUM(Q23:S23)+U23+V23+Z23+AB23+AF23,IF($C$7="Grade 4",SUM(H23:J23)+SUM(M23:O23)+SUM(Q23:S23),0))),0) -> 2 | BE23: =IF($BA23<>0,IF($C$7="Grade 6",L23+P23+T23+SUM(W23:Y23)+AA23+SUM(AC23:AE23)+AG23+AI23+AT23,IF($C$7="Grade 5",L23+P23+T23+SUM(W23:Y23)+AA23+SUM(AC23:AE23)+AG23,IF($C$7="Grade 4",L23+P23,0))),0) -> 0 | BF23: =IF($BA23<>0,IF($C$7="Grade 6",K23+AH23+AK23+AL23+AR23+AS23+AW23,IF($C$7="Grade 5",K23+AH23,IF($C$7="Grade 4",K23,0))),0) -> 0 | BG23: =IF($BA23<>0,IF($C$7="Grade 6",H23+K23+M23+S23+T23+V23+W23+Z23+AB23+AC23+SUM(AH23:AJ23)+AN23+AP23+AQ23+AS23+AT23,IF($C$7="Grade 5",H23+K23+M23+S23+T23+V23+W23+Z23+AB23+AC23+AH23,IF($C$7="Grade 4",H23+K23+M23+S23,0))),0) -> 0 | BH23: =IF($BA23<>0,IF($C$7="Grade 6",I23+J23+L23+N23+O23+R23+U23+Y23+SUM(AE23:AG23)+AK23+AM23+AO23+AU23+AV23+AW23,IF($C$7="Grade 5",I23+J23+L23+N23+O23+R23+U23+Y23+SUM(AE23:AG23),IF($C$7="Grade 4",I23+J23+L23+N23+O23+R23,0))),0) -> 2 | BI23: =IF($BA23<>0,IF($C$7="Grade 6",P23+Q23+X23+AA23+AD23+AL23+AR23,IF($C$7="Grade 5",P23+Q23+X23+AA23+AD23,IF($C$7="Grade 4",P23+Q23,0))),0) -> 0 | BN23: =IF($BA23<>"",IF(BD23/BN$9>=0.75,1,0),"") -> 0 | BO23: =IF($BA23<>"",IF(BE23/BO$9>=0.75,1,0),"") -> 0 | BP23: =IF($BA23<>"",IF(BF23/BP$9>=0.75,1,0),"") -> 0 | BQ23: =IF($BA23<>"",IF(SUM(BD23:BF23)/BQ$9>=0.75,1,0),"") -> 0 | BR23: =IF($BA23<>"",IF(BG23/BR$9>=0.75,1,0),"") -> 0 | BS23: =IF($BA23<>"",IF(BH23/BS$9>=0.75,1,0),"") -> 0 | BT23: =IF($BA23<>"",IF(BI23/BT$9>=0.75,1,0),"") -> 0 | BU23: =IF($BA23<>"",IF(SUM(BG23:BI23)/BU$9>=0.75,1,0),"") -> 0
A24: 15 | B24: 117443210015 | C24: ABAY,QUEENSIE ANNE, - | D24: Female | E24: 42391 | F24: 46085 | G24: =IF(C24<>"",(F24-E24)/365,"") -> 10.120548 | H24: 1 | I24: 0 | J24: 1 | K24: 0 | L24: 0 | M24: 1 | N24: 0 | O24: 1 | P24: 1 | Q24: 0 | R24: 1 | S24: 0 | T24: 0 | U24: 1 | V24: 0 | W24: 0 | X24: 0 | Y24: 0 | Z24: 0 | AA24: 1 | AB24: 0 | AC24: 1 | AD24: 0 | AE24: 0 | AF24: 0 | AG24: 0 | AH24: 1 | AI24: 1 | AJ24: 0 | AK24: 0 | AL24: 0 | AM24: 0 | AN24: 0 | AO24: 0 | AP24: 1 | AQ24: 1 | AR24: 0 | AS24: 1 | AT24: 0 | AU24: 0 | AV24: 0 | AW24: 0 | AX24: =IF($C24<>"",SUM(H24:S24),"") -> 6 | AY24: =IF($C24<>"",SUM(T24:AH24),"") -> 4 | AZ24: =IF($C24<>"",SUM(AI24:AW24),"") -> 4 | BA24: =_xlfn.IFNA(IF(AND($C$4<>"",$C$7<>"",C24<>""),IF($C$7="Grade 4",AX24,IF($C$7="Grade 5",AX24+AY24,IF($C$7="Grade 6",AX24+AY24+AZ24,0))),""),"") -> 6 | BB24: =IFERROR(IF(AND(BA24>0,C24<>""),BA24/$BA$9,""),"") -> 0.46153846 | BC24: =IF($BA24="","",IF($BA$9=50,IF($BA24>=45,"At Grade Level (Highly Proficient)",IF($BA24>=39,"Transitioning (Proficient)",IF($BA24>=29,"Developing (Nearly Proficient)",IF($BA24>=15,"Emerging (Low Proficient)","Emerging (Not Proficient)")))),IF($BA$9=32,IF($BA24>=27,"At Grade Level (Highly Proficient)",IF($BA24>=21,"Transitioning (Proficient)",IF($BA24>=14,"Developing (Nearly Proficient)",IF($BA24>=7,"Emerging (Low Proficient)","Emerging (Not Proficient)")))),IF($BA$9=13,IF($BA24>=11,"At Grade Level (Highly Proficient)",IF($BA24>=8,"Transitioning (Proficient)",IF($BA24>=5,"Developing (Nearly Proficient)",IF($BA24>=3,"Emerging (Low Proficient)","Emerging (Not Proficient)")))),"")))) -> Developing (Nearly Proficient) | BD24: =IF($BA24<>0,IF($C$7="Grade 6",SUM(H24:J24)+SUM(M24:O24)+SUM(Q24:S24)+U24+V24+Z24+AB24+AF24+AJ24+SUM(AM24:AQ24)+AU24+AV24,IF($C$7="Grade 5",SUM(H24:J24)+SUM(M24:O24)+SUM(Q24:S24)+U24+V24+Z24+AB24+AF24,IF($C$7="Grade 4",SUM(H24:J24)+SUM(M24:O24)+SUM(Q24:S24),0))),0) -> 5 | BE24: =IF($BA24<>0,IF($C$7="Grade 6",L24+P24+T24+SUM(W24:Y24)+AA24+SUM(AC24:AE24)+AG24+AI24+AT24,IF($C$7="Grade 5",L24+P24+T24+SUM(W24:Y24)+AA24+SUM(AC24:AE24)+AG24,IF($C$7="Grade 4",L24+P24,0))),0) -> 1 | BF24: =IF($BA24<>0,IF($C$7="Grade 6",K24+AH24+AK24+AL24+AR24+AS24+AW24,IF($C$7="Grade 5",K24+AH24,IF($C$7="Grade 4",K24,0))),0) -> 0 | BG24: =IF($BA24<>0,IF($C$7="Grade 6",H24+K24+M24+S24+T24+V24+W24+Z24+AB24+AC24+SUM(AH24:AJ24)+AN24+AP24+AQ24+AS24+AT24,IF($C$7="Grade 5",H24+K24+M24+S24+T24+V24+W24+Z24+AB24+AC24+AH24,IF($C$7="Grade 4",H24+K24+M24+S24,0))),0) -> 2 | BH24: =IF($BA24<>0,IF($C$7="Grade 6",I24+J24+L24+N24+O24+R24+U24+Y24+SUM(AE24:AG24)+AK24+AM24+AO24+AU24+AV24+AW24,IF($C$7="Grade 5",I24+J24+L24+N24+O24+R24+U24+Y24+SUM(AE24:AG24),IF($C$7="Grade 4",I24+J24+L24+N24+O24+R24,0))),0) -> 3 | BI24: =IF($BA24<>0,IF($C$7="Grade 6",P24+Q24+X24+AA24+AD24+AL24+AR24,IF($C$7="Grade 5",P24+Q24+X24+AA24+AD24,IF($C$7="Grade 4",P24+Q24,0))),0) -> 1 | BN24: =IF($BA24<>"",IF(BD24/BN$9>=0.75,1,0),"") -> 0 | BO24: =IF($BA24<>"",IF(BE24/BO$9>=0.75,1,0),"") -> 0 | BP24: =IF($BA24<>"",IF(BF24/BP$9>=0.75,1,0),"") -> 0 | BQ24: =IF($BA24<>"",IF(SUM(BD24:BF24)/BQ$9>=0.75,1,0),"") -> 0 | BR24: =IF($BA24<>"",IF(BG24/BR$9>=0.75,1,0),"") -> 0 | BS24: =IF($BA24<>"",IF(BH24/BS$9>=0.75,1,0),"") -> 0 | BT24: =IF($BA24<>"",IF(BI24/BT$9>=0.75,1,0),"") -> 0 | BU24: =IF($BA24<>"",IF(SUM(BG24:BI24)/BU$9>=0.75,1,0),"") -> 0
A25: 16 | B25: 136651210213 | C25: ABRINILLO,AMANDA, SIASAT | D25: Female | E25: 42407 | F25: 46085 | G25: =IF(C25<>"",(F25-E25)/365,"") -> 10.076712 | H25: 1 | I25: 0 | J25: 1 | K25: 0 | L25: 0 | M25: 1 | N25: 0 | O25: 1 | P25: 1 | Q25: 0 | R25: 1 | S25: 1 | T25: 0 | U25: 1 | V25: 0 | W25: 0 | X25: 0 | Y25: 0 | Z25: 1 | AA25: 1 | AB25: 0 | AC25: 0 | AD25: 0 | AE25: 0 | AF25: 1 | AG25: 0 | AH25: 1 | AI25: 0 | AJ25: 1 | AK25: 0 | AL25: 0 | AM25: 0 | AN25: 0 | AO25: 0 | AP25: 1 | AQ25: 1 | AR25: 0 | AS25: 1 | AT25: 0 | AU25: 0 | AV25: 0 | AW25: 0 | AX25: =IF($C25<>"",SUM(H25:S25),"") -> 7 | AY25: =IF($C25<>"",SUM(T25:AH25),"") -> 5 | AZ25: =IF($C25<>"",SUM(AI25:AW25),"") -> 4 | BA25: =_xlfn.IFNA(IF(AND($C$4<>"",$C$7<>"",C25<>""),IF($C$7="Grade 4",AX25,IF($C$7="Grade 5",AX25+AY25,IF($C$7="Grade 6",AX25+AY25+AZ25,0))),""),"") -> 7 | BB25: =IFERROR(IF(AND(BA25>0,C25<>""),BA25/$BA$9,""),"") -> 0.53846154 | BC25: =IF($BA25="","",IF($BA$9=50,IF($BA25>=45,"At Grade Level (Highly Proficient)",IF($BA25>=39,"Transitioning (Proficient)",IF($BA25>=29,"Developing (Nearly Proficient)",IF($BA25>=15,"Emerging (Low Proficient)","Emerging (Not Proficient)")))),IF($BA$9=32,IF($BA25>=27,"At Grade Level (Highly Proficient)",IF($BA25>=21,"Transitioning (Proficient)",IF($BA25>=14,"Developing (Nearly Proficient)",IF($BA25>=7,"Emerging (Low Proficient)","Emerging (Not Proficient)")))),IF($BA$9=13,IF($BA25>=11,"At Grade Level (Highly Proficient)",IF($BA25>=8,"Transitioning (Proficient)",IF($BA25>=5,"Developing (Nearly Proficient)",IF($BA25>=3,"Emerging (Low Proficient)","Emerging (Not Proficient)")))),"")))) -> Developing (Nearly Proficient) | BD25: =IF($BA25<>0,IF($C$7="Grade 6",SUM(H25:J25)+SUM(M25:O25)+SUM(Q25:S25)+U25+V25+Z25+AB25+AF25+AJ25+SUM(AM25:AQ25)+AU25+AV25,IF($C$7="Grade 5",SUM(H25:J25)+SUM(M25:O25)+SUM(Q25:S25)+U25+V25+Z25+AB25+AF25,IF($C$7="Grade 4",SUM(H25:J25)+SUM(M25:O25)+SUM(Q25:S25),0))),0) -> 6 | BE25: =IF($BA25<>0,IF($C$7="Grade 6",L25+P25+T25+SUM(W25:Y25)+AA25+SUM(AC25:AE25)+AG25+AI25+AT25,IF($C$7="Grade 5",L25+P25+T25+SUM(W25:Y25)+AA25+SUM(AC25:AE25)+AG25,IF($C$7="Grade 4",L25+P25,0))),0) -> 1 | BF25: =IF($BA25<>0,IF($C$7="Grade 6",K25+AH25+AK25+AL25+AR25+AS25+AW25,IF($C$7="Grade 5",K25+AH25,IF($C$7="Grade 4",K25,0))),0) -> 0 | BG25: =IF($BA25<>0,IF($C$7="Grade 6",H25+K25+M25+S25+T25+V25+W25+Z25+AB25+AC25+SUM(AH25:AJ25)+AN25+AP25+AQ25+AS25+AT25,IF($C$7="Grade 5",H25+K25+M25+S25+T25+V25+W25+Z25+AB25+AC25+AH25,IF($C$7="Grade 4",H25+K25+M25+S25,0))),0) -> 3 | BH25: =IF($BA25<>0,IF($C$7="Grade 6",I25+J25+L25+N25+O25+R25+U25+Y25+SUM(AE25:AG25)+AK25+AM25+AO25+AU25+AV25+AW25,IF($C$7="Grade 5",I25+J25+L25+N25+O25+R25+U25+Y25+SUM(AE25:AG25),IF($C$7="Grade 4",I25+J25+L25+N25+O25+R25,0))),0) -> 3 | BI25: =IF($BA25<>0,IF($C$7="Grade 6",P25+Q25+X25+AA25+AD25+AL25+AR25,IF($C$7="Grade 5",P25+Q25+X25+AA25+AD25,IF($C$7="Grade 4",P25+Q25,0))),0) -> 1 | BN25: =IF($BA25<>"",IF(BD25/BN$9>=0.75,1,0),"") -> 0 | BO25: =IF($BA25<>"",IF(BE25/BO$9>=0.75,1,0),"") -> 0 | BP25: =IF($BA25<>"",IF(BF25/BP$9>=0.75,1,0),"") -> 0 | BQ25: =IF($BA25<>"",IF(SUM(BD25:BF25)/BQ$9>=0.75,1,0),"") -> 0 | BR25: =IF($BA25<>"",IF(BG25/BR$9>=0.75,1,0),"") -> 1 | BS25: =IF($BA25<>"",IF(BH25/BS$9>=0.75,1,0),"") -> 0 | BT25: =IF($BA25<>"",IF(BI25/BT$9>=0.75,1,0),"") -> 0 | BU25: =IF($BA25<>"",IF(SUM(BG25:BI25)/BU$9>=0.75,1,0),"") -> 0
